Workbook

Sheet Index
A1: f | B1: Dedicated Freight Corridor Corporation of India | L1: C & P Items
A2: Index | L2: Furniture Items
A3: Sr.No. | B3: Particular | C3: Page No. | D3: izkfIr Receipt | E3: LFkkukarj.k Transfer | F3: fuxZe Issues | G3: 'ks"k Balance | H3: Remarks | I3: QR | L3: Cash Imprest Items
A4: 1 | B4: Detonators | C4: 3001 | D4: ='3001'!E6 -> 1100 | E4: ='3001'!F6 -> 0 | F4: ='3001'!G6 -> 980 | G4: ='3001'!H6 -> 120 | H4: NOS. | I4: =_xlfn.IMAGE("https://quickchart.io/qr?text="&_xlfn.ENCODEURL("Sr No: "&#REF!&" | Item: "&#REF!&" | Page No: "&#REF!&" | Receipt: "&#REF!&" | Transfer: "&#REF!&" | Issues: "&#REF!&" | Balance: "&#REF!&" | Remarks: "&#REF!)) -> #REF!
A5: 2 | B5: Graphite Grease (IS: 408-202) | C5: 3005 | D5: ='3005'!E6 -> 1280 | E5: ='3005'!F6 -> 0 | F5: ='3005'!G6 -> 975 | G5: ='3005'!H6 -> 305 | H5: NOS. | I5: =_xlfn.IMAGE("https://quickchart.io/qr?text="&_xlfn.ENCODEURL("Sr No: "&#REF!&" | Item: "&#REF!&" | Page No: "&#REF!&" | Receipt: "&#REF!&" | Transfer: "&#REF!&" | Issues: "&#REF!&" | Balance: "&#REF!&" | Remarks: "&#REF!)) -> #REF!
A6: 3 | B6: Black OIL (used) | C6: 3008 | D6: ='3008'!E6 -> 200 | E6: ='3008'!F6 -> 0 | F6: ='3008'!G6 -> 100 | G6: ='3008'!H6 -> 100 | H6: NOS. | I6: =_xlfn.IMAGE("https://quickchart.io/qr?text="&_xlfn.ENCODEURL("Sr No: "&A4&" | Item: "&#REF!&" | Page No: "&C4&" | Receipt: "&D4&" | Transfer: "&E4&" | Issues: "&F4&" | Balance: "&G4&" | Remarks: "&H4)) -> #REF!
A7: 4 | B7: Water Bottle | C7: 3011 | D7: ='3011'!E6 -> 150 | E7: ='3011'!F6 -> 0 | F7: ='3011'!G6 -> 123 | G7: ='3011'!H6 -> 27 | H7: NOS. | I7: =_xlfn.IMAGE("https://quickchart.io/qr?text="&_xlfn.ENCODEURL("Sr No: "&A5&" | Item: "&B5&" | Page No: "&C5&" | Receipt: "&D5&" | Transfer: "&E5&" | Issues: "&F5&" | Balance: "&G5&" | Remarks: "&H5)) -> #VALUE!
A8: 5 | B8: Mobile Dustbin | C8: 3015 | D8: ='3015'!E6 -> 6 | E8: ='3015'!F6 -> 0 | F8: ='3015'!G6 -> 2 | G8: ='3015'!H6 -> 4 | H8: NOS. | I8: =_xlfn.IMAGE("https://quickchart.io/qr?text="&_xlfn.ENCODEURL("Sr No: "&A6&" | Item: "&B6&" | Page No: "&C6&" | Receipt: "&D6&" | Transfer: "&E6&" | Issues: "&F6&" | Balance: "&G6&" | Remarks: "&H6)) -> #VALUE!
A9: 6 | B9: Alumino-Thermic portion 60kg(Rail) | C9: 3017 | D9: ='3017'!E6 -> 46 | E9: ='3017'!F6 -> 0 | F9: ='3017'!G6 -> 35 | G9: ='3017'!H6 -> 11 | H9: NOS. | I9: =_xlfn.IMAGE("https://quickchart.io/qr?text="&_xlfn.ENCODEURL("Sr No: "&A7&" | Item: "&B7&" | Page No: "&C7&" | Receipt: "&D7&" | Transfer: "&E7&" | Issues: "&F7&" | Balance: "&G7&" | Remarks: "&H7)) -> #VALUE!
A10: 7 | B10: Prelerbricated Dry Mould -Three | C10: 3020 | D10: ='3020'!E6 -> 48 | E10: ='3020'!F6 -> 0 | F10: ='3020'!G6 -> 40 | G10: ='3020'!H6 -> 8 | H10: NOS. | I10: =_xlfn.IMAGE("https://quickchart.io/qr?text="&_xlfn.ENCODEURL("Sr No: "&A8&" | Item: "&B8&" | Page No: "&C8&" | Receipt: "&D8&" | Transfer: "&E8&" | Issues: "&F8&" | Balance: "&G8&" | Remarks: "&H8)) -> #VALUE!
A11: 8 | B11: Single shot Crucible | C11: 3023 | D11: ='3023'!E6 -> 46 | E11: ='3023'!F6 -> 0 | F11: ='3023'!G6 -> 36 | G11: ='3023'!H6 -> 10 | H11: NOS. | I11: =_xlfn.IMAGE("https://quickchart.io/qr?text="&_xlfn.ENCODEURL("Sr No: "&A9&" | Item: "&B9&" | Page No: "&C9&" | Receipt: "&D9&" | Transfer: "&E9&" | Issues: "&F9&" | Balance: "&G9&" | Remarks: "&H9)) -> #VALUE!
A12: 9 | B12: Luting Sand | C12: 3026 | D12: ='3026'!E6 -> 51 | E12: ='3026'!F6 -> 0 | F12: ='3026'!G6 -> 48 | G12: ='3026'!H6 -> 3 | H12: NOS. | I12: =_xlfn.IMAGE("https://quickchart.io/qr?text="&_xlfn.ENCODEURL("Sr No: "&A10&" | Item: "&B10&" | Page No: "&C10&" | Receipt: "&D10&" | Transfer: "&E10&" | Issues: "&F10&" | Balance: "&G10&" | Remarks: "&H10)) -> #VALUE!
A13: 10 | B13: Igniter | C13: ='[1]Igniter '!I3 -> 3028 | D13: ='3028'!E6 -> 46 | E13: ='3028'!F6 -> 0 | F13: ='3028'!G6 -> 44 | G13: ='3028'!H6 -> 2 | H13: NOS. | I13: =_xlfn.IMAGE("https://quickchart.io/qr?text="&_xlfn.ENCODEURL("Sr No: "&A11&" | Item: "&B15&" | Page No: "&C11&" | Receipt: "&D11&" | Transfer: "&E11&" | Issues: "&F11&" | Balance: "&G11&" | Remarks: "&H11)) -> #VALUE!
A14: 11 | B14: Rail Grinding Stone ( weld Grin | C14: 3030 | D14: ='3030'!E6 -> 28 | E14: ='3030'!F6 -> 0 | F14: ='3030'!G6 -> 21 | G14: ='3030'!H6 -> 7 | H14: NOS. | I14: =_xlfn.IMAGE("https://quickchart.io/qr?text="&_xlfn.ENCODEURL("Sr No: "&A12&" | Item: "&B14&" | Page No: "&C12&" | Receipt: "&D12&" | Transfer: "&E12&" | Issues: "&F12&" | Balance: "&G12&" | Remarks: "&H12)) -> #VALUE!
A15: 12 | B15: Wooden Block | C15: 3033 | D15: ='3033'!E6 -> 250 | E15: ='3033'!F6 -> 0 | F15: ='3033'!G6 -> 203 | G15: ='3033'!H6 -> 47 | H15: NOS. | I15: =_xlfn.IMAGE("https://quickchart.io/qr?text="&_xlfn.ENCODEURL("Sr No: "&A13&" | Item: "&B13&" | Page No: "&C13&" | Receipt: "&D13&" | Transfer: "&E13&" | Issues: "&F13&" | Balance: "&G13&" | Remarks: "&H13)) -> #VALUE!
A16: 13 | B16: Sythtic Lubricating Grease (Lithum) | C16: 3036 | D16: ='3036'!E6 -> 546 | E16: ='3036'!F6 -> 0 | F16: ='3036'!G6 -> 364 | G16: ='3036'!H6 -> 182 | H16: NOS. | I16: =_xlfn.IMAGE("https://quickchart.io/qr?text="&_xlfn.ENCODEURL("Sr No: "&A14&" | Item: "&B12&" | Page No: "&C14&" | Receipt: "&D14&" | Transfer: "&E14&" | Issues: "&F14&" | Balance: "&G14&" | Remarks: "&H14)) -> #VALUE!
A17: 14 | B17: Herbicide | C17: 3038 | D17: ='3038'!E6 -> 520 | E17: ='3038'!F6 -> 0 | F17: ='3038'!G6 -> 366 | G17: ='3038'!H6 -> 154 | H17: NOS. | I17: =_xlfn.IMAGE("https://quickchart.io/qr?text="&_xlfn.ENCODEURL("Sr No: "&A15&" | Item: "&B11&" | Page No: "&C15&" | Receipt: "&D15&" | Transfer: "&E15&" | Issues: "&F15&" | Balance: "&G15&" | Remarks: "&H15)) -> #VALUE!
A18: 15 | B18: Safety Jacket | C18: 3047 | D18: ='3047'!E6 -> 300 | E18: ='3047'!F6 -> 0 | F18: ='3047'!G6 -> 255 | G18: ='3047'!H6 -> 45 | H18: NOS. | I18: =_xlfn.IMAGE("https://quickchart.io/qr?text="&_xlfn.ENCODEURL("Sr No: "&A16&" | Item: "&B16&" | Page No: "&C16&" | Receipt: "&D16&" | Transfer: "&E16&" | Issues: "&F16&" | Balance: "&G16&" | Remarks: "&H16)) -> #VALUE!
A19: 16 | B19: Empty goney bags (Earth bag) | C19: 3049 | D19: ='3049'!E6 -> 6300 | E19: ='3049'!F6 -> 0 | F19: ='3049'!G6 -> 1300 | G19: ='3049'!H6 -> 5000 | H19: NOS. | I19: =_xlfn.IMAGE("https://quickchart.io/qr?text="&_xlfn.ENCODEURL("Sr No: "&A17&" | Item: "&B17&" | Page No: "&C17&" | Receipt: "&D17&" | Transfer: "&E17&" | Issues: "&F17&" | Balance: "&G17&" | Remarks: "&H17)) -> #VALUE!
A20: 17 | B20: Wooden Block For Check Rail | C20: 3051 | D20: ='3051'!E6 -> 50 | E20: ='3051'!F6 -> 0 | F20: ='3051'!G6 -> 32 | G20: ='3051'!H6 -> 18 | H20: NOS. | I20: =_xlfn.IMAGE("https://quickchart.io/qr?text="&_xlfn.ENCODEURL("Sr No: "&A18&" | Item: "&B4&" | Page No: "&C18&" | Receipt: "&D18&" | Transfer: "&E18&" | Issues: "&F18&" | Balance: "&G18&" | Remarks: "&H18)) -> #VALUE!
A21: 18 | B21: Patrolman/Handheld rechageable Torch | C21: 3052 | D21: ='3052'!E6 -> 150 | E21: ='3052'!F6 -> 0 | F21: ='3052'!G6 -> 150 | G21: ='3052'!H6 -> 0 | H21: NOS. | I21: =_xlfn.IMAGE("https://quickchart.io/qr?text="&_xlfn.ENCODEURL("Sr No: "&A19&" | Item: "&B19&" | Page No: "&C19&" | Receipt: "&D19&" | Transfer: "&E19&" | Issues: "&F19&" | Balance: "&G19&" | Remarks: "&H19)) -> #VALUE!
A22: 19 | B22: Dragon Torch | C22: 3056 | D22: ='3056'!E6 -> 12 | E22: ='3056'!F6 -> 0 | F22: ='3056'!G6 -> 12 | G22: ='3056'!H6 -> 0 | H22: NOS. | I22: =_xlfn.IMAGE("https://quickchart.io/qr?text="&_xlfn.ENCODEURL("Sr No: "&A20&" | Item: "&B20&" | Page No: "&C20&" | Receipt: "&D20&" | Transfer: "&E20&" | Issues: "&F20&" | Balance: "&G20&" | Remarks: "&H20)) -> #VALUE!
A23: 20 | B23: Umrella | C23: 3057 | D23: ='3057'!E6 -> 25 | E23: ='3057'!F6 -> 0 | F23: ='3057'!G6 -> 21 | G23: ='3057'!H6 -> 4 | H23: NOS. | I23: =_xlfn.IMAGE("https://quickchart.io/qr?text="&_xlfn.ENCODEURL("Sr No: "&A21&" | Item: "&B21&" | Page No: "&C21&" | Receipt: "&D21&" | Transfer: "&E21&" | Issues: "&F21&" | Balance: "&G21&" | Remarks: "&H21)) -> #VALUE!
A24: 21 | B24: Banner Flage | C24: 3059 | D24: ='3059'!E6 -> 50 | E24: ='3059'!F6 -> 0 | F24: ='3059'!G6 -> 27 | G24: ='3059'!H6 -> 23 | H24: NOS. | I24: =_xlfn.IMAGE("https://quickchart.io/qr?text="&_xlfn.ENCODEURL("Sr No: "&A22&" | Item: "&B22&" | Page No: "&C22&" | Receipt: "&D22&" | Transfer: "&E22&" | Issues: "&F22&" | Balance: "&G22&" | Remarks: "&H22)) -> #VALUE!
A25: 22 | B25: Keyman Bag | C25: 3061 | D25: ='3061'!E6 -> 150 | E25: ='3061'!F6 -> 0 | F25: ='3061'!G6 -> 103 | G25: ='3061'!H6 -> 47 | H25: NOS.
A26: 23 | B26: Tri color Troch | C26: 3064 | D26: ='3064'!E6 -> 100 | E26: ='3064'!F6 -> 0 | F26: ='3064'!G6 -> 95 | G26: ='3064'!H6 -> 5 | H26: NOS.
A27: 24 | B27: HS Flag Red | C27: 3067 | D27: ='3067'!E6 -> 300 | E27: ='3067'!F6 -> 0 | F27: ='3067'!G6 -> 244 | G27: ='3067'!H6 -> 56 | H27: NOS.
A28: 25 | B28: HS Flag Green | C28: 3070 | D28: ='3070'!E7 -> 250 | E28: ='3070'!F7 -> 0 | F28: ='3070'!G7 -> 165 | G28: ='3070'!H7 -> 85 | H28: NOS.
A29: 26 | B29: Rail Disc Cutter Wheel Stone | C29: 3073 | D29: ='3073'!E6 -> 100 | E29: ='3073'!F6 -> 0 | F29: ='3073'!G6 -> 95 | G29: ='3073'!H6 -> 5 | H29: NOS.
A30: 27 | D30: ='[1]Rail Disc cutter wheel stone '!E12 -> 0 | E30: ='[1]Rail Disc cutter wheel stone '!F12 -> 0 | F30: ='[1]Rail Disc cutter wheel stone '!G12 -> 0 | G30: ='[1]Rail Disc cutter wheel stone '!H12 -> 0 | H30: NOS.
A31: 28 | D31: ='[1]Rail Disc cutter wheel stone '!E13 -> 0 | E31: ='[1]Rail Disc cutter wheel stone '!F13 -> 0 | F31: ='[1]Rail Disc cutter wheel stone '!G13 -> 0 | G31: ='[1]Rail Disc cutter wheel stone '!H13 -> 0 | H31: NOS.
A32: 29 | D32: ='[1]Rail Disc cutter wheel stone '!E14 -> 0 | E32: ='[1]Rail Disc cutter wheel stone '!F14 -> 0 | F32: ='[1]Rail Disc cutter wheel stone '!G14 -> 0 | G32: ='[1]Rail Disc cutter wheel stone '!H14 -> 0 | H32: NOS.
A33: 30 | D33: ='[1]Rail Disc cutter wheel stone '!E15 -> 0 | E33: ='[1]Rail Disc cutter wheel stone '!F15 -> 0 | F33: ='[1]Rail Disc cutter wheel stone '!G15 -> 0 | G33: ='[1]Rail Disc cutter wheel stone '!H15 -> 0 | H33: NOS.
A34: 31 | D34: ='[1]Rail Disc cutter wheel stone '!E16 -> 0 | E34: ='[1]Rail Disc cutter wheel stone '!F16 -> 0 | F34: ='[1]Rail Disc cutter wheel stone '!G16 -> 0 | G34: ='[1]Rail Disc cutter wheel stone '!H16 -> 0 | H34: NOS.
A35: 32 | D35: ='[1]Rail Disc cutter wheel stone '!E17 -> 0 | E35: ='[1]Rail Disc cutter wheel stone '!F17 -> 0 | F35: ='[1]Rail Disc cutter wheel stone '!G17 -> 0 | G35: ='[1]Rail Disc cutter wheel stone '!H17 -> 0 | H35: NOS.
A36: 33 | D36: ='[1]Rail Disc cutter wheel stone '!E18 -> 0 | E36: ='[1]Rail Disc cutter wheel stone '!F18 -> 0 | F36: ='[1]Rail Disc cutter wheel stone '!G18 -> 0 | G36: ='[1]Rail Disc cutter wheel stone '!H18 -> 0 | H36: NOS.
A37: 34 | D37: ='[1]Rail Disc cutter wheel stone '!E19 -> 0 | E37: ='[1]Rail Disc cutter wheel stone '!F19 -> 0 | F37: ='[1]Rail Disc cutter wheel stone '!G19 -> 0 | G37: ='[1]Rail Disc cutter wheel stone '!H19 -> 0 | H37: NOS.
A38: 35 | D38: ='[1]Rail Disc cutter wheel stone '!E20 -> 0 | E38: ='[1]Rail Disc cutter wheel stone '!F20 -> 0 | F38: ='[1]Rail Disc cutter wheel stone '!G20 -> 0 | G38: ='[1]Rail Disc cutter wheel stone '!H20 -> 0 | H38: NOS.
A39: 36 | D39: ='[1]Rail Disc cutter wheel stone '!E21 -> 0 | E39: ='[1]Rail Disc cutter wheel stone '!F21 -> 0 | F39: ='[1]Rail Disc cutter wheel stone '!G21 -> 0 | G39: ='[1]Rail Disc cutter wheel stone '!H21 -> 0 | H39: NOS.
A40: 37 | D40: ='[1]Rail Disc cutter wheel stone '!E22 -> 0 | E40: ='[1]Rail Disc cutter wheel stone '!F22 -> 0 | F40: ='[1]Rail Disc cutter wheel stone '!G22 -> 0 | G40: ='[1]Rail Disc cutter wheel stone '!H22 -> 0 | H40: NOS.
...

Sheet 3001
B1: foHkkxh; [kkrk feyku iqLrd DEPARTMENTAL LEDGER AND TALLY BOOK
A2: ewY; lwph@dwV la[;k Price List / Code No. | D2: 1 | E2: feyku i= la[;k Tally Code No. | H2: 2 | I2: ;wfuV Unit | J2: 1
A3: oLrq dk fooj.k Description of the Article | D3: Detonators | E3: ys[kk dk;kZy; i`"B la[;k Accounts Office File No. | I3: 3001
A4: ekg vkSj rkjh[k Month and Date | B4: izkfIr ;k fuxZe okmpj la[;k vkSj rkjh[k No. and Date of Receiot or issue Voucher | C4: fdlls izkIr gqvk ;k fdls tkjh fd;k From Whom received or to whom issued | D4: izkfIr ;k fuxZe dk mn~ns'; Purpose for which received or issue | E4: izkfIr Receipt | F4: LFkkukarj.k Transfer | G4: fuxZe Issues | H4: 'ks"k Balance | I4: vk|{kj Signature
E5: ux No. Vu Tonnes fd-xzk-Kgs. | F5: ux No. Vu Tonnes fd-xzk-Kgs. | G5: ux No. Vu Tonnes fd-xzk-Kgs. | H5: ux No. Vu Tonnes fd-xzk-Kgs.
A6: A | B6: B | C6: C | D6: D | E6: =SUM(E7:E1000) -> 1100 | F6: =SUM(F7:F1000) -> 0 | G6: =SUM(G7:G1000) -> 980 | H6: =SUM(E6-F6-G6) -> 120
A7: 25/04/2024 | B7: E-waybill- 20240014 dated 20.04.2024 | C7: Multination india ltd. (Ordnance factory Dehuroad) | D7: Track Maintenance | E7: 1100 | F7: 0 | G7: 0 | H7: =SUM(E7:G7) -> 1100
A8: 45356 | B8: Munilions India Pvt. Ltd, Delhi Road | C8: JPM/OP&BD / JUDN UDHAM SOLANKI | D8: Sation Safity Equipment | E8: 0 | F8: 0 | G8: 220 | H8: =H7-G8-F8+E8 -> 880
A9: 28/05/2024 | B9: Munilions India Pvt. Ltd, Delhi Road | C9: ExrlCIVILl -1 / JUDN Sh. Abhishek Sharma | D9: Issued to IMSD/ JUDN | E9: 0 | F9: 0 | G9: 440 | H9: =H8-G9-F9+E9 -> 440
A10: 30/05/2024 | B10: Munilions India Pvt. Ltd, Delhi Road | C10: Sr. Exe/CIVILl/ SMUN Sh. Surendera Kumar | D10: Hot weather Patrolman | E10: 0 | F10: 0 | G10: 100 | H10: =H9-G10-F10+E10 -> 340
A11: 30/05/2024 | B11: Munilions India Pvt. Ltd, Delhi Road | C11: Sr. Exe/CIVILl/ SMUN Sh.Harpal singh | D11: Hot weather Patrolman | E11: 0 | F11: 0 | G11: 110 | H11: =H10-G11-F11+E11 -> 230
A12: 45507 | B12: GD/DFC/Ambala Sr. 1210 | C12: DY CDM/ Elee /UMB | D12: Safity Item | E12: 0 | F12: 0 | G12: 10 | H12: =H11-G12-F12+E12 -> 220
A13: 45510 | B13: GD/DFC/ Ambala Sr. No. 1211 | C13: DY DM/ Elee /JUDN | D13: Safity Item | E13: 0 | F13: 0 | G13: 10 | H13: =H12-G13-F13+E13 -> 210
A14: 45622 | B14: GP/DFC/ Ambala 1180dl - 26.11.2024 | C14: Surendera Kumar Sr. Exe/Civil/KNNN | D14: For L/C Gate | E14: 0 | F14: 0 | G14: 50 | H14: =H13-G14-F14+E14 -> 160
A15: 45638 | B15: GP/DFC/ Ambala 1183dl - 12.12.2024 | C15: Sub Shyam lal , Retd AWPO Ambala | D15: For Patrolmen | E15: 0 | F15: 0 | G15: 40 | H15: =H14-G15-F15+E15 -> 120

Sheet 3005
B1: foHkkxh; [kkrk feyku iqLrd DEPARTMENTAL LEDGER AND TALLY BOOK
A2: ewY; lwph@dwV la[;k Price List / Code No. | E2: feyku i= la[;k Tally Code No. | I2: ;wfuV Unit | J2: 3005
A3: oLrq dk fooj.k Description of the Article | D3: GREASE ( IS : 408-2020) | E3: ys[kk dk;kZy; i`"B la[;k Accounts Office File No.
A4: ekg vkSj rkjh[k Month and Date | B4: izkfIr ;k fuxZe okmpj la[;k vkSj rkjh[k No. and Date of Receiot or issue Voucher | C4: fdlls izkIr gqvk ;k fdls tkjh fd;k From Whom received or to whom issued | D4: izkfIr ;k fuxZe dk mn~ns'; Purpose for which received or issue | E4: izkfIr Receipt | F4: LFkkukarj.k Transfer | G4: fuxZe Issues | H4: 'ks"k Balance | I4: vk|{kj Signature
E5: ux No. Vu Tonnes fd-xzk-Kgs. Ltr. | F5: ux No. Vu Tonnes fd-xzk-Kgs. | G5: ux No. Vu Tonnes fd-xzk-Kgs. | H5: ux No. Vu Tonnes fd-xzk-Kgs.
E6: =SUM(E7:E1001) -> 1280 | F6: =SUM(F7:F1001) -> 0 | G6: =G7+G8+G9+G10+G11+G12+G13+G15+G16+G17 -> 975 | H6: =E6-F6-G6 -> 305
A7: 45296 | B7: Invoice No.11 dtol 08/04/2024 | C7: Bombay Industries Ludhiana, Punjab | D7: For lubriling ERCS & T10 | E7: 180 | F7: 0 | G7: 0 | H7: 180
A8: 45542 | B8: 1202/GD/DFC/ Ambala Date 09/07/2024 | C8: Executive /CIVILl / JUDN | D8: P-way work | E8: 0 | F8: 0 | G8: 50 | H8: =H7+E8-F8-G8 -> 130
A9: 45606 | B9: 102/09/10/2024 | C9: Sai Associates Sector 50 Noida | D9: P-way work | E9: 1100 | F9: 0 | G9: 0 | H9: =H8+E9-F9-G9 -> 1230
A10: 14/10/2024 | B10: Gp/DFC/ Ambala Sr. 1223 Date 14/10/2024 | C10: Executive /CIVILl / JUDN | D10: P-way work | E10: 0 | F10: 0 | G10: 545 | H10: =H9+E10-F10-G10 -> 685
A11: 13/8/2025 | B11: Gp/DFC/ Ambala Sr. 1152 Date 13/8/2025 | C11: CHAN YARD | D11: P-way work | E11: 0 | F11: 0 | G11: 50 | H11: =H10+E11-F11-G11 -> 635
A12: 31/1/2026 | B12: Gp/DFC/ Ambala Sr. 1171 | C12: Use in Yard for Greasing of Point at IMSD Section | D12: P-way work | E12: 0 | F12: 0 | G12: 100 | H12: =H11+E12-F12-G12 -> 535
A13: 46144 | B13: Gp/DFC/ Ambala Sr. 1173 | C13: Use in Yard for Greasing of Point at IMSD Section | D13: P-way work | E13: 0 | F13: 0 | G13: 50 | H13: =H12+E13-F13-G13 -> 485
A14: 46298 | B14: Gp/DFC/ Ambala Sr. 1175 | C14: Use in Sleeper Scerew greas | D14: P-way work | E14: 0 | F14: 0 | G14: 50 | H14: =H13+E14-F14-G14 -> 435
A15: 20/3/2026 | B15: Gp/DFC/ Ambala Sr. 2203 | C15: Use in Sleeper Scerew greas | D15: P-way work | E15: 0 | F15: 0 | G15: 60 | H15: =H14+E15-F15-G15 -> 375
A16: 22/04/2026 | B16: Gp/DFC/ Ambala Sr. 2206 | C16: Use in Sleeper Scerew greas | D16: P-way work | E16: 0 | F16: 0 | G16: 100 | H16: =H15+E16-F16-G16 -> 275
A17: 46162 | B17: GP/DFC/Ambala sr.no. 2210 dt. 20/05/2026 | C17: point greasing | D17: P-way work | E17: 0 | F17: 0 | G17: 20 | H17: =H16+E17-F17-G17 -> 255
H85: =H84-G85-F85+E85 -> 0
H86: =H85-G86-F86+E86 -> 0
H87: =H86-G87-F87+E87 -> 0
H88: =H87-G88-F88+E88 -> 0
H89: =H88-G89-F89+E89 -> 0
H90: =H89-G90-F90+E90 -> 0
H91: =H90-G91-F91+E91 -> 0
H92: =H91-G92-F92+E92 -> 0
H93: =H92-G93-F93+E93 -> 0
H94: =H93-G94-F94+E94 -> 0
H95: =H94-G95-F95+E95 -> 0
H96: =H95-G96-F96+E96 -> 0
... H674: =H673-G674-F674+E674 -> 0
E1048572: 2

Sheet 3008
B1: foHkkxh; [kkrk feyku iqLrd DEPARTMENTAL LEDGER AND TALLY BOOK
A2: ewY; lwph@dwV la[;k Price List / Code No. | D2: 3 | E2: feyku i= la[;k Tally Code No. | I2: ;wfuV Unit
A3: oLrq dk fooj.k Description of the Article | D3: Block Oil (used) | E3: ys[kk dk;kZy; i`"B la[;k Accounts Office File No. | I3: 3008
A4: ekg vkSj rkjh[k Month and Date | B4: izkfIr ;k fuxZe okmpj la[;k vkSj rkjh[k No. and Date of Receiot or issue Voucher | C4: fdlls izkIr gqvk ;k fdls tkjh fd;k From Whom received or to whom issued | D4: izkfIr ;k fuxZe dk mn~ns'; Purpose for which received or issue | E4: izkfIr Receipt | F4: LFkkukarj.k Transfer | G4: fuxZe Issues | H4: 'ks"k Balance | I4: vk|{kj Signature
E5: ux No. Vu Tonnes fd-xzk-Kgs. Ltr. | F5: ux No. Vu Tonnes fd-xzk-Kgs. | G5: ux No. Vu Tonnes fd-xzk-Kgs. | H5: ux No. Vu Tonnes fd-xzk-Kgs.
E6: =SUM(E7:E1004) -> 200 | F6: =SUM(F7:F1004) -> 0 | G6: =SUM(G7:G1004) -> 100 | H6: =SUM(E6-F6-G6) -> 100
A7: 45296 | B7: Invoice no. 11 08/04/2024 | C7: Bombay Industries Ludhiana , Punjab | D7: For lubricabing ERCS &t10 | E7: 200 | F7: 0 | G7: 0 | H7: =SUM(E7:G7) -> 200
A8: 13/8/2025 | B8: GP/DFC/Ambala Sr. No. 1152 | C8: Km - 1236 / 15-16 CHAN Yard | D8: P-way | E8: 0 | F8: 0 | G8: 50 | H8: =H7+E8-F8-G8 -> 150
A9: 46144 | B9: GP/DFC/Ambala Sr. No. 1173 | C9: Use in Point and IMSD SMUN Section | D9: P-way | E9: 0 | F9: 0 | G9: 20 | H9: =H8+E9-F9-G9 -> 130
A10: 46298 | B10: GP/DFC/Ambala Sr. No. 1173 | C10: Use Sleeper sce Greasing | D10: P-way | E10: 0 | F10: 0 | G10: 20 | H10: =H9+E10-F10-G10 -> 110
A11: 46162 | B11: GP/DFC/Ambala Sr. No. 1173 20.05.2026 | C11: Use Sleeper sce Greasing | D11: P-way | E11: 0 | F11: 0 | G11: 10 | H11: =H10+E11-F11-G11 -> 100
I42: ML
I43: ML
H525: =H524-G525-F525+E525 -> 0
H526: =H525-G526-F526+E526 -> 0
H527: =H526-G527-F527+E527 -> 0
H528: =H527-G528-F528+E528 -> 0
H529: =H528-G529-F529+E529 -> 0
H530: =H529-G530-F530+E530 -> 0
H531: =H530-G531-F531+E531 -> 0
H532: =H531-G532-F532+E532 -> 0
H533: =H532-G533-F533+E533 -> 0
H534: =H533-G534-F534+E534 -> 0
H535: =H534-G535-F535+E535 -> 0
H536: =H535-G536-F536+E536 -> 0
... H677: =H676-G677-F677+E677 -> 0
E1048575: 2

Sheet 3011
B1: foHkkxh; [kkrk feyku iqLrd DEPARTMENTAL LEDGER AND TALLY BOOK
A2: ewY; lwph@dwV la[;k Price List / Code No. | D2: 4 | E2: feyku i= la[;k Tally Code No. | I2: ;wfuV Unit
A3: oLrq dk fooj.k Description of the Article | D3: Water Bottle | E3: ys[kk dk;kZy; i`"B la[;k Accounts Office File No. | I3: 3011
A4: ekg vkSj rkjh[k Month and Date | B4: izkfIr ;k fuxZe okmpj la[;k vkSj rkjh[k No. and Date of Receiot or issue Voucher | C4: fdlls izkIr gqvk ;k fdls tkjh fd;k From Whom received or to whom issued | D4: izkfIr ;k fuxZe dk mn~ns'; Purpose for which received or issue | E4: izkfIr Receipt | F4: LFkkukarj.k Transfer | G4: fuxZe Issues | H4: 'ks"k Balance | I4: vk|{kj Signature
E5: ux No. Vu Tonnes fd-xzk-Kgs. Ltr. | F5: ux No. Vu Tonnes fd-xzk-Kgs. | G5: ux No. Vu Tonnes fd-xzk-Kgs. | H5: ux No. Vu Tonnes fd-xzk-Kgs.
E6: =SUM(E7:E975) -> 150 | F6: =SUM(F7:F975) -> 0 | G6: =SUM(G7:G975) -> 123 | H6: =SUM(E6-F6-G6) -> 27
A7: 27/05/2024 | B7: 24-25/DC/03 Dated : 27/05/2024 | C7: Papu Assoriata Ambala | D7: H.W PAPOLING | E7: 150 | F7: 0 | G7: 0 | H7: =SUM(E7:G7) -> 150
A8: 28/05/2024 | B8: 24-25/ DC/ 03 Dated: 28.5.2024 | C8: Sh. Abhishek Sharma Exr / CIVILl/ JUDN | D8: Issued to IMSD / JUDN | E8: 0 | F8: 0 | G8: 75 | H8: =H7-G8-F8+E8 -> 75
A9: 28/05/2024 | B9: 24-25 / DC/ 03 Dated : 28/05/2024 | C9: Sr. Exe/ CIVILl / SMUN Harpal singh | D9: Hot weather Patrol men | E9: 0 | F9: 0 | G9: 11 | H9: =H8-G9-F9+E9 -> 64
A10: 28/05/2024 | B10: 24-25/DC/03 Dated : 28/05/2024 | C10: Sr. Exe/ CIVILl /KNNN Surendera kumar | D10: Hot weather Patrol men | E10: 0 | F10: 0 | G10: 10 | H10: =H9-G10-F10+E10 -> 54
A11: 31/3/2026 | B11: GP / DFC/ Ambala Sr. No 2204 | C11: For use in Keyman Patrolman And staff | D11: Hot weather Patrol men | E11: 0 | F11: 0 | G11: 27 | H11: 27
H56: =H55-G56-F56+E56 -> 0
H57: =H56-G57-F57+E57 -> 0
H58: =H57-G58-F58+E58 -> 0
H59: =H58-G59-F59+E59 -> 0
H60: =H59-G60-F60+E60 -> 0
H61: =H60-G61-F61+E61 -> 0
H62: =H61-G62-F62+E62 -> 0
H63: =H62-G63-F63+E63 -> 0
H64: =H63-G64-F64+E64 -> 0
H65: =H64-G65-F65+E65 -> 0
H66: =H65-G66-F66+E66 -> 0
H67: =H66-G67-F67+E67 -> 0
... H648: =H647-G648-F648+E648 -> 0
E1048546: 2

Sheet 3015
A1: 744 | B1: foHkkxh; [kkrk feyku iqLrd DEPARTMENTAL LEDGER AND TALLY BOOK
A2: ewY; lwph@dwV la[;k Price List / Code No. | D2: 5 | E2: feyku i= la[;k Tally Code No. | I2: ;wfuV Unit
A3: oLrq dk fooj.k Description of the Article | D3: Mobile Dustbin | E3: ys[kk dk;kZy; i`"B la[;k Accounts Office File No. | I3: 3015
A4: ekg vkSj rkjh[k Month and Date | B4: izkfIr ;k fuxZe okmpj la[;k vkSj rkjh[k No. and Date of Receiot or issue Voucher | C4: fdlls izkIr gqvk ;k fdls tkjh fd;k From Whom received or to whom issued | D4: izkfIr ;k fuxZe dk mn~ns'; Purpose for which received or issue | E4: izkfIr Receipt | F4: LFkkukarj.k Transfer | G4: fuxZe Issues | H4: 'ks"k Balance | I4: vk|{kj Signature
E5: ux No. Vu Tonnes fd-xzk-Kgs. Ltr. | F5: ux No. Vu Tonnes fd-xzk-Kgs. | G5: ux No. Vu Tonnes fd-xzk-Kgs. | H5: ux No. Vu Tonnes fd-xzk-Kgs.
E6: =SUM(E7:E975) -> 6 | F6: =SUM(F7:F975) -> 0 | G6: =SUM(G7:G975) -> 2 | H6: =SUM(E6-F6-G6) -> 4
A7: 31/05/2024 | B7: Invoice no. 1853 Dated 31/5/2024 | C7: Prabhu steels | D7: For IMSD SMUN & IMSD JUDN | E7: 4 | F7: 0 | G7: 0 | H7: 4
A8: 31/05/2024 | B8: Invoice no. 1853 Dated 31/5/2024 Prabhu steels | C8: Sh. Abhishek Sharma Exc./ CIVILl/ JUDN | D8: For IMJD JUDN | E8: 0 | F8: 0 | G8: 2 | H8: =+H7+E8-F8-G8 -> 2
A9: 29/10/2025 | B9: Mobile Container Dustbin solid waste | C9: IMD CHAN | D9: For waste use | E9: 2 | F9: 0 | G9: 0 | H9: 4
H464: =H463-G464-F464+E464 -> 0
H465: =H464-G465-F465+E465 -> 0
H466: =H465-G466-F466+E466 -> 0
H467: =H466-G467-F467+E467 -> 0
H468: =H467-G468-F468+E468 -> 0
H469: =H468-G469-F469+E469 -> 0
H470: =H469-G470-F470+E470 -> 0
H471: =H470-G471-F471+E471 -> 0
H472: =H471-G472-F472+E472 -> 0
H473: =H472-G473-F473+E473 -> 0
H474: =H473-G474-F474+E474 -> 0
H475: =H474-G475-F475+E475 -> 0
... H648: =H647-G648-F648+E648 -> 0
E1048546: 2

Sheet 3017
A1: 744 | B1: foHkkxh; [kkrk feyku iqLrd DEPARTMENTAL LEDGER AND TALLY BOOK
A2: ewY; lwph@dwV la[;k Price List / Code No. | D2: 5 | E2: feyku i= la[;k Tally Code No. | I2: ;wfuV Unit
A3: oLrq dk fooj.k Description of the Article | D3: Portion 60 kg | E3: ys[kk dk;kZy; i`"B la[;k Accounts Office File No. | I3: 3017
A4: ekg vkSj rkjh[k Month and Date | B4: izkfIr ;k fuxZe okmpj la[;k vkSj rkjh[k No. and Date of Receiot or issue Voucher | C4: fdlls izkIr gqvk ;k fdls tkjh fd;k From Whom received or to whom issued | D4: izkfIr ;k fuxZe dk mn~ns'; Purpose for which received or issue | E4: izkfIr Receipt | F4: LFkkukarj.k Transfer | G4: fuxZe Issues | H4: 'ks"k Balance | I4: vk|{kj Signature
E5: ux No. Vu Tonnes fd-xzk-Kgs. Ltr. | F5: ux No. Vu Tonnes fd-xzk-Kgs. | G5: ux No. Vu Tonnes fd-xzk-Kgs. | H5: ux No. Vu Tonnes fd-xzk-Kgs.
E6: =SUM(E7:E975) -> 46 | F6: =SUM(F7:F975) -> 0 | G6: =SUM(G7:G975) -> 35 | H6: =SUM(E6-F6-G6) -> 11
A7: 45473 | B7: Invoice no. 0101 Dated 30.06.2024 | C7: M/S chakradhar industries llp | D7: Track related work | E7: 40 | F7: 0 | G7: 0 | H7: 40
A8: 45480 | B8: GP/DFC/AMBALA sr.no. 1203 dt. 07.07.2024 | C8: sr.exe./c/smun | D8: Track related work | E8: 0 | F8: 0 | G8: 15 | H8: =+H7+E8-F8-G8 -> 25
A9: 45488 | B9: GP/DFC/AMBALA sr.no. 1208 dt. 15.07.2024 | C9: IMSD/JUDN | D9: Track related work | E9: 0 | F9: 0 | G9: 4 | H9: =+H8+E9-F9-G9 -> 21
A10: 45741 | B10: GP/DFC/AMBALA sr.no. 1198 dt. 25.03.2025 | C10: IMSD/JUDN | D10: Track related work | E10: 0 | F10: 0 | G10: 4 | H10: =+H9+E10-F10-G10 -> 17
A11: 45882 | B11: GP/DFC/AMBALA sr.no. 1151 dt. 13.08.2025 | C11: km 1236/15-16 | D11: Track related work | E11: 0 | F11: 0 | G11: 4 | H11: =+H10+E11-F11-G11 -> 13
A12: 45979 | B12: GP/DFC/AMBALA sr.no. 1159 dt. 18.11.2025 | C12: 1212/2-3 | D12: Track related work | E12: 0 | F12: 0 | G12: 2 | H12: =+H11+E12-F12-G12 -> 11
A13: 45993 | B13: GP/DFC/AMBALA sr.no. 1162 dt. 02.12.2025 | C13: 1176.925 | D13: Track related work | E13: 0 | F13: 0 | G13: 2 | H13: =+H12+E13-F13-G13 -> 9
A14: 46051 | B14: GP/DFC/AMBALA sr.no. 1168 dt.29.01.2026 | C14: 1208/15-16 | D14: Track related work | E14: 0 | F14: 0 | G14: 2 | H14: =+H13+E14-F14-G14 -> 7
A15: 46078 | B15: MTO/350/35 DT. 21.02.2026 | C15: IMSD/SKFN | D15: Track related work | E15: 6 | F15: 0 | G15: 0 | H15: =+H14+E15-F15-G15 -> 13
A16: 46078 | B16: GP/DFC/AMBALA sr.no. 1174 dt. 25.02.2026 | C16: 1212/02 AND 1208/15 | D16: Track related work | E16: 0 | F16: 0 | G16: 2 | H16: =+H15+E16-F16-G16 -> 11
H464: =H463-G464-F464+E464 -> 0
H465: =H464-G465-F465+E465 -> 0
H466: =H465-G466-F466+E466 -> 0
H467: =H466-G467-F467+E467 -> 0
H468: =H467-G468-F468+E468 -> 0
H469: =H468-G469-F469+E469 -> 0
H470: =H469-G470-F470+E470 -> 0
H471: =H470-G471-F471+E471 -> 0
H472: =H471-G472-F472+E472 -> 0
H473: =H472-G473-F473+E473 -> 0
H474: =H473-G474-F474+E474 -> 0
H475: =H474-G475-F475+E475 -> 0
... H648: =H647-G648-F648+E648 -> 0
E1048546: 2

Sheet 3020
B1: foHkkxh; [kkrk feyku iqLrd DEPARTMENTAL LEDGER AND TALLY BOOK
A2: ewY; lwph@dwV la[;k Price List / Code No. | D2: 7 | E2: feyku i= la[;k Tally Code No. | H2: 2 | I2: ;wfuV Unit | J2: 6
A3: oLrq dk fooj.k Description of the Article | D3: Prelerbricated Dry Mould - Three Pc. (60 kg Rail) | E3: ys[kk dk;kZy; i`"B la[;k Accounts Office File No. | I3: 3020
A4: ekg vkSj rkjh[k Month and Date | B4: izkfIr ;k fuxZe okmpj la[;k vkSj rkjh[k No. and Date of Receiot or issue Voucher | C4: fdlls izkIr gqvk ;k fdls tkjh fd;k From Whom received or to whom issued | D4: izkfIr ;k fuxZe dk mn~ns'; Purpose for which received or issue | E4: izkfIr Receipt | F4: LFkkukarj.k Transfer | G4: fuxZe Issues | H4: 'ks"k Balance | I4: vk|{kj Signature
E5: ux No. Vu Tonnes fd-xzk-Kgs. | F5: ux No. Vu Tonnes fd-xzk-Kgs. | G5: ux No. Vu Tonnes fd-xzk-Kgs. | H5: ux No. Vu Tonnes fd-xzk-Kgs.
E6: =SUM(E7:E1001) -> 48 | F6: =SUM(F7:F1001) -> 0 | G6: =SUM(G7:G1001) -> 40 | H6: =+E6-F6-G6 -> 8
A7: 30/6/2024 | B7: 0101/24-25 | C7: M/S Chakradhar Industries | D7: Track Related works | E7: 42 | F7: 0 | G7: 0 | H7: =SUM(E7:G7) -> 42
A8: 45480 | B8: GP/ DFC Ambala 1203 Dated: 07/07/2024 | C8: Sr. Exe /CIVILl/ SMUN | D8: P- way work | E8: 0 | F8: 0 | G8: 15 | H8: =H7-G8-F8+E8 -> 27
A9: 15/07/2025 | B9: GP / DFC/ Ambala Sr. No. 1208 | C9: IMSD / JUDN | D9: P- way work | E9: 0 | F9: 0 | G9: 5 | H9: =H8-G9-F9+E9 -> 22
A10: 25/03/2025 | B10: GP/DFC/Ambala Sr.No. 1198 Dated 25.03.2025 | C10: IMSD/ JUDN | D10: P- way work | E10: 0 | F10: 0 | G10: 4 | H10: =H9-G10-F10+E10 -> 18
A11: 13/8/2025 | B11: GP/DFC/Ambala Sr.No. 1151 | C11: Km -1236/15-16 CHAN Yard | D11: P- way work | E11: 0 | F11: 0 | G11: 6 | H11: 12
A12: 18/11/2025 | B12: GP/DFC/Ambala Sr.No. 1159 | C12: Km -1212 / 2-3 GVGN Yard | D12: P- way work | E12: 0 | F12: 0 | G12: 3 | H12: 9
A13: 45700 | B13: GP/DFC/Ambala Sr.No. 1162 | C13: Km - 1176 /9-25 RPJ Link Line Br.115 | D13: P- way work | E13: 0 | F13: 0 | G13: 2 | H13: 7
A14: 29/01/2026 | B14: GP/DFC/Ambala Sr.No. 1168 | C14: Km 1208/15-16 NSIR- GVGN Block Section | D14: P- way work | E14: 0 | F14: 0 | G14: 3 | H14: 4
A15: 25/02/2026 | B15: IMSD/SKFM/MTO 350/35 | C15: IMSD / SKM | D15: P- way work | E15: 6 | F15: 0 | G15: 0 | H15: 10
A16: 25/02/2026 | B16: GP/DFC/Ambala Sr.No. 1174 | C16: KM 1212 / 02 and 1208/ 15 | D16: P- way work | E16: 0 | F16: 0 | G16: 2 | H16: 8

Sheet 3023
B1: foHkkxh; [kkrk feyku iqLrd DEPARTMENTAL LEDGER AND TALLY BOOK
A2: ewY; lwph@dwV la[;k Price List / Code No. | D2: 8 | E2: feyku i= la[;k Tally Code No. | H2: 2 | I2: ;wfuV Unit | J2: 8
A3: oLrq dk fooj.k Description of the Article | D3: Single shot Cruible | E3: ys[kk dk;kZy; i`"B la[;k Accounts Office File No. | I3: 3023
A4: ekg vkSj rkjh[k Month and Date | B4: izkfIr ;k fuxZe okmpj la[;k vkSj rkjh[k No. and Date of Receiot or issue Voucher | C4: fdlls izkIr gqvk ;k fdls tkjh fd;k From Whom received or to whom issued | D4: izkfIr ;k fuxZe dk mn~ns'; Purpose for which received or issue | E4: izkfIr Receipt | F4: LFkkukarj.k Transfer | G4: fuxZe Issues | H4: 'ks"k Balance | I4: vk|{kj Signature
E5: ux No. Vu Tonnes fd-xzk-Kgs. | F5: ux No. Vu Tonnes fd-xzk-Kgs. | G5: ux No. Vu Tonnes fd-xzk-Kgs. | H5: ux No. Vu Tonnes fd-xzk-Kgs.
E6: =SUM(E7:E1000) -> 46 | F6: =SUM(F7:F1000) -> 0 | G6: =SUM(G7:G1000) -> 36 | H6: =+E6-F6-G6 -> 10
A7: 30/06/2024 | B7: 0101/24-25 | C7: M/S Chakradhar Industries LLP | D7: Track Related work | E7: 40 | F7: 0 | G7: 0 | H7: =SUM(E7:G7) -> 40
A8: 45480 | B8: 1203/GP?DFC/ Ambal Date: 07/07/2024 | C8: Sr. exe/ SMUN/CIVIL/ | D8: P- way works | E8: 0 | F8: 0 | G8: 15 | H8: =H7-G8-F8+E8 -> 25
A9: 15-07-2024 | B9: GP/DFC/ Ambala Sr. 1208 | C9: IMSD/ JUDN | D9: P- way works | E9: 0 | F9: 0 | G9: 4 | H9: =H8-G9-F9+E9 -> 21
A10: 25/03/2025 | B10: GP/DFC/ Ambala sr.No. 1198 | C10: IMSD/ JUDN | D10: P- way works | E10: 0 | F10: 0 | G10: 4 | H10: =H9-G10-F10+E10 -> 17
A11: 13/08/2025 | B11: GP/DFC/ Ambala Sr.No. 1151 | C11: Km 1236/15-16 CHAN Yard | D11: P- way works | E11: 0 | F11: 0 | G11: 5 | H11: 12
A12: 18/8/2025 | B12: GP/DFC/ Ambala Sr.No. 1159 | C12: Km 1212/2-3 GVGN Yard | D12: P- way works | E12: 0 | F12: 0 | G12: 2 | H12: 10
A13: 45700 | B13: GP/DFC/ Ambala Sr.No. 1162 | C13: Km 1176/925 RPJ Link Line Br. 115 | D13: P- way works | E13: 0 | F13: 0 | G13: 2 | H13: 8
A14: 29/01/2026 | B14: GP/DFC/ Ambala Sr.No. 1168 | C14: Km 1208/ 15-16 NSIR GVGN Bolck section | D14: P- way works | E14: 0 | F14: 0 | G14: 2 | H14: 6
A15: 25/02/2026 | B15: IMSD / SKFM / MTO 350/35 | C15: IMSD / SKFM | D15: P- way works | E15: 6 | F15: 0 | G15: 0 | H15: 12
A16: 25/02/2026 | B16: GP/DFC/ Ambala Sr.No. 1124 | C16: Km 1212/02 and 1225/15 | D16: P- way works | E16: 0 | F16: 0 | G16: 2 | H16: 10

Sheet 3026
B1: foHkkxh; [kkrk feyku iqLrd DEPARTMENTAL LEDGER AND TALLY BOOK
A2: ewY; lwph@dwV la[;k Price List / Code No. | D2: 9 | E2: feyku i= la[;k Tally Code No. | H2: 2 | I2: ;wfuV Unit | J2: 9
A3: oLrq dk fooj.k Description of the Article | D3: Luting Sand | E3: ys[kk dk;kZy; i`"B la[;k Accounts Office File No. | I3: 3026
A4: ekg vkSj rkjh[k Month and Date | B4: izkfIr ;k fuxZe okmpj la[;k vkSj rkjh[k No. and Date of Receiot or issue Voucher | C4: fdlls izkIr gqvk ;k fdls tkjh fd;k From Whom received or to whom issued | D4: izkfIr ;k fuxZe dk mn~ns'; Purpose for which received or issue | E4: izkfIr Receipt | F4: LFkkukarj.k Transfer | G4: fuxZe Issues | H4: 'ks"k Balance | I4: vk|{kj Signature
E5: ux No. Vu Tonnes fd-xzk-Kgs. | F5: ux No. Vu Tonnes fd-xzk-Kgs. | G5: ux No. Vu Tonnes fd-xzk-Kgs. | H5: ux No. Vu Tonnes fd-xzk-Kgs.
E6: =SUM(E7:E998) -> 51 | F6: =SUM(F7:F998) -> 0 | G6: =SUM(G7:G998) -> 48 | H6: =+E6-F6-G6 -> 3
A7: 30/06/2024 | B7: 0101/24-25 | C7: M/S Chakradhar Industories LLP | D7: Track Related work | E7: 45 | F7: 0 | G7: 0 | H7: =SUM(E7:G7) -> 45
A8: 45480 | B8: 1203/GP/DFC /Ambala Sr | C8: Sr. exe/CIVILl / SMUN | D8: P-way work | E8: 0 | F8: 0 | G8: 15 | H8: =H7+E8-F8-G8 -> 30
A9: 15/07/2024 | B9: GP/DFC/ Ambal;a Sr.No. 1208 | C9: IMSD/ JUDN | D9: P-way work | E9: 0 | F9: 0 | G9: 4 | H9: =H8+E9-F9-G9 -> 26
A10: 25/03/2025 | B10: GP/DFC/ Ambala Sr.No. 1198 Dated: 25/03/2025 | C10: IMSD/ JUDN | D10: P-way work | E10: 0 | F10: 0 | G10: 4 | H10: =H9+E10-F10-G10 -> 22
A11: 13/8/2025 | B11: GP/DFC/ Ambala Sr.No. 1151 | C11: Km 1236 / 15-16 CHAN Yard | D11: P-way work | E11: 0 | F11: 0 | G11: 11 | H11: =H10+E11-F11-G11 -> 11
A12: 45969 | B12: GP/DFC/ Ambala Sr.No. 1159 | C12: Km 1212/2-3 GVGN Yard | D12: P-way work | E12: 0 | F12: 0 | G12: 5 | H12: =H11+E12-F12-G12 -> 6
A13: 45993 | B13: GP/DFC/ Ambala Sr.No. 1162 | C13: Km 1176/925 RPJ Link Line Br. 115 APM | D13: P-way work | E13: 0 | F13: 0 | G13: 3 | H13: =H12+E13-F13-G13 -> 3
A14: 29/01/2026 | B14: GP/DFC/ Ambala Sr.No. 1168 | C14: Km 1208/15-16 NSIR -GVGN Block | D14: P-way work | E14: 0 | F14: 0 | G14: 2 | H14: =H13+E14-F14-G14 -> 1
A15: 25/02/2026 | B15: IMSD / SKFN / MTO 350/35 | C15: IMSD/SKFM | D15: P-way work | E15: 6 | F15: 0 | G15: 0 | H15: =H14+E15-F15-G15 -> 7
A16: 25/02/2026 | B16: GP/DFC/ Ambala Sr.No. 1174 | C16: 1208/15 and 1202/02 km | D16: P-way work | E16: 0 | F16: 0 | G16: 4 | H16: =H15+E16-F16-G16 -> 3

Sheet 3028
B1: foHkkxh; [kkrk feyku iqLrd DEPARTMENTAL LEDGER AND TALLY BOOK
A2: ewY; lwph@dwV la[;k Price List / Code No. | D2: 10 | E2: feyku i= la[;k Tally Code No. | H2: 2 | I2: ;wfuV Unit | J2: 10
A3: oLrq dk fooj.k Description of the Article | D3: Ig niter | E3: ys[kk dk;kZy; i`"B la[;k Accounts Office File No. | I3: 3028
A4: ekg vkSj rkjh[k Month and Date | B4: izkfIr ;k fuxZe okmpj la[;k vkSj rkjh[k No. and Date of Receiot or issue Voucher | C4: fdlls izkIr gqvk ;k fdls tkjh fd;k From Whom received or to whom issued | D4: izkfIr ;k fuxZe dk mn~ns'; Purpose for which received or issue | E4: izkfIr Receipt | F4: LFkkukarj.k Transfer | G4: fuxZe Issues | H4: 'ks"k Balance | I4: vk|{kj Signature
E5: ux No. Vu Tonnes fd-xzk-Kgs. | F5: ux No. Vu Tonnes fd-xzk-Kgs. | G5: ux No. Vu Tonnes fd-xzk-Kgs. | H5: ux No. Vu Tonnes fd-xzk-Kgs.
E6: =SUM(E7:E1000) -> 46 | F6: =SUM(F7:F1000) -> 0 | G6: =SUM(G7:G1000) -> 44 | H6: =+E6-F6-G6 -> 2
A7: 30/06/2024 | B7: 0101/24-25 | C7: M/S Chakradhar Industries LLp | D7: Track Related work | E7: 40 | F7: 0 | G7: 0 | H7: =SUM(E7:G7) -> 40
A8: 45480 | B8: 1203/GP/DFC/ Ambala dated: 07/07/2024 | C8: Sr.Exe/CIVIL/SMUN | D8: P-way works | E8: 0 | F8: 0 | G8: 15 | H8: =H7-G8-F8+E8 -> 25
A9: 15/07/2024 | B9: GP/DFC/Ambala Sr.No. 1208 | C9: IMSD/JUDN | D9: P-way works | E9: 0 | F9: 0 | G9: 4 | H9: =H8-G9-F9+E9 -> 21
A10: 25/03/2025 | B10: GP/DFC Ambala 1198 Dated: 25/03/2025 | C10: IMSD/JUDN | D10: P-way works | E10: 0 | F10: 0 | G10: 4 | H10: =H9-G10-F10+E10 -> 17
A11: 13/8/2025 | B11: GP/DFC Ambala Sr No. 1151 | C11: Km 1236/15-16 CHAN Yard | D11: P-way works | E11: 0 | F11: 0 | G11: 8 | H11: =H10-G11-F11+E11 -> 9
A12: 45969 | B12: GP/DFC Ambala Sr No.1159 | C12: Km 1212/2-3 GVGN Yard | D12: P-way works | E12: 0 | F12: 0 | G12: 9 | H12: =H11-G12-F12+E12 -> 0
A13: 25/2/2026 | B13: IMSD SKFN/MTO/350/35 dt 21.02.2026 | C13: IMSD/SKFM | D13: P-way works | E13: 6 | F13: 0 | G13: 0 | H13: =H12-G13-F13+E13 -> 6
A14: 25/02/2026 | B14: GP/DFC Ambala Sr No. 1174 | C14: Km 1208/15 and 1212/02 | D14: P-way works | E14: 0 | F14: 0 | G14: 4 | H14: =H13-G14-F14+E14 -> 2

Sheet 3030
B1: foHkkxh; [kkrk feyku iqLrd DEPARTMENTAL LEDGER AND TALLY BOOK
A2: ewY; lwph@dwV la[;k Price List / Code No. | D2: 11 | E2: feyku i= la[;k Tally Code No. | H2: 1 | I2: ;wfuV Unit | J2: 3
A3: oLrq dk fooj.k Description of the Article | D3: RAIL GRINDING STONE | E3: ys[kk dk;kZy; i`"B la[;k Accounts Office File No. | I3: 3030
A4: ekg vkSj rkjh[k Month and Date | B4: izkfIr ;k fuxZe okmpj la[;k vkSj rkjh[k No. and Date of Receiot or issue Voucher | C4: fdlls izkIr gqvk ;k fdls tkjh fd;k From Whom received or to whom issued | D4: izkfIr ;k fuxZe dk mn~ns'; Purpose for which received or issue | E4: izkfIr Receipt | F4: LFkkukarj.k Transfer | G4: fuxZe Issues | H4: 'ks"k Balance | I4: 3
E5: ux No. Vu Tonnes fd-xzk-Kgs. | F5: ux No. Vu Tonnes fd-xzk-Kgs. | G5: ux No. Vu Tonnes fd-xzk-Kgs. | H5: ux No. Vu Tonnes fd-xzk-Kgs.
E6: =SUM(E7:E998) -> 28 | F6: =SUM(F7:F998) -> 0 | G6: =SUM(G7:G998) -> 21 | H6: =+E6-F6-G6 -> 7
A7: 45601 | B7: 183 Dated 10.5.2024 | C7: M.S Trades & Eng | D7: Track Related works | E7: 25 | F7: 0 | G7: 0 | H7: =SUM(E7:G7) -> 25
A8: 16/05/2024 | B8: 183 Dated 10.5.2024 M.S Trades & engg | C8: Abhishek Sharma Executive/CIVILl/ JUDN | D8: P-Way works | E8: 0 | F8: 0 | G8: 12 | H8: =H7+E8+-F8-G8 -> 13
A9: 45473 | B9: 0101/24-25 dt. 30.06.2024 | C9: M/S chakradher industries | D9: P-Way works | E9: 3 | F9: 0 | G9: 0 | H9: =H8+E9+-F9-G9 -> 16
A10: 45480 | B10: GP/DFC/Ambala sr. no 1204 dt. 07.07.2024 | C10: Sr.Exex./SMUN/c | D10: P-Way works | E10: 0 | F10: 0 | G10: 1 | H10: =H9+E10+-F10-G10 -> 15
A11: 15.07.2024 | B11: GP/DFC/Ambala sr. no 1208 dt. 15.07.2024 | C11: Sr.Exex./SMUN/c | D11: P-Way works | E11: 0 | F11: 0 | G11: 1 | H11: =H10+E11+-F11-G11 -> 14
A12: 46051 | B12: GP/DFC/Ambala sr. no 1169 dt. 29.01.2026 | C12: km 1208 | D12: P-Way works | E12: 0 | F12: 0 | G12: 2 | H12: =H11+E12+-F12-G12 -> 12
A13: 46112 | B13: GP/DFC/Ambala sr. no 2204dt. 31.03.2026 | C13: welding site | D13: P-Way works | E13: 0 | F13: 0 | G13: 3 | H13: =H12+E13+-F13-G13 -> 9
A14: 46134 | B14: GP/DFC/Ambala sr. no 2206 dt. 22.04.2026 | C14: welding site | D14: P-Way works | E14: 0 | F14: 0 | G14: 2 | H14: =H13+E14+-F14-G14 -> 7

Sheet 3033
B1: foHkkxh; [kkrk feyku iqLrd DEPARTMENTAL LEDGER AND TALLY BOOK
A2: ewY; lwph@dwV la[;k Price List / Code No. | D2: 12 | E2: feyku i= la[;k Tally Code No. | H2: 2 | I2: ;wfuV Unit | J2: 12
A3: oLrq dk fooj.k Description of the Article | D3: Wooden Block | E3: ys[kk dk;kZy; i`"B la[;k Accounts Office File No. | I3: 3033
A4: ekg vkSj rkjh[k Month and Date | B4: izkfIr ;k fuxZe okmpj la[;k vkSj rkjh[k No. and Date of Receiot or issue Voucher | C4: fdlls izkIr gqvk ;k fdls tkjh fd;k From Whom received or to whom issued | D4: izkfIr ;k fuxZe dk mn~ns'; Purpose for which received or issue | E4: izkfIr Receipt | F4: LFkkukarj.k Transfer | G4: fuxZe Issues | H4: 'ks"k Balance | I4: vk|{kj Signature
E5: ux No. Vu Tonnes fd-xzk-Kgs. | F5: ux No. Vu Tonnes fd-xzk-Kgs. | G5: ux No. Vu Tonnes fd-xzk-Kgs. | H5: ux No. Vu Tonnes fd-xzk-Kgs.
E6: =SUM(E7:E1000) -> 250 | F6: =SUM(F7:F1000) -> 0 | G6: =SUM(G7:G1000) -> 203 | H6: =+E6-F6-G6 -> 47
A7: 20/07/2024 | B7: 11 Dated 20/07/2024 | C7: M/S Traders & engineers. | D7: P-way works | E7: 248 | F7: 0 | G7: 0 | H7: =SUM(E7:G7) -> 248
A8: 26/07/2024 | B8: 11 Dated 20/07/2024 | C8: M/S Traders & engineers. | D8: P-way works | E8: 2 | F8: 0 | G8: 0 | H8: =SUM(E8:G8) -> 2
A9: 45512 | B9: GP/DFC/ Ambala Sr.No. 1213 | C9: Abhishek Sharma /Exe / CIVILi/ JUDN/ IMSD /JUDN | D9: P-way works | E9: 0 | F9: 0 | G9: 125 | H9: =H8-G9-F9+E9 -> -123
A10: 30/01/2025 | B10: GP/DFC/ Ambala 1192 dated: 30/01/2025 | C10: Surendera Kumar Sr. Exec/ CIVILl/ KNNN | D10: p-way maint works | E10: 0 | F10: 0 | G10: 3 | H10: =H9-G10-F10+E10 -> -126
A11: 29/01/2026 | B11: GP/DFC/ Ambala Sr. No. 1168 | C11: km 1208/15-16 for welding work and Br.170 and 165 | D11: p-way maint works | E11: 0 | F11: 0 | G11: 10 | H11: 112
A12: 46298 | B12: GP/DFC/ Ambala Sr. No. 1168 | C12: Gaurd Rail use to MSD | D12: p-way maint works | E12: 0 | F12: 0 | G12: 15 | H12: 97
A13: 22/04/2026 | B13: GP/DFC/ Ambala Sr. No. 1168 | C13: Use in om weding work | D13: p-way maint works | E13: 0 | F13: 0 | G13: 50 | H13: 47

Sheet 3036
B1: foHkkxh; [kkrk feyku iqLrd DEPARTMENTAL LEDGER AND TALLY BOOK
A2: ewY; lwph@dwV la[;k Price List / Code No. | D2: 13 | E2: feyku i= la[;k Tally Code No. | H2: 2 | I2: ;wfuV Unit | J2: 13
A3: oLrq dk fooj.k Description of the Article | D3: Synthetic Lubricating Grease (Lithm) | E3: ys[kk dk;kZy; i`"B la[;k Accounts Office File No. | I3: 3036
A4: ekg vkSj rkjh[k Month and Date | B4: izkfIr ;k fuxZe okmpj la[;k vkSj rkjh[k No. and Date of Receiot or issue Voucher | C4: fdlls izkIr gqvk ;k fdls tkjh fd;k From Whom received or to whom issued | D4: izkfIr ;k fuxZe dk mn~ns'; Purpose for which received or issue | E4: izkfIr Receipt | F4: LFkkukarj.k Transfer | G4: fuxZe Issues | H4: 'ks"k Balance | I4: vk|{kj Signature
E5: ux No. Vu Tonnes fd-xzk-Kgs. | F5: ux No. Vu Tonnes fd-xzk-Kgs. | G5: ux No. Vu Tonnes fd-xzk-Kgs. | H5: ux No. Vu Tonnes fd-xzk-Kgs.
E6: =SUM(E7:E1000) -> 546 | F6: =SUM(F7:F1000) -> 0 | G6: =SUM(G7:G1000) -> 364 | H6: =+E6-F6-G6 -> 182
A7: 45606 | B7: 101/09.10.2024 | C7: Sai Associates Sector -50 Noida | D7: P-way works | E7: 546 | F7: 0 | G7: 0 | H7: =SUM(E7:G7) -> 546
A8: 14/10/2024 | B8: 1223/GP/DFC/ Ambala dated: 14/10/2024 | C8: IMSD JUDN Executive / CIVILl/ JUDN | D8: P-way works | E8: 0 | F8: 0 | G8: 364 | H8: =H7-G8-F8+E8 -> 182

Sheet 3038
B1: foHkkxh; [kkrk feyku iqLrd DEPARTMENTAL LEDGER AND TALLY BOOK
A2: ewY; lwph@dwV la[;k Price List / Code No. | D2: 14 | E2: feyku i= la[;k Tally Code No. | H2: 2 | I2: ;wfuV Unit | J2: 14
A3: oLrq dk fooj.k Description of the Article | D3: Herbicide (HERBICIDE) | E3: ys[kk dk;kZy; i`"B la[;k Accounts Office File No. | I3: 3038
A4: ekg vkSj rkjh[k Month and Date | B4: izkfIr ;k fuxZe okmpj la[;k vkSj rkjh[k No. and Date of Receiot or issue Voucher | C4: fdlls izkIr gqvk ;k fdls tkjh fd;k From Whom received or to whom issued | D4: izkfIr ;k fuxZe dk mn~ns'; Purpose for which received or issue | E4: izkfIr Receipt | F4: LFkkukarj.k Transfer | G4: fuxZe Issues | H4: 'ks"k Balance | I4: vk|{kj Signature
E5: ux No. Vu Tonnes fd-xzk-Kgs. | F5: ux No. Vu Tonnes fd-xzk-Kgs. | G5: ux No. Vu Tonnes fd-xzk-Kgs. | H5: ux No. Vu Tonnes fd-xzk-Kgs.
E6: =SUM(E7:E998) -> 520 | F6: =SUM(F7:F998) -> 0 | G6: =SUM(G7:G998) -> 366 | H6: =+E6-F6-G6 -> 154
A7: 20/9/2024 | B7: 1301 Dated 16.09.2024 (imprest) | C7: AMTTAL PESTCIDES Near Amar hossssspital ghnour | D7: P-way Related work | E7: 3.5 | F7: 0 | G7: 0 | H7: 3.5
A8: 24/10/2024 | B8: 1303 Dated 3.10.2024 (imprest) | C8: AMTTAL PESTCIDES Near Amar hossssspital ghnour | D8: P-way Related work | E8: 3.5 | F8: 0 | G8: 0 | H8: =H7+E8-F8-G8 -> 7
A9: 24/10/2024 | B9: 409 Date 13.10.2024 (imprest) | C9: M/S DAWRA SEEDS RAIPURA | D9: P-way Related work | E9: 4 | F9: 0 | G9: 0 | H9: =H8-G9-F9+E9 -> 11
A10: 24/10/2024 | B10: 410 Date 13.10.2024 (imprest) | C10: M/S DAWRA SEEDS RAIPURA | D10: P-way Related work | E10: 4 | F10: 0 | G10: 0 | H10: =H9-G10-F10+E10 -> 15
A11: 24/10/2024 | B11: 411 Date 13.10.2024 (imprest) | C11: M/S DAWRA SEEDS RAIPURA | D11: P-way Related work | E11: 5 | F11: 0 | G11: 0 | H11: =H10-G11-F11+E11 -> 20
A12: 24/10/2024 | B12: Gp/DFC/ Ambala Sr. No. 1176 24.10.2024 | C12: Harpal singh Sr. exe/CIVILl/ SMUN | D12: P-way Related work | E12: 0 | F12: 0 | G12: 20 | H12: =H11-G12-F12+E12 -> 0
A13: 28/01/2024 | B13: Invoice No. Inr- 2024-25-80 date 24.01.2025 | C13: Alfa Express services | D13: P-way Related work | E13: 500 | F13: 0 | G13: 0 | H13: =H12-G13-F13+E13 -> 500
A14: 2.12.2025 | B14: GP/DFC/ Ambala Sr. No. 1163 | C14: Use in gate LC | D14: P-way Related work | E14: 0 | F14: 0 | G14: 15 | H14: 485
A15: 13.12.2025 | B15: GP/DFC/ Ambala Sr. No. 1164 | C15: Use in section | D15: P-way Related work | E15: 0 | F15: 0 | G15: 15 | H15: 470
A16: 22/1/2026 | B16: GP/DFC/ Ambala Sr. No. 1165 | C16: IMSD/JUDN | D16: P-way Related work | E16: 0 | F16: 0 | G16: 250 | H16: 220
A17: 31/1/2026 | B17: GP/DFC/ Ambala Sr. No. 1171 | C17: Use in section at km 1190 to 1201 and 1175 to 1180 | D17: P-way Related work | E17: 0 | F17: 0 | G17: 34 | H17: 186
A18: 46162 | B18: GP/DFC/ Ambala Sr. No. 2210 | C18: use in section at SBJN Yard | D18: P-way Related work | E18: 0 | F18: 0 | G18: 20 | H18: 166
A19: 46231 | B19: GP/DFC/ Ambala Sr. No. 2026 | C19: Elect dept | D19: P-way Related work | E19: 0 | F19: 0 | G19: 12 | H19: 154

Sheet 3047
B1: foHkkxh; [kkrk feyku iqLrd DEPARTMENTAL LEDGER AND TALLY BOOK
A2: ewY; lwph@dwV la[;k Price List / Code No. | D2: 22 | E2: feyku i= la[;k Tally Code No. | H2: 1 | I2: ;wfuV Unit | J2: 1
A3: oLrq dk fooj.k Description of the Article | D3: Safety Jacket | E3: ys[kk dk;kZy; i`"B la[;k Accounts Office File No. | I3: 3047
A4: ekg vkSj rkjh[k Month and Date | B4: izkfIr ;k fuxZe okmpj la[;k vkSj rkjh[k No. and Date of Receiot or issue Voucher | C4: fdlls izkIr gqvk ;k fdls tkjh fd;k From Whom received or to whom issued | D4: izkfIr ;k fuxZe dk mn~ns'; Purpose for which received or issue | E4: izkfIr Receipt | F4: LFkkukarj.k Transfer | G4: fuxZe Issues | H4: 'ks"k Balance | I4: 3
E5: ux No. Vu Tonnes fd-xzk-Kgs. | F5: ux No. Vu Tonnes fd-xzk-Kgs. | G5: ux No. Vu Tonnes fd-xzk-Kgs. | H5: ux No. Vu Tonnes fd-xzk-Kgs.
E6: =SUM(E7:E998) -> 300 | F6: =SUM(F7:F998) -> 0 | G6: =SUM(G7:G998) -> 255 | H6: =+E6-F6-G6 -> 45
A7: 17/03/2024 | B7: 167 Dated 16.03.2024 | C7: M.S Traders & Enginers | D7: Track mainteance Related work | E7: 100 | F7: 0 | G7: 0 | H7: =SUM(E7:G7) -> 100
A8: 28/05//2024 | B8: 167 DATED 16.03.2024 M.S. Tradness & engg | C8: Exce/ CIVILl-1/ JUDN Abhishek Sharma | D8: issued to IMSD JUDN | E8: 0 | F8: 0 | G8: 50 | H8: =H7+E8-F8-G8 -> 50
A9: 45363 | B9: GP/DFC/ Ambala /1182 dated 03.12.2024 | C9: Sub shyam lal,Retd AWPO Ambala | D9: for patrolmen | E9: 0 | F9: 0 | G9: 35 | H9: =H8+E9-F9-G9 -> 15
A10: 16/12/2024 | B10: GP/DFC/ Ambala /1184 dated 16.12.2024 | C10: Vibhanshu Prasher Exce/ CIVILl/ JUDN | D10: P-way maint work | E10: 0 | F10: 0 | G10: 10 | H10: =H9+E10-F10-G10 -> 5
A11: 15/11/2024 | B11: Invoice No. 2425069 date 11/11/2024 | C11: G.S Technology | D11: for P-way releted works Safety | E11: 200 | F11: 0 | G11: 0 | H11: =H10+E11-F11-G11 -> 205
A12: 29/01/2024 | B12: GP/DFC/ Ambala /1190 dtae 29.01.2025 | C12: Harpal singh Sr. Exe/CIVILl/SMUN | D12: P-way works | E12: 0 | F12: 0 | G12: 10 | H12: =H11+E12-F12-G12 -> 195
A13: 45759 | B13: Note Dated 12/04/2025 IMSD/incharge | C13: for Keyman use | D13: key man use | E13: 0 | F13: 0 | G13: 19 | H13: =H12+E13-F13-G13 -> 176
A14: 45846 | B14: for Mansoon patrolling | C14: for Mansoon patrolling | D14: for Mansoon patrolling | E14: 0 | F14: 0 | G14: 22 | H14: =H13+E14-F14-G14 -> 154
A15: 45973 | B15: for cold weather patrolman | C15: for cold weather patrolman | D15: for cold weather patrolman | E15: 0 | F15: 0 | G15: 25 | H15: =H14+E15-F15-G15 -> 129
A16: 46247 | B16: GP/26/000115 dt. 13.08.2026 | C16: Security Patrolling after bomb blast | D16: Track Patrolling | E16: 0 | F16: 0 | G16: 29 | H16: =H15+E16-F16-G16 -> 100
A17: 46247 | B17: GP/26/000116 dt. 13.08.2026 | C17: Keyman | D17: Track Patrolling | E17: 0 | F17: 0 | G17: 18 | H17: =H16+E17-F17-G17 -> 82
A18: 46247 | B18: GP/26/000117 dt. 13.08.2026 | C18: Bridge Watchman | D18: Track Patrolling | E18: 0 | F18: 0 | G18: 3 | H18: =H17+E18-F18-G18 -> 79
A19: 46247 | B19: GP/26/000118 dt. 13.08.2026 | C19: Black Smith and helper | D19: Track Patrolling | E19: 0 | F19: 0 | G19: 3 | H19: =H18+E19-F19-G19 -> 76
A20: 46247 | B20: GP/26/000119dt. 13.08.2026 | C20: Rpf Staff | D20: Track Patrolling | E20: 0 | F20: 0 | G20: 5 | H20: =H19+E20-F20-G20 -> 71
A21: 46247 | B21: GP/26/000120dt. 13.08.2026 | C21: Gang Staff | D21: Track Patrolling | E21: 0 | F21: 0 | G21: 16 | H21: =H20+E21-F21-G21 -> 55
A22: 46247 | B22: GP/26/000121dt. 13.08.2027 | C22: MTS Staff | D22: Track Patrolling | E22: 0 | F22: 0 | G22: 10 | H22: =H21+E22-F22-G22 -> 45

Sheet 3049
B1: foHkkxh; [kkrk feyku iqLrd DEPARTMENTAL LEDGER AND TALLY BOOK
A2: ewY; lwph@dwV la[;k Price List / Code No. | D2: 22 | E2: feyku i= la[;k Tally Code No. | H2: 1 | I2: ;wfuV Unit | J2: 1
A3: oLrq dk fooj.k Description of the Article | D3: Empty Bag | E3: ys[kk dk;kZy; i`"B la[;k Accounts Office File No. | I3: 3049
A4: ekg vkSj rkjh[k Month and Date | B4: izkfIr ;k fuxZe okmpj la[;k vkSj rkjh[k No. and Date of Receiot or issue Voucher | C4: fdlls izkIr gqvk ;k fdls tkjh fd;k From Whom received or to whom issued | D4: izkfIr ;k fuxZe dk mn~ns'; Purpose for which received or issue | E4: izkfIr Receipt | F4: LFkkukarj.k Transfer | G4: fuxZe Issues | H4: 'ks"k Balance | I4: 3
E5: ux No. Vu Tonnes fd-xzk-Kgs. | F5: ux No. Vu Tonnes fd-xzk-Kgs. | G5: ux No. Vu Tonnes fd-xzk-Kgs. | H5: ux No. Vu Tonnes fd-xzk-Kgs.
E6: =SUM(E7:E998) -> 6300 | F6: =SUM(F7:F998) -> 0 | G6: =SUM(G7:G998) -> 1300 | H6: =+E6-F6-G6 -> 5000
A7: 45839 | B7: GP/DFC/Ambala/sr.no. 1551 dt. 01.07.2025 | C7: IMD/CHAN | D7: Track mainteance Related work | E7: 100 | F7: 0 | G7: 0 | H7: =SUM(E7:G7) -> 100
A8: 45867 | B8: GP/DFC/Ambala/sr.no. 1555dt. 29.07.2026 | C8: IMD/CHAN | D8: Track mainteance Related work | E8: 100 | F8: 0 | G8: 0 | H8: =+H7+E8-F8-G8 -> 200
A9: 45868 | B9: GP/DFC/Ambala/sr.no. 1556 dt. 30.07.2025 | C9: IMD/CHAN | D9: Track mainteance Related work | E9: 100 | F9: 0 | G9: 0 | H9: =+H8+E9-F9-G9 -> 300
A10: 45869 | B10: GP/DFC/Ambala/sr.no. 1557 dt. 31.07.2025 | C10: IMD/CHAN | D10: Track mainteance Related work | E10: 1000 | F10: 0 | G10: 0 | H10: =+H9+E10-F10-G10 -> 1300
A11: 46189 | B11: GP/DFC/Ambala/sr.no.2139 dt. 16.06.2026 | C11: Use in Rain Cut | D11: Track mainteance Related work | E11: 0 | F11: 0 | G11: 1300 | H11: =+H10+E11-F11-G11 -> 0
A12: 46223 | B12: GP/DFC/Ambala/sr.no.1575 dt. 20.07.2026 | C12: IMD/CHAN | D12: Track mainteance Related work | E12: 5000 | F12: 0 | G12: 0 | H12: =+H11+E12-F12-G12 -> 5000

Sheet 3051
B1: foHkkxh; [kkrk feyku iqLrd DEPARTMENTAL LEDGER AND TALLY BOOK
A2: ewY; lwph@dwV la[;k Price List / Code No. | D2: 22 | E2: feyku i= la[;k Tally Code No. | H2: 1 | I2: ;wfuV Unit | J2: 1
A3: oLrq dk fooj.k Description of the Article | D3: Wooden block fo Guaard Rail | E3: ys[kk dk;kZy; i`"B la[;k Accounts Office File No. | I3: 3051
A4: ekg vkSj rkjh[k Month and Date | B4: izkfIr ;k fuxZe okmpj la[;k vkSj rkjh[k No. and Date of Receiot or issue Voucher | C4: fdlls izkIr gqvk ;k fdls tkjh fd;k From Whom received or to whom issued | D4: izkfIr ;k fuxZe dk mn~ns'; Purpose for which received or issue | E4: izkfIr Receipt | F4: LFkkukarj.k Transfer | G4: fuxZe Issues | H4: 'ks"k Balance | I4: 3
E5: ux No. Vu Tonnes fd-xzk-Kgs. | F5: ux No. Vu Tonnes fd-xzk-Kgs. | G5: ux No. Vu Tonnes fd-xzk-Kgs. | H5: ux No. Vu Tonnes fd-xzk-Kgs.
E6: =SUM(E7:E998) -> 50 | F6: =SUM(F7:F998) -> 0 | G6: =SUM(G7:G998) -> 32 | H6: =+E6-F6-G6 -> 18
A7: 45913 | B7: Invoice no.125 Dated 13.09.2025 | C7: Sai Associates | D7: for guard Rail | E7: 50 | F7: 0 | G7: 0 | H7: =SUM(E7:G7) -> 50
A8: 45922 | B8: Gate Pass No. GP/25/000111 Date 22.09.2026 | C8: IMSD/JUDN | D8: for guard Rail | E8: 0 | F8: 0 | G8: 20 | H8: =+H7+E8-F8-G8 -> 30
A9: 46241 | B9: GP/DFC/ Ambala sr.No. 2216 dt. 07.08.2026 | C9: Abhay kr. Maury Exe C/CHAN | D9: for guard Rail | E9: 0 | F9: 0 | G9: 12 | H9: =+H8+E9-F9-G9 -> 18

Sheet 3052
B1: foHkkxh; [kkrk feyku iqLrd DEPARTMENTAL LEDGER AND TALLY BOOK
A2: ewY; lwph@dwV la[;k Price List / Code No. | D2: 4 | E2: feyku i= la[;k Tally Code No. | H2: 1 | I2: ;wfuV Unit | J2: 1
A3: oLrq dk fooj.k Description of the Article | D3: PATROLMAN TORCH | E3: ys[kk dk;kZy; i`"B la[;k Accounts Office File No. | I3: 3052
A4: ekg vkSj rkjh[k Month and Date | B4: izkfIr ;k fuxZe okmpj la[;k vkSj rkjh[k No. and Date of Receiot or issue Voucher | C4: fdlls izkIr gqvk ;k fdls tkjh fd;k From Whom received or to whom issued | D4: izkfIr ;k fuxZe dk mn~ns'; Purpose for which received or issue | E4: izkfIr Receipt | F4: LFkkukarj.k Transfer | G4: fuxZe Issues | H4: 'ks"k Balance | I4: vk|{kj Signature
E5: ux No. Vu Tonnes fd-xzk-Kgs. | F5: ux No. Vu Tonnes fd-xzk-Kgs. | G5: ux No. Vu Tonnes fd-xzk-Kgs. | H5: ux No. Vu Tonnes fd-xzk-Kgs.
E6: =SUM(E7:E998) -> 150 | F6: =SUM(F7:F998) -> 0 | G6: =SUM(G7:G998) -> 150 | H6: =+E6-F6-G6 -> 0
A7: 17/03/2024 | B7: 167 Dated 16.03.2024 | C7: M.S Traders & Enginers | D7: For track Maintence & Related works | E7: 50 | F7: 0 | G7: 0 | H7: =SUM(E7:G7) -> 50
A8: 28/05/2024 | B8: 167 Date 16.03.2024 M.S Treades & engg | C8: Exce/ CIVILl-1/ JUDN Abhishek Sharma | D8: Issued to IMSD JUDN | E8: 0 | F8: 0 | G8: 25 | H8: =H7+E8-F8-G8 -> 25
A9: 45329 | B9: 167 Date 16.03.2024 M.S Treades & engg | C9: Dy. CPM/ENGG/-11/UMB J.P GOYAL | D9: For officiol Purpose | E9: 0 | F9: 0 | G9: 1 | H9: =H8+E9-F9-G9 -> 24
A10: 17/08/2024 | B10: 167 Date 16.03.2024 M.S Treades & engg | C10: DPM/ENGG-111/UMB Amarnath | D10: For officiol Purpose | E10: 0 | F10: 0 | G10: 1 | H10: =H9+E10-F10-G10 -> 23
A11: 27/11/2024 | B11: GP/DFC/ Ambala / 1181 Dated: 27.11.2024 | C11: Gurnaam singh operation officer, AWPO | D11: For Petrolmen | E11: 0 | F11: 0 | G11: 10 | H11: =H10+E11-F11-G11 -> 13
A12: 45363 | B12: GP/DFC/ Ambala / 1182 Dated: 03.12.2024 | C12: Sub,Shyamlal, Retd Aunpo, Ambala | D12: For Petrolmen | E12: 0 | F12: 0 | G12: 10 | H12: =H11+E12-F12-G12 -> 3
A13: 16/12/2024 | B13: GP/DFC/ Ambala / 1182 Dated: 16.12.2024 | C13: Vibhanshu Prasher, Exe/ar/ JUDN | D13: P-way maint work | E13: 0 | F13: 0 | G13: 3 | H13: =H12+E13-F13-G13 -> 0
A14: 20/12/2024 | B14: Invoice No. 026/ 24-25 dated 17.12.2024 | C14: Shri Bala ji seth enterprises | D14: P-way Related work | E14: 100 | F14: 0 | G14: 0 | H14: =H13+E14-F14-G14 -> 100
A15: 26/12/2024 | B15: GP/DFC/Ambala SR. NO. 1185 DATE 26.12.2024 | C15: Arvind yadav Executive/CIVILl/ JUDN | D15: P-way Related work | E15: 0 | F15: 0 | G15: 50 | H15: =H14+E15-F15-G15 -> 50
A16: 45973 | B16: issue for patrolman | C16: Mansoon and Cold weather patrolman | D16: P-way Related work | E16: 0 | F16: 0 | G16: 22 | H16: =H15+E16-F16-G16 -> 28
A17: 46247 | B17: GP/26/000115 dt. 13.08.2026 | C17: Security Patrolling | D17: P-way Related work | E17: 0 | F17: 0 | G17: 28 | H17: =H16+E17-F17-G17 -> 0

Sheet 3056
B1: foHkkxh; [kkrk feyku iqLrd DEPARTMENTAL LEDGER AND TALLY BOOK
A2: ewY; lwph@dwV la[;k Price List / Code No. | D2: 6 | E2: feyku i= la[;k Tally Code No. | H2: 1 | I2: ;wfuV Unit | J2: 1
A3: oLrq dk fooj.k Description of the Article | D3: DRAGON TORCH | E3: ys[kk dk;kZy; i`"B la[;k Accounts Office File No. | I3: 3056
A4: ekg vkSj rkjh[k Month and Date | B4: izkfIr ;k fuxZe okmpj la[;k vkSj rkjh[k No. and Date of Receiot or issue Voucher | C4: fdlls izkIr gqvk ;k fdls tkjh fd;k From Whom received or to whom issued | D4: izkfIr ;k fuxZe dk mn~ns'; Purpose for which received or issue | E4: izkfIr Receipt | F4: LFkkukarj.k Transfer | G4: fuxZe Issues | H4: 'ks"k Balance | I4: s
E5: ux No. Vu Tonnes fd-xzk-Kgs. | F5: ux No. Vu Tonnes fd-xzk-Kgs. | G5: ux No. Vu Tonnes fd-xzk-Kgs. | H5: ux No. Vu Tonnes fd-xzk-Kgs.
E6: =SUM(E7:E998) -> 12 | F6: =SUM(F7:F998) -> 0 | G6: =SUM(G7:G998) -> 12 | H6: =+E6-F6-G6 -> 0
A7: 17/03/2024 | B7: 167 Dated 16.03.2024 | C7: M.S Traders & Enginers | D7: For track Maintence & Related works | E7: 12 | F7: 0 | G7: 0 | H7: =SUM(E7:G7) -> 12
A8: 28/05/2024 | B8: 167 Date 16.03.2024 M.S Treades & engg | C8: Exce/ CIVILl-1/ JUDN Abhishek Sharma | D8: Issued to IMSD JUDN | E8: 0 | F8: 0 | G8: 6 | H8: =H7-G8-F8+E8 -> 6
A9: 28/05/2024 | B9: 167 Date 16.03.2024 M.S Treades & engg Issue note-40 & Date 28.05.2024 | C9: Dy. CPM/Engg-11/UNB J.P Goyal | D9: for official purpose | E9: 0 | F9: 0 | G9: 6 | H9: =H8-G9-F9+E9 -> 0

Sheet 3057
B1: foHkkxh; [kkrk feyku iqLrd DEPARTMENTAL LEDGER AND TALLY BOOK
A2: ewY; lwph@dwV la[;k Price List / Code No. | D2: 5 | E2: feyku i= la[;k Tally Code No. | H2: 1 | I2: ;wfuV Unit | J2: 1
A3: oLrq dk fooj.k Description of the Article | D3: UMBERELLA | E3: ys[kk dk;kZy; i`"B la[;k Accounts Office File No. | I3: 3212
A4: ekg vkSj rkjh[k Month and Date | B4: izkfIr ;k fuxZe okmpj la[;k vkSj rkjh[k No. and Date of Receiot or issue Voucher | C4: fdlls izkIr gqvk ;k fdls tkjh fd;k From Whom received or to whom issued | D4: izkfIr ;k fuxZe dk mn~ns'; Purpose for which received or issue | E4: izkfIr Receipt | F4: LFkkukarj.k Transfer | G4: fuxZe Issues | H4: 'ks"k Balance | I4: s
E5: ux No. Vu Tonnes fd-xzk-Kgs. | F5: ux No. Vu Tonnes fd-xzk-Kgs. | G5: ux No. Vu Tonnes fd-xzk-Kgs. | H5: ux No. Vu Tonnes fd-xzk-Kgs.
E6: =SUM(E7:E998) -> 25 | F6: =SUM(F7:F998) -> 0 | G6: =SUM(G7:G998) -> 21 | H6: =+E6-F6-G6 -> 4
A7: 17/03/2024 | B7: 167 Dated 16.03.2024 | C7: M.S Traders & Enginers | D7: For track Maintence & Related works | E7: 25 | F7: 0 | G7: 0 | H7: =SUM(E7:G7) -> 25
A8: 28/05/2024 | B8: 167 Date 16.03.2024 M.S Treades & engg | C8: Exce/ CIVILl-1/ JUDN Abhishek Sharma | D8: Issued to IMSD JUDN | E8: 0 | F8: 0 | G8: 12 | H8: =H7+E8-F8-G8 -> 13
A9: 45329 | B9: 167 Date 16.03.2024 M.S Treades & engg | C9: Dy. CPM/Engg-11/UNB J.P Goyal | D9: for official purpose | E9: 0 | F9: 0 | G9: 1 | H9: =H8+E9-F9-G9 -> 12
A10: 22/01/2026 | B10: GP/DFC/AMBALA/Sr. No. 1166 | C10: IMD/CHAN | D10: for official purpose | E10: 0 | F10: 0 | G10: 8 | H10: =H9+E10-F10-G10 -> 4

Sheet 3059
B1: foHkkxh; [kkrk feyku iqLrd DEPARTMENTAL LEDGER AND TALLY BOOK
A2: ewY; lwph@dwV la[;k Price List / Code No. | D2: 20 | E2: feyku i= la[;k Tally Code No. | H2: 1 | I2: ;wfuV Unit | J2: 1
A3: oLrq dk fooj.k Description of the Article | D3: BANNER FLAG | E3: ys[kk dk;kZy; i`"B la[;k Accounts Office File No. | I3: 3059
A4: ekg vkSj rkjh[k Month and Date | B4: izkfIr ;k fuxZe okmpj la[;k vkSj rkjh[k No. and Date of Receiot or issue Voucher | C4: fdlls izkIr gqvk ;k fdls tkjh fd;k From Whom received or to whom issued | D4: izkfIr ;k fuxZe dk mn~ns'; Purpose for which received or issue | E4: izkfIr Receipt | F4: LFkkukarj.k Transfer | G4: fuxZe Issues | H4: 'ks"k Balance | I4: 3
E5: ux No. Vu Tonnes fd-xzk-Kgs. | F5: ux No. Vu Tonnes fd-xzk-Kgs. | G5: ux No. Vu Tonnes fd-xzk-Kgs. | H5: ux No. Vu Tonnes fd-xzk-Kgs.
E6: =SUM(E7:E998) -> 50 | F6: =SUM(F7:F998) -> 0 | G6: =SUM(G7:G998) -> 27 | H6: =+E6-F6-G6 -> 23
A7: 17/03/2024 | B7: 167 Dated 16.03.2024 | C7: M.S Traders & Enginers | D7: For Track Related works | E7: 50 | F7: 0 | G7: 0 | H7: =SUM(E7:G7) -> 50
A8: 17/03/2024 | B8: 167 Dated 16.03.2024 | C8: JPM/ENGG/JUDN Sh. Pankaj Joshi | D8: For Track Related works | E8: 0 | F8: 0 | G8: 6 | H8: 44
A9: 28/05/2024 | B9: 167 Date 16.03.2024 M.S Treades & engg | C9: Exce/ engg l-1/ JUDN Abhishek Sharma | D9: issued to IMSD JUDN | E9: 0 | F9: 0 | G9: 19 | H9: 25
A10: 16/08/2024 | B10: GP/DFC/ Ambala Sr. No. 1217 | C10: Satish kumar Bhardwaj Sr.exe/mech/SMUN | D10: Machine department | E10: 0 | F10: 0 | G10: 2 | H10: 23

Sheet 3061
B1: foHkkxh; [kkrk feyku iqLrd DEPARTMENTAL LEDGER AND TALLY BOOK
A2: ewY; lwph@dwV la[;k Price List / Code No. | D2: 25 | E2: feyku i= la[;k Tally Code No. | H2: 1 | I2: ;wfuV Unit | J2: 1
A3: oLrq dk fooj.k Description of the Article | D3: KEY MEN BAG | E3: ys[kk dk;kZy; i`"B la[;k Accounts Office File No. | I3: 3061
A4: ekg vkSj rkjh[k Month and Date | B4: izkfIr ;k fuxZe okmpj la[;k vkSj rkjh[k No. and Date of Receiot or issue Voucher | C4: fdlls izkIr gqvk ;k fdls tkjh fd;k From Whom received or to whom issued | D4: izkfIr ;k fuxZe dk mn~ns'; Purpose for which received or issue | E4: izkfIr Receipt | F4: LFkkukarj.k Transfer | G4: fuxZe Issues | H4: 'ks"k Balance | I4: 3
E5: ux No. Vu Tonnes fd-xzk-Kgs. | F5: ux No. Vu Tonnes fd-xzk-Kgs. | G5: ux No. Vu Tonnes fd-xzk-Kgs. | H5: ux No. Vu Tonnes fd-xzk-Kgs.
E6: =SUM(E7:E998) -> 150 | F6: =SUM(F7:F998) -> 0 | G6: =SUM(G7:G998) -> 103 | H6: =+E6-F6-G6 -> 47
A7: 17/03/2024 | B7: 167 Dated 16.03.2024 | C7: M.S Traders & Enginers | D7: For Mantince Related works | E7: 150 | F7: 0 | G7: 0 | H7: =SUM(E7:G7) -> 150
A8: 28/05/2024 | B8: 167 Date 16.03.2024 M.S Treades & engg | C8: Exce/ CIVILL-1/ JUDN Abhishek Sharma | D8: issued to IMSD JUDN | E8: 0 | F8: 0 | G8: 75 | H8: =H7+E8-F8-G8 -> 75
A9: 13/09/2025 | B9: ISSUE FOR KEYMAN AT IMSD SMUN | C9: FOR KEYMAN USE | D9: P-WAY WORK | E9: 0 | F9: 0 | G9: 9 | H9: =H8+E9-F9-G9 -> 66
