Workbook

Sheet Index 
A1: f | B1: Dedicated Freight Corridor Corporation of India
A2: Index
A3: Sr.No. | B3: Particular | C3: Page No. | D3: izkfIr Receipt | E3: LFkkukarj.k Transfer | F3: fuxZe Issues | G3: 'ks"k Balance | H3: Remarks | I3: QR
A4: =ROW(A1) -> 1 | B4: GFN Liner RT-8223 and 8222 | C4: ='GFN Liner'!I3 -> 1201 | D4: ='GFN Liner'!E6 -> 19754 | E4: ='GFN Liner'!F6 -> 0 | F4: ='GFN Liner'!G6 -> 17665 | G4: ='GFN Liner'!H6 -> 2089 | H4: Pair | I4: =_xlfn.IMAGE("https://quickchart.io/qr?text="&_xlfn.ENCODEURL("Sr No: "&A2&" | Item: "&B2&" | Page No: "&C2&" | Receipt: "&D2&" | Transfer: "&E2&" | Issues: "&F2&" | Balance: "&G2&" | Remarks: "&H2)) -> #VALUE!
A5: 2 | B5: GRSP Rubber Pad RT-7010 | C5: 1205 | D5: ='Rubber pad'!E6 -> 19754 | E5: ='Rubber pad'!F6 -> 0 | F5: ='Rubber pad'!G6 -> 16510 | G5: ='Rubber pad'!H6 -> 3244 | H5: NOS. | I5: =_xlfn.IMAGE("https://quickchart.io/qr?text="&_xlfn.ENCODEURL("Sr No: "&A4&" | Item: "&B4&" | Page No: "&C4&" | Receipt: "&D4&" | Transfer: "&E4&" | Issues: "&F4&" | Balance: "&G4&" | Remarks: "&H4)) -> #VALUE!
A6: =ROW(A3) -> 3 | B6: ERC (MK-V) RT-5919 | C6: 1211 | D6: =ERC!E6 -> 39508 | E6: =ERC!F6 -> 0 | F6: =ERC!G6 -> 14335 | G6: =ERC!H6 -> 25173 | H6: NOS. | I6: =_xlfn.IMAGE("https://quickchart.io/qr?text="&_xlfn.ENCODEURL("Sr No: "&#REF!&" | Item: "&#REF!&" | Page No: "&#REF!&" | Receipt: "&#REF!&" | Transfer: "&#REF!&" | Issues: "&#REF!&" | Balance: "&#REF!&" | Remarks: "&#REF!)) -> #REF!
A7: 3 | B7: Rail 60kg | C7: 1216 | D7: =Rail!E6 -> 420 | E7: =Rail!F6 -> 0 | F7: =Rail!G6 -> 37.5 | G7: =Rail!H6 -> 382.5 | H7: NOS. | I7: =_xlfn.IMAGE("https://quickchart.io/qr?text="&_xlfn.ENCODEURL("Sr No: "&A5&" | Item: "&B5&" | Page No: "&C5&" | Receipt: "&D5&" | Transfer: "&E5&" | Issues: "&F5&" | Balance: "&G5&" | Remarks: "&H5)) -> #VALUE!
A8: =ROW(A5) -> 5 | B8: PSC Sleeper(1 in 12 DFCC D/S (trap) | C8: 1220 | D8: ='PSC Sleeper(1 in 12 DFCC D S '!E6 -> 1 | E8: ='PSC Sleeper(1 in 12 DFCC D S '!F6 -> 0 | F8: ='PSC Sleeper(1 in 12 DFCC D S '!H6 -> 1 | G8: ='PSC Sleeper(1 in 12 DFCC D S '!H6 -> 1 | H8: Sets | I8: =_xlfn.IMAGE("https://quickchart.io/qr?text="&_xlfn.ENCODEURL("Sr No: "&A6&" | Item: "&B6&" | Page No: "&C6&" | Receipt: "&D6&" | Transfer: "&E6&" | Issues: "&F6&" | Balance: "&G6&" | Remarks: "&H6)) -> #VALUE!
A9: 4 | B9: Bridge Approach Sleeper(RT-8229-8237) | C9: 1223 | D9: =' Br Sleeper(8229-37)'!E6 -> 6 | E9: =' Br Sleeper(8229-37)'!F6 -> 0 | F9: =' Br Sleeper(8229-37)'!G6 -> 0 | G9: =' Br Sleeper(8229-37)'!H6 -> 6 | H9: Sets | I9: =_xlfn.IMAGE("https://quickchart.io/qr?text="&_xlfn.ENCODEURL("Sr No: "&A7&" | Item: "&B7&" | Page No: "&C7&" | Receipt: "&D7&" | Transfer: "&E7&" | Issues: "&F7&" | Balance: "&G7&" | Remarks: "&H7)) -> #VALUE!
A10: =ROW(A7) -> 7 | B10: Level Crossing Sleeper RT-8225 | C10: 1227 | D10: ='LC Sleeper'!E6 -> 6 | E10: ='LC Sleeper'!F6 -> 0 | F10: ='LC Sleeper'!G6 -> 0 | G10: ='[1]Power Exetenter Board '!H6 -> 1 | H10: NOS. | I10: =_xlfn.IMAGE("https://quickchart.io/qr?text="&_xlfn.ENCODEURL("Sr No: "&A8&" | Item: "&B8&" | Page No: "&C8&" | Receipt: "&D8&" | Transfer: "&E8&" | Issues: "&F8&" | Balance: "&G8&" | Remarks: "&H8)) -> #VALUE!
A11: 5 | B11: Sej Sleeper (T-4149) | C11: 1228 | D11: ='SEJ Sleeper'!E6 -> 12 | E11: ='SEJ Sleeper'!F6 -> 0 | F11: ='SEJ Sleeper'!G6 -> 0 | G11: ='SEJ Sleeper'!H6 -> 12 | H11: NOS. | I11: =_xlfn.IMAGE("https://quickchart.io/qr?text="&_xlfn.ENCODEURL("Sr No: "&A9&" | Item: "&B9&" | Page No: "&C9&" | Receipt: "&D9&" | Transfer: "&E9&" | Issues: "&F9&" | Balance: "&G9&" | Remarks: "&H9)) -> #VALUE!
A12: =ROW(A9) -> 9 | B12: PSC Sleeper Bridge RT-8228 | C12: 1230 | D12: ='Br Sleeper 8228'!E6 -> 36 | E12: ='Br Sleeper 8228'!F6 -> 0 | F12: ='Br Sleeper 8228'!G6 -> 0 | G12: ='Br Sleeper 8228'!H6 -> 36 | H12: NOS.
A13: 6 | B13: PSC Sleeper RT-7008 | C13: 1234 | D13: =' Sleeper7008'!E6 -> 3499 | E13: =' Sleeper7008'!F6 -> 0 | F13: =' Sleeper7008'!G6 -> 20 | G13: =' Sleeper7008'!H6 -> 3479 | H13: NOS. | I13: =_xlfn.IMAGE("https://quickchart.io/qr?text="&_xlfn.ENCODEURL("Sr No: "&A10&" | Item: "&B10&" | Page No: "&C10&" | Receipt: "&D10&" | Transfer: "&E10&" | Issues: "&F10&" | Balance: "&G10&" | Remarks: "&H10)) -> #VALUE!
A14: =ROW(A11) -> 11 | B14: Derailing Switch With out Fitting | C14: 1238 | D14: =' Derailing Switch '!E6 -> 1 | E14: =' Derailing Switch '!F6 -> 0 | F14: =' Derailing Switch '!G6 -> 0 | G14: =' Derailing Switch '!H6 -> 1 | H14: NOS. | I14: =_xlfn.IMAGE("https://quickchart.io/qr?text="&_xlfn.ENCODEURL("Sr No: "&A11&" | Item: "&B12&" | Page No: "&C12&" | Receipt: "&D11&" | Transfer: "&E11&" | Issues: "&F11&" | Balance: "&G11&" | Remarks: "&H11)) -> #VALUE!
A15: 7 | B15: Sej with Fitting only Chair plate (Improved Single Gap) | C15: 1242 | D15: ='SEJ '!E6 -> 1 | E15: ='SEJ '!F6 -> 0 | F15: ='SEJ '!G6 -> 0 | G15: ='SEJ '!H6 -> 1 | H15: NOS. | I15: =_xlfn.IMAGE("https://quickchart.io/qr?text="&_xlfn.ENCODEURL("Sr No: "&A13&" | Item: "&B13&" | Page No: "&C13&" | Receipt: "&D13&" | Transfer: "&E13&" | Issues: "&F13&" | Balance: "&G13&" | Remarks: "&H13)) -> #VALUE!
A16: =ROW(A13) -> 13 | B16: Hook Bolt 288 x 310 mm | C16: 1245 | D16: ='Hook Bolt '!E6 -> 140 | E16: ='Hook Bolt '!F6 -> 0 | F16: ='Hook Bolt '!G6 -> 10 | G16: ='Hook Bolt '!H6 -> 130 | H16: NOS. | I16: =_xlfn.IMAGE("https://quickchart.io/qr?text="&_xlfn.ENCODEURL("Sr No: "&A14&" | Item: "&B14&" | Page No: "&C14&" | Receipt: "&D14&" | Transfer: "&E14&" | Issues: "&F14&" | Balance: "&G14&" | Remarks: "&H14)) -> #VALUE!
A17: 8 | B17: Nut Lock 24 mm | C17: 1248 | D17: ='Nut lock'!E6 -> 140 | E17: ='Nut lock'!F6 -> 0 | F17: ='Nut lock'!G6 -> 0 | G17: ='Nut lock'!H6 -> 140 | H17: NOS. | I17: =_xlfn.IMAGE("https://quickchart.io/qr?text="&_xlfn.ENCODEURL("Sr No: "&A15&" | Item: "&B15&" | Page No: "&C15&" | Receipt: "&D15&" | Transfer: "&E15&" | Issues: "&F15&" | Balance: "&G15&" | Remarks: "&H15)) -> #VALUE!
A18: =ROW(A15) -> 15 | B18: Guard Rail Galvanised RDSO T-5163 | C18: 1250 | D18: ='Gaurd Rail Rubber pad'!E6 -> 140 | E18: ='Gaurd Rail Rubber pad'!F6 -> 0 | F18: ='Gaurd Rail Rubber pad'!G6 -> 0 | G18: ='Gaurd Rail Rubber pad'!H6 -> 140 | H18: NOS. | I18: =_xlfn.IMAGE("https://quickchart.io/qr?text="&_xlfn.ENCODEURL("Sr No: "&A16&" | Item: "&B16&" | Page No: "&C16&" | Receipt: "&D16&" | Transfer: "&E16&" | Issues: "&F16&" | Balance: "&G16&" | Remarks: "&H16)) -> #VALUE!
A19: 9 | B19: Round Washer Plain 8mm | C19: 1252 | D19: ='Round Washer Plan 8mm'!E6 -> 60 | E19: ='Round Washer Plan 8mm'!F6 -> 0 | F19: ='Round Washer Plan 8mm'!G6 -> 0 | G19: ='Round Washer Plan 8mm'!H6 -> 60 | H19: NOS. | I19: =_xlfn.IMAGE("https://quickchart.io/qr?text="&_xlfn.ENCODEURL("Sr No: "&A17&" | Item: "&B17&" | Page No: "&C17&" | Receipt: "&D17&" | Transfer: "&E17&" | Issues: "&F17&" | Balance: "&G17&" | Remarks: "&H17)) -> #VALUE!
A20: =ROW(A17) -> 17 | B20: Washer Plain 10mm | C20: 1254 | D20: =' Washer Plan 10mm '!E6 -> 60 | E20: =' Washer Plan 10mm '!F6 -> 0 | F20: =' Washer Plan 10mm '!G6 -> 0 | G20: =' Washer Plan 10mm '!H6 -> 60 | H20: NOS. | I20: =_xlfn.IMAGE("https://quickchart.io/qr?text="&_xlfn.ENCODEURL("Sr No: "&A18&" | Item: "&B18&" | Page No: "&C18&" | Receipt: "&D18&" | Transfer: "&E18&" | Issues: "&F18&" | Balance: "&G18&" | Remarks: "&H18)) -> #VALUE!
A21: 10 | B21: Square Washer flat 10mm | C21: 1256 | D21: =' Square Washer 10mm'!E6 -> 60 | E21: =' Square Washer 10mm'!F6 -> 0 | F21: =' Square Washer 10mm'!G6 -> 0 | G21: =' Square Washer 10mm'!H6 -> 60 | H21: NOS. | I21: =_xlfn.IMAGE("https://quickchart.io/qr?text="&_xlfn.ENCODEURL("Sr No: "&A19&" | Item: "&B19&" | Page No: "&C19&" | Receipt: "&D19&" | Transfer: "&E19&" | Issues: "&F19&" | Balance: "&G19&" | Remarks: "&H19)) -> #VALUE!
A22: =ROW(A19) -> 19 | B22: Single Coil Washer T Bolt | C22: 1258 | D22: ='Single coil washer '!E6 -> 130 | E22: ='Single coil washer '!F6 -> 0 | F22: ='Single coil washer '!G6 -> 0 | G22: ='Single coil washer '!H6 -> 130 | H22: NOS. | I22: =_xlfn.IMAGE("https://quickchart.io/qr?text="&_xlfn.ENCODEURL("Sr No: "&A20&" | Item: "&B20&" | Page No: "&C20&" | Receipt: "&D20&" | Transfer: "&E20&" | Issues: "&F20&" | Balance: "&G20&" | Remarks: "&H20)) -> #VALUE!
A23: 11 | B23: Pad 25mm Rubber | C23: 1260 | D23: ='Rubber Pad 25 mm'!E6 -> 60 | E23: ='Rubber Pad 25 mm'!F6 -> 0 | F23: ='Rubber Pad 25 mm'!G6 -> 13 | G23: ='Rubber Pad 25 mm'!H6 -> 47 | H23: NOS. | I23: =_xlfn.IMAGE("https://quickchart.io/qr?text="&_xlfn.ENCODEURL("Sr No: "&A21&" | Item: "&B21&" | Page No: "&C21&" | Receipt: "&D21&" | Transfer: "&E21&" | Issues: "&F21&" | Balance: "&G21&" | Remarks: "&H21)) -> #VALUE!
A24: =ROW(A21) -> 21 | B24: Clip Outer RDSO/T-5157 | C24: 1262 | D24: ='MS Clip 5157'!E6 -> 80 | E24: ='MS Clip 5157'!F6 -> 0 | F24: ='MS Clip 5157'!G6 -> 0 | G24: ='MS Clip 5157'!H6 -> 80 | H24: NOS. | I24: =_xlfn.IMAGE("https://quickchart.io/qr?text="&_xlfn.ENCODEURL("Sr No: "&A22&" | Item: "&B22&" | Page No: "&C22&" | Receipt: "&D22&" | Transfer: "&E22&" | Issues: "&F22&" | Balance: "&G22&" | Remarks: "&H22)) -> #VALUE!
A25: 12 | B25: Clip Iner RDSO/T-5158 | C25: 1264 | D25: ='MS Clip 5158'!E6 -> 80 | E25: ='MS Clip 5158'!F6 -> 0 | F25: ='MS Clip 5158'!G6 -> 0 | G25: ='MS Clip 5158'!H6 -> 80 | H25: NOS. | I25: =_xlfn.IMAGE("https://quickchart.io/qr?text="&_xlfn.ENCODEURL("Sr No: "&A23&" | Item: "&B23&" | Page No: "&C23&" | Receipt: "&D23&" | Transfer: "&E23&" | Issues: "&F23&" | Balance: "&G23&" | Remarks: "&H23)) -> #VALUE!
A26: =ROW(A23) -> 23 | B26: Cap Angular as per RDSO/T-5159 | C26: 1266 | D26: ='Angular cap 5159'!E6 -> 140 | E26: ='Angular cap 5159'!F6 -> 0 | F26: ='Angular cap 5159'!G6 -> 0 | G26: ='Angular cap 5159'!H6 -> 140 | H26: NOS. | I26: =_xlfn.IMAGE("https://quickchart.io/qr?text="&_xlfn.ENCODEURL("Sr No: "&A24&" | Item: "&B24&" | Page No: "&C24&" | Receipt: "&D24&" | Transfer: "&E24&" | Issues: "&F24&" | Balance: "&G24&" | Remarks: "&H24)) -> #VALUE!
A27: 13 | B27: Spring Single Coil Hook Bolt | C27: 1267 | D27: ='Spring washer Sinle coil '!E6 -> 140 | E27: ='Spring washer Sinle coil '!F6 -> 0 | F27: ='Spring washer Sinle coil '!G6 -> 0 | G27: ='Spring washer Sinle coil '!H6 -> 140 | H27: NOS. | I27: =_xlfn.IMAGE("https://quickchart.io/qr?text="&_xlfn.ENCODEURL("Sr No: "&A25&" | Item: "&B25&" | Page No: "&C25&" | Receipt: "&D25&" | Transfer: "&E25&" | Issues: "&F25&" | Balance: "&G25&" | Remarks: "&H25)) -> #VALUE!
A28: =ROW(A25) -> 25 | B28: Split Pin | C28: 1269 | D28: ='Spilt Pin '!E6 -> 200 | E28: ='Spilt Pin '!F6 -> 0 | F28: ='Spilt Pin '!G6 -> 0 | G28: ='Spilt Pin '!H6 -> 200 | H28: NOS. | I28: =_xlfn.IMAGE("https://quickchart.io/qr?text="&_xlfn.ENCODEURL("Sr No: "&A26&" | Item: "&B26&" | Page No: "&C26&" | Receipt: "&D26&" | Transfer: "&E26&" | Issues: "&F26&" | Balance: "&G26&" | Remarks: "&H26)) -> #VALUE!
A29: 14 | B29: Bolt, T-Galvanized as per RDSO/T-5160 | C29: 1271 | D29: ='T-Bolt 5160'!E6 -> 130 | E29: ='T-Bolt 5160'!F6 -> 0 | F29: ='T-Bolt 5160'!G6 -> 0 | G29: ='T-Bolt 5160'!H6 -> 130 | H29: NOS. | I29: =_xlfn.IMAGE("https://quickchart.io/qr?text="&_xlfn.ENCODEURL("Sr No: "&A27&" | Item: "&B27&" | Page No: "&C27&" | Receipt: "&D27&" | Transfer: "&E27&" | Issues: "&F27&" | Balance: "&G27&" | Remarks: "&H27)) -> #VALUE!
A30: =ROW(A27) -> 27 | B30: D Grooved 10mm Rubber as per RDSO/T-5156 | C30: 1273 | D30: ='Channel Sleeper pad '!E7 -> 60 | E30: ='Channel Sleeper pad '!F6 -> 0 | F30: ='Channel Sleeper pad '!G6 -> 35 | G30: ='Channel Sleeper pad '!H6 -> 25 | H30: NOS. | I30: =_xlfn.IMAGE("https://quickchart.io/qr?text="&_xlfn.ENCODEURL("Sr No: "&A28&" | Item: "&B28&" | Page No: "&C28&" | Receipt: "&D28&" | Transfer: "&E28&" | Issues: "&F28&" | Balance: "&G28&" | Remarks: "&H28)) -> #VALUE!
A31: 15 | B31: Joggled Fish Plate | C31: 1275 | D31: ='Joggled Fish plate'!E6 -> 440 | E31: ='Joggled Fish plate'!F6 -> 0 | F31: ='Joggled Fish plate'!G6 -> 416 | G31: ='Joggled Fish plate'!H6 -> 24 | H31: NOS. | I31: =_xlfn.IMAGE("https://quickchart.io/qr?text="&_xlfn.ENCODEURL("Sr No: "&A29&" | Item: "&B29&" | Page No: "&C29&" | Receipt: "&D29&" | Transfer: "&E29&" | Issues: "&F29&" | Balance: "&G29&" | Remarks: "&H29)) -> #VALUE!
A32: =ROW(A29) -> 29 | B32: Fish Plate 1 Mtr | C32: 1277 | D32: ='Fish Plate 1 Mtr'!E6 -> 100 | E32: ='Fish Plate 1 Mtr'!F6 -> 0 | F32: ='Fish Plate 1 Mtr'!G6 -> 64 | G32: ='Fish Plate 1 Mtr'!H6 -> 36 | H32: NOS. | I32: =_xlfn.IMAGE("https://quickchart.io/qr?text="&_xlfn.ENCODEURL("Sr No: "&A30&" | Item: "&B30&" | Page No: "&C30&" | Receipt: "&D30&" | Transfer: "&E30&" | Issues: "&F30&" | Balance: "&G30&" | Remarks: "&H30)) -> #VALUE!
A33: 16 | B33: C-Clamp (Two Piece Clamp) | C33: 1279 | D33: ='C-Clamp '!E6 -> 880 | E33: ='C-Clamp '!F6 -> 0 | F33: ='C-Clamp '!G6 -> 832 | G33: ='C-Clamp '!H6 -> 48 | H33: NOS. | I33: =_xlfn.IMAGE("https://quickchart.io/qr?text="&_xlfn.ENCODEURL("Sr No: "&A31&" | Item: "&B31&" | Page No: "&C31&" | Receipt: "&D31&" | Transfer: "&E31&" | Issues: "&F31&" | Balance: "&G31&" | Remarks: "&H31)) -> #VALUE!
A34: =ROW(A31) -> 31 | B34: C-Clamp (Two Piece Clamp) Bolt & Nut | C34: 1281 | D34: ='C-Clamp bolt & nut'!E6 -> 400 | E34: ='C-Clamp bolt & nut'!F6 -> 0 | F34: ='C-Clamp bolt & nut'!G6 -> 400 | G34: ='C-Clamp bolt & nut'!H6 -> 0 | H34: NOS. | I34: =_xlfn.IMAGE("https://quickchart.io/qr?text="&_xlfn.ENCODEURL("Sr No: "&A32&" | Item: "&B32&" | Page No: "&C32&" | Receipt: "&D32&" | Transfer: "&E32&" | Issues: "&F32&" | Balance: "&G32&" | Remarks: "&H32)) -> #VALUE!
A35: 17 | B35: Joggled Fish Plate Bolt & Nut | C35: 1283 | D35: ='Joggled fish bolt & nut'!E6 -> 400 | E35: ='Joggled fish bolt & nut'!F6 -> 0 | F35: ='Joggled fish bolt & nut'!G6 -> 100 | G35: ='Joggled fish bolt & nut'!H6 -> 300 | H35: NOS. | I35: =_xlfn.IMAGE("https://quickchart.io/qr?text="&_xlfn.ENCODEURL("Sr No: "&A33&" | Item: "&B33&" | Page No: "&C33&" | Receipt: "&D33&" | Transfer: "&E33&" | Issues: "&F33&" | Balance: "&G33&" | Remarks: "&H33)) -> #VALUE!
A36: =ROW(A33) -> 33 | B36: Nut & Bolt 1 Mtr Fish Plate | C36: 1285 | D36: ='1 mtr fish bolt & nut (2)'!E6 -> 300 | E36: ='1 mtr fish bolt & nut (2)'!F6 -> 0 | F36: ='1 mtr fish bolt & nut (2)'!G6 -> 256 | G36: ='1 mtr fish bolt & nut (2)'!H6 -> 44 | H36: NOS. | I36: =_xlfn.IMAGE("https://quickchart.io/qr?text="&_xlfn.ENCODEURL("Sr No: "&A34&" | Item: "&B34&" | Page No: "&C34&" | Receipt: "&D34&" | Transfer: "&E34&" | Issues: "&F34&" | Balance: "&G34&" | Remarks: "&H34)) -> #VALUE!
A37: 18 | B37: C-Clamp RT-5856 (Screw Type) | C37: 1287 | D37: ='C-Clamp RT-5856 '!E6 -> 50 | E37: ='C-Clamp RT-5856 '!F6 -> 0 | F37: ='C-Clamp RT-5856 '!G6 -> 25 | G37: ='C-Clamp RT-5856 '!H6 -> 25 | H37: NOS. | I37: =_xlfn.IMAGE("https://quickchart.io/qr?text="&_xlfn.ENCODEURL("Sr No: "&A35&" | Item: "&B35&" | Page No: "&C35&" | Receipt: "&D35&" | Transfer: "&E35&" | Issues: "&F35&" | Balance: "&G35&" | Remarks: "&H35)) -> #VALUE!
A38: =ROW(A35) -> 35 | B38: ACD PIN For VAE VKN Made | C38: 1288 | D38: ='[1]PHOWRA SPADE'!E6 -> 50 | E38: ='[1]PHOWRA SPADE'!F6 -> 0 | F38: ='[1]PHOWRA SPADE'!G6 -> 25 | G38: ='[1]PHOWRA SPADE'!H6 -> 25 | H38: NOS. | I38: =_xlfn.IMAGE("https://quickchart.io/qr?text="&_xlfn.ENCODEURL("Sr No: "&A36&" | Item: "&B36&" | Page No: "&C36&" | Receipt: "&D36&" | Transfer: "&E36&" | Issues: "&F36&" | Balance: "&G36&" | Remarks: "&H36)) -> #VALUE!
A39: 19 | B39: ACD Fork For VAE VKN Made | C39: 1289 | D39: ='Fork ACD'!E6 -> 7 | E39: ='Fork ACD'!F6 -> 0 | F39: ='Fork ACD'!G6 -> 4 | G39: ='Fork ACD'!H6 -> 3 | H39: NOS. | I39: =_xlfn.IMAGE("https://quickchart.io/qr?text="&_xlfn.ENCODEURL("Sr No: "&A37&" | Item: "&B37&" | Page No: "&C37&" | Receipt: "&D37&" | Transfer: "&E37&" | Issues: "&F37&" | Balance: "&G37&" | Remarks: "&H37)) -> #VALUE!
A40: =ROW(A37) -> 37 | B40: Bolt M27*140N for ACD PIN For VAE VKN Made | C40: 1290 | D40: ='BOLT ACD PIN'!E6 -> 40 | E40: ='BOLT ACD PIN'!F6 -> 0 | F40: ='BOLT ACD PIN'!G6 -> 16 | G40: ='BOLT ACD PIN'!H6 -> 24 | H40: NOS. | I40: =_xlfn.IMAGE("https://quickchart.io/qr?text="&_xlfn.ENCODEURL("Sr No: "&A38&" | Item: "&B38&" | Page No: "&C38&" | Receipt: "&D38&" | Transfer: "&E38&" | Issues: "&F38&" | Balance: "&G38&" | Remarks: "&H38)) -> #VALUE!
...

Sheet GFN Liner
A1: 744 | B1: foHkkxh; [kkrk feyku iqLrd DEPARTMENTAL LEDGER AND TALLY BOOK
A2: ewY; lwph@dwV la[;k Price List / Code No. | D2: 5 | E2: feyku i= la[;k Tally Code No. | I2: ;wfuV Unit
A3: oLrq dk fooj.k Description of the Article | D3: GFN Liner | E3: ys[kk dk;kZy; i`"B la[;k Accounts Office File No. | I3: 1201
A4: ekg vkSj rkjh[k Month and Date | B4: izkfIr ;k fuxZe okmpj la[;k vkSj rkjh[k No. and Date of Receiot or issue Voucher | C4: fdlls izkIr gqvk ;k fdls tkjh fd;k From Whom received or to whom issued | D4: izkfIr ;k fuxZe dk mn~ns'; Purpose for which received or issue | E4: izkfIr Receipt | F4: LFkkukarj.k Transfer | G4: fuxZe Issues | H4: 'ks"k Balance | I4: vk|{kj Signature
E5: ux No. Vu Tonnes fd-xzk-Kgs. Ltr. | F5: ux No. Vu Tonnes fd-xzk-Kgs. | G5: ux No. Vu Tonnes fd-xzk-Kgs. | H5: ux No. Vu Tonnes fd-xzk-Kgs.
E6: =SUM(E7:E963) -> 19754 | F6: =SUM(F7:F963) -> 0 | G6: =SUM(G7:G963) -> 17665 | H6: =SUM(E6-F6-G6) -> 2089
A7: 46113 | B7: GIL-TPL JV /EDFC / 301/2023/ LON/6547 04.03.2024 | C7: TPL-GIL JV | D7: Track work | E7: 19754 | F7: 0 | G7: 0 | H7: =SUM(E7-F7-G7) -> 19754
A8: 45677 | B8: GP/DFC/AMBALA / SR. 1186 Dt. 20.01.2025 | C8: Surendra Kumar/sr.Ex/c/KNNN | D8: Track work | E8: 0 | F8: 0 | G8: 130 | H8: =+H7+E8-F8-G8 -> 19624
A9: 45961 | B9: GP/DFC/AMBALA / SR. 1154 Dt. 31.10.2025 | C9: Keyman | D9: Track work | E9: 0 | F9: 0 | G9: 20 | H9: =H8-G9 -> 19604
A10: 45961 | B10: GP/DFC/AMBALA / SR. 1155 Dt. 31.10.2025 | C10: Keyman | D10: Track work | E10: 0 | F10: 0 | G10: 180 | H10: =H9-G10 -> 19424
A11: 45961 | B11: GP/DFC/AMBALA / SR. 1156 Dt. 31.10.2025 | C11: Keyman | D11: Track work | E11: 0 | F11: 0 | G11: 55 | H11: =H10-G11 -> 19369
A12: 45961 | B12: GP/DFC/AMBALA / SR. 1157 Dt. 31.10.2025 | C12: Keyman | D12: Track work | E12: 0 | F12: 0 | G12: 90 | H12: =H11-G12 -> 19279
A13: 46051 | B13: GP/DFC/AMBALA / SR. 1169 Dt. 29.01.2026 | C13: 1208/15-16 | D13: Track work | E13: 0 | F13: 0 | G13: 40 | H13: =H12-G13 -> 19239
A14: 46101 | B14: GP/DFC/AMBALA / SR.2202 Dt. 20.03.2026 | C14: IMD/CHAN | D14: Track work | E14: 0 | F14: 0 | G14: 16750 | H14: =H13-G14 -> 2489
A15: 46101 | B15: GP/DFC/AMBALA / SR.2203 Dt. 20.03.2027 | C15: Section use | D15: Track work | E15: 0 | F15: 0 | G15: 300 | H15: =H14-G15 -> 2189
A16: 46139 | B16: GP/DFC/AMBALA / SR. 2207 Dt. 20.03.2028 | C16: 1174/4-5 | D16: Track work | E16: 0 | F16: 0 | G16: 100 | H16: =H15-G16 -> 2089
E17: 0 | F17: 0 | H17: =H16-G17 -> 2089
H452: =H451-G452-F452+E452 -> 0
H453: =H452-G453-F453+E453 -> 0
H454: =H453-G454-F454+E454 -> 0
H455: =H454-G455-F455+E455 -> 0
H456: =H455-G456-F456+E456 -> 0
H457: =H456-G457-F457+E457 -> 0
H458: =H457-G458-F458+E458 -> 0
H459: =H458-G459-F459+E459 -> 0
H460: =H459-G460-F460+E460 -> 0
H461: =H460-G461-F461+E461 -> 0
H462: =H461-G462-F462+E462 -> 0
H463: =H462-G463-F463+E463 -> 0
... H636: =H635-G636-F636+E636 -> 0
E1048534: 2

Sheet Rubber pad
A1: 744 | B1: foHkkxh; [kkrk feyku iqLrd DEPARTMENTAL LEDGER AND TALLY BOOK
A2: ewY; lwph@dwV la[;k Price List / Code No. | D2: 5 | E2: feyku i= la[;k Tally Code No. | I2: ;wfuV Unit
A3: oLrq dk fooj.k Description of the Article | D3: Rubber pad | E3: ys[kk dk;kZy; i`"B la[;k Accounts Office File No. | I3: 1205
A4: ekg vkSj rkjh[k Month and Date | B4: izkfIr ;k fuxZe okmpj la[;k vkSj rkjh[k No. and Date of Receiot or issue Voucher | C4: fdlls izkIr gqvk ;k fdls tkjh fd;k From Whom received or to whom issued | D4: izkfIr ;k fuxZe dk mn~ns'; Purpose for which received or issue | E4: izkfIr Receipt | F4: LFkkukarj.k Transfer | G4: fuxZe Issues | H4: 'ks"k Balance | I4: vk|{kj Signature
E5: ux No. Vu Tonnes fd-xzk-Kgs. Ltr. | F5: ux No. Vu Tonnes fd-xzk-Kgs. | G5: ux No. Vu Tonnes fd-xzk-Kgs. | H5: ux No. Vu Tonnes fd-xzk-Kgs.
E6: =SUM(E7:E958) -> 19754 | F6: =SUM(F7:F958) -> 0 | G6: =SUM(G7:G958) -> 16510 | H6: =SUM(E6-F6-G6) -> 3244
A7: 46113 | B7: GIL-TPL JV /EDFC / 301/2023/ LON/6547 04.03.2024 | C7: TPL-GIL JV | D7: Track work | E7: 19754 | F7: 0 | G7: 0 | H7: =SUM(E7-F7-G7) -> 19754
A8: 46051 | B8: GP/DFC/AMBALA / SR. 1169 Dt. 29.01.2026 | C8: 1208/15-16 | D8: Track work | E8: 0 | F8: 0 | G8: 10 | H8: =H7-G8 -> 19744
A9: 46099 | B9: GP/DFC/AMBALA / SR.2201 Dt. 20.03.2026 | C9: IMD/CHAN | D9: Track work | E9: 0 | F9: 0 | G9: 12450 | H9: =H8-G9 -> 7294
A10: 46101 | B10: GP/DFC/AMBALA / SR.2202 Dt. 20.03.2027 | C10: IMD/CHAN | D10: Track work | E10: 0 | F10: 0 | G10: 4050 | H10: =H9-G10 -> 3244
H11: =H10-G11 -> 3244
E12: 0 | F12: 0 | H12: =H11-G12 -> 3244
H447: =H446-G447-F447+E447 -> 0
H448: =H447-G448-F448+E448 -> 0
H449: =H448-G449-F449+E449 -> 0
H450: =H449-G450-F450+E450 -> 0
H451: =H450-G451-F451+E451 -> 0
H452: =H451-G452-F452+E452 -> 0
H453: =H452-G453-F453+E453 -> 0
H454: =H453-G454-F454+E454 -> 0
H455: =H454-G455-F455+E455 -> 0
H456: =H455-G456-F456+E456 -> 0
H457: =H456-G457-F457+E457 -> 0
H458: =H457-G458-F458+E458 -> 0
... H631: =H630-G631-F631+E631 -> 0
E1048529: 2

Sheet ERC
A1: 744 | B1: foHkkxh; [kkrk feyku iqLrd DEPARTMENTAL LEDGER AND TALLY BOOK
A2: ewY; lwph@dwV la[;k Price List / Code No. | D2: 5 | E2: feyku i= la[;k Tally Code No. | I2: ;wfuV Unit
A3: oLrq dk fooj.k Description of the Article | D3: ERC mark-V | E3: ys[kk dk;kZy; i`"B la[;k Accounts Office File No. | I3: 1211
A4: ekg vkSj rkjh[k Month and Date | B4: izkfIr ;k fuxZe okmpj la[;k vkSj rkjh[k No. and Date of Receiot or issue Voucher | C4: fdlls izkIr gqvk ;k fdls tkjh fd;k From Whom received or to whom issued | D4: izkfIr ;k fuxZe dk mn~ns'; Purpose for which received or issue | E4: izkfIr Receipt | F4: LFkkukarj.k Transfer | G4: fuxZe Issues | H4: 'ks"k Balance | I4: vk|{kj Signature
E5: ux No. Vu Tonnes fd-xzk-Kgs. Ltr. | F5: ux No. Vu Tonnes fd-xzk-Kgs. | G5: ux No. Vu Tonnes fd-xzk-Kgs. | H5: ux No. Vu Tonnes fd-xzk-Kgs.
E6: =SUM(E7:E963) -> 39508 | F6: =SUM(F7:F963) -> 0 | G6: =SUM(G7:G963) -> 14335 | H6: =SUM(E6-F6-G6) -> 25173
A7: 46121 | B7: GIL-TPL JV /EDFC / 301/2023/ LON/6547 04.03.2024 | C7: TPL-GIL JV | D7: Track work | E7: 39508 | F7: 0 | G7: 0 | H7: =SUM(E7-F7-G7) -> 39508
A8: 46207 | B8: GP/DFC/AMBALA / SR. 1186 Dt. 20.01.2025 | C8: Surendra Kumar/sr.Ex/c/KNNN | D8: Track work | E8: 0 | F8: 0 | G8: 150 | H8: =+H7+E8-F8-G8 -> 39358
A9: 45961 | B9: GP/DFC/AMBALA / SR. 1155 Dt. 31.10.2025 | C9: exe/c/smun Arjun kumar | D9: Track work | E9: 0 | F9: 0 | G9: 450 | H9: =H8-G9 -> 38908
A10: 45961 | B10: GP/DFC/AMBALA / SR. 1156 Dt. 31.10.2025 | C10: Keyman | D10: Track work | E10: 0 | F10: 0 | G10: 97 | H10: =H9-G10 -> 38811
A11: 46051 | B11: GP/DFC/AMBALA / SR.1169 Dt. 29.01.2026 | C11: 1208/15-16 | D11: Track work | E11: 0 | F11: 0 | G11: 20 | H11: =H10-G11 -> 38791
A12: 46091 | B12: GP/DFC/AMBALA / SR. 1175 Dt. 10.03.2026 | C12: section use | D12: Track work | E12: 0 | F12: 0 | G12: 34 | H12: =H11-G12 -> 38757
A13: 46101 | B13: GP/DFC/AMBALA / SR. 2203 Dt. 20.03.2026 | C13: section use | D13: Track work | E13: 0 | F13: 0 | G13: 34 | H13: =H12-G13 -> 38723
A14: 46139 | B14: GP/DFC/AMBALA / SR.2207 Dt. 27.04.2026 | C14: 1174/5-6 | D14: Track work | E14: 0 | F14: 0 | G14: 100 | H14: =H13-G14 -> 38623
A15: 46234 | B15: GP/DFC/AMBALA / SR.2214 Dt. 31.07.2026 | C15: IMD/CHAN | D15: Track work | E15: 0 | F15: 0 | G15: 7950 | H15: =H14-G15 -> 30673
A16: 46238 | B16: GP/DFC/AMBALA / SR.2215 Dt. 04.08.2026 | C16: IMD/CHAN | D16: Track work | E16: 0 | F16: 0 | G16: 5500 | H16: =H15-G16 -> 25173
H452: =H451-G452-F452+E452 -> 0
H453: =H452-G453-F453+E453 -> 0
H454: =H453-G454-F454+E454 -> 0
H455: =H454-G455-F455+E455 -> 0
H456: =H455-G456-F456+E456 -> 0
H457: =H456-G457-F457+E457 -> 0
H458: =H457-G458-F458+E458 -> 0
H459: =H458-G459-F459+E459 -> 0
H460: =H459-G460-F460+E460 -> 0
H461: =H460-G461-F461+E461 -> 0
H462: =H461-G462-F462+E462 -> 0
H463: =H462-G463-F463+E463 -> 0
... H636: =H635-G636-F636+E636 -> 0
E1048534: 2

Sheet Rail
A1: 744 | B1: foHkkxh; [kkrk feyku iqLrd DEPARTMENTAL LEDGER AND TALLY BOOK
A2: ewY; lwph@dwV la[;k Price List / Code No. | D2: 5 | E2: feyku i= la[;k Tally Code No. | I2: ;wfuV Unit
A3: oLrq dk fooj.k Description of the Article | D3: Rail 60 kg | E3: ys[kk dk;kZy; i`"B la[;k Accounts Office File No. | I3: 1216
A4: ekg vkSj rkjh[k Month and Date | B4: izkfIr ;k fuxZe okmpj la[;k vkSj rkjh[k No. and Date of Receiot or issue Voucher | C4: fdlls izkIr gqvk ;k fdls tkjh fd;k From Whom received or to whom issued | D4: izkfIr ;k fuxZe dk mn~ns'; Purpose for which received or issue | E4: izkfIr Receipt | F4: LFkkukarj.k Transfer | G4: fuxZe Issues | H4: 'ks"k Balance | I4: vk|{kj Signature
E5: ux No. Vu Tonnes fd-xzk-Kgs. Ltr. | F5: ux No. Vu Tonnes fd-xzk-Kgs. | G5: ux No. Vu Tonnes fd-xzk-Kgs. | H5: ux No. Vu Tonnes fd-xzk-Kgs.
E6: =SUM(E7:E963) -> 420 | F6: =SUM(F7:F963) -> 0 | G6: =SUM(G7:G963) -> 37.5 | H6: =SUM(E6-F6-G6) -> 382.5
A7: 46121 | B7: GIL-TPL JV /EDFC / 301/2023/ LON/6547 04.03.2024 | C7: TPL-GIL JV | D7: Track work | E7: 400 | F7: 0 | G7: 0 | H7: =SUM(E7-F7-G7) -> 400
A8: 46123 | B8: GIL-TPL JV /EDFC / 301/B1-60023 25.09.2024 | C8: TPL-GIL JV | D8: Track work | E8: 20 | F8: 0 | G8: 0 | H8: =+H7+E8-F8-G8 -> 420
A9: 46123 | B9: GIL-TPL JV /EDFC / 301/B1-60023 25.09.2025 | C9: Dfccil Repertative at NISR | D9: USE for Derailment Site Nsir yard | E9: 0 | F9: 0 | G9: 20 | H9: =H8-G9 -> 400
A10: 45993 | B10: GP/DFC/AMBALA / SR. 1163 Dt. 02.12.2025 | C10: km 1176/925 Rpj line | D10: Track work | E10: 0 | F10: 0 | G10: 0.5 | H10: =H9-G10 -> 399.5
A11: 46134 | B11: GP/DFC/AMBALA / SR.2206 Dt. 22.04.2026 | C11: 1227/10-11 | D11: Track work | E11: 0 | F11: 0 | G11: 14 | H11: =H10-G11 -> 385.5
A12: 27.04.2026 | B12: GP/DFC/AMBALA / SR.2207 Dt. 27.04.2026 | C12: 1174/5 | D12: Track work | E12: 0 | F12: 0 | G12: 3 | H12: =H11-G12 -> 382.5
H452: =H451-G452-F452+E452 -> 0
H453: =H452-G453-F453+E453 -> 0
H454: =H453-G454-F454+E454 -> 0
H455: =H454-G455-F455+E455 -> 0
H456: =H455-G456-F456+E456 -> 0
H457: =H456-G457-F457+E457 -> 0
H458: =H457-G458-F458+E458 -> 0
H459: =H458-G459-F459+E459 -> 0
H460: =H459-G460-F460+E460 -> 0
H461: =H460-G461-F461+E461 -> 0
H462: =H461-G462-F462+E462 -> 0
H463: =H462-G463-F463+E463 -> 0
... H636: =H635-G636-F636+E636 -> 0
E1048534: 2

Sheet PSC Sleeper(1 in 12 DFCC D S 
A1: 744 | B1: foHkkxh; [kkrk feyku iqLrd DEPARTMENTAL LEDGER AND TALLY BOOK
A2: ewY; lwph@dwV la[;k Price List / Code No. | D2: 5 | E2: feyku i= la[;k Tally Code No. | I2: ;wfuV Unit
A3: oLrq dk fooj.k Description of the Article | D3: PSC Sleeper(1 in 12 DFCC D/S (trap) | E3: ys[kk dk;kZy; i`"B la[;k Accounts Office File No. | I3: 1220
A4: ekg vkSj rkjh[k Month and Date | B4: izkfIr ;k fuxZe okmpj la[;k vkSj rkjh[k No. and Date of Receiot or issue Voucher | C4: fdlls izkIr gqvk ;k fdls tkjh fd;k From Whom received or to whom issued | D4: izkfIr ;k fuxZe dk mn~ns'; Purpose for which received or issue | E4: izkfIr Receipt | F4: LFkkukarj.k Transfer | G4: fuxZe Issues | H4: 'ks"k Balance | I4: vk|{kj Signature
E5: ux No. Vu Tonnes fd-xzk-Kgs. Ltr. | F5: ux No. Vu Tonnes fd-xzk-Kgs. | G5: ux No. Vu Tonnes fd-xzk-Kgs. | H5: ux No. Vu Tonnes fd-xzk-Kgs.
E6: =SUM(E7:E963) -> 1 | F6: =SUM(F7:F963) -> 0 | G6: =SUM(G7:G963) -> 0 | H6: =SUM(E6-F6-G6) -> 1
A7: 45428 | B7: GIL-TPL JV /EDFC / 301/2023/ LON/6547 04.03.2024 | C7: TPL-GIL JV | D7: Track work | E7: 1 | F7: 0 | G7: 0 | H7: =SUM(E7-F7-G7) -> 1
H452: =H451-G452-F452+E452 -> 0
H453: =H452-G453-F453+E453 -> 0
H454: =H453-G454-F454+E454 -> 0
H455: =H454-G455-F455+E455 -> 0
H456: =H455-G456-F456+E456 -> 0
H457: =H456-G457-F457+E457 -> 0
H458: =H457-G458-F458+E458 -> 0
H459: =H458-G459-F459+E459 -> 0
H460: =H459-G460-F460+E460 -> 0
H461: =H460-G461-F461+E461 -> 0
H462: =H461-G462-F462+E462 -> 0
H463: =H462-G463-F463+E463 -> 0
... H636: =H635-G636-F636+E636 -> 0
E1048534: 2

Sheet   Br Sleeper(8229-37)
A1: 744 | B1: foHkkxh; [kkrk feyku iqLrd DEPARTMENTAL LEDGER AND TALLY BOOK
A2: ewY; lwph@dwV la[;k Price List / Code No. | D2: 5 | E2: feyku i= la[;k Tally Code No. | I2: ;wfuV Unit
A3: oLrq dk fooj.k Description of the Article | D3: Bridge Approach Sleeper(RT-8229-8237) | E3: ys[kk dk;kZy; i`"B la[;k Accounts Office File No. | I3: 1220
A4: ekg vkSj rkjh[k Month and Date | B4: izkfIr ;k fuxZe okmpj la[;k vkSj rkjh[k No. and Date of Receiot or issue Voucher | C4: fdlls izkIr gqvk ;k fdls tkjh fd;k From Whom received or to whom issued | D4: izkfIr ;k fuxZe dk mn~ns'; Purpose for which received or issue | E4: izkfIr Receipt | F4: LFkkukarj.k Transfer | G4: fuxZe Issues | H4: 'ks"k Balance | I4: vk|{kj Signature
E5: ux No. Vu Tonnes fd-xzk-Kgs. Ltr. | F5: ux No. Vu Tonnes fd-xzk-Kgs. | G5: ux No. Vu Tonnes fd-xzk-Kgs. | H5: ux No. Vu Tonnes fd-xzk-Kgs.
E6: =SUM(E7:E963) -> 6 | F6: =SUM(F7:F963) -> 0 | G6: =SUM(G7:G963) -> 0 | H6: =SUM(E6-F6-G6) -> 6
A7: 45428 | B7: GIL-TPL JV /EDFC / 301/2023/ LON/6547 04.03.2024 | C7: TPL-GIL JV | D7: Track work | E7: 1 | F7: 0 | G7: 0 | H7: =SUM(E7-F7-G7) -> 1
A8: 46078 | B8: VK/2025-26/00410 date 20.02.2026 | C8: VEE KAY Prestressed PVT LTD. | D8: Track work | E8: 5 | F8: 0 | G8: 0 | H8: =H7+E8-G8-F8 -> 6
F9: 0 | G9: 0
F10: 0 | G10: 0
F11: 0 | G11: 0
F12: 0 | G12: 0
F13: 0 | G13: 0
F14: 0 | G14: 0
F15: 0 | G15: 0
F16: 0 | G16: 0
F17: 0 | G17: 0
F18: 0 | G18: 0
F19: 0 | G19: 0
F20: 0 | G20: 0
... F131: 0 | G131: 0
G132: 0
G133: 0
G134: 0
G135: 0
G136: 0 | H136: =H135+E136-G136-F136 -> 0
G137: 0 | H137: =H136+E137-G137-F137 -> 0
G138: 0 | H138: =H137+E138-G138-F138 -> 0
G139: 0
H452: =H451-G452-F452+E452 -> 0
H453: =H452-G453-F453+E453 -> 0
H454: =H453-G454-F454+E454 -> 0
H455: =H454-G455-F455+E455 -> 0
H456: =H455-G456-F456+E456 -> 0
H457: =H456-G457-F457+E457 -> 0
H458: =H457-G458-F458+E458 -> 0
H459: =H458-G459-F459+E459 -> 0
H460: =H459-G460-F460+E460 -> 0
H461: =H460-G461-F461+E461 -> 0
H462: =H461-G462-F462+E462 -> 0
...

Sheet LC Sleeper
A1: LC | B1: foHkkxh; [kkrk feyku iqLrd DEPARTMENTAL LEDGER AND TALLY BOOK
A2: ewY; lwph@dwV la[;k Price List / Code No. | D2: 5 | E2: feyku i= la[;k Tally Code No. | I2: ;wfuV Unit
A3: oLrq dk fooj.k Description of the Article | D3: Level Crossing Sleeper RT-8225 | E3: ys[kk dk;kZy; i`"B la[;k Accounts Office File No. | I3: 1220
A4: ekg vkSj rkjh[k Month and Date | B4: izkfIr ;k fuxZe okmpj la[;k vkSj rkjh[k No. and Date of Receiot or issue Voucher | C4: fdlls izkIr gqvk ;k fdls tkjh fd;k From Whom received or to whom issued | D4: izkfIr ;k fuxZe dk mn~ns'; Purpose for which received or issue | E4: izkfIr Receipt | F4: LFkkukarj.k Transfer | G4: fuxZe Issues | H4: 'ks"k Balance | I4: vk|{kj Signature
E5: ux No. Vu Tonnes fd-xzk-Kgs. Ltr. | F5: ux No. Vu Tonnes fd-xzk-Kgs. | G5: ux No. Vu Tonnes fd-xzk-Kgs. | H5: ux No. Vu Tonnes fd-xzk-Kgs.
E6: =SUM(E7:E963) -> 6 | F6: =SUM(F7:F963) -> 0 | G6: =SUM(G7:G963) -> 0 | H6: =SUM(E6-F6-G6) -> 6
A7: 45428 | B7: GIL-TPL JV /EDFC / 301/2023/ LON/6547 04.03.2024 | C7: TPL-GIL JV | D7: Track work | E7: 1 | F7: 0 | G7: 0 | H7: =SUM(E7-F7-G7) -> 1
A8: 46078 | B8: VK/2025-26/00409 date 20.02.2026 | C8: VEE KAY Prestressed PVT LTD. | D8: Track work | E8: 5 | F8: 0 | G8: 0 | H8: =H7+E8-G8-F8 -> 6
F9: 0 | G9: 0
F10: 0 | G10: 0
F11: 0 | G11: 0
F12: 0 | G12: 0
F13: 0 | G13: 0
F14: 0 | G14: 0
F15: 0 | G15: 0
F16: 0 | G16: 0
F17: 0 | G17: 0
F18: 0 | G18: 0
F19: 0 | G19: 0
F20: 0 | G20: 0
... F131: 0 | G131: 0
G132: 0
G133: 0
G134: 0
G135: 0
G136: 0 | H136: =H135+E136-G136-F136 -> 0
G137: 0 | H137: =H136+E137-G137-F137 -> 0
G138: 0 | H138: =H137+E138-G138-F138 -> 0
G139: 0
H452: =H451-G452-F452+E452 -> 0
H453: =H452-G453-F453+E453 -> 0
H454: =H453-G454-F454+E454 -> 0
H455: =H454-G455-F455+E455 -> 0
H456: =H455-G456-F456+E456 -> 0
H457: =H456-G457-F457+E457 -> 0
H458: =H457-G458-F458+E458 -> 0
H459: =H458-G459-F459+E459 -> 0
H460: =H459-G460-F460+E460 -> 0
H461: =H460-G461-F461+E461 -> 0
H462: =H461-G462-F462+E462 -> 0
...

Sheet SEJ Sleeper
A1: LC | B1: foHkkxh; [kkrk feyku iqLrd DEPARTMENTAL LEDGER AND TALLY BOOK
A2: ewY; lwph@dwV la[;k Price List / Code No. | D2: 5 | E2: feyku i= la[;k Tally Code No. | I2: ;wfuV Unit
A3: oLrq dk fooj.k Description of the Article | D3: Sej Sleeper (T-4149) | E3: ys[kk dk;kZy; i`"B la[;k Accounts Office File No. | I3: 1228
A4: ekg vkSj rkjh[k Month and Date | B4: izkfIr ;k fuxZe okmpj la[;k vkSj rkjh[k No. and Date of Receiot or issue Voucher | C4: fdlls izkIr gqvk ;k fdls tkjh fd;k From Whom received or to whom issued | D4: izkfIr ;k fuxZe dk mn~ns'; Purpose for which received or issue | E4: izkfIr Receipt | F4: LFkkukarj.k Transfer | G4: fuxZe Issues | H4: 'ks"k Balance | I4: vk|{kj Signature
E5: ux No. Vu Tonnes fd-xzk-Kgs. Ltr. | F5: ux No. Vu Tonnes fd-xzk-Kgs. | G5: ux No. Vu Tonnes fd-xzk-Kgs. | H5: ux No. Vu Tonnes fd-xzk-Kgs.
E6: =SUM(E7:E963) -> 12 | F6: =SUM(F7:F963) -> 0 | G6: =SUM(G7:G963) -> 0 | H6: =SUM(E6-F6-G6) -> 12
A7: 46078 | B7: VK/2025-26/00408 date 20.02.2026 | C7: VEE KAY Prestressed PVT LTD. | D7: Track work | E7: 12 | F7: 0 | G7: 0 | H7: =SUM(E7-F7-G7) -> 12
F8: 0 | G8: 0
F9: 0 | G9: 0
F10: 0 | G10: 0
F11: 0 | G11: 0
F12: 0 | G12: 0
F13: 0 | G13: 0
F14: 0 | G14: 0
F15: 0 | G15: 0
F16: 0 | G16: 0
F17: 0 | G17: 0
F18: 0 | G18: 0
F19: 0 | G19: 0
... F131: 0 | G131: 0
G132: 0
G133: 0
G134: 0
G135: 0
G136: 0 | H136: =H135+E136-G136-F136 -> 0
G137: 0 | H137: =H136+E137-G137-F137 -> 0
G138: 0 | H138: =H137+E138-G138-F138 -> 0
G139: 0
H452: =H451-G452-F452+E452 -> 0
H453: =H452-G453-F453+E453 -> 0
H454: =H453-G454-F454+E454 -> 0
H455: =H454-G455-F455+E455 -> 0
H456: =H455-G456-F456+E456 -> 0
H457: =H456-G457-F457+E457 -> 0
H458: =H457-G458-F458+E458 -> 0
H459: =H458-G459-F459+E459 -> 0
H460: =H459-G460-F460+E460 -> 0
H461: =H460-G461-F461+E461 -> 0
H462: =H461-G462-F462+E462 -> 0
H463: =H462-G463-F463+E463 -> 0
...

Sheet Br Sleeper 8228
A1: LC | B1: foHkkxh; [kkrk feyku iqLrd DEPARTMENTAL LEDGER AND TALLY BOOK
A2: ewY; lwph@dwV la[;k Price List / Code No. | D2: 5 | E2: feyku i= la[;k Tally Code No. | I2: ;wfuV Unit
A3: oLrq dk fooj.k Description of the Article | D3: PSC Sleeper Bridge RT-8228 | E3: ys[kk dk;kZy; i`"B la[;k Accounts Office File No. | I3: 1228
A4: ekg vkSj rkjh[k Month and Date | B4: izkfIr ;k fuxZe okmpj la[;k vkSj rkjh[k No. and Date of Receiot or issue Voucher | C4: fdlls izkIr gqvk ;k fdls tkjh fd;k From Whom received or to whom issued | D4: izkfIr ;k fuxZe dk mn~ns'; Purpose for which received or issue | E4: izkfIr Receipt | F4: LFkkukarj.k Transfer | G4: fuxZe Issues | H4: 'ks"k Balance | I4: vk|{kj Signature
E5: ux No. Vu Tonnes fd-xzk-Kgs. Ltr. | F5: ux No. Vu Tonnes fd-xzk-Kgs. | G5: ux No. Vu Tonnes fd-xzk-Kgs. | H5: ux No. Vu Tonnes fd-xzk-Kgs.
E6: =SUM(E7:E963) -> 36 | F6: =SUM(F7:F963) -> 0 | G6: =SUM(G7:G963) -> 0 | H6: =SUM(E6-F6-G6) -> 36
A7: 45441 | B7: GIL-TPL JV /EDFC / 301/2023/ LON/6547 04.03.2024 | C7: TPL-GIL JV | D7: Track work | E7: 36 | F7: 0 | G7: 0 | H7: =SUM(E7-F7-G7) -> 36
F8: 0 | G8: 0
F9: 0 | G9: 0
F10: 0 | G10: 0
F11: 0 | G11: 0
F12: 0 | G12: 0
F13: 0 | G13: 0
F14: 0 | G14: 0
F15: 0 | G15: 0
F16: 0 | G16: 0
F17: 0 | G17: 0
F18: 0 | G18: 0
F19: 0 | G19: 0
... F131: 0 | G131: 0
G132: 0
G133: 0
G134: 0
G135: 0
G136: 0 | H136: =H135+E136-G136-F136 -> 0
G137: 0 | H137: =H136+E137-G137-F137 -> 0
G138: 0 | H138: =H137+E138-G138-F138 -> 0
G139: 0
H452: =H451-G452-F452+E452 -> 0
H453: =H452-G453-F453+E453 -> 0
H454: =H453-G454-F454+E454 -> 0
H455: =H454-G455-F455+E455 -> 0
H456: =H455-G456-F456+E456 -> 0
H457: =H456-G457-F457+E457 -> 0
H458: =H457-G458-F458+E458 -> 0
H459: =H458-G459-F459+E459 -> 0
H460: =H459-G460-F460+E460 -> 0
H461: =H460-G461-F461+E461 -> 0
H462: =H461-G462-F462+E462 -> 0
H463: =H462-G463-F463+E463 -> 0
...

Sheet  Sleeper7008
A1: LC | B1: foHkkxh; [kkrk feyku iqLrd DEPARTMENTAL LEDGER AND TALLY BOOK
A2: ewY; lwph@dwV la[;k Price List / Code No. | D2: 5 | E2: feyku i= la[;k Tally Code No. | I2: ;wfuV Unit
A3: oLrq dk fooj.k Description of the Article | D3: PSC Sleeper RT-7008 | E3: ys[kk dk;kZy; i`"B la[;k Accounts Office File No. | I3: 1234
A4: ekg vkSj rkjh[k Month and Date | B4: izkfIr ;k fuxZe okmpj la[;k vkSj rkjh[k No. and Date of Receiot or issue Voucher | C4: fdlls izkIr gqvk ;k fdls tkjh fd;k From Whom received or to whom issued | D4: izkfIr ;k fuxZe dk mn~ns'; Purpose for which received or issue | E4: izkfIr Receipt | F4: LFkkukarj.k Transfer | G4: fuxZe Issues | H4: 'ks"k Balance | I4: vk|{kj Signature
E5: ux No. Vu Tonnes fd-xzk-Kgs. Ltr. | F5: ux No. Vu Tonnes fd-xzk-Kgs. | G5: ux No. Vu Tonnes fd-xzk-Kgs. | H5: ux No. Vu Tonnes fd-xzk-Kgs.
E6: =SUM(E7:E963) -> 3499 | F6: =SUM(F7:F963) -> 0 | G6: =SUM(G7:G963) -> 20 | H6: =SUM(E6-F6-G6) -> 3479
A7: 45441 | B7: GIL-TPL JV /EDFC / 301/2023/ LON/6547 04.03.2024 | C7: TPL-GIL JV | D7: Track work | E7: 500 | F7: 0 | G7: 0 | H7: =SUM(E7-F7-G7) -> 500
A8: 46072 | B8: VK/2025-26/00391 date 18.02.2026 | C8: VEE KAY Prestressed PVT LTD. | D8: Track work | E8: 170 | F8: 0 | G8: 0 | H8: =H7+E8-G8-F8 -> 670
A9: 46072 | B9: VK/2025-26/00390 date 18.02.2026 | C9: VEE KAY Prestressed PVT LTD. | D9: Track work | E9: 180 | F9: 0 | G9: 0 | H9: =H8+E9-G9-F9 -> 850
A10: 46072 | B10: VK/2025-26/00392 date 18.02.2026 | C10: VEE KAY Prestressed PVT LTD. | D10: Track work | E10: 170 | F10: 0 | G10: 0 | H10: =H9+E10-G10-F10 -> 1020
A11: 46072 | B11: VK/2025-26/00389 date 18.02.2026 | C11: VEE KAY Prestressed PVT LTD. | D11: Track work | E11: 180 | F11: 0 | G11: 0 | H11: =H10+E11-G11-F11 -> 1200
A12: 46073 | B12: VK/2025-26/00401 date 19.02.2026 | C12: VEE KAY Prestressed PVT LTD. | D12: Track work | E12: 146 | F12: 0 | G12: 0 | H12: =H11+E12-G12-F12 -> 1346
A13: 46073 | B13: VK/2025-26/00402 date 19.02.2026 | C13: VEE KAY Prestressed PVT LTD. | D13: Track work | E13: 118 | F13: 0 | G13: 0 | H13: =H12+E13-G13-F13 -> 1464
A14: 46073 | B14: VK/2025-26/00403 date 19.02.2026 | C14: VEE KAY Prestressed PVT LTD. | D14: Track work | E14: 148 | F14: 0 | G14: 0 | H14: =H13+E14-G14-F14 -> 1612
A15: 46074 | B15: VK/2025-26/00404 date 19.02.2026 | C15: VEE KAY Prestressed PVT LTD. | D15: Track work | E15: 170 | F15: 0 | G15: 0 | H15: =H14+E15-G15-F15 -> 1782
A16: 46074 | B16: VK/2025-26/00405 date 19.02.2026 | C16: VEE KAY Prestressed PVT LTD. | D16: Track work | E16: 170 | F16: 0 | G16: 0 | H16: =H15+E16-G16-F16 -> 1952
A17: 46074 | B17: VK/2025-26/00420 date 19.02.2026 | C17: VEE KAY Prestressed PVT LTD. | D17: Track work | E17: 146 | F17: 0 | G17: 0 | H17: =H16+E17-G17-F17 -> 2098
A18: 46074 | B18: VK/2025-26/00407 date 19.02.2026 | C18: VEE KAY Prestressed PVT LTD. | D18: Track work | E18: 180 | F18: 0 | G18: 0 | H18: =H17+E18-G18-F18 -> 2278
A19: 46074 | B19: VK/2025-26/00406 date 19.02.2026 | C19: VEE KAY Prestressed PVT LTD. | D19: Track work | E19: 180 | F19: 0 | G19: 0 | H19: =H18+E19-G19-F19 -> 2458
... A26: 46139 | B26: GP/DFC/AMBALA / SR. 2207 Dt. 27.04.2026 | C26: 1174/5-6 | D26: Track work | E26: 0 | F26: 0 | G26: 20 | H26: =H25+E26-G26-F26 -> 3479
H452: =H451-G452-F452+E452 -> 0
H453: =H452-G453-F453+E453 -> 0
H454: =H453-G454-F454+E454 -> 0
H455: =H454-G455-F455+E455 -> 0
H456: =H455-G456-F456+E456 -> 0
H457: =H456-G457-F457+E457 -> 0
H458: =H457-G458-F458+E458 -> 0
H459: =H458-G459-F459+E459 -> 0
H460: =H459-G460-F460+E460 -> 0
H461: =H460-G461-F461+E461 -> 0
H462: =H461-G462-F462+E462 -> 0
H463: =H462-G463-F463+E463 -> 0
... H636: =H635-G636-F636+E636 -> 0
E1048534: 2

Sheet  Derailing Switch 
A1: LC | B1: foHkkxh; [kkrk feyku iqLrd DEPARTMENTAL LEDGER AND TALLY BOOK
A2: ewY; lwph@dwV la[;k Price List / Code No. | D2: 5 | E2: feyku i= la[;k Tally Code No. | I2: ;wfuV Unit
A3: oLrq dk fooj.k Description of the Article | D3: Derailing Switch With out Fitting | E3: ys[kk dk;kZy; i`"B la[;k Accounts Office File No. | I3: 1238
A4: ekg vkSj rkjh[k Month and Date | B4: izkfIr ;k fuxZe okmpj la[;k vkSj rkjh[k No. and Date of Receiot or issue Voucher | C4: fdlls izkIr gqvk ;k fdls tkjh fd;k From Whom received or to whom issued | D4: izkfIr ;k fuxZe dk mn~ns'; Purpose for which received or issue | E4: izkfIr Receipt | F4: LFkkukarj.k Transfer | G4: fuxZe Issues | H4: 'ks"k Balance | I4: vk|{kj Signature
E5: ux No. Vu Tonnes fd-xzk-Kgs. Ltr. | F5: ux No. Vu Tonnes fd-xzk-Kgs. | G5: ux No. Vu Tonnes fd-xzk-Kgs. | H5: ux No. Vu Tonnes fd-xzk-Kgs.
E6: =SUM(E7:E963) -> 1 | F6: =SUM(F7:F963) -> 0 | G6: =SUM(G7:G963) -> 0 | H6: =SUM(E6-F6-G6) -> 1
A7: 45441 | B7: GIL-TPL JV /EDFC / 301/2023/ LON/6547 04.03.2024 | C7: TPL-GIL JV | D7: Track work | E7: 1 | F7: 0 | G7: 0 | H7: =SUM(E7-F7-G7) -> 1
H452: =H451-G452-F452+E452 -> 0
H453: =H452-G453-F453+E453 -> 0
H454: =H453-G454-F454+E454 -> 0
H455: =H454-G455-F455+E455 -> 0
H456: =H455-G456-F456+E456 -> 0
H457: =H456-G457-F457+E457 -> 0
H458: =H457-G458-F458+E458 -> 0
H459: =H458-G459-F459+E459 -> 0
H460: =H459-G460-F460+E460 -> 0
H461: =H460-G461-F461+E461 -> 0
H462: =H461-G462-F462+E462 -> 0
H463: =H462-G463-F463+E463 -> 0
... H636: =H635-G636-F636+E636 -> 0
E1048534: 2

Sheet SEJ 
A1: LC | B1: foHkkxh; [kkrk feyku iqLrd DEPARTMENTAL LEDGER AND TALLY BOOK
A2: ewY; lwph@dwV la[;k Price List / Code No. | D2: 5 | E2: feyku i= la[;k Tally Code No. | I2: ;wfuV Unit
A3: oLrq dk fooj.k Description of the Article | D3: Sej | E3: ys[kk dk;kZy; i`"B la[;k Accounts Office File No. | I3: 1242
A4: ekg vkSj rkjh[k Month and Date | B4: izkfIr ;k fuxZe okmpj la[;k vkSj rkjh[k No. and Date of Receiot or issue Voucher | C4: fdlls izkIr gqvk ;k fdls tkjh fd;k From Whom received or to whom issued | D4: izkfIr ;k fuxZe dk mn~ns'; Purpose for which received or issue | E4: izkfIr Receipt | F4: LFkkukarj.k Transfer | G4: fuxZe Issues | H4: 'ks"k Balance | I4: vk|{kj Signature
E5: ux No. Vu Tonnes fd-xzk-Kgs. Ltr. | F5: ux No. Vu Tonnes fd-xzk-Kgs. | G5: ux No. Vu Tonnes fd-xzk-Kgs. | H5: ux No. Vu Tonnes fd-xzk-Kgs.
E6: =SUM(E7:E963) -> 1 | F6: =SUM(F7:F963) -> 0 | G6: =SUM(G7:G963) -> 0 | H6: =SUM(E6-F6-G6) -> 1
A7: 45441 | B7: GIL-TPL JV /EDFC / 301/2023/ LON/6547 04.03.2024 | C7: TPL-GIL JV | D7: Track work | E7: 1 | F7: 0 | G7: 0 | H7: =SUM(E7-F7-G7) -> 1
H452: =H451-G452-F452+E452 -> 0
H453: =H452-G453-F453+E453 -> 0
H454: =H453-G454-F454+E454 -> 0
H455: =H454-G455-F455+E455 -> 0
H456: =H455-G456-F456+E456 -> 0
H457: =H456-G457-F457+E457 -> 0
H458: =H457-G458-F458+E458 -> 0
H459: =H458-G459-F459+E459 -> 0
H460: =H459-G460-F460+E460 -> 0
H461: =H460-G461-F461+E461 -> 0
H462: =H461-G462-F462+E462 -> 0
H463: =H462-G463-F463+E463 -> 0
... H636: =H635-G636-F636+E636 -> 0
E1048534: 2

Sheet Hook Bolt 
A1: LC | B1: foHkkxh; [kkrk feyku iqLrd DEPARTMENTAL LEDGER AND TALLY BOOK
A2: ewY; lwph@dwV la[;k Price List / Code No. | D2: 5 | E2: feyku i= la[;k Tally Code No. | I2: ;wfuV Unit
A3: oLrq dk fooj.k Description of the Article | D3: Hook Bolt 288 x 310 mm | E3: ys[kk dk;kZy; i`"B la[;k Accounts Office File No. | I3: 1245
A4: ekg vkSj rkjh[k Month and Date | B4: izkfIr ;k fuxZe okmpj la[;k vkSj rkjh[k No. and Date of Receiot or issue Voucher | C4: fdlls izkIr gqvk ;k fdls tkjh fd;k From Whom received or to whom issued | D4: izkfIr ;k fuxZe dk mn~ns'; Purpose for which received or issue | E4: izkfIr Receipt | F4: LFkkukarj.k Transfer | G4: fuxZe Issues | H4: 'ks"k Balance | I4: vk|{kj Signature
E5: ux No. Vu Tonnes fd-xzk-Kgs. Ltr. | F5: ux No. Vu Tonnes fd-xzk-Kgs. | G5: ux No. Vu Tonnes fd-xzk-Kgs. | H5: ux No. Vu Tonnes fd-xzk-Kgs.
E6: =SUM(E7:E963) -> 140 | F6: =SUM(F7:F963) -> 0 | G6: =SUM(G7:G963) -> 10 | H6: =SUM(E6-F6-G6) -> 130
A7: 45532 | B7: TCS/24-25/002 dated 27.08.2024 | C7: Uniclimb Enterprises PVT LTD. | D7: Fr Channel sleeper | E7: 140 | F7: 0 | G7: 0 | H7: =SUM(E7-F7-G7) -> 140
A8: 46189 | B8: GP/DFC/Ambala Sr. No. 2212 | C8: JE/C/SMUN | D8: For Bridge work | E8: 0 | F8: 0 | G8: 10 | H8: =H7+E8-F8-G8 -> 130
H452: =H451-G452-F452+E452 -> 0
H453: =H452-G453-F453+E453 -> 0
H454: =H453-G454-F454+E454 -> 0
H455: =H454-G455-F455+E455 -> 0
H456: =H455-G456-F456+E456 -> 0
H457: =H456-G457-F457+E457 -> 0
H458: =H457-G458-F458+E458 -> 0
H459: =H458-G459-F459+E459 -> 0
H460: =H459-G460-F460+E460 -> 0
H461: =H460-G461-F461+E461 -> 0
H462: =H461-G462-F462+E462 -> 0
H463: =H462-G463-F463+E463 -> 0
... H636: =H635-G636-F636+E636 -> 0
E1048534: 2

Sheet Nut lock
A1: LC | B1: foHkkxh; [kkrk feyku iqLrd DEPARTMENTAL LEDGER AND TALLY BOOK
A2: ewY; lwph@dwV la[;k Price List / Code No. | D2: 5 | E2: feyku i= la[;k Tally Code No. | I2: ;wfuV Unit
A3: oLrq dk fooj.k Description of the Article | D3: Nut Lock 24 mm | E3: ys[kk dk;kZy; i`"B la[;k Accounts Office File No. | I3: 1248
A4: ekg vkSj rkjh[k Month and Date | B4: izkfIr ;k fuxZe okmpj la[;k vkSj rkjh[k No. and Date of Receiot or issue Voucher | C4: fdlls izkIr gqvk ;k fdls tkjh fd;k From Whom received or to whom issued | D4: izkfIr ;k fuxZe dk mn~ns'; Purpose for which received or issue | E4: izkfIr Receipt | F4: LFkkukarj.k Transfer | G4: fuxZe Issues | H4: 'ks"k Balance | I4: vk|{kj Signature
E5: ux No. Vu Tonnes fd-xzk-Kgs. Ltr. | F5: ux No. Vu Tonnes fd-xzk-Kgs. | G5: ux No. Vu Tonnes fd-xzk-Kgs. | H5: ux No. Vu Tonnes fd-xzk-Kgs.
E6: =SUM(E7:E963) -> 140 | F6: =SUM(F7:F963) -> 0 | G6: =SUM(G7:G963) -> 0 | H6: =SUM(E6-F6-G6) -> 140
A7: 45532 | B7: TCS/24-25/002 dated 27.08.2024 | C7: Uniclimb Enterprises PVT LTD. | D7: Fr Channel sleeper | E7: 140 | F7: 0 | G7: 0 | H7: =SUM(E7-F7-G7) -> 140
H452: =H451-G452-F452+E452 -> 0
H453: =H452-G453-F453+E453 -> 0
H454: =H453-G454-F454+E454 -> 0
H455: =H454-G455-F455+E455 -> 0
H456: =H455-G456-F456+E456 -> 0
H457: =H456-G457-F457+E457 -> 0
H458: =H457-G458-F458+E458 -> 0
H459: =H458-G459-F459+E459 -> 0
H460: =H459-G460-F460+E460 -> 0
H461: =H460-G461-F461+E461 -> 0
H462: =H461-G462-F462+E462 -> 0
H463: =H462-G463-F463+E463 -> 0
... H636: =H635-G636-F636+E636 -> 0
E1048534: 2

Sheet Gaurd Rail Rubber pad
A1: LC | B1: foHkkxh; [kkrk feyku iqLrd DEPARTMENTAL LEDGER AND TALLY BOOK
A2: ewY; lwph@dwV la[;k Price List / Code No. | D2: 5 | E2: feyku i= la[;k Tally Code No. | I2: ;wfuV Unit
A3: oLrq dk fooj.k Description of the Article | D3: Guard Rail Rubber pad RDSO T-5163 | E3: ys[kk dk;kZy; i`"B la[;k Accounts Office File No. | I3: 1250
A4: ekg vkSj rkjh[k Month and Date | B4: izkfIr ;k fuxZe okmpj la[;k vkSj rkjh[k No. and Date of Receiot or issue Voucher | C4: fdlls izkIr gqvk ;k fdls tkjh fd;k From Whom received or to whom issued | D4: izkfIr ;k fuxZe dk mn~ns'; Purpose for which received or issue | E4: izkfIr Receipt | F4: LFkkukarj.k Transfer | G4: fuxZe Issues | H4: 'ks"k Balance | I4: vk|{kj Signature
E5: ux No. Vu Tonnes fd-xzk-Kgs. Ltr. | F5: ux No. Vu Tonnes fd-xzk-Kgs. | G5: ux No. Vu Tonnes fd-xzk-Kgs. | H5: ux No. Vu Tonnes fd-xzk-Kgs.
E6: =SUM(E7:E963) -> 140 | F6: =SUM(F7:F963) -> 0 | G6: =SUM(G7:G963) -> 0 | H6: =SUM(E6-F6-G6) -> 140
A7: 45532 | B7: TCS/24-25/002 dated 27.08.2024 | C7: Uniclimb Enterprises PVT LTD. | D7: Fr Channel sleeper | E7: 140 | F7: 0 | G7: 0 | H7: =SUM(E7-F7-G7) -> 140
H452: =H451-G452-F452+E452 -> 0
H453: =H452-G453-F453+E453 -> 0
H454: =H453-G454-F454+E454 -> 0
H455: =H454-G455-F455+E455 -> 0
H456: =H455-G456-F456+E456 -> 0
H457: =H456-G457-F457+E457 -> 0
H458: =H457-G458-F458+E458 -> 0
H459: =H458-G459-F459+E459 -> 0
H460: =H459-G460-F460+E460 -> 0
H461: =H460-G461-F461+E461 -> 0
H462: =H461-G462-F462+E462 -> 0
H463: =H462-G463-F463+E463 -> 0
... H636: =H635-G636-F636+E636 -> 0
E1048534: 2

Sheet Round Washer Plan 8mm
A1: LC | B1: foHkkxh; [kkrk feyku iqLrd DEPARTMENTAL LEDGER AND TALLY BOOK
A2: ewY; lwph@dwV la[;k Price List / Code No. | D2: 5 | E2: feyku i= la[;k Tally Code No. | I2: ;wfuV Unit
A3: oLrq dk fooj.k Description of the Article | D3: Round Washer Plain 8mm | E3: ys[kk dk;kZy; i`"B la[;k Accounts Office File No. | I3: 1252
A4: ekg vkSj rkjh[k Month and Date | B4: izkfIr ;k fuxZe okmpj la[;k vkSj rkjh[k No. and Date of Receiot or issue Voucher | C4: fdlls izkIr gqvk ;k fdls tkjh fd;k From Whom received or to whom issued | D4: izkfIr ;k fuxZe dk mn~ns'; Purpose for which received or issue | E4: izkfIr Receipt | F4: LFkkukarj.k Transfer | G4: fuxZe Issues | H4: 'ks"k Balance | I4: vk|{kj Signature
E5: ux No. Vu Tonnes fd-xzk-Kgs. Ltr. | F5: ux No. Vu Tonnes fd-xzk-Kgs. | G5: ux No. Vu Tonnes fd-xzk-Kgs. | H5: ux No. Vu Tonnes fd-xzk-Kgs.
E6: =SUM(E7:E963) -> 60 | F6: =SUM(F7:F963) -> 0 | G6: =SUM(G7:G963) -> 0 | H6: =SUM(E6-F6-G6) -> 60
A7: 45532 | B7: TCS/24-25/002 dated 27.08.2024 | C7: Uniclimb Enterprises PVT LTD. | D7: Fr Channel sleeper | E7: 60 | F7: 0 | G7: 0 | H7: =SUM(E7-F7-G7) -> 60
H452: =H451-G452-F452+E452 -> 0
H453: =H452-G453-F453+E453 -> 0
H454: =H453-G454-F454+E454 -> 0
H455: =H454-G455-F455+E455 -> 0
H456: =H455-G456-F456+E456 -> 0
H457: =H456-G457-F457+E457 -> 0
H458: =H457-G458-F458+E458 -> 0
H459: =H458-G459-F459+E459 -> 0
H460: =H459-G460-F460+E460 -> 0
H461: =H460-G461-F461+E461 -> 0
H462: =H461-G462-F462+E462 -> 0
H463: =H462-G463-F463+E463 -> 0
... H636: =H635-G636-F636+E636 -> 0
E1048534: 2

Sheet  Washer Plan 10mm 
A1: LC | B1: foHkkxh; [kkrk feyku iqLrd DEPARTMENTAL LEDGER AND TALLY BOOK
A2: ewY; lwph@dwV la[;k Price List / Code No. | D2: 5 | E2: feyku i= la[;k Tally Code No. | I2: ;wfuV Unit
A3: oLrq dk fooj.k Description of the Article | D3: Washer Plain 10mm | E3: ys[kk dk;kZy; i`"B la[;k Accounts Office File No. | I3: 1254
A4: ekg vkSj rkjh[k Month and Date | B4: izkfIr ;k fuxZe okmpj la[;k vkSj rkjh[k No. and Date of Receiot or issue Voucher | C4: fdlls izkIr gqvk ;k fdls tkjh fd;k From Whom received or to whom issued | D4: izkfIr ;k fuxZe dk mn~ns'; Purpose for which received or issue | E4: izkfIr Receipt | F4: LFkkukarj.k Transfer | G4: fuxZe Issues | H4: 'ks"k Balance | I4: vk|{kj Signature
E5: ux No. Vu Tonnes fd-xzk-Kgs. Ltr. | F5: ux No. Vu Tonnes fd-xzk-Kgs. | G5: ux No. Vu Tonnes fd-xzk-Kgs. | H5: ux No. Vu Tonnes fd-xzk-Kgs.
E6: =SUM(E7:E963) -> 60 | F6: =SUM(F7:F963) -> 0 | G6: =SUM(G7:G963) -> 0 | H6: =SUM(E6-F6-G6) -> 60
A7: 45532 | B7: TCS/24-25/002 dated 27.08.2024 | C7: Uniclimb Enterprises PVT LTD. | D7: Fr Channel sleeper | E7: 60 | F7: 0 | G7: 0 | H7: =SUM(E7-F7-G7) -> 60
H452: =H451-G452-F452+E452 -> 0
H453: =H452-G453-F453+E453 -> 0
H454: =H453-G454-F454+E454 -> 0
H455: =H454-G455-F455+E455 -> 0
H456: =H455-G456-F456+E456 -> 0
H457: =H456-G457-F457+E457 -> 0
H458: =H457-G458-F458+E458 -> 0
H459: =H458-G459-F459+E459 -> 0
H460: =H459-G460-F460+E460 -> 0
H461: =H460-G461-F461+E461 -> 0
H462: =H461-G462-F462+E462 -> 0
H463: =H462-G463-F463+E463 -> 0
... H636: =H635-G636-F636+E636 -> 0
E1048534: 2

Sheet  Square Washer 10mm
A1: LC | B1: foHkkxh; [kkrk feyku iqLrd DEPARTMENTAL LEDGER AND TALLY BOOK
A2: ewY; lwph@dwV la[;k Price List / Code No. | D2: 5 | E2: feyku i= la[;k Tally Code No. | I2: ;wfuV Unit
A3: oLrq dk fooj.k Description of the Article | D3: Square Washer flat 10mm | E3: ys[kk dk;kZy; i`"B la[;k Accounts Office File No. | I3: 1256
A4: ekg vkSj rkjh[k Month and Date | B4: izkfIr ;k fuxZe okmpj la[;k vkSj rkjh[k No. and Date of Receiot or issue Voucher | C4: fdlls izkIr gqvk ;k fdls tkjh fd;k From Whom received or to whom issued | D4: izkfIr ;k fuxZe dk mn~ns'; Purpose for which received or issue | E4: izkfIr Receipt | F4: LFkkukarj.k Transfer | G4: fuxZe Issues | H4: 'ks"k Balance | I4: vk|{kj Signature
E5: ux No. Vu Tonnes fd-xzk-Kgs. Ltr. | F5: ux No. Vu Tonnes fd-xzk-Kgs. | G5: ux No. Vu Tonnes fd-xzk-Kgs. | H5: ux No. Vu Tonnes fd-xzk-Kgs.
E6: =SUM(E7:E963) -> 60 | F6: =SUM(F7:F963) -> 0 | G6: =SUM(G7:G963) -> 0 | H6: =SUM(E6-F6-G6) -> 60
A7: 45532 | B7: TCS/24-25/002 dated 27.08.2024 | C7: Uniclimb Enterprises PVT LTD. | D7: Fr Channel sleeper | E7: 60 | F7: 0 | G7: 0 | H7: =SUM(E7-F7-G7) -> 60
H452: =H451-G452-F452+E452 -> 0
H453: =H452-G453-F453+E453 -> 0
H454: =H453-G454-F454+E454 -> 0
H455: =H454-G455-F455+E455 -> 0
H456: =H455-G456-F456+E456 -> 0
H457: =H456-G457-F457+E457 -> 0
H458: =H457-G458-F458+E458 -> 0
H459: =H458-G459-F459+E459 -> 0
H460: =H459-G460-F460+E460 -> 0
H461: =H460-G461-F461+E461 -> 0
H462: =H461-G462-F462+E462 -> 0
H463: =H462-G463-F463+E463 -> 0
... H636: =H635-G636-F636+E636 -> 0
E1048534: 2

Sheet Single coil washer 
A1: LC | B1: foHkkxh; [kkrk feyku iqLrd DEPARTMENTAL LEDGER AND TALLY BOOK
A2: ewY; lwph@dwV la[;k Price List / Code No. | D2: 5 | E2: feyku i= la[;k Tally Code No. | I2: ;wfuV Unit
A3: oLrq dk fooj.k Description of the Article | D3: Single Coil Washer T Bolt | E3: ys[kk dk;kZy; i`"B la[;k Accounts Office File No. | I3: 1258
A4: ekg vkSj rkjh[k Month and Date | B4: izkfIr ;k fuxZe okmpj la[;k vkSj rkjh[k No. and Date of Receiot or issue Voucher | C4: fdlls izkIr gqvk ;k fdls tkjh fd;k From Whom received or to whom issued | D4: izkfIr ;k fuxZe dk mn~ns'; Purpose for which received or issue | E4: izkfIr Receipt | F4: LFkkukarj.k Transfer | G4: fuxZe Issues | H4: 'ks"k Balance | I4: vk|{kj Signature
E5: ux No. Vu Tonnes fd-xzk-Kgs. Ltr. | F5: ux No. Vu Tonnes fd-xzk-Kgs. | G5: ux No. Vu Tonnes fd-xzk-Kgs. | H5: ux No. Vu Tonnes fd-xzk-Kgs.
E6: =SUM(E7:E963) -> 130 | F6: =SUM(F7:F963) -> 0 | G6: =SUM(G7:G963) -> 0 | H6: =SUM(E6-F6-G6) -> 130
A7: 45532 | B7: TCS/24-25/002 dated 27.08.2024 | C7: Uniclimb Enterprises PVT LTD. | D7: Fr Channel sleeper | E7: 130 | F7: 0 | G7: 0 | H7: =SUM(E7-F7-G7) -> 130
H452: =H451-G452-F452+E452 -> 0
H453: =H452-G453-F453+E453 -> 0
H454: =H453-G454-F454+E454 -> 0
H455: =H454-G455-F455+E455 -> 0
H456: =H455-G456-F456+E456 -> 0
H457: =H456-G457-F457+E457 -> 0
H458: =H457-G458-F458+E458 -> 0
H459: =H458-G459-F459+E459 -> 0
H460: =H459-G460-F460+E460 -> 0
H461: =H460-G461-F461+E461 -> 0
H462: =H461-G462-F462+E462 -> 0
H463: =H462-G463-F463+E463 -> 0
... H636: =H635-G636-F636+E636 -> 0
E1048534: 2

Sheet Rubber Pad 25 mm
A1: LC | B1: foHkkxh; [kkrk feyku iqLrd DEPARTMENTAL LEDGER AND TALLY BOOK
A2: ewY; lwph@dwV la[;k Price List / Code No. | D2: 5 | E2: feyku i= la[;k Tally Code No. | I2: ;wfuV Unit
A3: oLrq dk fooj.k Description of the Article | D3: Pad 25mm Rubber | E3: ys[kk dk;kZy; i`"B la[;k Accounts Office File No. | I3: 1260
A4: ekg vkSj rkjh[k Month and Date | B4: izkfIr ;k fuxZe okmpj la[;k vkSj rkjh[k No. and Date of Receiot or issue Voucher | C4: fdlls izkIr gqvk ;k fdls tkjh fd;k From Whom received or to whom issued | D4: izkfIr ;k fuxZe dk mn~ns'; Purpose for which received or issue | E4: izkfIr Receipt | F4: LFkkukarj.k Transfer | G4: fuxZe Issues | H4: 'ks"k Balance | I4: vk|{kj Signature
E5: ux No. Vu Tonnes fd-xzk-Kgs. Ltr. | F5: ux No. Vu Tonnes fd-xzk-Kgs. | G5: ux No. Vu Tonnes fd-xzk-Kgs. | H5: ux No. Vu Tonnes fd-xzk-Kgs.
E6: =SUM(E7:E963) -> 60 | F6: =SUM(F7:F963) -> 0 | G6: =SUM(G7:G963) -> 13 | H6: =SUM(E6-F6-G6) -> 47
A7: 45532 | B7: TCS/24-25/002 dated 27.08.2024 | C7: Uniclimb Enterprises PVT LTD. | D7: Fr Channel sleeper | E7: 60 | F7: 0 | G7: 0 | H7: =SUM(E7-F7-G7) -> 60
A8: 46189 | B8: GP/DFC/Ambala Sr. No. 2212 dt. 16.06.2026 | C8: JE/C/SMUN | D8: For Bridge Work | E8: 0 | F8: 0 | G8: 13 | H8: =H7+E8-F8-G8 -> 47
H452: =H451-G452-F452+E452 -> 0
H453: =H452-G453-F453+E453 -> 0
H454: =H453-G454-F454+E454 -> 0
H455: =H454-G455-F455+E455 -> 0
H456: =H455-G456-F456+E456 -> 0
H457: =H456-G457-F457+E457 -> 0
H458: =H457-G458-F458+E458 -> 0
H459: =H458-G459-F459+E459 -> 0
H460: =H459-G460-F460+E460 -> 0
H461: =H460-G461-F461+E461 -> 0
H462: =H461-G462-F462+E462 -> 0
H463: =H462-G463-F463+E463 -> 0
... H636: =H635-G636-F636+E636 -> 0
E1048534: 2

Sheet MS Clip 5157
A1: LC | B1: foHkkxh; [kkrk feyku iqLrd DEPARTMENTAL LEDGER AND TALLY BOOK
A2: ewY; lwph@dwV la[;k Price List / Code No. | D2: 5 | E2: feyku i= la[;k Tally Code No. | I2: ;wfuV Unit
A3: oLrq dk fooj.k Description of the Article | D3: Clip Outer RDSO/T-5157 | E3: ys[kk dk;kZy; i`"B la[;k Accounts Office File No. | I3: 1262
A4: ekg vkSj rkjh[k Month and Date | B4: izkfIr ;k fuxZe okmpj la[;k vkSj rkjh[k No. and Date of Receiot or issue Voucher | C4: fdlls izkIr gqvk ;k fdls tkjh fd;k From Whom received or to whom issued | D4: izkfIr ;k fuxZe dk mn~ns'; Purpose for which received or issue | E4: izkfIr Receipt | F4: LFkkukarj.k Transfer | G4: fuxZe Issues | H4: 'ks"k Balance | I4: vk|{kj Signature
E5: ux No. Vu Tonnes fd-xzk-Kgs. Ltr. | F5: ux No. Vu Tonnes fd-xzk-Kgs. | G5: ux No. Vu Tonnes fd-xzk-Kgs. | H5: ux No. Vu Tonnes fd-xzk-Kgs.
E6: =SUM(E7:E963) -> 80 | F6: =SUM(F7:F963) -> 0 | G6: =SUM(G7:G963) -> 0 | H6: =SUM(E6-F6-G6) -> 80
A7: 45532 | B7: TCS/24-25/002 dated 27.08.2024 | C7: Uniclimb Enterprises PVT LTD. | D7: Fr Channel sleeper | E7: 80 | F7: 0 | G7: 0 | H7: =SUM(E7-F7-G7) -> 80
H452: =H451-G452-F452+E452 -> 0
H453: =H452-G453-F453+E453 -> 0
H454: =H453-G454-F454+E454 -> 0
H455: =H454-G455-F455+E455 -> 0
H456: =H455-G456-F456+E456 -> 0
H457: =H456-G457-F457+E457 -> 0
H458: =H457-G458-F458+E458 -> 0
H459: =H458-G459-F459+E459 -> 0
H460: =H459-G460-F460+E460 -> 0
H461: =H460-G461-F461+E461 -> 0
H462: =H461-G462-F462+E462 -> 0
H463: =H462-G463-F463+E463 -> 0
... H636: =H635-G636-F636+E636 -> 0
E1048534: 2

Sheet MS Clip 5158
A1: LC | B1: foHkkxh; [kkrk feyku iqLrd DEPARTMENTAL LEDGER AND TALLY BOOK
A2: ewY; lwph@dwV la[;k Price List / Code No. | D2: 5 | E2: feyku i= la[;k Tally Code No. | I2: ;wfuV Unit
A3: oLrq dk fooj.k Description of the Article | D3: Clip Iner RDSO/T-5158 | E3: ys[kk dk;kZy; i`"B la[;k Accounts Office File No. | I3: 1264
A4: ekg vkSj rkjh[k Month and Date | B4: izkfIr ;k fuxZe okmpj la[;k vkSj rkjh[k No. and Date of Receiot or issue Voucher | C4: fdlls izkIr gqvk ;k fdls tkjh fd;k From Whom received or to whom issued | D4: izkfIr ;k fuxZe dk mn~ns'; Purpose for which received or issue | E4: izkfIr Receipt | F4: LFkkukarj.k Transfer | G4: fuxZe Issues | H4: 'ks"k Balance | I4: vk|{kj Signature
E5: ux No. Vu Tonnes fd-xzk-Kgs. Ltr. | F5: ux No. Vu Tonnes fd-xzk-Kgs. | G5: ux No. Vu Tonnes fd-xzk-Kgs. | H5: ux No. Vu Tonnes fd-xzk-Kgs.
E6: =SUM(E7:E963) -> 80 | F6: =SUM(F7:F963) -> 0 | G6: =SUM(G7:G963) -> 0 | H6: =SUM(E6-F6-G6) -> 80
A7: 45532 | B7: TCS/24-25/002 dated 27.08.2024 | C7: Uniclimb Enterprises PVT LTD. | D7: Fr Channel sleeper | E7: 80 | F7: 0 | G7: 0 | H7: =SUM(E7-F7-G7) -> 80
H452: =H451-G452-F452+E452 -> 0
H453: =H452-G453-F453+E453 -> 0
H454: =H453-G454-F454+E454 -> 0
H455: =H454-G455-F455+E455 -> 0
H456: =H455-G456-F456+E456 -> 0
H457: =H456-G457-F457+E457 -> 0
H458: =H457-G458-F458+E458 -> 0
H459: =H458-G459-F459+E459 -> 0
H460: =H459-G460-F460+E460 -> 0
H461: =H460-G461-F461+E461 -> 0
H462: =H461-G462-F462+E462 -> 0
H463: =H462-G463-F463+E463 -> 0
... H636: =H635-G636-F636+E636 -> 0
E1048534: 2

Sheet Angular cap 5159
A1: LC | B1: foHkkxh; [kkrk feyku iqLrd DEPARTMENTAL LEDGER AND TALLY BOOK
A2: ewY; lwph@dwV la[;k Price List / Code No. | D2: 5 | E2: feyku i= la[;k Tally Code No. | I2: ;wfuV Unit
A3: oLrq dk fooj.k Description of the Article | D3: Cap Angular as per RDSO/T-5159 | E3: ys[kk dk;kZy; i`"B la[;k Accounts Office File No. | I3: 1266
A4: ekg vkSj rkjh[k Month and Date | B4: izkfIr ;k fuxZe okmpj la[;k vkSj rkjh[k No. and Date of Receiot or issue Voucher | C4: fdlls izkIr gqvk ;k fdls tkjh fd;k From Whom received or to whom issued | D4: izkfIr ;k fuxZe dk mn~ns'; Purpose for which received or issue | E4: izkfIr Receipt | F4: LFkkukarj.k Transfer | G4: fuxZe Issues | H4: 'ks"k Balance | I4: vk|{kj Signature
E5: ux No. Vu Tonnes fd-xzk-Kgs. Ltr. | F5: ux No. Vu Tonnes fd-xzk-Kgs. | G5: ux No. Vu Tonnes fd-xzk-Kgs. | H5: ux No. Vu Tonnes fd-xzk-Kgs.
E6: =SUM(E7:E963) -> 140 | F6: =SUM(F7:F963) -> 0 | G6: =SUM(G7:G963) -> 0 | H6: =SUM(E6-F6-G6) -> 140
A7: 45532 | B7: TCS/24-25/002 dated 27.08.2024 | C7: Uniclimb Enterprises PVT LTD. | D7: Fr Channel sleeper | E7: 140 | F7: 0 | G7: 0 | H7: =SUM(E7-F7-G7) -> 140
H452: =H451-G452-F452+E452 -> 0
H453: =H452-G453-F453+E453 -> 0
H454: =H453-G454-F454+E454 -> 0
H455: =H454-G455-F455+E455 -> 0
H456: =H455-G456-F456+E456 -> 0
H457: =H456-G457-F457+E457 -> 0
H458: =H457-G458-F458+E458 -> 0
H459: =H458-G459-F459+E459 -> 0
H460: =H459-G460-F460+E460 -> 0
H461: =H460-G461-F461+E461 -> 0
H462: =H461-G462-F462+E462 -> 0
H463: =H462-G463-F463+E463 -> 0
... H636: =H635-G636-F636+E636 -> 0
E1048534: 2

Sheet Spring washer Sinle coil 
A1: LC | B1: foHkkxh; [kkrk feyku iqLrd DEPARTMENTAL LEDGER AND TALLY BOOK
