Workbook

Sheet Index 
A1: f | B1: Dedicated Freight Corridor Corporation of India
A2: Index
A3: Sr.No. | B3: Particular | C3: Page No. | D3: izkfIr Receipt | E3: LFkkukarj.k Transfer | F3: fuxZe Issues | G3: 'ks"k Balance | H3: Remarks | I3: QR
A4: 1 | B4: PUNJI | C4: 3101 | D4: ='3101'!E6 -> 100 | E4: ='3101'!F6 -> 0 | F4: ='3101'!G6 -> 72 | G4: ='3101'!H6 -> 28 | H4: Nos
A5: 2 | B5: Pick Axe | C5: 3104 | D5: ='3104'!E6 -> 50 | E5: ='3104'!F6 -> 0 | F5: ='3104'!G6 -> 25 | G5: ='3104'!H6 -> 25 | H5: Nos
A6: 3 | B6: ALUMINIUM LADDER | C6: 3107 | D6: ='3107'!E6 -> 4 | E6: ='3107'!F6 -> 0 | F6: ='3107'!G6 -> 2 | G6: ='3107'!H6 -> 2 | H6: Nos
A7: 4 | B7: RAIL DISC CUTTER | C7: 3109 | D7: ='3109'!E6 -> 4 | E7: ='3109'!F6 -> 0 | F7: ='3109'!G6 -> 2 | G7: ='3109'!H6 -> 2 | H7: Nos
A8: 5 | B8: Rail Drilling machine | C8: 3114 | D8: ='3114'!E6 -> 4 | E8: ='3114'!F6 -> 0 | F8: ='3114'!G6 -> 2 | G8: ='3114'!H6 -> 2 | H8: Nos
A9: 6 | B9: AT WELDING TRIMMER | C9: 3116 | D9: ='3116'!E6 -> 2 | E9: ='3116'!F6 -> 0 | F9: ='3116'!G6 -> 1 | G9: ='3116'!H6 -> 1 | H9: Nos
A10: 7 | B10: RAIL MEATING BLOWER FOR AT WELD | C10: 3119 | D10: ='3119'!E6 -> 2 | E10: ='3119'!F6 -> 0 | F10: ='3119'!G6 -> 1 | G10: ='3119'!H6 -> 1 | H10: Nos
A11: 8 | B11: THERMIT WELDING TOOL SET | C11: 3122 | D11: ='3122'!E6 -> 4 | E11: ='3122'!F6 -> 0 | F11: ='3122'!G6 -> 1 | G11: ='3122'!H6 -> 3 | H11: Nos
A12: 9 | B12: RAIL PROFILE WELD GRINDER | C12: 3125 | D12: ='3125'!E6 -> 3 | E12: ='3125'!F6 -> 0 | F12: ='3125'!G6 -> 1 | G12: ='3125'!H6 -> 2 | H12: Nos
A13: 10 | B13: TRACK JACK MECHANICAL | C13: 3131 | D13: ='3131'!E6 -> 10 | E13: ='3131'!F6 -> 0 | F13: ='3131'!G6 -> 7 | G13: ='3131'!H6 -> 3 | H13: Nos
A14: 11 | B14: HEXAGONAL BARI FOR TRACK WORIS | C14: 3134 | D14: ='3134'!E6 -> 100 | E14: ='3134'!F6 -> 0 | F14: ='3134'!G6 -> 67 | G14: ='3134'!H6 -> 33 | H14: Nos
A15: 12 | B15: FISH BULT SPANNER | C15: 3138 | D15: ='3138'!E6 -> 100 | E15: ='3138'!F6 -> 0 | F15: ='3138'!G6 -> 60 | G15: ='3138'!H6 -> 40 | H15: Nos
A16: 13 | B16: Keying Hammer | C16: 3142 | D16: ='3142'!E6 -> 100 | E16: ='3142'!F6 -> 0 | F16: ='3142'!G6 -> 65 | G16: ='3142'!H6 -> 35 | H16: Nos
A17: 14 | B17: P-WAY INSPECTION TROLLY | C17: 3145 | D17: ='3145'!E6 -> 5 | E17: ='3145'!F6 -> 0 | F17: ='3145'!G6 -> 5 | G17: ='3145'!H6 -> 0 | H17: Nos
A18: 15 | B18: MAGNIFYING GLASS 100 MM | C18: 3147 | D18: ='3147'!E6 -> 50 | E18: ='3147'!F6 -> 0 | F18: ='3147'!G6 -> 25 | G18: ='3147'!H6 -> 25 | H18: Nos
A19: 16 | B19: PLATE SCREW TUBULAR SPANNER | C19: 3150 | D19: ='3150'!E6 -> 20 | E19: ='3150'!F6 -> 0 | F19: ='3150'!G6 -> 10 | G19: ='3150'!H6 -> 10 | H19: Nos
A20: 17 | B20: POWRAM SPADE | C20: 3153 | D20: ='3153'!E6 -> 50 | E20: ='3153'!F6 -> 0 | F20: ='3153'!G6 -> 25 | G20: ='3153'!H6 -> 25 | H20: Nos
A21: 18 | B21: PAN MORTAR | C21: 3156 | D21: ='3156'!E6 -> 100 | E21: ='3156'!F6 -> 0 | F21: ='3156'!G6 -> 60 | G21: ='3156'!H6 -> 40 | H21: Nos
A22: 19 | B22: GREASE GUN | C22: 3159 | D22: ='3159'!E6 -> 14 | E22: ='3159'!F6 -> 0 | F22: ='3159'!G6 -> 7 | G22: ='3159'!H6 -> 7 | H22: Nos
A23: 20 | B23: CONTINUAU RAL THERMOMETER(CRT) | C23: 3160 | D23: ='3160'!E6 -> 1 | E23: ='3160'!F6 -> 0 | F23: ='3160'!G6 -> 1 | G23: ='3160'!H6 -> 0 | H23: Nos
A24: 21 | B24: Rail Clip Applicator | C24: 3161 | D24: ='3161'!E6 -> 40 | E24: ='3161'!F6 -> 0 | F24: ='3161'!G6 -> 20 | G24: ='3161'!H6 -> 20 | H24: Nos
A25: 22 | B25: Chambering Kit | C25: 3162 | D25: ='3162'!E6 -> 5 | E25: ='3162'!F6 -> 0 | F25: ='3162'!G6 -> 2 | G25: ='3162'!H6 -> 3 | H25: Nos
A26: 23 | B26: Insulated Rail dolly | C26: 3163 | D26: ='3163'!E6 -> 10 | E26: ='3163'!F6 -> 0 | F26: ='3163'!G6 -> 4 | G26: ='3163'!H6 -> 6 | H26: Nos
A27: 24 | B27: Rail Tong | C27: 3164 | D27: ='3164'!E6 -> 20 | E27: ='3164'!F6 -> 0 | F27: ='3164'!G6 -> 10 | G27: ='3164'!H6 -> 10 | H27: Nos
A28: 25 | B28: PRC SLEEPER CAHIN | C28: 3165 | D28: ='3165'!E6 -> 10 | E28: ='3165'!F6 -> 0 | F28: ='3165'!G6 -> 4 | G28: ='3165'!H6 -> 6 | H28: Nos
A29: 26 | B29: MATERIAL TROLLEY | C29: 3168 | D29: ='3168'!E6 -> 2 | E29: ='3168'!F6 -> 0 | F29: ='3168'!G6 -> 1 | G29: ='3168'!H6 -> 1 | H29: Nos
A30: 27 | B30: DIP LORRY | C30: 3169 | D30: ='3169'!E6 -> 10 | E30: ='3169'!F6 -> 0 | F30: ='3169'!G6 -> 4 | G30: ='3169'!H6 -> 6 | H30: Nos
A31: 28 | B31: wire Basket | C31: 3170 | D31: ='3170'!E6 -> 50 | E31: ='3170'!F6 -> 0 | F31: ='3170'!G6 -> 29 | G31: ='3170'!H6 -> 21 | H31: Nos
A32: 29 | B32: Rake Ballast | C32: 3172 | D32: ='3172'!E6 -> 50 | E32: ='3172'!F6 -> 0 | F32: ='3170'!G6 -> 29 | G32: ='3172'!H6 -> 25 | H32: Nos
A33: 30 | B33: Chain Saw | C33: 3174 | D33: ='3174'!E6 -> 5 | E33: ='3174'!F6 -> 0 | F33: ='3174'!G6 -> 2 | G33: ='3174'!H6 -> 3 | H33: Nos
A34: 31 | B34: Bush Cutter (MC) | C34: 3175 | D34: ='3175'!E6 -> 5 | E34: ='3175'!F6 -> 0 | F34: ='3175'!G6 -> 3 | G34: ='3175'!H6 -> 2 | H34: Nos
A35: 32 | B35: Digital Toe Load Machine | C35: 3177 | D35: ='3177'!E6 -> 2 | E35: ='3177'!F6 -> 0 | F35: ='3177'!G6 -> 0 | G35: ='3177'!H6 -> 2 | H35: Nos
A36: 33 | B36: Safety Belt | C36: 3179 | D36: ='3179'!E6 -> 2 | E36: ='3179'!F6 -> 0 | F36: ='3179'!G6 -> 1 | G36: ='3179'!H6 -> 1 | H36: Nos
A37: 34 | B37: Emergency Lighting (Aska Light) | C37: 3180 | D37: ='3180'!E6 -> 2 | E37: ='3180'!F6 -> 0 | F37: ='3180'!G6 -> 0 | G37: ='3180'!H6 -> 2 | H37: Nos
A38: 35 | B38: Caution Board | C38: 3181 | D38: ='3181'!E6 -> 10 | E38: ='3181'!F6 -> 0 | F38: ='3181'!G6 -> 7 | G38: ='3181'!H6 -> 3 | H38: Nos
A39: 36 | B39: TG Board | C39: 3183 | D39: ='3183'!E6 -> 10 | E39: ='3183'!F6 -> 0 | F39: ='3183'!G6 -> 7 | G39: ='3183'!H6 -> 3 | H39: Nos
A40: 37 | B40: Speed Indicator 10kmph | C40: 3185 | D40: ='3185'!E6 -> 5 | E40: ='3185'!F6 -> 0 | F40: ='3185'!G6 -> 3 | G40: ='3185'!H6 -> 2 | H40: Nos
...

Sheet 3101
B1: foHkkxh; [kkrk feyku iqLrd DEPARTMENTAL LEDGER AND TALLY BOOK
A2: ewY; lwph@dwV la[;k Price List / Code No. | D2: 1 | E2: feyku i= la[;k Tally Code No. | H2: 1 | I2: ;wfuV Unit | J2: 1
A3: oLrq dk fooj.k Description of the Article | D3: PUNJI | E3: ys[kk dk;kZy; i`"B la[;k Accounts Office File No. | I3: 3101
A4: ekg vkSj rkjh[k Month and Date | B4: izkfIr ;k fuxZe okmpj la[;k vkSj rkjh[k No. and Date of Receiot or issue Voucher | C4: fdlls izkIr gqvk ;k fdls tkjh fd;k From Whom received or to whom issued | D4: izkfIr ;k fuxZe dk mn~ns'; Purpose for which received or issue | E4: izkfIr Receipt | F4: LFkkukarj.k Transfer | G4: fuxZe Issues | H4: 'ks"k Balance | I4: 3
E5: ux No. Vu Tonnes fd-xzk-Kgs. | F5: ux No. Vu Tonnes fd-xzk-Kgs. | G5: ux No. Vu Tonnes fd-xzk-Kgs. | H5: ux No. Vu Tonnes fd-xzk-Kgs.
E6: =SUM(E7:E1000) -> 100 | F6: =SUM(F7:F1000) -> 0 | G6: =SUM(G7:G1000) -> 72 | H6: =+E6-F6-G6 -> 28
A7: 45601 | B7: 183 Dated 10.5.2024 | C7: M.S Trades & Eng | D7: For Truck maint. Work | E7: 100 | F7: 0 | G7: 0 | H7: =SUM(E7:G7) -> 100
A8: 16/05/2024 | B8: 183 Dated 10.5.2024 M.S Trades & engg | C8: Abhishek Sharma Executive/CIVILl/ JUDN | D8: For Truck maint. Work | E8: 0 | F8: 0 | G8: 50 | H8: =H7+E8-F8-G8 -> 50
A9: 20/11/2024 | B9: GP/1178/DFC/ Ambala dated 20.11.2024 | C9: Umesh kumar Exel OP&BD/ SMUN | D9: For Truck maint. Work | E9: 0 | F9: 0 | G9: 12 | H9: =H8+E9-F9-G9 -> 38
A10: 30/01/2025 | B10: GP//DFC/ Ambala 1192 dated 20.11.2024 | C10: Surendra kumar Sr. Exec/civ/KNNN | D10: For P- way maint. Work | E10: 0 | F10: 0 | G10: 10 | H10: =H9+E10-F10-G10 -> 28
E11: 0 | F11: 0 | G11: 0 | H11: 0
E12: 0 | F12: 0 | G12: 0 | H12: 0
E13: 0 | F13: 0 | G13: 0 | H13: 0
E14: 0 | F14: 0 | G14: 0 | H14: 0
E15: 0 | F15: 0 | G15: 0 | H15: 0
E16: 0 | F16: 0 | G16: 0 | H16: 0
E17: 0 | F17: 0 | G17: 0 | H17: 0
E18: 0 | F18: 0 | G18: 0 | H18: 0
E19: 0 | F19: 0 | G19: 0 | H19: 0
E20: 0 | F20: 0 | G20: 0 | H20: 0
E21: 0 | F21: 0 | G21: 0 | H21: 0
E22: 0 | F22: 0 | G22: 0 | H22: 0
E23: 0 | F23: 0 | G23: 0 | H23: 0

Sheet 3104
B1: foHkkxh; [kkrk feyku iqLrd DEPARTMENTAL LEDGER AND TALLY BOOK
A2: ewY; lwph@dwV la[;k Price List / Code No. | D2: 2 | E2: feyku i= la[;k Tally Code No. | H2: 1 | I2: ;wfuV Unit | J2: 3
A3: oLrq dk fooj.k Description of the Article | D3: PUNJI | E3: ys[kk dk;kZy; i`"B la[;k Accounts Office File No. | I3: 3104
A4: ekg vkSj rkjh[k Month and Date | B4: izkfIr ;k fuxZe okmpj la[;k vkSj rkjh[k No. and Date of Receiot or issue Voucher | C4: fdlls izkIr gqvk ;k fdls tkjh fd;k From Whom received or to whom issued | D4: izkfIr ;k fuxZe dk mn~ns'; Purpose for which received or issue | E4: izkfIr Receipt | F4: LFkkukarj.k Transfer | G4: fuxZe Issues | H4: 'ks"k Balance | I4: 3
E5: ux No. Vu Tonnes fd-xzk-Kgs. | F5: ux No. Vu Tonnes fd-xzk-Kgs. | G5: ux No. Vu Tonnes fd-xzk-Kgs. | H5: ux No. Vu Tonnes fd-xzk-Kgs.
E6: =SUM(E7:E1000) -> 50 | F6: =SUM(F7:F1000) -> 0 | G6: =SUM(G7:G1000) -> 25 | H6: =+E6-F6-G6 -> 25
A7: 45601 | B7: 183 Dated 10.5.2024 | C7: M.S Trades & Eng | D7: For Truck maint. Work | E7: 50 | F7: 0 | G7: 0 | H7: =E7-F7-G7 -> 50
A8: 16/05/2024 | B8: 183 Dated 10.5.2024 M.S Trades & engg | C8: Abhishek Sharma Executive/CIVILl/ JUDN | D8: For Truck maint. Work | E8: 0 | F8: 0 | G8: 25 | H8: =H7+E8-F8-G8 -> 25
E9: 0 | F9: 0 | G9: 0 | H9: 0
E10: 0 | F10: 0 | G10: 0 | H10: =H9+E10-F10-G10 -> 0
E11: 0 | F11: 0 | G11: 0 | H11: =H10+E11-F11-G11 -> 0
E12: 0 | F12: 0 | G12: 0 | H12: =H11+E12-F12-G12 -> 0
E13: 0 | F13: 0 | G13: 0 | H13: =H12+E13-F13-G13 -> 0
E14: 0 | F14: 0 | G14: 0 | H14: =H13+E14-F14-G14 -> 0
E15: 0 | F15: 0 | G15: 0 | H15: =H14+E15-F15-G15 -> 0
E16: 0 | F16: 0 | G16: 0 | H16: =H15+E16-F16-G16 -> 0
E17: 0 | F17: 0 | G17: 0 | H17: =H16+E17-F17-G17 -> 0
E18: 0 | F18: 0 | G18: 0 | H18: =H17+E18-F18-G18 -> 0
E19: 0 | F19: 0 | G19: 0 | H19: =H18+E19-F19-G19 -> 0
E20: 0 | F20: 0 | G20: 0 | H20: =H19+E20-F20-G20 -> 0
E21: 0 | F21: 0 | G21: 0 | H21: =H20+E21-F21-G21 -> 0
E22: 0 | F22: 0 | G22: 0 | H22: =H21+E22-F22-G22 -> 0
G23: 0 | H23: =H22+E23-F23-G23 -> 0

Sheet 3107
B1: foHkkxh; [kkrk feyku iqLrd DEPARTMENTAL LEDGER AND TALLY BOOK
A2: ewY; lwph@dwV la[;k Price List / Code No. | D2: 3 | E2: feyku i= la[;k Tally Code No. | H2: 1 | I2: ;wfuV Unit | J2: 3
A3: oLrq dk fooj.k Description of the Article | D3: ALUMINIUM LADDER | E3: ys[kk dk;kZy; i`"B la[;k Accounts Office File No. | I3: 3107
A4: ekg vkSj rkjh[k Month and Date | B4: izkfIr ;k fuxZe okmpj la[;k vkSj rkjh[k No. and Date of Receiot or issue Voucher | C4: fdlls izkIr gqvk ;k fdls tkjh fd;k From Whom received or to whom issued | D4: izkfIr ;k fuxZe dk mn~ns'; Purpose for which received or issue | E4: izkfIr Receipt | F4: LFkkukarj.k Transfer | G4: fuxZe Issues | H4: 'ks"k Balance | I4: 3
E5: ux No. Vu Tonnes fd-xzk-Kgs. | F5: ux No. Vu Tonnes fd-xzk-Kgs. | G5: ux No. Vu Tonnes fd-xzk-Kgs. | H5: ux No. Vu Tonnes fd-xzk-Kgs.
E6: =SUM(E7:E1000) -> 4 | F6: =SUM(F7:F1000) -> 0 | G6: =SUM(G7:G1000) -> 2 | H6: =+E6-F6-G6 -> 2
A7: 45601 | B7: 183 Dated 10.5.2024 | C7: M.S Trades & Eng | D7: Track Related works | E7: 4 | F7: 0 | G7: 0 | H7: =SUM(E7:G7) -> 4
A8: 16/05/2024 | B8: 183 Dated 10.5.2024 M.S Trades & engg | C8: Abhishek Sharma Executive/CIVILl/ JUDN | D8: Track Related works | E8: 0 | F8: 0 | G8: 2 | H8: =SUM(E8:G8) -> 2

Sheet 3109
B1: foHkkxh; [kkrk feyku iqLrd DEPARTMENTAL LEDGER AND TALLY BOOK
A2: ewY; lwph@dwV la[;k Price List / Code No. | D2: 4 | E2: feyku i= la[;k Tally Code No. | H2: 1 | I2: ;wfuV Unit | J2: 3
A3: oLrq dk fooj.k Description of the Article | D3: RAIL DISC CUTTER | E3: ys[kk dk;kZy; i`"B la[;k Accounts Office File No. | I3: 3109
A4: ekg vkSj rkjh[k Month and Date | B4: izkfIr ;k fuxZe okmpj la[;k vkSj rkjh[k No. and Date of Receiot or issue Voucher | C4: fdlls izkIr gqvk ;k fdls tkjh fd;k From Whom received or to whom issued | D4: izkfIr ;k fuxZe dk mn~ns'; Purpose for which received or issue | E4: izkfIr Receipt | F4: LFkkukarj.k Transfer | G4: fuxZe Issues | H4: 'ks"k Balance | I4: 3
E5: ux No. Vu Tonnes fd-xzk-Kgs. | F5: ux No. Vu Tonnes fd-xzk-Kgs. | G5: ux No. Vu Tonnes fd-xzk-Kgs. | H5: ux No. Vu Tonnes fd-xzk-Kgs.
E6: =SUM(E7:E1000) -> 4 | F6: =SUM(F7:F1000) -> 0 | G6: =SUM(G7:G1000) -> 2 | H6: =+E6-F6-G6 -> 2
A7: 45601 | B7: 183 Dated 10.5.2024 | C7: M.S Trades & Eng | D7: Track Related works | E7: 4 | F7: 0 | G7: 0 | H7: =SUM(E7:G7) -> 4
A8: 16/05/2024 | B8: 183 Dated 10.5.2024 M.S Trades & engg | C8: Abhishek Sharma Executive/CIVILl/ JUDN | D8: Track Related works | E8: 0 | F8: 0 | G8: 2 | H8: =SUM(E8:G8) -> 2

Sheet 3114
B1: foHkkxh; [kkrk feyku iqLrd DEPARTMENTAL LEDGER AND TALLY BOOK
A2: ewY; lwph@dwV la[;k Price List / Code No. | D2: 6 | E2: feyku i= la[;k Tally Code No. | H2: 1 | I2: ;wfuV Unit | J2: 3
A3: oLrq dk fooj.k Description of the Article | D3: Rail Drilling machine | E3: ys[kk dk;kZy; i`"B la[;k Accounts Office File No. | I3: 3114
A4: ekg vkSj rkjh[k Month and Date | B4: izkfIr ;k fuxZe okmpj la[;k vkSj rkjh[k No. and Date of Receiot or issue Voucher | C4: fdlls izkIr gqvk ;k fdls tkjh fd;k From Whom received or to whom issued | D4: izkfIr ;k fuxZe dk mn~ns'; Purpose for which received or issue | E4: izkfIr Receipt | F4: LFkkukarj.k Transfer | G4: fuxZe Issues | H4: 'ks"k Balance | I4: 3
E5: ux No. Vu Tonnes fd-xzk-Kgs. | F5: ux No. Vu Tonnes fd-xzk-Kgs. | G5: ux No. Vu Tonnes fd-xzk-Kgs. | H5: ux No. Vu Tonnes fd-xzk-Kgs.
E6: =SUM(E7:E1000) -> 4 | F6: =SUM(F7:F1000) -> 0 | G6: =SUM(G7:G1000) -> 2 | H6: =+E6-F6-G6 -> 2
A7: 45601 | B7: 183 Dated 10.5.2024 | C7: M.S Trades & Eng | D7: Track Related works | E7: 4 | F7: 0 | G7: 0 | H7: =SUM(E7:G7) -> 4
A8: 16/05/2024 | B8: 183 Dated 10.5.2024 M.S Trades & engg | C8: Abhishek Sharma Executive/CIVILl/ JUDN | D8: Track Related works | E8: 0 | F8: 0 | G8: 2 | H8: =SUM(E8:G8) -> 2

Sheet 3116
B1: foHkkxh; [kkrk feyku iqLrd DEPARTMENTAL LEDGER AND TALLY BOOK
A2: ewY; lwph@dwV la[;k Price List / Code No. | D2: 7 | E2: feyku i= la[;k Tally Code No. | H2: 1 | I2: ;wfuV Unit | J2: 3
A3: oLrq dk fooj.k Description of the Article | D3: AT WELDING TRIMMER | E3: ys[kk dk;kZy; i`"B la[;k Accounts Office File No. | I3: 3116
A4: ekg vkSj rkjh[k Month and Date | B4: izkfIr ;k fuxZe okmpj la[;k vkSj rkjh[k No. and Date of Receiot or issue Voucher | C4: fdlls izkIr gqvk ;k fdls tkjh fd;k From Whom received or to whom issued | D4: izkfIr ;k fuxZe dk mn~ns'; Purpose for which received or issue | E4: izkfIr Receipt | F4: LFkkukarj.k Transfer | G4: fuxZe Issues | H4: 'ks"k Balance | I4: 3
E5: ux No. Vu Tonnes fd-xzk-Kgs. | F5: ux No. Vu Tonnes fd-xzk-Kgs. | G5: ux No. Vu Tonnes fd-xzk-Kgs. | H5: ux No. Vu Tonnes fd-xzk-Kgs.
E6: =SUM(E7:E1000) -> 2 | F6: =SUM(F7:F1000) -> 0 | G6: =SUM(G7:G1000) -> 1 | H6: =+E6-F6-G6 -> 1
A7: 45601 | B7: 183 Dated 10.5.2024 | C7: M.S Trades & Eng | D7: Track Related works | E7: 2 | F7: 0 | G7: 0 | H7: =SUM(E7:G7) -> 2
A8: 16/05/2024 | B8: 183 Dated 10.5.2024 M.S Trades & engg | C8: Abhishek Sharma Executive/CIVILl/ JUDN | D8: P-WAY | E8: 0 | F8: 0 | G8: 1 | H8: =SUM(E8:G8) -> 1

Sheet 3119
B1: foHkkxh; [kkrk feyku iqLrd DEPARTMENTAL LEDGER AND TALLY BOOK
A2: ewY; lwph@dwV la[;k Price List / Code No. | D2: 8 | E2: feyku i= la[;k Tally Code No. | H2: 1 | I2: ;wfuV Unit | J2: 3
A3: oLrq dk fooj.k Description of the Article | D3: RAIL MEATING BLOWER FOR AT WELD | E3: ys[kk dk;kZy; i`"B la[;k Accounts Office File No. | I3: 3119
A4: ekg vkSj rkjh[k Month and Date | B4: izkfIr ;k fuxZe okmpj la[;k vkSj rkjh[k No. and Date of Receiot or issue Voucher | C4: fdlls izkIr gqvk ;k fdls tkjh fd;k From Whom received or to whom issued | D4: izkfIr ;k fuxZe dk mn~ns'; Purpose for which received or issue | E4: izkfIr Receipt | F4: LFkkukarj.k Transfer | G4: fuxZe Issues | H4: 'ks"k Balance | I4: 3
E5: ux No. Vu Tonnes fd-xzk-Kgs. | F5: ux No. Vu Tonnes fd-xzk-Kgs. | G5: ux No. Vu Tonnes fd-xzk-Kgs. | H5: ux No. Vu Tonnes fd-xzk-Kgs.
E6: =SUM(E7:E1000) -> 2 | F6: =SUM(F7:F1000) -> 0 | G6: =SUM(G7:G1000) -> 1 | H6: =+E6-F6-G6 -> 1
A7: 45601 | B7: 183 Dated 10.5.2024 | C7: M.S Trades & Eng | D7: Track Related works | E7: 2 | F7: 0 | G7: 0 | H7: =SUM(E7:G7) -> 2
A8: 16/05/2024 | B8: 183 Dated 10.5.2024 M.S Trades & engg | C8: Abhishek Sharma Executive/CIVILl/ JUDN | D8: P-Way works | E8: 0 | F8: 0 | G8: 1 | H8: =SUM(E8:G8) -> 1

Sheet 3122
B1: foHkkxh; [kkrk feyku iqLrd DEPARTMENTAL LEDGER AND TALLY BOOK
A2: ewY; lwph@dwV la[;k Price List / Code No. | D2: 9 | E2: feyku i= la[;k Tally Code No. | H2: 1 | I2: ;wfuV Unit | J2: 3
A3: oLrq dk fooj.k Description of the Article | D3: THERMIT WELDING TOOL SET | E3: ys[kk dk;kZy; i`"B la[;k Accounts Office File No. | I3: 3122
A4: ekg vkSj rkjh[k Month and Date | B4: izkfIr ;k fuxZe okmpj la[;k vkSj rkjh[k No. and Date of Receiot or issue Voucher | C4: fdlls izkIr gqvk ;k fdls tkjh fd;k From Whom received or to whom issued | D4: izkfIr ;k fuxZe dk mn~ns'; Purpose for which received or issue | E4: izkfIr Receipt | F4: LFkkukarj.k Transfer | G4: fuxZe Issues | H4: 'ks"k Balance | I4: 3
E5: ux No. Vu Tonnes fd-xzk-Kgs. | F5: ux No. Vu Tonnes fd-xzk-Kgs. | G5: ux No. Vu Tonnes fd-xzk-Kgs. | H5: ux No. Vu Tonnes fd-xzk-Kgs.
E6: =SUM(E7:E1000) -> 4 | F6: =SUM(F7:F1000) -> 0 | G6: =SUM(G7:G1000) -> 1 | H6: =+E6-F6-G6 -> 3
A7: 45601 | B7: 183 Dated 10.5.2024 | C7: M.S Trades & Eng | D7: Track Related works | E7: 2 | F7: 0 | G7: 0 | H7: =SUM(E7:G7) -> 2
A8: 16/05/2024 | B8: 183 Dated 10.5.2024 M.S Trades & engg | C8: Abhishek Sharma Executive/CIVILl/ JUDN | D8: P-Way works | E8: 0 | F8: 0 | G8: 1 | H8: =SUM(E8:G8) -> 1
A9: 30/06/2024 | B9: 0101/24-25 | C9: Chakradhav industries | D9: P-Way works | E9: 2 | F9: 0 | G9: 0 | H9: 3

Sheet 3125
B1: foHkkxh; [kkrk feyku iqLrd DEPARTMENTAL LEDGER AND TALLY BOOK
A2: ewY; lwph@dwV la[;k Price List / Code No. | D2: 10 | E2: feyku i= la[;k Tally Code No. | H2: 1 | I2: ;wfuV Unit | J2: 3
A3: oLrq dk fooj.k Description of the Article | D3: RAIL PROFILE WELD GRINDER | E3: ys[kk dk;kZy; i`"B la[;k Accounts Office File No. | I3: 3125
A4: ekg vkSj rkjh[k Month and Date | B4: izkfIr ;k fuxZe okmpj la[;k vkSj rkjh[k No. and Date of Receiot or issue Voucher | C4: fdlls izkIr gqvk ;k fdls tkjh fd;k From Whom received or to whom issued | D4: izkfIr ;k fuxZe dk mn~ns'; Purpose for which received or issue | E4: izkfIr Receipt | F4: LFkkukarj.k Transfer | G4: fuxZe Issues | H4: 'ks"k Balance | I4: 3
E5: ux No. Vu Tonnes fd-xzk-Kgs. | F5: ux No. Vu Tonnes fd-xzk-Kgs. | G5: ux No. Vu Tonnes fd-xzk-Kgs. | H5: ux No. Vu Tonnes fd-xzk-Kgs.
E6: =SUM(E7:E1000) -> 3 | F6: =SUM(F7:F1000) -> 0 | G6: =SUM(G7:G1000) -> 1 | H6: =+E6-F6-G6 -> 2
A7: 45601 | B7: 183 Dated 10.5.2024 | C7: M.S Trades & Eng | D7: Track Related works | E7: 3 | F7: 0 | G7: 0 | H7: =SUM(E7:G7) -> 3
A8: 16/05/2024 | B8: 183 Dated 10.5.2024 M.S Trades & engg | C8: Abhishek Sharma Executive/CIVILl/ JUDN | D8: P-Way works | E8: 0 | F8: 0 | G8: 1 | H8: 2

Sheet 3131
B1: foHkkxh; [kkrk feyku iqLrd DEPARTMENTAL LEDGER AND TALLY BOOK
A2: ewY; lwph@dwV la[;k Price List / Code No. | D2: 12 | E2: feyku i= la[;k Tally Code No. | H2: 1 | I2: ;wfuV Unit | J2: 3
A3: oLrq dk fooj.k Description of the Article | D3: TRACK JACK MECHANICAL | E3: ys[kk dk;kZy; i`"B la[;k Accounts Office File No. | I3: 3131
A4: ekg vkSj rkjh[k Month and Date | B4: izkfIr ;k fuxZe okmpj la[;k vkSj rkjh[k No. and Date of Receiot or issue Voucher | C4: fdlls izkIr gqvk ;k fdls tkjh fd;k From Whom received or to whom issued | D4: izkfIr ;k fuxZe dk mn~ns'; Purpose for which received or issue | E4: izkfIr Receipt | F4: LFkkukarj.k Transfer | G4: fuxZe Issues | H4: 'ks"k Balance | I4: 3
E5: ux No. Vu Tonnes fd-xzk-Kgs. | F5: ux No. Vu Tonnes fd-xzk-Kgs. | G5: ux No. Vu Tonnes fd-xzk-Kgs. | H5: ux No. Vu Tonnes fd-xzk-Kgs.
E6: =SUM(E7:E1000) -> 10 | F6: =SUM(F7:F1000) -> 0 | G6: =SUM(G7:G1000) -> 7 | H6: =+E6-F6-G6 -> 3
A7: 45601 | B7: 183 Dated 10.5.2024 | C7: M.S Trades & Eng | D7: Track Related works | E7: 10 | F7: 0 | G7: 0 | H7: =SUM(E7:G7) -> 10
A8: 16/05/2024 | B8: 183 Dated 10.5.2024 M.S Trades & engg | C8: Abhishek Sharma Executive/CIVILl/ JUDN | D8: P-Way works | E8: 0 | F8: 0 | G8: 5 | H8: =SUM(E8:G8) -> 5
A9: 21/06/2024 | B9: 183 Dated 10.5.2024 M.S Trades & engg | C9: Sr. Exe/CIVILl/ KNNN Surendera kumar | D9: For use B/W NSIR -SNL Satition | E9: 0 | F9: 0 | G9: 1 | H9: 4
A10: 45687 | B10: GD/DFC/ Ambala sr. no. 1191 dated 30.01.2025 | C10: Surendera kumar Sr. exe/CIVIL/ KNNN | D10: P-Way works | E10: 0 | F10: 0 | G10: 1 | H10: 3

Sheet 3134
B1: foHkkxh; [kkrk feyku iqLrd DEPARTMENTAL LEDGER AND TALLY BOOK
A2: ewY; lwph@dwV la[;k Price List / Code No. | D2: 13 | E2: feyku i= la[;k Tally Code No. | H2: 1 | I2: ;wfuV Unit | J2: 3
A3: oLrq dk fooj.k Description of the Article | D3: HEXAGONAL BARI FOR TRACK WORIS | E3: ys[kk dk;kZy; i`"B la[;k Accounts Office File No. | I3: 3134 | J3: 3030
A4: ekg vkSj rkjh[k Month and Date | B4: izkfIr ;k fuxZe okmpj la[;k vkSj rkjh[k No. and Date of Receiot or issue Voucher | C4: fdlls izkIr gqvk ;k fdls tkjh fd;k From Whom received or to whom issued | D4: izkfIr ;k fuxZe dk mn~ns'; Purpose for which received or issue | E4: izkfIr Receipt | F4: LFkkukarj.k Transfer | G4: fuxZe Issues | H4: 'ks"k Balance | I4: 3
E5: ux No. Vu Tonnes fd-xzk-Kgs. | F5: ux No. Vu Tonnes fd-xzk-Kgs. | G5: ux No. Vu Tonnes fd-xzk-Kgs. | H5: ux No. Vu Tonnes fd-xzk-Kgs.
E6: =SUM(E7:E1000) -> 100 | F6: =SUM(F7:F1000) -> 0 | G6: =SUM(G7:G1000) -> 67 | H6: =+E6-F6-G6 -> 33
A7: 45601 | B7: 183 Dated 10.5.2024 | C7: M.S Trades & Eng | D7: Track Related works | E7: 100 | F7: 0 | G7: 0 | H7: =SUM(E7:G7) -> 100
A8: 16/05/2024 | B8: 183 Dated 10.5.2024 M.S Trades & engg | C8: Abhishek Sharma Executive/CIVILl/ JUDN | D8: P-Way works | E8: 0 | F8: 0 | G8: 50 | H8: =+H7+E8-F8-G8 -> 50
A9: 21/06/2024 | B9: 183 Dated 10.5.2024 M.S Trades & engg | C9: Executive/CIVILl/ KNNN Surendra kumar | D9: P-Way works B/W NSIR-SNL STATION | E9: 0 | F9: 0 | G9: 2 | H9: =+H8+E9-F9-G9 -> 48
A10: 16/08//2024 | B10: GP/DFC/ Ambala Dated : Sr. NO.1217 | C10: Satish Kumar Bhrdwaj Executive/mech/ SMUN | D10: Mech. Department use | E10: 0 | F10: 0 | G10: 2 | H10: =+H9+E10-F10-G10 -> 46
A11: 24/10/2024 | B11: Reaustion Note Dt: 18.10.2024 | C11: M/S goal brother .Rail in pvt. | D11: P-way works | E11: 0 | F11: 0 | G11: 10 | H11: =+H10+E11-F11-G11 -> 36
A12: 30/01/2025 | B12: GP/DFC/ Ambala Dated : Sr.no. 1192 dated 30.01.2025 | C12: Executive/CIVILl/ KNNN Surendra kumar | D12: P-way maint works | E12: 0 | F12: 0 | G12: 3 | H12: =+H11+E12-F12-G12 -> 33
G13: 0

Sheet 3138
B1: foHkkxh; [kkrk feyku iqLrd DEPARTMENTAL LEDGER AND TALLY BOOK
A2: ewY; lwph@dwV la[;k Price List / Code No. | D2: 14 | E2: feyku i= la[;k Tally Code No. | H2: 1 | I2: ;wfuV Unit | J2: 3
A3: oLrq dk fooj.k Description of the Article | D3: FISH BULT SPANNER | E3: ys[kk dk;kZy; i`"B la[;k Accounts Office File No. | I3: 3138
A4: ekg vkSj rkjh[k Month and Date | B4: izkfIr ;k fuxZe okmpj la[;k vkSj rkjh[k No. and Date of Receiot or issue Voucher | C4: fdlls izkIr gqvk ;k fdls tkjh fd;k From Whom received or to whom issued | D4: izkfIr ;k fuxZe dk mn~ns'; Purpose for which received or issue | E4: izkfIr Receipt | F4: LFkkukarj.k Transfer | G4: fuxZe Issues | H4: 'ks"k Balance | I4: 3
E5: ux No. Vu Tonnes fd-xzk-Kgs. | F5: ux No. Vu Tonnes fd-xzk-Kgs. | G5: ux No. Vu Tonnes fd-xzk-Kgs. | H5: ux No. Vu Tonnes fd-xzk-Kgs.
E6: =SUM(E7:E1000) -> 100 | F6: =SUM(F7:F1000) -> 0 | G6: =SUM(G7:G1000) -> 60 | H6: =+E6-F6-G6 -> 40
A7: 45601 | B7: 183 Dated 10.5.2024 | C7: M.S Trades & Eng | D7: Track Related works | E7: 50 | F7: 0 | G7: 0 | H7: =SUM(E7:G7) -> 50
A8: 45450 | B8: 197 Dated 29/063/2024 | C8: M.S Trades & Eng | D8: Track Related works | E8: 50 | F8: 0 | G8: 0 | H8: =+H7+E8-F8-G8 -> 100
A9: 45573 | B9: GP/DFC/ Ambala Sr. No. 1216 | C9: Abhishek Sharma Exe/CIVILl/ Sr. No. 1216 | D9: Track Related works | E9: 0 | F9: 0 | G9: 50 | H9: =+H8+E9-F9-G9 -> 50
A10: 27/11/2024 | B10: GP/DFC/ Ambala sr. no. 1217 dated | C10: Gurnam singh , Operational off. (AWPO) | D10: For Patrolman | E10: 0 | F10: 0 | G10: 10 | H10: =+H9+E10-F10-G10 -> 40

Sheet 3142
B1: foHkkxh; [kkrk feyku iqLrd DEPARTMENTAL LEDGER AND TALLY BOOK
A2: ewY; lwph@dwV la[;k Price List / Code No. | D2: 15 | E2: feyku i= la[;k Tally Code No. | H2: 1 | I2: ;wfuV Unit | J2: 3
A3: oLrq dk fooj.k Description of the Article | D3: Keying Hammer | E3: ys[kk dk;kZy; i`"B la[;k Accounts Office File No. | I3: 3142
A4: ekg vkSj rkjh[k Month and Date | B4: izkfIr ;k fuxZe okmpj la[;k vkSj rkjh[k No. and Date of Receiot or issue Voucher | C4: fdlls izkIr gqvk ;k fdls tkjh fd;k From Whom received or to whom issued | D4: izkfIr ;k fuxZe dk mn~ns'; Purpose for which received or issue | E4: izkfIr Receipt | F4: LFkkukarj.k Transfer | G4: fuxZe Issues | H4: 'ks"k Balance | I4: 3
E5: ux No. Vu Tonnes fd-xzk-Kgs. | F5: ux No. Vu Tonnes fd-xzk-Kgs. | G5: ux No. Vu Tonnes fd-xzk-Kgs. | H5: ux No. Vu Tonnes fd-xzk-Kgs.
E6: =SUM(E7:E1000) -> 100 | F6: =SUM(F7:F1000) -> 0 | G6: =SUM(G7:G1000) -> 65 | H6: =+E6-F6-G6 -> 35
A7: 45601 | B7: 183 Dated 10.5.2024 | C7: M.S Trades & Eng | D7: Track Related works | E7: 100 | F7: 0 | G7: 0 | H7: =SUM(E7:G7) -> 100
A8: 16/05/2024 | B8: 183 Dated 10.5.2024 M S. Tradres & engg | C8: M.S Trades & Eng | D8: Track Mainteance works | E8: 0 | F8: 0 | G8: 50 | H8: =H7+E8-F8-G8 -> 50
A9: 16/8/2024 | B9: GP/DFC/ Ambala sr. no. 1217 | C9: Abhishek Sharma Exe/CIVILl/ Sr. No. 1216 | D9: Machine Puse | E9: 0 | F9: 0 | G9: 1 | H9: =H8+E9-F9-G9 -> 49
A10: 27/11/2024 | B10: GP/DFC/ Ambala sr. no. 1181 Dated: 27.11.2024 | C10: Gurnam singh , Operational off. (AWPO) | D10: For Patrolman | E10: 0 | F10: 0 | G10: 10 | H10: =H9+E10-F10-G10 -> 39
A11: 30/01/2025 | B11: GP/DFC/ Ambala sr. no. 1192 Dated: 30.01.2025 | C11: Surendra Kumar Sr. Exec/civ/KNNN | D11: fFor track Maint work | E11: 0 | F11: 0 | G11: 4 | H11: =H10+E11-F11-G11 -> 35

Sheet 3145
B1: foHkkxh; [kkrk feyku iqLrd DEPARTMENTAL LEDGER AND TALLY BOOK
A2: ewY; lwph@dwV la[;k Price List / Code No. | D2: 16 | E2: feyku i= la[;k Tally Code No. | H2: 1 | I2: ;wfuV Unit | J2: 3
A3: oLrq dk fooj.k Description of the Article | D3: P-WAY INSPECTION TROLLEY | E3: ys[kk dk;kZy; i`"B la[;k Accounts Office File No. | I3: 3145
A4: ekg vkSj rkjh[k Month and Date | B4: izkfIr ;k fuxZe okmpj la[;k vkSj rkjh[k No. and Date of Receiot or issue Voucher | C4: fdlls izkIr gqvk ;k fdls tkjh fd;k From Whom received or to whom issued | D4: izkfIr ;k fuxZe dk mn~ns'; Purpose for which received or issue | E4: izkfIr Receipt | F4: LFkkukarj.k Transfer | G4: fuxZe Issues | H4: 'ks"k Balance | I4: 3
E5: ux No. Vu Tonnes fd-xzk-Kgs. | F5: ux No. Vu Tonnes fd-xzk-Kgs. | G5: ux No. Vu Tonnes fd-xzk-Kgs. | H5: ux No. Vu Tonnes fd-xzk-Kgs.
E6: =SUM(E7:E1000) -> 5 | F6: =SUM(F7:F1000) -> 0 | G6: =SUM(G7:G1000) -> 5 | H6: =+E6-F6-G6 -> 0
A7: 45601 | B7: 183 Dated 10.05.2024 | C7: M.S Traders & Enginers | D7: Track Related works | E7: 3 | F7: 0 | G7: 0 | H7: =SUM(E7:G7) -> 3
A8: 45601 | B8: 184 Dated 10.05.2024 | C8: M.S Traders & Enginers | D8: Track Related works | E8: 2 | F8: 0 | G8: 0 | H8: 5
A9: 16-05-2024 | B9: 183 Dated 10.05.2024 (M.S. Traders & engg) | C9: Surendera kumar Sr. Exec/CIVIL/ KNNN | D9: For track inspection | E9: 0 | F9: 0 | G9: 1 | H9: 4
A10: 16-05-2024 | B10: 183 Dated 10.05.2024 (M.S. Traders & engg) | C10: A.N.Tripathi JPM/ENGG/UMB | D10: For track inspection | E10: 0 | F10: 0 | G10: 1 | H10: 3
A11: 16-05-2024 | B11: 183 Dated 10.05.2024 (M.S. Traders & engg) | C11: Pradeep kumar Sr.Exe/CIVIL/JUDN | D11: For track inspection | E11: 0 | F11: 0 | G11: 1 | H11: 2
A12: 16-03-2024 | B12: 183 Dated 10.05.2024 (M.S. Traders & engg) | C12: Harpal Singh Sr.Exe/CIVIL/SMUN | D12: For track inspection | E12: 0 | F12: 0 | G12: 2 | H12: 0

Sheet 3147
B1: foHkkxh; [kkrk feyku iqLrd DEPARTMENTAL LEDGER AND TALLY BOOK
A2: ewY; lwph@dwV la[;k Price List / Code No. | D2: 17 | E2: feyku i= la[;k Tally Code No. | H2: 1 | I2: ;wfuV Unit | J2: 3
A3: oLrq dk fooj.k Description of the Article | D3: MAGNIFYING GLASS 100 MM | E3: ys[kk dk;kZy; i`"B la[;k Accounts Office File No. | I3: 3147
A4: ekg vkSj rkjh[k Month and Date | B4: izkfIr ;k fuxZe okmpj la[;k vkSj rkjh[k No. and Date of Receiot or issue Voucher | C4: fdlls izkIr gqvk ;k fdls tkjh fd;k From Whom received or to whom issued | D4: izkfIr ;k fuxZe dk mn~ns'; Purpose for which received or issue | E4: izkfIr Receipt | F4: LFkkukarj.k Transfer | G4: fuxZe Issues | H4: 'ks"k Balance | I4: 3
E5: ux No. Vu Tonnes fd-xzk-Kgs. | F5: ux No. Vu Tonnes fd-xzk-Kgs. | G5: ux No. Vu Tonnes fd-xzk-Kgs. | H5: ux No. Vu Tonnes fd-xzk-Kgs.
E6: =SUM(E7:E1000) -> 50 | F6: =SUM(F7:F1000) -> 0 | G6: =SUM(G7:G1000) -> 25 | H6: =+E6-F6-G6 -> 25
A7: 45601 | B7: 183 Dated 10.05.2024 | C7: M.S Traders & Enginers | D7: Track Related works | E7: 50 | F7: 0 | G7: 0 | H7: =SUM(E7:G7) -> 50
A8: 45601 | B8: 184 Dated 10.05.2024 M .S Traders & engg | C8: Abhishek Sharma Exe/CIVIL/JUDN | D8: Bridge Inspection Related works | E8: 0 | F8: 0 | G8: 25 | H8: 25

Sheet 3150
B1: foHkkxh; [kkrk feyku iqLrd DEPARTMENTAL LEDGER AND TALLY BOOK
A2: ewY; lwph@dwV la[;k Price List / Code No. | D2: 18 | E2: feyku i= la[;k Tally Code No. | H2: 1 | I2: ;wfuV Unit | J2: 3
A3: oLrq dk fooj.k Description of the Article | D3: PLATE SCREW TUBULAR SPANNER | E3: ys[kk dk;kZy; i`"B la[;k Accounts Office File No. | I3: 3150
A4: ekg vkSj rkjh[k Month and Date | B4: izkfIr ;k fuxZe okmpj la[;k vkSj rkjh[k No. and Date of Receiot or issue Voucher | C4: fdlls izkIr gqvk ;k fdls tkjh fd;k From Whom received or to whom issued | D4: izkfIr ;k fuxZe dk mn~ns'; Purpose for which received or issue | E4: izkfIr Receipt | F4: LFkkukarj.k Transfer | G4: fuxZe Issues | H4: 'ks"k Balance | I4: 3
E5: ux No. Vu Tonnes fd-xzk-Kgs. | F5: ux No. Vu Tonnes fd-xzk-Kgs. | G5: ux No. Vu Tonnes fd-xzk-Kgs. | H5: ux No. Vu Tonnes fd-xzk-Kgs.
E6: =SUM(E7:E1000) -> 20 | F6: =SUM(F7:F1000) -> 0 | G6: =SUM(G7:G1000) -> 10 | H6: =+E6-F6-G6 -> 10
A7: 45601 | B7: 183 Dated 10.05.2024 | C7: M.S Traders & Enginers | D7: Track Related works | E7: 20 | F7: 0 | G7: 0 | H7: =SUM(E7:G7) -> 20
A8: 2024-16-05 | B8: 184 Dated 10.05.2024 M .S Traders & engg | C8: Abhishek Sharma Exe/CIVIL/JUDN | D8: Bridge Inspection Related works | E8: 0 | F8: 0 | G8: 10 | H8: 10

Sheet 3153
B1: foHkkxh; [kkrk feyku iqLrd DEPARTMENTAL LEDGER AND TALLY BOOK
A2: ewY; lwph@dwV la[;k Price List / Code No. | D2: 19 | E2: feyku i= la[;k Tally Code No. | H2: 1 | I2: ;wfuV Unit | J2: 3
A3: oLrq dk fooj.k Description of the Article | D3: POWRAM SPADE | E3: ys[kk dk;kZy; i`"B la[;k Accounts Office File No. | I3: 3153
A4: ekg vkSj rkjh[k Month and Date | B4: izkfIr ;k fuxZe okmpj la[;k vkSj rkjh[k No. and Date of Receiot or issue Voucher | C4: fdlls izkIr gqvk ;k fdls tkjh fd;k From Whom received or to whom issued | D4: izkfIr ;k fuxZe dk mn~ns'; Purpose for which received or issue | E4: izkfIr Receipt | F4: LFkkukarj.k Transfer | G4: fuxZe Issues | H4: 'ks"k Balance | I4: 3
E5: ux No. Vu Tonnes fd-xzk-Kgs. | F5: ux No. Vu Tonnes fd-xzk-Kgs. | G5: ux No. Vu Tonnes fd-xzk-Kgs. | H5: ux No. Vu Tonnes fd-xzk-Kgs.
E6: =SUM(E7:E1000) -> 50 | F6: =SUM(F7:F1000) -> 0 | G6: =SUM(G7:G1000) -> 25 | H6: =+E6-F6-G6 -> 25
A7: 45601 | B7: 183 Dated 10.05.2024 | C7: M.S Traders & Enginers | D7: Track Related works | E7: 50 | F7: 0 | G7: 0 | H7: =SUM(E7:G7) -> 50
A8: 2024-16-05 | B8: 184 Dated 10.05.2024 M .S Traders & engg | C8: Abhishek Sharma Exe/CIVIL/JUDN | D8: Track Related works | E8: 0 | F8: 0 | G8: 25 | H8: 25

Sheet 3156
B1: foHkkxh; [kkrk feyku iqLrd DEPARTMENTAL LEDGER AND TALLY BOOK
A2: ewY; lwph@dwV la[;k Price List / Code No. | D2: 20 | E2: feyku i= la[;k Tally Code No. | H2: 1 | I2: ;wfuV Unit | J2: 3
A3: oLrq dk fooj.k Description of the Article | D3: PAN MORTAR | E3: ys[kk dk;kZy; i`"B la[;k Accounts Office File No. | I3: 3156
A4: ekg vkSj rkjh[k Month and Date | B4: izkfIr ;k fuxZe okmpj la[;k vkSj rkjh[k No. and Date of Receiot or issue Voucher | C4: fdlls izkIr gqvk ;k fdls tkjh fd;k From Whom received or to whom issued | D4: izkfIr ;k fuxZe dk mn~ns'; Purpose for which received or issue | E4: izkfIr Receipt | F4: LFkkukarj.k Transfer | G4: fuxZe Issues | H4: 'ks"k Balance | I4: 3
E5: ux No. Vu Tonnes fd-xzk-Kgs. | F5: ux No. Vu Tonnes fd-xzk-Kgs. | G5: ux No. Vu Tonnes fd-xzk-Kgs. | H5: ux No. Vu Tonnes fd-xzk-Kgs.
E6: =SUM(E7:E1000) -> 100 | F6: =SUM(F7:F1000) -> 0 | G6: =SUM(G7:G1000) -> 60 | H6: =+E6-F6-G6 -> 40
A7: 45601 | B7: 183 Dated 10.05.2024 | C7: M.S Traders & Enginers | D7: Track Related works | E7: 100 | F7: 0 | G7: 0 | H7: =SUM(E7:G7) -> 100
A8: 2024-16-05 | B8: 183 Dated 10.05.2024 M .S Traders & engg | C8: Abhishek Sharma Exe/CIVIL-1/JUDN | D8: Track maint. works | E8: 0 | F8: 0 | G8: 50 | H8: =H7+E8-F8-G8 -> 50
A9: 46044 | B9: GP/DFC/Ambala Sr.No. 1166 dt. 22.01.2026 | C9: IMD/CHAN | D9: Track maint. works | E9: 0 | F9: 0 | G9: 10 | H9: =H8+E9-F9-G9 -> 40
E10: 0 | F10: 0
E11: 0 | F11: 0
E12: 0 | F12: 0

Sheet 3159
B1: foHkkxh; [kkrk feyku iqLrd DEPARTMENTAL LEDGER AND TALLY BOOK
A2: ewY; lwph@dwV la[;k Price List / Code No. | D2: 21 | E2: feyku i= la[;k Tally Code No. | H2: 1 | I2: ;wfuV Unit | J2: 3
A3: oLrq dk fooj.k Description of the Article | D3: GREASE GUN | E3: ys[kk dk;kZy; i`"B la[;k Accounts Office File No. | I3: 3159
A4: ekg vkSj rkjh[k Month and Date | B4: izkfIr ;k fuxZe okmpj la[;k vkSj rkjh[k No. and Date of Receiot or issue Voucher | C4: fdlls izkIr gqvk ;k fdls tkjh fd;k From Whom received or to whom issued | D4: izkfIr ;k fuxZe dk mn~ns'; Purpose for which received or issue | E4: izkfIr Receipt | F4: LFkkukarj.k Transfer | G4: fuxZe Issues | H4: 'ks"k Balance | I4: 3
E5: ux No. Vu Tonnes fd-xzk-Kgs. | F5: ux No. Vu Tonnes fd-xzk-Kgs. | G5: ux No. Vu Tonnes fd-xzk-Kgs. | H5: ux No. Vu Tonnes fd-xzk-Kgs.
E6: =SUM(E7:E1000) -> 14 | F6: =SUM(F7:F1000) -> 0 | G6: =SUM(G7:G1000) -> 7 | H6: =+E6-F6-G6 -> 7
A7: 45601 | B7: 183 Dated 10.05.2024 | C7: M.S Traders & Enginers | D7: Track Related works | E7: 14 | F7: 0 | G7: 0 | H7: =SUM(E7:G7) -> 14
A8: 2024-16-05 | B8: 184 Dated 10.05.2024 M .S Traders & engg | C8: Abhishek Sharma Exe/CIVIL-1/JUDN | D8: Track works | E8: 0 | F8: 0 | G8: 7 | H8: 7

Sheet 3160
B1: foHkkxh; [kkrk feyku iqLrd DEPARTMENTAL LEDGER AND TALLY BOOK
A2: ewY; lwph@dwV la[;k Price List / Code No. | D2: 22 | E2: feyku i= la[;k Tally Code No. | H2: 1 | I2: ;wfuV Unit | J2: 3
A3: oLrq dk fooj.k Description of the Article | D3: CONTINUAUS RAIL THERMOMETER(CRT) | E3: ys[kk dk;kZy; i`"B la[;k Accounts Office File No. | I3: 3160
A4: ekg vkSj rkjh[k Month and Date | B4: izkfIr ;k fuxZe okmpj la[;k vkSj rkjh[k No. and Date of Receiot or issue Voucher | C4: fdlls izkIr gqvk ;k fdls tkjh fd;k From Whom received or to whom issued | D4: izkfIr ;k fuxZe dk mn~ns'; Purpose for which received or issue | E4: izkfIr Receipt | F4: LFkkukarj.k Transfer | G4: fuxZe Issues | H4: 'ks"k Balance | I4: 3
E5: ux No. Vu Tonnes fd-xzk-Kgs. | F5: ux No. Vu Tonnes fd-xzk-Kgs. | G5: ux No. Vu Tonnes fd-xzk-Kgs. | H5: ux No. Vu Tonnes fd-xzk-Kgs. | L5: Index '!B23
E6: =SUM(E7:E1000) -> 1 | F6: =SUM(F7:F1000) -> 0 | G6: =SUM(G7:G1000) -> 1 | H6: =+E6-F6-G6 -> 0
A7: 29-06-2024 | B7: DIE- 2024-25-241 Dated 26-06-2024 | C7: Paragon Instrumentaton Engineers pvt ltd (DIE) | D7: Track Related works | E7: 1 | F7: 0 | G7: 0 | H7: =SUM(E7:G7) -> 1
A8: 14-10-2024 | B8: 184 Dated 10.05.2024 M .S Traders & engg | C8: IMSD JUDN, Vibhanshu Prasher , Exe/CIVIL | D8: Track Related works | E8: 0 | F8: 0 | G8: 1 | H8: 0

Sheet 3161
B1: foHkkxh; [kkrk feyku iqLrd DEPARTMENTAL LEDGER AND TALLY BOOK
A2: ewY; lwph@dwV la[;k Price List / Code No. | D2: 23 | E2: feyku i= la[;k Tally Code No. | H2: 1 | I2: ;wfuV Unit | J2: 3
A3: oLrq dk fooj.k Description of the Article | D3: Rail Clip Applicator | E3: ys[kk dk;kZy; i`"B la[;k Accounts Office File No. | I3: 3161
A4: ekg vkSj rkjh[k Month and Date | B4: izkfIr ;k fuxZe okmpj la[;k vkSj rkjh[k No. and Date of Receiot or issue Voucher | C4: fdlls izkIr gqvk ;k fdls tkjh fd;k From Whom received or to whom issued | D4: izkfIr ;k fuxZe dk mn~ns'; Purpose for which received or issue | E4: izkfIr Receipt | F4: LFkkukarj.k Transfer | G4: fuxZe Issues | H4: 'ks"k Balance | I4: 3
E5: ux No. Vu Tonnes fd-xzk-Kgs. | F5: ux No. Vu Tonnes fd-xzk-Kgs. | G5: ux No. Vu Tonnes fd-xzk-Kgs. | H5: ux No. Vu Tonnes fd-xzk-Kgs.
E6: =SUM(E7:E1000) -> 40 | F6: =SUM(F7:F1000) -> 0 | G6: =SUM(G7:G1000) -> 20 | H6: =+E6-F6-G6 -> 20
A7: 45450 | B7: 197 dated 29/06/2024 | C7: M.S Traders & Engg. | D7: Track Related works | E7: 40 | F7: 0 | G7: 0 | H7: =SUM(E7:G7) -> 40
A8: 45573 | B8: GP/DFC/ Ambala Sr. no. 1214 | C8: Abhishek Sharma Exe/CIVIL/JUDN IMSD/JUDN | D8: Track Related works | E8: 0 | F8: 0 | G8: 20 | H8: 20

Sheet 3162
B1: foHkkxh; [kkrk feyku iqLrd DEPARTMENTAL LEDGER AND TALLY BOOK
A2: ewY; lwph@dwV la[;k Price List / Code No. | D2: 24 | E2: feyku i= la[;k Tally Code No. | H2: 1 | I2: ;wfuV Unit | J2: 3
A3: oLrq dk fooj.k Description of the Article | D3: chambering Kit | E3: ys[kk dk;kZy; i`"B la[;k Accounts Office File No. | I3: 3162
A4: ekg vkSj rkjh[k Month and Date | B4: izkfIr ;k fuxZe okmpj la[;k vkSj rkjh[k No. and Date of Receiot or issue Voucher | C4: fdlls izkIr gqvk ;k fdls tkjh fd;k From Whom received or to whom issued | D4: izkfIr ;k fuxZe dk mn~ns'; Purpose for which received or issue | E4: izkfIr Receipt | F4: LFkkukarj.k Transfer | G4: fuxZe Issues | H4: 'ks"k Balance | I4: 3
E5: ux No. Vu Tonnes fd-xzk-Kgs. | F5: ux No. Vu Tonnes fd-xzk-Kgs. | G5: ux No. Vu Tonnes fd-xzk-Kgs. | H5: ux No. Vu Tonnes fd-xzk-Kgs.
E6: =SUM(E7:E1000) -> 5 | F6: =SUM(F7:F1000) -> 0 | G6: =SUM(G7:G1000) -> 2 | H6: =+E6-F6-G6 -> 3
A7: 45450 | B7: 197 dated 29/06/2024 | C7: M.S Traders & Engg. | D7: Track Related works | E7: 5 | F7: 0 | G7: 0 | H7: =SUM(E7:G7) -> 5
A8: 45573 | B8: GP/DFC/ Ambala Sr. no. 1214 | C8: Abhishek Sharma Exe/CIVIL/JUDN IMSD/JUDN | D8: Track Related works | E8: 0 | F8: 0 | G8: 2 | H8: 3

Sheet 3163
B1: foHkkxh; [kkrk feyku iqLrd DEPARTMENTAL LEDGER AND TALLY BOOK
A2: ewY; lwph@dwV la[;k Price List / Code No. | D2: 25 | E2: feyku i= la[;k Tally Code No. | H2: 1 | I2: ;wfuV Unit | J2: 3
A3: oLrq dk fooj.k Description of the Article | D3: Insulated Rail dolly | E3: ys[kk dk;kZy; i`"B la[;k Accounts Office File No. | I3: 3163
A4: ekg vkSj rkjh[k Month and Date | B4: izkfIr ;k fuxZe okmpj la[;k vkSj rkjh[k No. and Date of Receiot or issue Voucher | C4: fdlls izkIr gqvk ;k fdls tkjh fd;k From Whom received or to whom issued | D4: izkfIr ;k fuxZe dk mn~ns'; Purpose for which received or issue | E4: izkfIr Receipt | F4: LFkkukarj.k Transfer | G4: fuxZe Issues | H4: 'ks"k Balance | I4: 3
E5: ux No. Vu Tonnes fd-xzk-Kgs. | F5: ux No. Vu Tonnes fd-xzk-Kgs. | G5: ux No. Vu Tonnes fd-xzk-Kgs. | H5: ux No. Vu Tonnes fd-xzk-Kgs.
E6: =SUM(E7:E1000) -> 10 | F6: =SUM(F7:F1000) -> 0 | G6: =SUM(G7:G1000) -> 4 | H6: =+E6-F6-G6 -> 6
A7: 45450 | B7: 197 dated 29/06/2024 | C7: M.S Traders & Engg. | D7: Track Related works | E7: 10 | F7: 0 | G7: 0 | H7: =SUM(E7:G7) -> 10
A8: 45573 | B8: GP/DFC/ Ambala Sr. no. 1214 | C8: Abhishek Sharma Exe/CIVIL/JUDN IMSD/JUDN | D8: Track Related works | E8: 0 | F8: 0 | G8: 4 | H8: 6

Sheet 3164
B1: foHkkxh; [kkrk feyku iqLrd DEPARTMENTAL LEDGER AND TALLY BOOK
A2: ewY; lwph@dwV la[;k Price List / Code No. | D2: 26 | E2: feyku i= la[;k Tally Code No. | H2: 1 | I2: ;wfuV Unit | J2: 3
A3: oLrq dk fooj.k Description of the Article | D3: Rail Tong | E3: ys[kk dk;kZy; i`"B la[;k Accounts Office File No. | I3: 3164
A4: ekg vkSj rkjh[k Month and Date | B4: izkfIr ;k fuxZe okmpj la[;k vkSj rkjh[k No. and Date of Receiot or issue Voucher | C4: fdlls izkIr gqvk ;k fdls tkjh fd;k From Whom received or to whom issued | D4: izkfIr ;k fuxZe dk mn~ns'; Purpose for which received or issue | E4: izkfIr Receipt | F4: LFkkukarj.k Transfer | G4: fuxZe Issues | H4: 'ks"k Balance | I4: 3
E5: ux No. Vu Tonnes fd-xzk-Kgs. | F5: ux No. Vu Tonnes fd-xzk-Kgs. | G5: ux No. Vu Tonnes fd-xzk-Kgs. | H5: ux No. Vu Tonnes fd-xzk-Kgs.
E6: =SUM(E7:E1000) -> 20 | F6: =SUM(F7:F1000) -> 0 | G6: =SUM(G7:G1000) -> 10 | H6: =+E6-F6-G6 -> 10
A7: 45450 | B7: 197 dated 29/06/2024 | C7: M.S Traders & Engg. | D7: Track Related works | E7: 20 | F7: 0 | G7: 0 | H7: =SUM(E7:G7) -> 20
A8: 45573 | B8: GP/DFC/ Ambala Sr. no. 1214 | C8: Abhishek Sharma Exe/CIVIL/JUDN IMSD/JUDN | D8: Track Related works | E8: 0 | F8: 0 | G8: 10 | H8: 10

Sheet 3165
B1: foHkkxh; [kkrk feyku iqLrd DEPARTMENTAL LEDGER AND TALLY BOOK
A2: ewY; lwph@dwV la[;k Price List / Code No. | D2: 27 | E2: feyku i= la[;k Tally Code No. | H2: 1 | I2: ;wfuV Unit | J2: 3
A3: oLrq dk fooj.k Description of the Article | D3: PRC SLEEPER CHAIN | E3: ys[kk dk;kZy; i`"B la[;k Accounts Office File No. | I3: 3165
A4: ekg vkSj rkjh[k Month and Date | B4: izkfIr ;k fuxZe okmpj la[;k vkSj rkjh[k No. and Date of Receiot or issue Voucher | C4: fdlls izkIr gqvk ;k fdls tkjh fd;k From Whom received or to whom issued | D4: izkfIr ;k fuxZe dk mn~ns'; Purpose for which received or issue | E4: izkfIr Receipt | F4: LFkkukarj.k Transfer | G4: fuxZe Issues | H4: 'ks"k Balance | I4: 3
E5: ux No. Vu Tonnes fd-xzk-Kgs. | F5: ux No. Vu Tonnes fd-xzk-Kgs. | G5: ux No. Vu Tonnes fd-xzk-Kgs. | H5: ux No. Vu Tonnes fd-xzk-Kgs.
E6: =SUM(E7:E1000) -> 10 | F6: =SUM(F7:F1000) -> 0 | G6: =SUM(G7:G1000) -> 4 | H6: =+E6-F6-G6 -> 6
A7: 45450 | B7: 197 dated 29/06/2024 | C7: M.S Traders & Engg. | D7: Track Related works | E7: 10 | F7: 0 | G7: 0 | H7: =SUM(E7:G7) -> 10
A8: 45573 | B8: GP/DFC/ Ambala Sr. no. 1214 | C8: Abhishek Sharma Exe/CIVIL/JUDN IMSD/JUDN | D8: Track Related works | E8: 0 | F8: 0 | G8: 4 | H8: 6

Sheet 3168
B1: foHkkxh; [kkrk feyku iqLrd DEPARTMENTAL LEDGER AND TALLY BOOK
A2: ewY; lwph@dwV la[;k Price List / Code No. | D2: 29 | E2: feyku i= la[;k Tally Code No. | H2: 1 | I2: ;wfuV Unit | J2: 3
A3: oLrq dk fooj.k Description of the Article | D3: MATERIAL TROLLEY | E3: ys[kk dk;kZy; i`"B la[;k Accounts Office File No. | I3: 3168
A4: ekg vkSj rkjh[k Month and Date | B4: izkfIr ;k fuxZe okmpj la[;k vkSj rkjh[k No. and Date of Receiot or issue Voucher | C4: fdlls izkIr gqvk ;k fdls tkjh fd;k From Whom received or to whom issued | D4: izkfIr ;k fuxZe dk mn~ns'; Purpose for which received or issue | E4: izkfIr Receipt | F4: LFkkukarj.k Transfer | G4: fuxZe Issues | H4: 'ks"k Balance | I4: 3
E5: ux No. Vu Tonnes fd-xzk-Kgs. | F5: ux No. Vu Tonnes fd-xzk-Kgs. | G5: ux No. Vu Tonnes fd-xzk-Kgs. | H5: ux No. Vu Tonnes fd-xzk-Kgs.
E6: =SUM(E7:E1000) -> 2 | F6: =SUM(F7:F1000) -> 0 | G6: =SUM(G7:G1000) -> 1 | H6: =+E6-F6-G6 -> 1
A7: 45450 | B7: 197 dated 29/06/2024 | C7: M.S Traders & Engg. | D7: Track Related works | E7: 2 | F7: 0 | G7: 0 | H7: =SUM(E7:G7) -> 2
A8: 46053 | B8: GP/DFC/Ambala Sr.no. 1170 dt 31.01.2026 | C8: IMSD/JUDN | D8: Track Related works | E8: 0 | F8: 0 | G8: 1 | H8: =H7+E8-F8-G8 -> 1

Sheet 3169
B1: foHkkxh; [kkrk feyku iqLrd DEPARTMENTAL LEDGER AND TALLY BOOK
A2: ewY; lwph@dwV la[;k Price List / Code No. | D2: 30 | E2: feyku i= la[;k Tally Code No. | H2: 1 | I2: ;wfuV Unit | J2: 3
A3: oLrq dk fooj.k Description of the Article | D3: DIP LORRY | E3: ys[kk dk;kZy; i`"B la[;k Accounts Office File No. | I3: 3169
A4: ekg vkSj rkjh[k Month and Date | B4: izkfIr ;k fuxZe okmpj la[;k vkSj rkjh[k No. and Date of Receiot or issue Voucher | C4: fdlls izkIr gqvk ;k fdls tkjh fd;k From Whom received or to whom issued | D4: izkfIr ;k fuxZe dk mn~ns'; Purpose for which received or issue | E4: izkfIr Receipt | F4: LFkkukarj.k Transfer | G4: fuxZe Issues | H4: 'ks"k Balance | I4: 3
E5: ux No. Vu Tonnes fd-xzk-Kgs. | F5: ux No. Vu Tonnes fd-xzk-Kgs. | G5: ux No. Vu Tonnes fd-xzk-Kgs. | H5: ux No. Vu Tonnes fd-xzk-Kgs.
E6: =SUM(E7:E1000) -> 10 | F6: =SUM(F7:F1000) -> 0 | G6: =SUM(G7:G1000) -> 4 | H6: =+E6-F6-G6 -> 6
A7: 45450 | B7: 197 dated 29/06/2024 | C7: M.S Traders & Engg. | D7: Track Related works | E7: 2 | F7: 0 | G7: 0 | H7: =SUM(E7:G7) -> 2
A8: 45511 | B8: 198 dated 05/07/2024 | C8: M.S Traders & Engg. | D8: Track Related works | E8: 8 | F8: 0 | G8: 0 | H8: 10
A9: 45573 | B9: GP/DFC/ Ambala Sr. no. 1215 | C9: Abhishek Sharma Exe/CIVIL/JUDN IMSD/JUDN | D9: Track Related works | E9: 0 | F9: 0 | G9: 4 | H9: 6

Sheet 3170
B1: foHkkxh; [kkrk feyku iqLrd DEPARTMENTAL LEDGER AND TALLY BOOK
A2: ewY; lwph@dwV la[;k Price List / Code No. | D2: 31 | E2: feyku i= la[;k Tally Code No. | H2: 1 | I2: ;wfuV Unit | J2: 3
A3: oLrq dk fooj.k Description of the Article | D3: Wire Basket | E3: ys[kk dk;kZy; i`"B la[;k Accounts Office File No. | I3: 3170
A4: ekg vkSj rkjh[k Month and Date | B4: izkfIr ;k fuxZe okmpj la[;k vkSj rkjh[k No. and Date of Receiot or issue Voucher | C4: fdlls izkIr gqvk ;k fdls tkjh fd;k From Whom received or to whom issued | D4: izkfIr ;k fuxZe dk mn~ns'; Purpose for which received or issue | E4: izkfIr Receipt | F4: LFkkukarj.k Transfer | G4: fuxZe Issues | H4: 'ks"k Balance | I4: 3
E5: ux No. Vu Tonnes fd-xzk-Kgs. | F5: ux No. Vu Tonnes fd-xzk-Kgs. | G5: ux No. Vu Tonnes fd-xzk-Kgs. | H5: ux No. Vu Tonnes fd-xzk-Kgs.
E6: =SUM(E7:E1000) -> 50 | F6: =SUM(F7:F1000) -> 0 | G6: =SUM(G7:G1000) -> 29 | H6: =+E6-F6-G6 -> 21
A7: 45450 | B7: 197 dated 29/06/2024 | C7: M.S Traders & Engg. | D7: Track Related works | E7: 50 | F7: 0 | G7: 0 | H7: =SUM(E7:G7) -> 50
A8: 45511 | B8: GP/DFC/ Ambala Sr. no. 1215 | C8: Abhishek Sharma Exe/CIVIL/JUDN IMSD/JUDN | D8: Track Related works | E8: 0 | F8: 0 | G8: 25 | H8: 25
A9: 30/1/2024 | B9: GP/DFC/ Ambala Sr. no. 1192 dated 30.01.2025 | C9: Surendera Kumar Exe/CIVIL/JUDN IMSD/JUDN | D9: P-way maint work | E9: 0 | F9: 0 | G9: 4 | H9: 21

Sheet 3172
B1: foHkkxh; [kkrk feyku iqLrd DEPARTMENTAL LEDGER AND TALLY BOOK
A2: ewY; lwph@dwV la[;k Price List / Code No. | D2: 32 | E2: feyku i= la[;k Tally Code No. | H2: 1 | I2: ;wfuV Unit | J2: 3
A3: oLrq dk fooj.k Description of the Article | D3: Rake Ballast | E3: ys[kk dk;kZy; i`"B la[;k Accounts Office File No. | I3: 3172
A4: ekg vkSj rkjh[k Month and Date | B4: izkfIr ;k fuxZe okmpj la[;k vkSj rkjh[k No. and Date of Receiot or issue Voucher | C4: fdlls izkIr gqvk ;k fdls tkjh fd;k From Whom received or to whom issued | D4: izkfIr ;k fuxZe dk mn~ns'; Purpose for which received or issue | E4: izkfIr Receipt | F4: LFkkukarj.k Transfer | G4: fuxZe Issues | H4: 'ks"k Balance | I4: 3
E5: ux No. Vu Tonnes fd-xzk-Kgs. | F5: ux No. Vu Tonnes fd-xzk-Kgs. | G5: ux No. Vu Tonnes fd-xzk-Kgs. | H5: ux No. Vu Tonnes fd-xzk-Kgs.
E6: =SUM(E7:E1000) -> 50 | F6: =SUM(F7:F1000) -> 0 | G6: =SUM(G7:G1000) -> 25 | H6: =+E6-F6-G6 -> 25
A7: 45450 | B7: 197 dated 29/06/2024 | C7: M.S Traders & Engg. | D7: Track Related works | E7: 50 | F7: 0 | G7: 0 | H7: =SUM(E7:G7) -> 50
A8: 45573 | B8: GP/DFC/ Ambala Sr. no. 1215 | C8: Abhishek Sharma Exe/CIVIL/JUDN IMSD/JUDN | D8: Track Related works | E8: 0 | F8: 0 | G8: 25 | H8: 25

Sheet 3174
B1: foHkkxh; [kkrk feyku iqLrd DEPARTMENTAL LEDGER AND TALLY BOOK
A2: ewY; lwph@dwV la[;k Price List / Code No. | D2: 33 | E2: feyku i= la[;k Tally Code No. | H2: 1 | I2: ;wfuV Unit | J2: 3
A3: oLrq dk fooj.k Description of the Article | D3: Chain Saw | E3: ys[kk dk;kZy; i`"B la[;k Accounts Office File No. | I3: 3174
A4: ekg vkSj rkjh[k Month and Date | B4: izkfIr ;k fuxZe okmpj la[;k vkSj rkjh[k No. and Date of Receiot or issue Voucher | C4: fdlls izkIr gqvk ;k fdls tkjh fd;k From Whom received or to whom issued | D4: izkfIr ;k fuxZe dk mn~ns'; Purpose for which received or issue | E4: izkfIr Receipt | F4: LFkkukarj.k Transfer | G4: fuxZe Issues | H4: 'ks"k Balance | I4: 3
E5: ux No. Vu Tonnes fd-xzk-Kgs. | F5: ux No. Vu Tonnes fd-xzk-Kgs. | G5: ux No. Vu Tonnes fd-xzk-Kgs. | H5: ux No. Vu Tonnes fd-xzk-Kgs.
E6: =SUM(E7:E1000) -> 5 | F6: =SUM(F7:F1000) -> 0 | G6: =SUM(G7:G1000) -> 2 | H6: =+E6-F6-G6 -> 3
A7: 45450 | B7: 197 dated 29/06/2024 | C7: M.S Traders & Engg. | D7: Track Related works | E7: 5 | F7: 0 | G7: 0 | H7: =SUM(E7:G7) -> 5
A8: 45573 | B8: GP/DFC/ Ambala Sr. no. 1215 | C8: Abhishek Sharma Exe/CIVIL/JUDN IMSD/JUDN | D8: Track Related works | E8: 0 | F8: 0 | G8: 2 | H8: 3

Sheet 3175
B1: foHkkxh; [kkrk feyku iqLrd DEPARTMENTAL LEDGER AND TALLY BOOK
A2: ewY; lwph@dwV la[;k Price List / Code No. | D2: 34 | E2: feyku i= la[;k Tally Code No. | H2: 1 | I2: ;wfuV Unit | J2: 3
A3: oLrq dk fooj.k Description of the Article | D3: Bush Cutter (M/C) | E3: ys[kk dk;kZy; i`"B la[;k Accounts Office File No. | I3: 3175
A4: ekg vkSj rkjh[k Month and Date | B4: izkfIr ;k fuxZe okmpj la[;k vkSj rkjh[k No. and Date of Receiot or issue Voucher | C4: fdlls izkIr gqvk ;k fdls tkjh fd;k From Whom received or to whom issued | D4: izkfIr ;k fuxZe dk mn~ns'; Purpose for which received or issue | E4: izkfIr Receipt | F4: LFkkukarj.k Transfer | G4: fuxZe Issues | H4: 'ks"k Balance | I4: 3
E5: ux No. Vu Tonnes fd-xzk-Kgs. | F5: ux No. Vu Tonnes fd-xzk-Kgs. | G5: ux No. Vu Tonnes fd-xzk-Kgs. | H5: ux No. Vu Tonnes fd-xzk-Kgs.
E6: =SUM(E7:E1000) -> 5 | F6: =SUM(F7:F1000) -> 0 | G6: =SUM(G7:G1000) -> 3 | H6: =+E6-F6-G6 -> 2
A7: 45450 | B7: M.S Traders & Engg 197 dated 29/06/2024 | C7: M.S Traders & Engg. | D7: Track Related works | E7: 5 | F7: 0 | G7: 0 | H7: =SUM(E7:G7) -> 5
A8: 45573 | B8: GP/DFC/ Ambala Sr. no. 1215 | C8: Abhishek Sharma Exe/CIVIL/JUDN IMSD/JUDN | D8: Track Related works | E8: 0 | F8: 0 | G8: 2 | H8: =H7+E8-F8-G8 -> 3
A9: 46043 | B9: GP/DFC/ Ambala Sr. no. 1166 | C9: IMD/CHAN | D9: Track Related works | E9: 0 | F9: 0 | G9: 1 | H9: =H8+E9-F9-G9 -> 2

Sheet 3177
B1: foHkkxh; [kkrk feyku iqLrd DEPARTMENTAL LEDGER AND TALLY BOOK
A2: ewY; lwph@dwV la[;k Price List / Code No. | D2: 35 | E2: feyku i= la[;k Tally Code No. | H2: 1 | I2: ;wfuV Unit | J2: 3
A3: oLrq dk fooj.k Description of the Article | D3: Digital Toe Load Machine | E3: ys[kk dk;kZy; i`"B la[;k Accounts Office File No. | I3: 3177
A4: ekg vkSj rkjh[k Month and Date | B4: izkfIr ;k fuxZe okmpj la[;k vkSj rkjh[k No. and Date of Receiot or issue Voucher | C4: fdlls izkIr gqvk ;k fdls tkjh fd;k From Whom received or to whom issued | D4: izkfIr ;k fuxZe dk mn~ns'; Purpose for which received or issue | E4: izkfIr Receipt | F4: LFkkukarj.k Transfer | G4: fuxZe Issues | H4: 'ks"k Balance | I4: 3
E5: ux No. Vu Tonnes fd-xzk-Kgs. | F5: ux No. Vu Tonnes fd-xzk-Kgs. | G5: ux No. Vu Tonnes fd-xzk-Kgs. | H5: ux No. Vu Tonnes fd-xzk-Kgs.
E6: =SUM(E7:E1000) -> 2 | F6: =SUM(F7:F1000) -> 0 | G6: =SUM(G7:G1000) -> 0 | H6: =+E6-F6-G6 -> 2
A7: 45450 | B7: 201 dated 25/07/2024 | C7: M.S Traders & Engg. | D7: Track Related works | E7: 2 | F7: 0 | G7: 0 | H7: =SUM(E7:G7) -> 2

Sheet 3179
B1: foHkkxh; [kkrk feyku iqLrd DEPARTMENTAL LEDGER AND TALLY BOOK
A2: ewY; lwph@dwV la[;k Price List / Code No. | D2: 36 | E2: feyku i= la[;k Tally Code No. | H2: 1 | I2: ;wfuV Unit | J2: 3
A3: oLrq dk fooj.k Description of the Article | D3: Salety Belt | E3: ys[kk dk;kZy; i`"B la[;k Accounts Office File No. | I3: 3179
A4: ekg vkSj rkjh[k Month and Date | B4: izkfIr ;k fuxZe okmpj la[;k vkSj rkjh[k No. and Date of Receiot or issue Voucher | C4: fdlls izkIr gqvk ;k fdls tkjh fd;k From Whom received or to whom issued | D4: izkfIr ;k fuxZe dk mn~ns'; Purpose for which received or issue | E4: izkfIr Receipt | F4: LFkkukarj.k Transfer | G4: fuxZe Issues | H4: 'ks"k Balance | I4: 3
E5: ux No. Vu Tonnes fd-xzk-Kgs. | F5: ux No. Vu Tonnes fd-xzk-Kgs. | G5: ux No. Vu Tonnes fd-xzk-Kgs. | H5: ux No. Vu Tonnes fd-xzk-Kgs.
E6: =SUM(E7:E1000) -> 2 | F6: =SUM(F7:F1000) -> 0 | G6: =SUM(G7:G1000) -> 1 | H6: =+E6-F6-G6 -> 1
A7: 45450 | B7: 197 dated 29/06/2024 | C7: M.S Traders & Engg. | D7: P-way works | E7: 2 | F7: 0 | G7: 0 | H7: =SUM(E7:G7) -> 2
A8: 45512 | B8: GP/DFC/ Ambala Sr. no. 1213 | C8: Abhishek Sharma Exe/CIVIL/JUDN IMSD/JUDN | D8: P-way works | E8: 0 | F8: 0 | G8: 1 | H8: 1

Sheet 3180
B1: foHkkxh; [kkrk feyku iqLrd DEPARTMENTAL LEDGER AND TALLY BOOK
A2: ewY; lwph@dwV la[;k Price List / Code No. | D2: 37 | E2: feyku i= la[;k Tally Code No. | H2: 1 | I2: ;wfuV Unit | J2: 3
A3: oLrq dk fooj.k Description of the Article | D3: Emergency Lighting (Aska Lioght ) | E3: ys[kk dk;kZy; i`"B la[;k Accounts Office File No. | I3: 3180
A4: ekg vkSj rkjh[k Month and Date | B4: izkfIr ;k fuxZe okmpj la[;k vkSj rkjh[k No. and Date of Receiot or issue Voucher | C4: fdlls izkIr gqvk ;k fdls tkjh fd;k From Whom received or to whom issued | D4: izkfIr ;k fuxZe dk mn~ns'; Purpose for which received or issue | E4: izkfIr Receipt | F4: LFkkukarj.k Transfer | G4: fuxZe Issues | H4: 'ks"k Balance | I4: 3
E5: ux No. Vu Tonnes fd-xzk-Kgs. | F5: ux No. Vu Tonnes fd-xzk-Kgs. | G5: ux No. Vu Tonnes fd-xzk-Kgs. | H5: ux No. Vu Tonnes fd-xzk-Kgs.
E6: =SUM(E7:E1000) -> 2 | F6: =SUM(F7:F1000) -> 0 | G6: =SUM(G7:G1000) -> 0 | H6: =+E6-F6-G6 -> 2
A7: 45299 | B7: LR/IN/24-25/ 0112 Date : 19-07-2024 | C7: LOKOZO Technologics Pvt. Ltd. | D7: P-Way Related work | E7: 2 | F7: 0 | G7: 0 | H7: =SUM(E7:G7) -> 2

Sheet 3181
B1: foHkkxh; [kkrk feyku iqLrd DEPARTMENTAL LEDGER AND TALLY BOOK
A2: ewY; lwph@dwV la[;k Price List / Code No. | D2: 38 | E2: feyku i= la[;k Tally Code No. | H2: 1 | I2: ;wfuV Unit | J2: 3
A3: oLrq dk fooj.k Description of the Article | D3: Caution Board | E3: ys[kk dk;kZy; i`"B la[;k Accounts Office File No. | I3: 3181
A4: ekg vkSj rkjh[k Month and Date | B4: izkfIr ;k fuxZe okmpj la[;k vkSj rkjh[k No. and Date of Receiot or issue Voucher | C4: fdlls izkIr gqvk ;k fdls tkjh fd;k From Whom received or to whom issued | D4: izkfIr ;k fuxZe dk mn~ns'; Purpose for which received or issue | E4: izkfIr Receipt | F4: LFkkukarj.k Transfer | G4: fuxZe Issues | H4: 'ks"k Balance | I4: 3
E5: ux No. Vu Tonnes fd-xzk-Kgs. | F5: ux No. Vu Tonnes fd-xzk-Kgs. | G5: ux No. Vu Tonnes fd-xzk-Kgs. | H5: ux No. Vu Tonnes fd-xzk-Kgs.
E6: =SUM(E7:E1000) -> 10 | F6: =SUM(F7:F1000) -> 0 | G6: =SUM(G7:G1000) -> 7 | H6: =+E6-F6-G6 -> 3
A7: 45451 | B7: 12 dated 06/08/2024 | C7: M.S Traders & Engg. | D7: P-way works | E7: 10 | F7: 0 | G7: 0 | H7: =+E7+F7+G7 -> 10
A8: 45512 | B8: GP/DFC/ Ambala Sr. no. 1212 | C8: Abhishek Sharma Exe/CIVIL/JUDN IMSD/JUDN | D8: P-way works | E8: 0 | F8: 0 | G8: 5 | H8: =+H7+E8-F8-G8 -> 5
A9: 45452 | B9: GP/DFC/ Ambala Sr. no. 1219 | C9: Surendra Kumar Sr. Exe/CIVILl/KNNN | D9: P-way works | E9: 0 | F9: 0 | G9: 2 | H9: =+H8+E9-F9-G9 -> 3

Sheet 3183
B1: foHkkxh; [kkrk feyku iqLrd DEPARTMENTAL LEDGER AND TALLY BOOK
A2: ewY; lwph@dwV la[;k Price List / Code No. | D2: 39 | E2: feyku i= la[;k Tally Code No. | H2: 1 | I2: ;wfuV Unit | J2: 3
A3: oLrq dk fooj.k Description of the Article | D3: T/G Board | E3: ys[kk dk;kZy; i`"B la[;k Accounts Office File No. | I3: 3183
A4: ekg vkSj rkjh[k Month and Date | B4: izkfIr ;k fuxZe okmpj la[;k vkSj rkjh[k No. and Date of Receiot or issue Voucher | C4: fdlls izkIr gqvk ;k fdls tkjh fd;k From Whom received or to whom issued | D4: izkfIr ;k fuxZe dk mn~ns'; Purpose for which received or issue | E4: izkfIr Receipt | F4: LFkkukarj.k Transfer | G4: fuxZe Issues | H4: 'ks"k Balance | I4: 3
E5: ux No. Vu Tonnes fd-xzk-Kgs. | F5: ux No. Vu Tonnes fd-xzk-Kgs. | G5: ux No. Vu Tonnes fd-xzk-Kgs. | H5: ux No. Vu Tonnes fd-xzk-Kgs.
E6: =SUM(E7:E1000) -> 10 | F6: =SUM(F7:F1000) -> 0 | G6: =SUM(G7:G1000) -> 7 | H6: =+E6-F6-G6 -> 3
A7: 45451 | B7: 12 dated 06/08/2024 | C7: M.S Traders & Engg. | D7: P-way works | E7: 10 | F7: 0 | G7: 0 | H7: =+E7+F7+G7 -> 10
A8: 45512 | B8: GP/DFC/ Ambala Sr. no. 1212 | C8: Abhishek Sharma Exe/CIVIL/JUDN IMSD/JUDN | D8: P-way works | E8: 0 | F8: 0 | G8: 5 | H8: =+H7+E8-F8-G8 -> 5
A9: 45452 | B9: GP/DFC/ Ambala Sr. no. 1219 | C9: Surendra Kumar Sr. Exe/CIVILl/KNNN | D9: P-way works | E9: 0 | F9: 0 | G9: 2 | H9: 3

Sheet 3185
B1: foHkkxh; [kkrk feyku iqLrd DEPARTMENTAL LEDGER AND TALLY BOOK
A2: ewY; lwph@dwV la[;k Price List / Code No. | D2: 40 | E2: feyku i= la[;k Tally Code No. | H2: 1 | I2: ;wfuV Unit | J2: 3
A3: oLrq dk fooj.k Description of the Article | D3: Speed Indicator sign Board 10 km | E3: ys[kk dk;kZy; i`"B la[;k Accounts Office File No. | I3: 3185
A4: ekg vkSj rkjh[k Month and Date | B4: izkfIr ;k fuxZe okmpj la[;k vkSj rkjh[k No. and Date of Receiot or issue Voucher | C4: fdlls izkIr gqvk ;k fdls tkjh fd;k From Whom received or to whom issued | D4: izkfIr ;k fuxZe dk mn~ns'; Purpose for which received or issue | E4: izkfIr Receipt | F4: LFkkukarj.k Transfer | G4: fuxZe Issues | H4: 'ks"k Balance | I4: 3
E5: ux No. Vu Tonnes fd-xzk-Kgs. | F5: ux No. Vu Tonnes fd-xzk-Kgs. | G5: ux No. Vu Tonnes fd-xzk-Kgs. | H5: ux No. Vu Tonnes fd-xzk-Kgs.
E6: =SUM(E7:E1000) -> 5 | F6: =SUM(F7:F1000) -> 0 | G6: =SUM(G7:G1000) -> 3 | H6: =+E6-F6-G6 -> 2
A7: 45451 | B7: 12 dated 06/08/2024 | C7: M.S Traders & Engg. | D7: P-way works | E7: 5 | F7: 0 | G7: 0 | H7: 5
A8: 45512 | B8: GP/DFC/ Ambala Sr. no. 1212 | C8: Abhishek Sharma Exe/CIVIL/JUDN IMSD/JUDN | D8: P-way works | E8: 0 | F8: 0 | G8: 2 | H8: 3
A9: 45452 | B9: GP/DFC/ Ambala Sr. no. 1220 | C9: Surendra Kumar Sr. Exe/CIVILl/KNNN | D9: P-way works | E9: 0 | F9: 0 | G9: 1 | H9: 2

Sheet 3186
B1: foHkkxh; [kkrk feyku iqLrd DEPARTMENTAL LEDGER AND TALLY BOOK
A2: ewY; lwph@dwV la[;k Price List / Code No. | D2: 41 | E2: feyku i= la[;k Tally Code No. | H2: 1 | I2: ;wfuV Unit | J2: 3
A3: oLrq dk fooj.k Description of the Article | D3: Speed Indicator sign Board 20 km | E3: ys[kk dk;kZy; i`"B la[;k Accounts Office File No. | I3: 3186
A4: ekg vkSj rkjh[k Month and Date | B4: izkfIr ;k fuxZe okmpj la[;k vkSj rkjh[k No. and Date of Receiot or issue Voucher | C4: fdlls izkIr gqvk ;k fdls tkjh fd;k From Whom received or to whom issued | D4: izkfIr ;k fuxZe dk mn~ns'; Purpose for which received or issue | E4: izkfIr Receipt | F4: LFkkukarj.k Transfer | G4: fuxZe Issues | H4: 'ks"k Balance | I4: 3
E5: ux No. Vu Tonnes fd-xzk-Kgs. | F5: ux No. Vu Tonnes fd-xzk-Kgs. | G5: ux No. Vu Tonnes fd-xzk-Kgs. | H5: ux No. Vu Tonnes fd-xzk-Kgs.
E6: =SUM(E7:E1000) -> 10 | F6: =SUM(F7:F1000) -> 0 | G6: =SUM(G7:G1000) -> 7 | H6: =+E6-F6-G6 -> 3
A7: 45451 | B7: 12 dated 06/08/2024 | C7: M.S Traders & Engg. | D7: P-way works | E7: 10 | F7: 0 | G7: 0 | H7: 10
A8: 45512 | B8: GP/DFC/ Ambala Sr. no. 1212 | C8: Abhishek Sharma Exe/CIVIL/JUDN IMSD/JUDN | D8: P-way works | E8: 0 | F8: 0 | G8: 5 | H8: 5
A9: 45452 | B9: GP/DFC/ Ambala Sr. no. 1219 | C9: Surendra Kumar Sr. Exe/CIVILl/KNNN | D9: P-way works | E9: 0 | F9: 0 | G9: 2 | H9: 3

Sheet 3187
B1: foHkkxh; [kkrk feyku iqLrd DEPARTMENTAL LEDGER AND TALLY BOOK
A2: ewY; lwph@dwV la[;k Price List / Code No. | D2: 42 | E2: feyku i= la[;k Tally Code No. | H2: 1 | I2: ;wfuV Unit | J2: 3
A3: oLrq dk fooj.k Description of the Article | D3: Speed Indicator sign Board 30 km | E3: ys[kk dk;kZy; i`"B la[;k Accounts Office File No. | I3: 3187
A4: ekg vkSj rkjh[k Month and Date | B4: izkfIr ;k fuxZe okmpj la[;k vkSj rkjh[k No. and Date of Receiot or issue Voucher | C4: fdlls izkIr gqvk ;k fdls tkjh fd;k From Whom received or to whom issued | D4: izkfIr ;k fuxZe dk mn~ns'; Purpose for which received or issue | E4: izkfIr Receipt | F4: LFkkukarj.k Transfer | G4: fuxZe Issues | H4: 'ks"k Balance | I4: 3
E5: ux No. Vu Tonnes fd-xzk-Kgs. | F5: ux No. Vu Tonnes fd-xzk-Kgs. | G5: ux No. Vu Tonnes fd-xzk-Kgs. | H5: ux No. Vu Tonnes fd-xzk-Kgs.
E6: =SUM(E7:E1000) -> 25 | F6: =SUM(F7:F1000) -> 0 | G6: =SUM(G7:G1000) -> 14 | H6: =+E6-F6-G6 -> 11
A7: 45451 | B7: 12 dated 06/08/2024 | C7: M.S Traders & Engg. | D7: P-way works | E7: 10 | F7: 0 | G7: 0 | H7: 10
A8: 45512 | B8: GP/DFC/ Ambala Sr. no. 1212 | C8: Abhishek Sharma Exe/CIVIL/JUDN IMSD/JUDN | D8: P-way works | E8: 0 | F8: 0 | G8: 5 | H8: =+H7+E8-F8-G8 -> 5
A9: 45421 | B9: DC-193 Date- 05/09/2024 | C9: M.J Trade & Fabrication | D9: P-way works | E9: 15 | F9: 0 | G9: 0 | H9: =+H8+E9-F9-G9 -> 20
A10: 45452 | B10: GP/DFC/ Ambala Sr. no. 1219 | C10: Surendra Kumar Sr. Exe/CIVILl/KNNN | D10: P-way works | E10: 0 | F10: 0 | G10: 2 | H10: =+H9+E10-F10-G10 -> 18
A11: 14/09/2024 | B11: GP/DFC/ Ambala Sr. no. 1219 | C11: Vibhanshu Prashar Sr. Ex/CIVIL/JUDN IMSD/JUDN | D11: P-way works | E11: 0 | F11: 0 | G11: 7 | H11: =+H10+E11-F11-G11 -> 11

Sheet 3188
B1: foHkkxh; [kkrk feyku iqLrd DEPARTMENTAL LEDGER AND TALLY BOOK
A2: ewY; lwph@dwV la[;k Price List / Code No. | D2: 43 | E2: feyku i= la[;k Tally Code No. | H2: 1 | I2: ;wfuV Unit | J2: 3
