Workbook
Name Slicer_Column14: #REF!
Name Slicer_Column15: #REF!
Name SlicerCache_Table_1_Col_10: #N/A
Name SlicerCache_Table_1_Col_12: #N/A

Sheet Filter data
E7: NSIR | R7: ROB
A9: S. No | B9: Station | C9: Point No. | D9: Line | E9: Angle | F9: SRJ Chainage | G9: Laid On | H9: LH/RH | I9: Traffic | J9: SE | K9: D | L9: Stations behind the X-ing | O9: Bridge No. | P9: Section | Q9: From | R9: To | S9: Bridge Type | T9: Old Bridge No. | U9: Column15 | V9: Span Configuration | W9: Length of Bridge | X9: Linear Waterway
A10: =ROW()-9 -> 1 | B10: {=IF(E7="", "", IFERROR(_xlfn._xlws.FILTER(PNC!B:L, PNC!B:B=E7), "Data Not Found"))} -> NSIR | C10: 201b | D10: Main Line | E10: 1/12 | F10: 1200.778 | G10: Straight | H10: LH | I10: Facing | J10: 0 | L10: 3 | O10: {=IF(E7="","",IFERROR(_xlfn._xlws.FILTER(Bridge!B:K,Bridge!F:F=R7),"Data Not Found"))} -> 1169/1 | P10: 01. UBCD-SMUN | Q10: 1169.024 | R10: 1169.024 | S10: ROB | T10: 131 | U10: RCC/PSC Girder | V10: 1x26.00m | W10: 0
A11: =ROW()-9 -> 2 | B11: NSIR | C11: 243b | D11: Main Line | E11: 1/12 | F11: 1201.669 | G11: Curve | H11: LH | I11: Facing | J11: 20 | K11: 0.22 | L11: 3 | O11: 1178/2 | P11: 03. SMUN-SBJN | Q11: 1178.791 | R11: 1178.791 | S11: ROB | T11: 135 | U11: RCC/PSC Girder | V11: 1x8.50m | W11: 0
A12: =ROW()-9 -> 3 | B12: NSIR | C12: 244a | D12: Main Line | E12: 1/12 | F12: 1201.925 | G12: Curve | H12: RH | I12: Trailing | J12: 20 | K12: 0.22 | L12: 3 | O12: 1180/2 | P12: 03. SMUN-SBJN | Q12: 1180.604 | R12: 1180.604 | S12: ROB | T12: 120 | U12: Box | V12: 1x6.30m | W12: 0
A13: =ROW()-9 -> 4 | B13: NSIR | C13: 245a | D13: Main Line | E13: 1/12 | F13: 1201.938 | G13: Curve | H13: RH | I13: Facing | J13: 20 | K13: 0.22 | L13: 3 | O13: 1203/3 | P13: 06. NSIR Yard | Q13: 1203.476 | R13: 1203.476 | S13: ROB | T13: 145A | U13: RCC/PSC Girder | V13: 1x24.69m | W13: 0
A14: =ROW()-9 -> 5 | B14: NSIR | C14: 295b | D14: Main Line | E14: 1/12 | F14: 1203.015 | G14: Straight | H14: RH | I14: Trailing | J14: 0 | L14: 3 | O14: 1204/1 | P14: 06. NSIR Yard | Q14: 1204.021 | R14: 1204.021 | S14: ROB | T14: 145B | U14: RCC/PSC Girder | V14: 1x24.39m | W14: 0
A15: =ROW()-9 -> 6 | B15: NSIR | C15: 296b | D15: Main Line | E15: 1/12 | F15: 1203.076 | G15: Straight | H15: LH | I15: Trailing | J15: 0 | L15: 3 | O15: 1218/1 | P15: 09. GVGN-KNNN | Q15: 1218.166 | R15: 1218.166 | S15: ROB | T15: 153 C | U15: Composite Girder | V15: 1x30.18m | W15: 0
A16: =ROW()-9 -> 7 | B16: NSIR | C16: 297a | D16: Main Line | E16: 1/12 | F16: 1203.089 | G16: Straight | H16: LH | I16: Facing | J16: 0 | L16: 3 | O16: 1223/1 | P16: 09. GVGN-KNNN | Q16: 1223.362 | R16: 1223.362 | S16: ROB | T16: ROB Khanna | U16: RCC/PSC Girder | V16: 1x31.40m | W16: 0
A17: =ROW()-9 -> 8 | B17: NSIR | C17: 299b | D17: Main Line | E17: 1/12 | F17: 1203.97 | G17: Curve | H17: LH | I17: Trailing | J17: 30 | K17: 0.49 | L17: 3 | O17: 1224/1 | P17: 09. GVGN-KNNN | Q17: 1224.99 | R17: 1224.99 | S17: ROB | T17: 155 B | U17: RCC/PSC Girder | V17: 1x33.52m | W17: 0
A18: =ROW()-9 -> 9 | B18: NSIR | C18: 201a | D18: Loop | E18: 1/12 | F18: 1200.899 | G18: Straight | H18: LH | I18: SL | J18: 0 | L18: 3 | O18: 1234/1 | P18: 11. KNNN-CHAN | Q18: 1234.357 | R18: 1234.357 | S18: ROB | T18: 161 | U18: RCC/PSC Girder | V18: 1x23.40m | W18: 0
A19: =ROW()-9 -> 10 | B19: NSIR | C19: 243a | D19: Loop | E19: 1/12 | F19: 1201.79 | G19: Straight | H19: RH | I19: SL | J19: 0 | L19: 3
A20: =ROW()-9 -> 11 | B20: NSIR | C20: 244b | D20: Loop | E20: 1/12 | F20: 1201.803 | G20: Curve | H20: RH | I20: SL | J20: 0 | K20: NA | L20: 3
A21: =ROW()-9 -> 12 | B21: NSIR | C21: 245b | D21: Loop | E21: 1/12 | F21: 1202.065 | G21: Straight | H21: RH | I21: SL | J21: 0 | L21: 3
A22: =ROW()-9 -> 13 | B22: NSIR | C22: 246a | D22: Loop | E22: 1/12 | F22: 1202.072 | G22: Straight | H22: RH | I22: SL | J22: 0 | L22: 10
A23: =ROW()-9 -> 14 | B23: NSIR | C23: 295a | D23: Loop | E23: 1/12 | F23: 1202.893 | G23: Straight | H23: RH | I23: SL | J23: 0 | L23: 3
A24: =ROW()-9 -> 15 | B24: NSIR | C24: 296a | D24: Loop | E24: 1/12 | F24: 1202.955 | G24: Straight | H24: RH | I24: SL | J24: 0 | L24: 3
A25: =ROW()-9 -> 16 | B25: NSIR | C25: 297b | D25: Loop | E25: 1/12 | F25: 1203.21 | G25: Straight | H25: LH | I25: SL | J25: 0 | L25: 3
A26: =ROW()-9 -> 17 | B26: NSIR | C26: 299a | D26: Loop | E26: 1/12 | F26: 1203.846 | G26: Curve | H26: LH | I26: SL | J26: 0 | K26: NA | L26: 3
A27: =ROW()-9 -> 18 | B27: NSIR | C27: 246b | D27: D/S | E27: 1/12 | F27: 1202.205 | G27: Curve | H27: LH | I27: SL | J27: 0 | K27: NA | L27: 0
A28: =ROW()-9 -> 19
A29: =ROW()-9 -> 20
A30: =ROW()-9 -> 21
A31: =ROW()-9 -> 22
A32: =ROW()-9 -> 23
A33: =ROW()-9 -> 24
A34: =ROW()-9 -> 25
A35: =ROW()-9 -> 26
A36: =ROW()-9 -> 27
A37: =ROW()-9 -> 28
A38: =ROW()-9 -> 29
A39: =ROW()-9 -> 30
... A44: =ROW()-9 -> 35

Sheet finder
V2: ID No. | X2: 14803 | AE2: =_xlfn.XLOOKUP(X2,ExMaster_DATA!B:B,ExMaster_DATA!L:L,"Not Found") -> #VALUE!
E7: SBJN | L7: 291a | Q7: {=_xlfn.XLOOKUP(1, (PNC!$B:$B=$E$7)*(PNC!$C:$C=$L$7), PNC!$H:$H, "")} -> RH | W7: ID: | Y7: =_xlfn.XLOOKUP($X$2,ExMaster_DATA!B:B,ExMaster_DATA!B:B,"Not Found") -> 14803
W8: Name: | Y8: =_xlfn.XLOOKUP(X2,ExMaster_DATA!B:B,ExMaster_DATA!C:C,"Not Found") -> Tarsem Singh
A9: Station Behind the crossing | D9: {=_xlfn.XLOOKUP(1, (PNC!$B:$B=$E$7)*(PNC!$C:$C=$L$7), PNC!$L:$L, "")} -> 3 | F9: Line | G9: {=_xlfn.XLOOKUP(1, (PNC!$B:$B=$E$7)*(PNC!$C:$C=$L$7), PNC!$D:$D, "")} -> Main Line | I9: SRJ Ch. | J9: {=_xlfn.XLOOKUP(1, (PNC!$B:$B=$E$7)*(PNC!$C:$C=$L$7), PNC!$F:$F, "")} -> 1189.578 | M9: Laid ON | N9: {=_xlfn.XLOOKUP(1, (PNC!$B:$B=$E$7)*(PNC!$C:$C=$L$7), PNC!$G:$G, "")} -> Straight | Q9: Angle | R9: {=_xlfn.XLOOKUP(1, (PNC!$B:$B=$E$7)*(PNC!$C:$C=$L$7), PNC!$E:$E, "")} -> 1/12 | Y9: =IF(W3="", "", IFERROR(VLOOKUP(W3, '[1]Mater DATA'!$A$2:$M$54, 4, FALSE), "Not Found"))
W10: Designation: | Y10: =_xlfn.XLOOKUP($X$2,ExMaster_DATA!B:B,ExMaster_DATA!H:H,"Not Found") -> Patrolman
A11: Curve-Finder | X11: =IF(W3="", "", IFERROR(VLOOKUP(W3, '[1]Mater DATA'!$A$2:$M$54, 5, FALSE), "Not Found")) | Y11: =IF(W3="", "", IFERROR(VLOOKUP(W3, '[1]Mater DATA'!$A$2:$M$54, 6, FALSE), "Not Found"))
W12: Address: | Y12: {=_xlfn.XLOOKUP($X$2,ExMaster_DATA!B:B,ExMaster_DATA!I:I & " " & ExMaster_DATA!J:J,"Not Found")} -> VPO Mohan pur Teh Khanna Ludhiana | AE12: =_xlfn.XLOOKUP(X2,ExMaster_DATA!B:B,ExMaster_DATA!M:M,"Not Found") -> #VALUE!
E13: 369 | I13: Km From | J13: =_xlfn.XLOOKUP($E$13, Curve!B:B, Curve!C:C, "") -> 1223.674 | L13: Km To | M13: =_xlfn.XLOOKUP(E13, Curve!B:B, Curve!D:D, "") -> 1223.751 | P13: Versine | Q13: =_xlfn.XLOOKUP(E13, Curve!B:B, Curve!I:I, "") -> 5
B15: Degree | D15: =_xlfn.XLOOKUP(E13, Curve!B:B, Curve!F:F, "") -> 0.17 | F15: TCL | G15: =_xlfn.XLOOKUP(E13, Curve!B:B, Curve!J:J, "") -> 20 | I15: CCL | J15: =_xlfn.XLOOKUP(E13, Curve!B:B, Curve!K:K, "") -> 36.88 | M15: Radius | N15: =_xlfn.XLOOKUP(E13, Curve!B:B, Curve!H:H, "") -> 10000 | Q15: SE | R15: =_xlfn.XLOOKUP(E13, Curve!B:B, Curve!M:M, "") -> 20 | W15: Beat Details | Y15: =_xlfn.XLOOKUP($X$2,ExMaster_DATA!B:B,ExMaster_DATA!E:E,"Not Found") -> SPN-09
Y16: =_xlfn.XLOOKUP($X$2,ExMaster_DATA!B:B,ExMaster_DATA!F:F,"Not Found") -> B 1226/1 to C 1233/16
A17: Bridge-Finder
E19: RUB | L19: 1177/CL/1 | Q19: Block Section or Yard
Q20: =_xlfn.XLOOKUP(L19,Bridge!B:B,Bridge!C:C,"") -> 14.SMUN-RPJ
B21: Old Bridge No. | D21: =_xlfn.XLOOKUP(L19,Bridge!B:B,Bridge!G:G,"") -> 115 | F21: Km From | G21: =_xlfn.XLOOKUP(L19,Bridge!B:B,Bridge!D:D,"") -> 1176.953 | I21: Km To | J21: =_xlfn.XLOOKUP(L19,Bridge!B:B,Bridge!E:E,"") -> 1177.085 | M21: =_xlfn.XLOOKUP(L19,Bridge!B:B,Bridge!F:F,"") -> MJB (OWG)
B23: Bridge Type | C23: =_xlfn.XLOOKUP(L19,Bridge!B:B,Bridge!H:H,"") -> OWG | I23: Span | K23: =_xlfn.XLOOKUP(L19,Bridge!B:B,Bridge!I:I,"") -> 4x31.10m

Sheet At a Glance
A1: Section under IMSD SMUN (Bridge Details)
A2: Section | B2: Line | C2: Chainage | E2: MJB | F2: MIB | G2: RUB | H2: ROB | I2: FOB | J2: OWG | K2: LC
C3: From | D3: To
A4: UBCD-SMUN | B4: SL | C4: 1167.21 | D4: 1170.435 | E4: 1 | F4: 2 | G4: 1 | H4: 1 | I4: 0 | J4: 0 | K4: 0
A5: SMUN-SBJN | B5: SL | C5: =+D4 -> 1170.435 | D5: 1188.575 | E5: 5 | F5: 19 | G5: 8 | H5: 2 | I5: 1 | J5: 1 | K5: 0
A6: SBJN-NSIR | B6: SL | C6: =+D5 -> 1188.575 | D6: 1202.015 | E6: 6 | F6: 16 | G6: 8 | H6: 0 | I6: 1 | J6: 0 | K6: 0
A7: NSIR-GVGN | B7: SL | C7: =+D6 -> 1202.015 | D7: 1213.187 | E7: 4 | F7: 11 | G7: 9 | H7: 2 | I7: 0 | J7: 2 | K7: 0
A8: GVGN-KNNN | B8: SL | C8: =+D7 -> 1213.187 | D8: 1229.087 | E8: 0 | F8: 10 | G8: 3 | H8: 3 | I8: 2 | J8: 0 | K8: 1
A9: KNNN-CHAN | B9: SL | C9: =+D8 -> 1229.087 | D9: 1235.837 | E9: 0 | F9: 6 | G9: 3 | H9: 1 | I9: 0 | J9: 0 | K9: 1
A10: CHAN-SNL | B10: SL | C10: =+D9 -> 1235.837 | D10: 1249.7 | E10: 1 | F10: 8 | G10: 3 | H10: 0 | I10: 2 | J10: 1 | K10: 3
A11: SMUN-RPJ | B11: SL | C11: 1168.697 | D11: 1178.15 | E11: 1 | F11: 2 | G11: 2 | H11: 0 | I11: 0 | J11: 1 | K11: 0
A12: Total | B12: SL | C12: =(D10-C4)+(D11-C11) -> 91.943 | E12: =SUM(E4:E11) -> 18 | F12: =SUM(F4:F11) -> 74 | G12: =SUM(G4:G11) -> 37 | H12: =SUM(H4:H11) -> 9 | I12: =SUM(I4:I11) -> 6 | J12: =SUM(J4:J11) -> 5 | K12: =SUM(K4:K11) -> 5
A13: Total | E13: =+E12+F12+G12+H12+I12 -> 144
A15: Section under IMSD SMUN (Point & Crossing Details)
A16: Station | B16: Centre | C16: From | D16: To | E16: 1 in 12 | F16: 1 in 8.5 | G16: DS | H16: Total | I16: Main | J16: Loop | K16: Total
A17: SMUN | B17: 1170.435 | C17: 1168.697 | D17: 1172.297 | E17: 25 | F17: 0 | G17: 10 | H17: =+G17+F17+E17 -> 35 | I17: 9 | J17: 26 | K17: =+J17+I17 -> 35
A18: SBJN | B18: 1188.575 | C18: 1186.837 | D18: 1190.292 | E18: 21 | F18: 0 | G18: 5 | H18: =+G18+F18+E18 -> 26 | I18: 7 | J18: 19 | K18: =+J18+I18 -> 26
A19: NSIR | B19: 1202.015 | C19: 1200.287 | D19: 1204.293 | E19: 17 | F19: 0 | G19: 1 | H19: =+G19+F19+E19 -> 18 | I19: 8 | J19: 10 | K19: =+J19+I19 -> 18
A20: GVGN | B20: 1213.187 | C20: 1211.29 | D20: 1215.054 | E20: 22 | F20: 0 | G20: 10 | H20: =+G20+F20+E20 -> 32 | I20: 7 | J20: 25 | K20: =+J20+I20 -> 32
A21: KNNN | B21: 1229.087 | C21: 1227.267 | D21: 1230.845 | E21: 10 | F21: 4 | G21: 8 | H21: =+G21+F21+E21 -> 22 | I21: 4 | J21: 18 | K21: =+J21+I21 -> 22
A22: CHAN | B22: 1235.837 | C22: 1235.837 | D22: 1239.419 | E22: 23 | F22: 0 | G22: 5 | H22: =+G22+F22+E22 -> 28 | I22: 6 | J22: 22 | K22: =+J22+I22 -> 28
A23: Total | E23: =+E17+E18+E19+E20+E21+E22 -> 118 | F23: =+F17+F18+F19+F20+F21+F22 -> 4 | G23: =+G17+G18+G19+G20+G21+G22 -> 39 | H23: =+H17+H18+H19+H20+H21+H22 -> 161 | I23: =+I17+I18+I19+I20+I21+I22 -> 41 | J23: =+J17+J18+J19+J20+J21+J22 -> 120 | K23: =+K17+K18+K19+K20+K21+K22 -> 161
A25: Summery of point & Crossing Under IMSD-SMUN
A26: Stations | B26: Angle | C26: Main line | F26: Loop lines | I26: DS | L26: Total
C27: RH | D27: LH | E27: Total | F27: RH | G27: LH | H27: Total | I27: RH | J27: LH | K27: Total
A28: CHAN | B28: 1:12 | C28: 4 | D28: 2 | E28: =+C28+D28 -> 6 | F28: 10 | G28: 7 | H28: =+F28+G28 -> 17 | I28: 3 | J28: 2 | K28: =+I28+J28 -> 5 | L28: =+E28+H28+K28 -> 28
A29: KNNN | B29: 1:12 | C29: 2 | D29: 2 | E29: =+C29+D29 -> 4 | F29: 4 | G29: 2 | H29: =+F29+G29 -> 6 | I29: 2 | J29: 4 | K29: =+I29+J29 -> 6 | L29: =+E29+H29+K29 -> 16
B30: 1:8.5 | C30: 0 | D30: 0 | E30: =+C30+D30 -> 0 | F30: 2 | G30: 2 | H30: =+F30+G30 -> 4 | I30: 0 | J30: 2 | K30: 2 | L30: =+E30+H30+K30 -> 6
A31: GVGN | B31: 1:12 | C31: 3 | D31: 4 | E31: =+C31+D31 -> 7 | F31: 7 | G31: 8 | H31: =+F31+G31 -> 15 | I31: 5 | J31: 5 | K31: =+I31+J31 -> 10 | L31: =+E31+H31+K31 -> 32
A32: NSIR | B32: 1:12 | C32: 3 | D32: 5 | E32: =+C32+D32 -> 8 | F32: 6 | G32: 3 | H32: =+F32+G32 -> 9 | I32: 0 | J32: 1 | K32: =+I32+J32 -> 1 | L32: =+E32+H32+K32 -> 18
A33: SBJN | B33: 1:12 | C33: 4 | D33: 3 | E33: =+C33+D33 -> 7 | F33: 8 | G33: 6 | H33: =+F33+G33 -> 14 | I33: 3 | J33: 2 | K33: =+I33+J33 -> 5 | L33: =+E33+H33+K33 -> 26
A34: SMUN | B34: 1:12 | C34: 5 | D34: 4 | E34: =+C34+D34 -> 9 | F34: 9 | G34: 7 | H34: =+F34+G34 -> 16 | I34: 6 | J34: 4 | K34: =+I34+J34 -> 10 | L34: =+E34+H34+K34 -> 35
G35: Grand Total | L35: =SUM(L28:L34) -> 161
A38: Section under IMSD SMUN (Curve Details)
A39: Section | B39: Line | C39: Chainage | E39: <1.50* | G39: >1.5* | I39: Total
C40: From | D40: To
A41: UBCD-SMUN | B41: SL | C41: 1167.21 | D41: 1170.435 | E41: 3 | G41: 0 | I41: =+G41+E41 -> 3
A42: SMUN-SBJN | B42: SL | C42: =+D41 -> 1170.435 | D42: 1188.575 | E42: 14 | G42: 3 | I42: =+G42+E42 -> 17
A43: SBJN-NSIR | B43: SL | C43: =+D42 -> 1188.575 | D43: 1202.015 | E43: 14 | G43: 0 | I43: =+G43+E43 -> 14
A44: NSIR-GVGN | B44: SL | C44: =+D43 -> 1202.015 | D44: 1213.187 | E44: 4 | G44: 6 | I44: =+G44+E44 -> 10
...

Sheet LC, LWR, SEJ
A1: Section under IMSD SMUN (LWR Details)
A2: S. No | B2: LWR No. | C2: Section | D2: SRJ Chainage | F2: Length | G2: Gap measured on
D3: From | E3: To
A4: 1 | B4: 9 | C4: NSIR - CHAN | D4: 1207.857 | E4: 1210.72 | F4: =+E4-D4 -> 2.863 | G4: Tongue Rail
A5: 2 | B5: 10 | C5: NSIR - CHAN | D5: 1210.863 | E5: 1244.814 | F5: =+E5-D5 -> 33.951 | G5: Tongue Rail
A6: 3 | B6: 11 | C6: NSIR - CHAN | D6: 1244.97 | E6: 1249.674 | F6: =+E6-D6 -> 4.704 | G6: Tongue Rail
A7: 4 | B7: 12 | C7: SMUN - RPJ | D7: 1172.01 | E7: 1176.92 | F7: =+E7-D7 -> 4.91 | G7: Stock Rail
A8: 5 | B8: 13 | C8: SMUN - RPJ | D8: 1177.135 | E8: 1178.15 | F8: =+E8-D8 -> 1.015 | G8: Stock Rail
A9: 6 | B9: 7 | C9: KNZN - SMUN | D9: 1149.333 | E9: 1175.831 | F9: =+E9-D9 -> 26.498 | G9: Tongue Rail
A10: 7 | B10: 8 | C10: SMUN - SBJN | D10: 1175.987 | E10: 1207.741 | F10: =+E10-D10 -> 31.754 | G10: Tongue Rail
A11: Section under IMSD SMUN (Level Crossing Details)
A12: S. No | B12: LC No. | C12: Blcok Section | E12: Chainage | F12: TUV
A14: 1 | B14: 151C | C14: GVGN | D14: KNNN | E14: 1215.034 | F14: 886440
A15: 2 | B15: 159C | C15: KNNN | D15: CHAN | E15: 1232.095 | F15: 183937.5
A16: 3 | B16: 163spl | C16: CHAN | D16: SNL | E16: 1239.827 | F16: 143633.76
A17: 4 | B17: 164spl | C17: CHAN | D17: SNL | E17: 1244.833 | F17: 599622.31
A18: 5 | B18: 167C | C18: CHAN | D18: SNL | E18: 1248.664 | F18: 232435.43
A19: Section under IMSD SMUN (SEJ Details)
A20: S. No | B20: SEJ No. | C20: Station | D20: SRJ Chainage | E20: DRG No. | G20: Temp.
A22: 1 | B22: 13 | C22: SMUN-SBJN | D22: 1175.831 | E22: Mod. SEJ | G22: 32
A23: 2 | B23: 14 | C23: SMUN-SBJN | D23: 1175.987 | E23: Mod. SEJ | G23: 32
A24: 3 | B24: 15 | C24: NSIR-GVGN | D24: 1207.741 | E24: Mod. SEJ | G24: 29
A25: 4 | B25: 16 | C25: NSIR-GVGN | D25: 1207.857 | E25: Mod. SEJ | G25: 30
A26: 5 | B26: 17 | C26: NSIR-GVGN | D26: 1210.72 | E26: Mod. SEJ | G26: 31
A27: 6 | B27: 18 | C27: NSIR-GVGN | D27: 1210.863 | E27: Mod. SEJ | G27: 32
A28: 7 | B28: 19 | C28: CHAN-SNL | D28: 1244.814 | E28: Mod. SEJ | G28: 32
A29: 8 | B29: 20 | C29: CHAN-SNL | D29: 1244.97 | E29: Mod. SEJ | G29: 31
A30: 9 | B30: 21 | C30: CHAN-SNL | D30: 1249.674 | E30: Mod. SEJ | G30: 32
A31: 10 | B31: 22 | C31: SMUN-RPJ | D31: 1176.92 | E31: 6902-60kg | G31: 36
A32: 11 | B32: 22 | C32: SMUN-RPJ | D32: 1177.135 | E32: 6902-60kg | G32: 36
A33: 12 | B33: Dummy 1 | C33: SMUN-RPJ | D33: 1172.01 | E33: 6902-60kg | G33: 38
A34: 13 | B34: Dummy 2 | C34: SMUN-RPJ | D34: 1178.15 | E34: 6902-60kg | G34: 39

Sheet Bridge
A1: S. No. | B1: Bridge No. | C1: Section | D1: From | E1: To | F1: Bridge Type | G1: Old Bridge No. | H1: Column15 | I1: Span Configuration | J1: Length of Bridge | K1: Linear Waterway
A2: =(ROW(A1)) -> 1 | B2: FOB(O)--08 | C2: 03. SMUN-SBJN | D2: 1179.287 | E2: 1179.287 | F2: FOB | G2: FOB Rajpura | H2: FOB | J2: 88.94 | L2: {=_xlfn.XLOOKUP(Table_1[[#This Row],[Bridge No.]],[2]DATA!$A$1:$A$65536,[2]DATA!$G$1:$H$65536,"")} -> Not Applicable | M2: FOB
A3: =(ROW(A2)) -> 2 | B3: FOB(O)--9 | C3: 05. SBJN-NSIR | D3: 1196.859 | E3: 1196.859 | F3: FOB | G3: FOB Sadhugarh | H3: FOB | J3: 49.19 | L3: {=_xlfn.XLOOKUP(Table_1[[#This Row],[Bridge No.]],[2]DATA!$A$1:$A$65536,[2]DATA!$G$1:$H$65536,"")} -> Not Applicable | M3: FOB
A4: =(ROW(A3)) -> 3 | B4: FOB(O)--10 | C4: 09. GVGN-KNNN | D4: 1215.74 | E4: 1215.74 | F4: FOB | G4: FOB Govindgarh | H4: FOB | J4: 59.48 | L4: {=_xlfn.XLOOKUP(Table_1[[#This Row],[Bridge No.]],[2]DATA!$A$1:$A$65536,[2]DATA!$G$1:$H$65536,"")} -> Not Applicable | M4: FOB
A5: =(ROW(A4)) -> 4 | B5: FOB(O)--11 | C5: 09. GVGN-KNNN | D5: 1224.069 | E5: 1224.069 | F5: FOB | G5: FOB Khanna | H5: FOB | J5: 15.09 | L5: {=_xlfn.XLOOKUP(Table_1[[#This Row],[Bridge No.]],[2]DATA!$A$1:$A$65536,[2]DATA!$G$1:$H$65536,"")} -> Not Applicable | M5: FOB
A6: =(ROW(A5)) -> 5 | B6: FOB(O)--12 | C6: 11. KNNN-CHAN | D6: 1234.828 | E6: 1234.828 | F6: FOB | G6: FOB Chawapail | H6: FOB | J6: 13.71 | L6: {=_xlfn.XLOOKUP(Table_1[[#This Row],[Bridge No.]],[2]DATA!$A$1:$A$65536,[2]DATA!$G$1:$H$65536,"")} -> Not Applicable | M6: FOB
A7: =(ROW(A6)) -> 6 | B7: FOB(O)-13 | C7: 13. CHAN-SNL | D7: 1244.112 | E7: 1244.112 | F7: FOB | G7: FOB DORAHA | H7: FOB | L7: {=_xlfn.XLOOKUP(Table_1[[#This Row],[Bridge No.]],[2]DATA!$A$1:$A$65536,[2]DATA!$G$1:$H$65536,"")}
A8: 1 | B8: 1167/1 | C8: 01. UBCD-SMUN | D8: 1167.528 | E8: 1167.559 | F8: MJB | G8: 96 | H8: Box | I8: 4x6.90m | J8: 31 | K8: 29 | L8: {=_xlfn.XLOOKUP(Table_1[[#This Row],[Bridge No.]],[2]DATA!$A$1:$A$65536,[2]DATA!$G$1:$H$65536,"")} -> Major | M8: Rail Bridge
A9: =(ROW(A8)) -> 8 | B9: 1172/2 | C9: 03. SMUN-SBJN | D9: 1172.753 | E9: 1172.821 | F9: MJB | G9: 103 | H9: Mixed | I9: 1x12.48m + 2x18.60m + 1x12.48m | J9: 68 | K9: 65 | L9: {=_xlfn.XLOOKUP(Table_1[[#This Row],[Bridge No.]],[2]DATA!$A$1:$A$65536,[2]DATA!$G$1:$H$65536,"")} -> Major | M9: Rail Bridge
A10: =(ROW(A9)) -> 9 | B10: 1175/2 | C10: 03. SMUN-SBJN | D10: 1175.857 | E10: 1175.964 | F10: MJB (ROR) | G10: 108 | H10: ROR | I10: 1x12.17m + 1x77.34m + 1x12.17m | J10: 107 | L10: {=_xlfn.XLOOKUP(Table_1[[#This Row],[Bridge No.]],[2]DATA!$A$1:$A$65536,[2]DATA!$G$1:$H$65536,"")} -> Major | M10: ROR
A11: =(ROW(A10)) -> 10 | B11: 1177/1 | C11: 03. SMUN-SBJN | D11: 1177.018 | E11: 1177.148 | F11: MJB | G11: 114 | H11: RCC/PSC Girder | I11: 1x30.02m + 2x30.80m + 1x30.02m | J11: 130 | K11: 127 | L11: {=_xlfn.XLOOKUP(Table_1[[#This Row],[Bridge No.]],[2]DATA!$A$1:$A$65536,[2]DATA!$G$1:$H$65536,"")} -> Major | M11: Rail Bridge
A12: =(ROW(A11)) -> 11 | B12: 1181/2 | C12: 03. SMUN-SBJN | D12: 1181.473 | E12: 1181.494 | F12: MJB | G12: 123 | H12: Slab | I12: 2x9.51m | J12: 21 | K12: 19.02 | L12: {=_xlfn.XLOOKUP(Table_1[[#This Row],[Bridge No.]],[2]DATA!$A$1:$A$65536,[2]DATA!$G$1:$H$65536,"")} -> Major | M12: Rail Bridge
A13: =(ROW(A12)) -> 12 | B13: 1183/3 | C13: 03. SMUN-SBJN | D13: 1183.905 | E13: 1184.013 | F13: MJB | G13: 126 | H13: Box | I13: 15x6.56m | J13: 108 | K13: 105 | L13: {=_xlfn.XLOOKUP(Table_1[[#This Row],[Bridge No.]],[2]DATA!$A$1:$A$65536,[2]DATA!$G$1:$H$65536,"")} -> Major | M13: Rail Bridge
A14: =(ROW(A13)) -> 13 | B14: 1190/1 | C14: 04. SBJN Yard | D14: 1190.113 | E14: 1190.17 | F14: MJB | G14: 134 | H14: Box | I14: 8x6.40m | J14: 57 | K14: 54 | L14: {=_xlfn.XLOOKUP(Table_1[[#This Row],[Bridge No.]],[2]DATA!$A$1:$A$65536,[2]DATA!$G$1:$H$65536,"")} -> Major | M14: Rail Bridge
A15: =(ROW(A14)) -> 14 | B15: 1191/1 | C15: 05. SBJN-NSIR | D15: 1191.089 | E15: 1191.146 | F15: MJB | G15: 135 | H15: Box | I15: 8x6.40m | J15: 57 | K15: 54 | L15: {=_xlfn.XLOOKUP(Table_1[[#This Row],[Bridge No.]],[2]DATA!$A$1:$A$65536,[2]DATA!$G$1:$H$65536,"")} -> Major | M15: Rail Bridge
A16: =(ROW(A15)) -> 15 | B16: 1191/2 | C16: 05. SBJN-NSIR | D16: 1191.366 | E16: 1191.387 | F16: MJB | G16: 136 | H16: Slab | I16: 2x9.51m | J16: 21 | K16: 18 | L16: {=_xlfn.XLOOKUP(Table_1[[#This Row],[Bridge No.]],[2]DATA!$A$1:$A$65536,[2]DATA!$G$1:$H$65536,"")} -> Major | M16: Rail Bridge
A17: =(ROW(A16)) -> 16 | B17: 1193/2 | C17: 05. SBJN-NSIR | D17: 1193.539 | E17: 1193.597 | F17: MJB | G17: 140 | H17: Box | I17: 8x6.60m | J17: 58 | K17: 55 | L17: {=_xlfn.XLOOKUP(Table_1[[#This Row],[Bridge No.]],[2]DATA!$A$1:$A$65536,[2]DATA!$G$1:$H$65536,"")} -> Major | M17: Rail Bridge
A18: =(ROW(A17)) -> 17 | B18: 1195/1 | C18: 05. SBJN-NSIR | D18: 1195.027 | E18: 1195.048 | F18: MJB | G18: 145 | H18: Slab | I18: 2x9.51m | J18: 21 | K18: 19 | L18: {=_xlfn.XLOOKUP(Table_1[[#This Row],[Bridge No.]],[2]DATA!$A$1:$A$65536,[2]DATA!$G$1:$H$65536,"")} -> Major | M18: Rail Bridge
A19: =(ROW(A18)) -> 18 | B19: 1195/4 | C19: 05. SBJN-NSIR | D19: 1195.932 | E19: 1195.968 | F19: MJB | G19: 148 | H19: Box | I19: 5x6.50m | J19: 36 | K19: 33 | L19: {=_xlfn.XLOOKUP(Table_1[[#This Row],[Bridge No.]],[2]DATA!$A$1:$A$65536,[2]DATA!$G$1:$H$65536,"")} -> Major | M19: Rail Bridge
A20: =(ROW(A19)) -> 19 | B20: 1206/1 | C20: 07. NSIR-GVGN | D20: 1206.045 | E20: 1206.127 | F20: MJB | G20: 163 | H20: RCC/PSC Girder | I20: 1x17.93m + 2x18.80m + 1x17.93m | J20: 82 | K20: 79 | L20: {=_xlfn.XLOOKUP(Table_1[[#This Row],[Bridge No.]],[2]DATA!$A$1:$A$65536,[2]DATA!$G$1:$H$65536,"")} -> Major | M20: Rail Bridge
A21: =(ROW(A20)) -> 20 | B21: 1206/2 | C21: 07. NSIR-GVGN | D21: 1206.497 | E21: 1206.544 | F21: MJB (ROR) | G21: 164 | H21: ROR | I21: 1x9.07m + 1x24.40m + 1x9.07m | J21: 47 | L21: {=_xlfn.XLOOKUP(Table_1[[#This Row],[Bridge No.]],[2]DATA!$A$1:$A$65536,[2]DATA!$G$1:$H$65536,"")} -> Major | M21: ROR
A22: =(ROW(A21)) -> 21 | B22: 1207/3 | C22: 07. NSIR-GVGN | D22: 1207.778 | E22: 1207.833 | F22: MJB (ROR) | G22: 165 | H22: ROR | I22: 1x9.16m + 1x31.46m + 1x9.16m | J22: 55 | L22: {=_xlfn.XLOOKUP(Table_1[[#This Row],[Bridge No.]],[2]DATA!$A$1:$A$65536,[2]DATA!$G$1:$H$65536,"")} -> Major | M22: ROR
A23: =(ROW(A22)) -> 22 | B23: 1210/2 | C23: 07. NSIR-GVGN | D23: 1210.76 | E23: 1210.824 | F23: MJB (OWG) | G23: 170 | H23: OWG | I23: 1x62.10m | J23: 64 | K23: 62.1 | L23: {=_xlfn.XLOOKUP(Table_1[[#This Row],[Bridge No.]],[2]DATA!$A$1:$A$65536,[2]DATA!$G$1:$H$65536,"")} -> Major | M23: Rail Bridge
A24: =(ROW(A23)) -> 23 | B24: 1244/2 | C24: 13. CHAN-SNL | D24: 1244.851 | E24: 1244.931 | F24: MJB (OWG) | G24: 199 | H24: OWG | I24: 1x78.05m | J24: 80 | K24: 78.05 | L24: {=_xlfn.XLOOKUP(Table_1[[#This Row],[Bridge No.]],[2]DATA!$A$1:$A$65536,[2]DATA!$G$1:$H$65536,"")} -> Major | M24: Rail Bridge
A25: =(ROW(A24)) -> 24 | B25: 1177/CL/1 | C25: 14.SMUN-RPJ | D25: 1176.953 | E25: 1177.085 | F25: MJB (OWG) | G25: 115 | H25: OWG | I25: 4x31.10m | J25: 132 | K25: 129 | L25: {=_xlfn.XLOOKUP(Table_1[[#This Row],[Bridge No.]],[2]DATA!$A$1:$A$65536,[2]DATA!$G$1:$H$65536,"")} -> Major | M25: Rail Bridge
A26: =(ROW(A25)) -> 25 | B26: 1169/2 | C26: 01. UBCD-SMUN | D26: 1169.849 | E26: 1169.852 | F26: Minor | G26: 98 | H26: Box | I26: 1x2.00m | J26: 3 | K26: 2 | L26: {=_xlfn.XLOOKUP(Table_1[[#This Row],[Bridge No.]],[2]DATA!$A$1:$A$65536,[2]DATA!$G$1:$H$65536,"")} -> Minor | M26: Rail Bridge
A27: =(ROW(A26)) -> 26 | B27: 1170/1 | C27: 02. SMUN Yard | D27: 1170.075 | E27: 1170.078 | F27: Minor | G27: 101 A | H27: Box | I27: 1x2.00m | J27: 3 | K27: 2 | L27: {=_xlfn.XLOOKUP(Table_1[[#This Row],[Bridge No.]],[2]DATA!$A$1:$A$65536,[2]DATA!$G$1:$H$65536,"")} -> Minor | M27: Rail Bridge
A28: =(ROW(A27)) -> 27 | B28: 1170/2 | C28: 02. SMUN Yard | D28: 1170.499 | E28: 1170.503 | F28: Minor | G28: 99 | H28: Box | I28: 1x3.00m | J28: 4 | K28: 3 | L28: {=_xlfn.XLOOKUP(Table_1[[#This Row],[Bridge No.]],[2]DATA!$A$1:$A$65536,[2]DATA!$G$1:$H$65536,"")} -> Minor | M28: Rail Bridge
A29: =(ROW(A28)) -> 28 | B29: 1170/3 | C29: 02. SMUN Yard | D29: 1170.972 | E29: 1170.976 | F29: Minor | G29: 100 | H29: Box | I29: 2x2.75m | J29: 4 | K29: 5.5 | L29: {=_xlfn.XLOOKUP(Table_1[[#This Row],[Bridge No.]],[2]DATA!$A$1:$A$65536,[2]DATA!$G$1:$H$65536,"")} -> Minor | M29: Rail Bridge
A30: =(ROW(A29)) -> 29 | B30: 1171/1 | C30: 02. SMUN Yard | D30: 1171.609 | E30: 1171.616 | F30: RUB | G30: LC 132 | H30: Box | I30: 1x5.50m | J30: 7 | L30: {=_xlfn.XLOOKUP(Table_1[[#This Row],[Bridge No.]],[2]DATA!$A$1:$A$65536,[2]DATA!$G$1:$H$65536,"")} -> Minor | M30: RUB
A31: =(ROW(A30)) -> 30 | B31: 1172/1 | C31: 03. SMUN-SBJN | D31: 1172.392 | E31: 1172.398 | F31: Minor | G31: 102 | H31: Box | I31: 1x4.50m | J31: 6 | K31: 4.5 | L31: {=_xlfn.XLOOKUP(Table_1[[#This Row],[Bridge No.]],[2]DATA!$A$1:$A$65536,[2]DATA!$G$1:$H$65536,"")} -> Minor | M31: Rail Bridge
A32: =(ROW(A31)) -> 31 | B32: 1174/1 | C32: 03. SMUN-SBJN | D32: 1174.865 | E32: 1174.873 | F32: Minor | G32: 104 | H32: Box | I32: 1x3.50m | J32: 8 | K32: 3.5 | L32: {=_xlfn.XLOOKUP(Table_1[[#This Row],[Bridge No.]],[2]DATA!$A$1:$A$65536,[2]DATA!$G$1:$H$65536,"")} -> Minor | M32: Rail Bridge
A33: =(ROW(A32)) -> 32 | B33: 1175/1 | C33: 03. SMUN-SBJN | D33: 1175.249 | E33: 1175.254 | F33: Minor | G33: 106 | H33: Box | I33: 1x4.00m | J33: 5 | K33: 4 | L33: {=_xlfn.XLOOKUP(Table_1[[#This Row],[Bridge No.]],[2]DATA!$A$1:$A$65536,[2]DATA!$G$1:$H$65536,"")} -> Minor | M33: Rail Bridge
A34: =(ROW(A33)) -> 33 | B34: 1176/2 | C34: 03. SMUN-SBJN | D34: 1176.615 | E34: 1176.633 | F34: Minor | G34: 111 | H34: Box | I34: 1x6.00m | J34: 18 | K34: 6 | L34: {=_xlfn.XLOOKUP(Table_1[[#This Row],[Bridge No.]],[2]DATA!$A$1:$A$65536,[2]DATA!$G$1:$H$65536,"")} -> Minor | M34: Rail Bridge
A35: =(ROW(A34)) -> 34 | B35: 1176/3 | C35: 03. SMUN-SBJN | D35: 1176.829 | E35: 1176.845 | F35: Minor | G35: 113 | H35: Box | I35: 1x6.05m | J35: 16 | K35: 6.05 | L35: {=_xlfn.XLOOKUP(Table_1[[#This Row],[Bridge No.]],[2]DATA!$A$1:$A$65536,[2]DATA!$G$1:$H$65536,"")} -> Minor | M35: Rail Bridge
A36: =(ROW(A35)) -> 35 | B36: 1178/3 | C36: 03. SMUN-SBJN | D36: 1178.985 | E36: 1178.987 | F36: Minor | G36: MIB | H36: Box | I36: 1x1.20m | J36: 2 | K36: 1.2 | L36: {=_xlfn.XLOOKUP(Table_1[[#This Row],[Bridge No.]],[2]DATA!$A$1:$A$65536,[2]DATA!$G$1:$H$65536,"")} -> Minor | M36: Rail Bridge
A37: =(ROW(A36)) -> 36 | B37: 1180/1 | C37: 03. SMUN-SBJN | D37: 1180.536 | E37: 1180.538 | F37: Minor | G37: 121 | H37: Box | I37: 1x1.20m | J37: 2 | K37: 1.2 | L37: {=_xlfn.XLOOKUP(Table_1[[#This Row],[Bridge No.]],[2]DATA!$A$1:$A$65536,[2]DATA!$G$1:$H$65536,"")} -> Minor | M37: Rail Bridge
A38: =(ROW(A37)) -> 37 | B38: 1180/3 | C38: 03. SMUN-SBJN | D38: 1180.955 | E38: 1180.959 | F38: Minor | G38: 119 | H38: Box | I38: 1x3.00m | J38: 4 | K38: 3 | L38: {=_xlfn.XLOOKUP(Table_1[[#This Row],[Bridge No.]],[2]DATA!$A$1:$A$65536,[2]DATA!$G$1:$H$65536,"")} -> Minor | M38: Rail Bridge
A39: =(ROW(A38)) -> 38 | B39: 1181/1 | C39: 03. SMUN-SBJN | D39: 1181.229 | E39: 1181.237 | F39: Minor | G39: 122 | H39: Box | I39: 2x3.40m | J39: 8 | K39: 6.8 | L39: {=_xlfn.XLOOKUP(Table_1[[#This Row],[Bridge No.]],[2]DATA!$A$1:$A$65536,[2]DATA!$G$1:$H$65536,"")} -> Minor | M39: Rail Bridge
A40: =(ROW(A39)) -> 39 | B40: 1182/1 | C40: 03. SMUN-SBJN | D40: 1182.908 | E40: 1182.925 | F40: Minor | G40: 124 | H40: Box | I40: 4x3.30m | J40: 17 | K40: 15 | L40: {=_xlfn.XLOOKUP(Table_1[[#This Row],[Bridge No.]],[2]DATA!$A$1:$A$65536,[2]DATA!$G$1:$H$65536,"")} -> Minor | M40: Rail Bridge
...

Sheet Curve
A1: Section under IMSD SMUN (Curve Details)
A2: S. No | B2: Curve No. | C2: From | D2: To | E2: L | F2: D | G2: R (TMS) | H2: R | I2: V | J2: TL | K2: CL | L2: TMS CL | M2: SE (TMS) | N2: SE
A3: 1 | B3: 315 | C3: 1167.627 | D3: 1167.789 | E3: 162 | F3: 1 | G3: 1750 | H3: 1750 | I3: 29 | J3: 70 | K3: 22.05 | L3: 22 | M3: 70 | O3: In-Charge
A4: 2 | B4: 316 | C4: 1168.062 | D4: 1168.323 | E4: 261 | F4: 0.5 | G4: 3500 | H4: 3500 | I4: 14 | J4: 40 | K4: 180.66 | L4: 181 | M4: 30
A5: 3 | B5: 317 | C5: 1169.543 | D5: 1169.645 | E5: 102 | F5: 0.29 | G5: 6034 | H5: 6000 | I5: 8 | J5: 40 | K5: 22.3 | L5: 22 | M5: 20 | N5: SMUN Yard
A6: 4 | B6: 318 | C6: 1172.295 | D6: 1172.401 | E6: 106 | F6: 0.35 | G6: 5000 | H6: 5000 | I6: 10 | J6: 40 | K6: 25.83 | L6: 26 | M6: 20
A7: 5 | B7: 319 | C7: 1172.568 | D7: 1172.673 | E7: 105 | F7: 0.35 | G7: 5000 | H7: 5000 | I7: 10 | J7: 40 | K7: 25.83 | L7: 25 | M7: 20
A8: 6 | B8: 320 | C8: 1173.228 | D8: 1173.342 | E8: 114 | F8: 0.17 | G8: 10294 | H8: 10000 | I8: 5 | J8: 20 | K8: 74.08 | L8: 74 | M8: 10
A9: 7 | B9: 321 | C9: 1174.826 | D9: 1175.167 | E9: 341 | F9: 2.2 | G9: 795 | H9: 800 | I9: 63 | J9: 140 | K9: 60.57 | L9: 61 | M9: 165 | O9: Sectional
A10: 8 | B10: 322 | C10: 1175.221 | D10: 1175.815 | E10: 594 | F10: 2.5 | G10: 700 | H10: 700 | I10: 71 | J10: 80 | K10: 433.87 | L10: 434 | M10: 150
A11: 9 | B11: 323 | C11: 1175.994 | D11: 1176.47 | E11: 476 | F11: 2.5 | G11: 700 | H11: 700 | I11: 71 | J11: 80 | K11: 316.09 | L11: 316 | M11: 150 | O11: In-Charge
A12: 10 | B12: 324 | C12: 1177.254 | D12: 1177.901 | E12: 647 | F12: 0.44 | G12: 3977 | H12: 4000 | I12: 13 | J12: 30 | K12: 586.92 | L12: 587 | M12: 30
A13: 11 | B13: 325 | C13: 1178.055 | D13: 1178.189 | E13: 134 | F13: 0.5 | G13: 3500 | H13: 3500 | I13: 14 | J13: 40 | K13: 54.3 | L13: 54 | M13: 40 | N13: 30 | O13: Sectional
A14: 12 | B14: 326 | C14: 1178.714 | D14: 1178.894 | E14: 180 | F14: 1.03 | G14: 1699 | H14: 1700 | I14: 29 | J14: 70 | K14: 39.33 | L14: 40 | M14: 80
A15: 13 | B15: 327 | C15: 1178.948 | D15: 1179.158 | E15: 210 | F15: 1 | G15: 1750 | H15: 1750 | I15: 29 | J15: 70 | K15: 69.89 | L15: 70 | M15: 70
A16: 14 | B16: 328 | C16: 1179.785 | D16: 1179.925 | E16: 140 | F16: 0.7 | G16: 2500 | H16: 2500 | I16: 20 | J16: 50 | K16: 39.33 | L16: 40 | M16: 50
A17: 15 | B17: 329 | C17: 1180.061 | D17: 1180.284 | E17: 223 | F17: 0.25 | G17: 7000 | H17: 7000 | I17: 7 | J17: 20 | K17: 182.93 | L17: 183 | M17: 20
A18: 16 | B18: 330 | C18: 1180.678 | D18: 1180.771 | E18: 93 | F18: 0.39 | G18: 4487 | H18: 4500 | I18: 11 | J18: 30 | K18: 32.5 | L18: 33 | M18: 30 | O18: In-Charge
A19: 17 | B19: 331 | C19: 1180.854 | D19: 1180.955 | E19: 101 | F19: 0.3 | G19: 5833 | H19: 5800 | I19: 9 | J19: 20 | K19: 60.55 | L19: 61 | M19: 20
A20: 18 | B20: 332 | C20: 1181.184 | D20: 1181.285 | E20: 101 | F20: 0.25 | G20: 7000 | H20: 7000 | I20: 7 | J20: 30 | K20: 40.51 | L20: 41 | M20: 10
A21: 19 | B21: 333 | C21: 1187.183 | D21: 1187.299 | E21: 116 | F21: 0.63 | G21: 2778 | H21: 2800 | I21: 18 | J21: 40 | K21: 35.72 | L21: 36 | M21: 40 | N21: SBJN Yard
A22: 20 | B22: 334 | C22: 1188.117 | D22: 1188.235 | E22: 118 | F22: 0.58 | G22: 3017 | H22: 3000 | I22: 17 | J22: 40 | K22: 37.61 | L22: 38 | M22: 40 | N22: SBJN Yard
A23: 21 | B23: 335 | C23: 1189.72 | D23: 1189.989 | E23: 269 | F23: 0.33 | G23: 5303 | H23: 5300 | I23: 9 | J23: 30 | K23: 208.96 | L23: 209 | M23: 20 | N23: SBJN Yard | O23: Sectional
A24: 22 | B24: 336 | C24: 1190.28 | D24: 1190.477 | E24: 197 | F24: 0.5 | G24: 3500 | H24: 3500 | I24: 14 | J24: 40 | K24: 116.24 | L24: 117 | M24: 30 | N24: SBJN Yard
A25: 23 | B25: 337 | C25: 1192.373 | D25: 1192.484 | E25: 111 | F25: 0.25 | G25: 7000 | H25: 7000 | I25: 7 | J25: 20 | K25: 70.55 | L25: 71 | M25: 10
A26: 24 | B26: 338 | C26: 1192.625 | D26: 1192.729 | E26: 104 | F26: 0.25 | G26: 7000 | H26: 7000 | I26: 7 | J26: 20 | K26: 63.73 | L26: 64 | M26: 10
A27: 25 | B27: 339 | C27: 1196.241 | D27: 1196.362 | E27: 121 | F27: 0.6 | G27: 2917 | H27: 2900 | I27: 17 | J27: 40 | K27: 41.53 | L27: 41 | M27: 40
A28: 26 | B28: 340 | C28: 1196.453 | D28: 1196.564 | E28: 111 | F28: 0.58 | G28: 3017 | H28: 3000 | I28: 17 | J28: 40 | K28: 30.98 | L28: 31 | M28: 40 | O28: In-Charge
A29: 27 | B29: 341 | C29: 1196.82 | D29: 1196.895 | E29: 75 | F29: 0.25 | G29: 7000 | H29: 7000 | I29: 7 | J29: 20 | K29: 34.48 | L29: 35 | M29: 15
A30: 28 | B30: 342 | C30: 1197.243 | D30: 1197.36 | E30: 117 | F30: 0.63 | G30: 2778 | H30: 2800 | I30: 18 | J30: 40 | K30: 36.8 | L30: 37 | M30: 40
A31: 29 | B31: 343 | C31: 1197.492 | D31: 1197.644 | E31: 152 | F31: 0.5 | G31: 3500 | H31: 3500 | I31: 14 | J31: 40 | K31: 71.8 | L31: 72 | M31: 30
A32: 30 | B32: 344 | C32: 1199.908 | D32: 1199.968 | E32: 60 | F32: 0.02 | G32: 87500 | H32: 85000 | I32: 1 | J32: 20 | K32: 20.51 | L32: 20 | M32: 10
A33: 31 | B33: 345 | C33: 1200.122 | D33: 1200.184 | E33: 62 | F33: 0.03 | G33: 58333 | H33: 60000 | I33: 1 | J33: 20 | K33: 21.28 | L33: 22 | M33: 10
A34: 32 | B34: 346 | C34: 1200.541 | D34: 1200.619 | E34: 78 | F34: 0.14 | G34: 12500 | H34: 12000 | I34: 4 | J34: 20 | K34: 37.44 | L34: 38 | M34: 10 | N34: NSIR Yard
A35: 33 | B35: 347 | C35: 1200.673 | D35: 1200.753 | E35: 80 | F35: 0.04 | G35: 43750 | H35: 40000 | I35: 1 | J35: 20 | K35: 39.82 | L35: 40 | M35: 10 | N35: NSIR Yard
A36: 34 | B36: 348 | C36: 1201.62 | D36: 1202.094 | E36: 474 | F36: 0.22 | G36: 7955 | H36: 8000 | I36: 6 | J36: 20 | K36: 434.38 | L36: 434 | M36: 20 | N36: NSIR Yard | O36: Sectional
A37: 35 | B37: 349 | C37: 1203.276 | D37: 1203.378 | E37: 102 | F37: 0.04 | G37: 43750 | H37: 43000 | I37: 1 | J37: 40 | K37: 21.9 | L37: 22 | M37: 10 | N37: NSIR Yard
A38: 36 | B38: 350 | C38: 1203.811 | D38: 1204.059 | E38: 248 | F38: 0.49 | G38: 3571 | H38: 3550 | I38: 14 | J38: 30 | K38: 188.62 | L38: 188 | M38: 30 | N38: NSIR Yard
A39: 37 | B39: 351 | C39: 1204.714 | D39: 1205.463 | E39: 749 | F39: 2.5 | G39: 700 | H39: 700 | I39: 71 | J39: 160 | K39: 428.47 | L39: 429 | M39: 165 | O39: In-Charge
A40: 38 | B40: 352 | C40: 1205.709 | D40: 1207.441 | E40: 1732 | F40: 2.5 | G40: 700 | H40: 700 | I40: 71 | J40: 160 | K40: 1411.71 | L40: 1412 | M40: 165 | O40: Sectional
...

Sheet PNC
A1: Section under IMSD SMUN (Point & Crossing Details)
A3: S. No | B3: Station | C3: Point No. | D3: Line | E3: Angle | F3: SRJ Chainage | G3: Laid On | H3: LH/RH | I3: Traffic | J3: SE | K3: D | L3: Stations behind the X-ing
A4: =ROW()-3 -> 1 | B4: SMUN | C4: 201 b | D4: Main Line | E4: 1/12 | F4: 1169.045 | G4: Straight | H4: LH | I4: Facing | L4: 3
A5: =ROW()-3 -> 2 | B5: SMUN | C5: 205b | D5: Main Line | E5: 1/12 | F5: 1169.412 | G5: Straight | H5: RH | I5: Facing | L5: 3
A6: =ROW()-3 -> 3 | B6: SMUN | C6: 243a | D6: Main Line | E6: 1/12 | F6: 1170.473 | G6: Straight | H6: LH | I6: Trailing | L6: 3
A7: =ROW()-3 -> 4 | B7: SMUN | C7: 245b | D7: Main Line | E7: 1/12 | F7: 1170.534 | G7: Straight | H7: RH | I7: Trailing | L7: 3
A8: =ROW()-3 -> 5 | B8: SMUN | C8: 248a | D8: Main Line | E8: 1/12 | F8: 1170.547 | G8: Straight | H8: LH | I8: Facing | L8: 3
A9: =ROW()-3 -> 6 | B9: SMUN | C9: 249a | D9: Main Line | E9: 1/12 | F9: 1170.608 | G9: Straight | H9: RH | I9: Facing | L9: 3
A10: =ROW()-3 -> 7 | B10: SMUN | C10: 295b | D10: Main Line | E10: 1/12 | F10: 1171.621 | G10: Straight | H10: LH | I10: Trailing | J10: PNC | L10: 3
A11: =ROW()-3 -> 8 | B11: SMUN | C11: 298b | D11: Main Line | E11: 1/12 | F11: 1171.847 | G11: Straight | H11: RH | I11: Trailing | L11: 3
A12: =ROW()-3 -> 9 | B12: SMUN | C12: 299a | D12: Main Line | E12: 1/12 | F12: 1171.86 | G12: Straight | H12: RH | I12: Facing | L12: 3
A13: =ROW()-3 -> 10 | B13: SMUN | C13: 297b | D13: Loop | E13: 1/12 | F13: 1171.712 | G13: Straight | H13: RH | I13: SL | L13: 10
A14: =ROW()-3 -> 11 | B14: SMUN | C14: 298a | D14: Loop | E14: 1/12 | F14: 1171.725 | G14: Straight | H14: RH | I14: SL | L14: 3
A15: =ROW()-3 -> 12 | B15: SMUN | C15: 299b | D15: Loop | E15: 1/12 | F15: 1171.981 | G15: Straight | H15: RH | I15: SL | L15: 3
A16: =ROW()-3 -> 13 | B16: SMUN | C16: 248b | D16: Loop | E16: 1/12 | F16: 1170.668 | G16: Straight | H16: LH | I16: SL | L16: 3
A17: =ROW()-3 -> 14 | B17: SMUN | C17: 250 | D17: Loop | E17: 1/12 | F17: 1170.681 | G17: Straight | H17: LH | I17: SL
A18: =ROW()-3 -> 15 | B18: SMUN | C18: 249b | D18: Loop | E18: 1/12 | F18: 1170.73 | G18: Straight | H18: RH | I18: SL | L18: 3
A19: =ROW()-3 -> 16 | B19: SMUN | C19: 251a | D19: Loop | E19: 1/12 | F19: 1170.756 | G19: Straight | H19: RH | I19: SL | L19: 10
A20: =ROW()-3 -> 17 | B20: SMUN | C20: 201a | D20: Loop | E20: 1/12 | F20: 1169.166 | G20: Straight | H20: LH | I20: SL | L20: 3
A21: =ROW()-3 -> 18 | B21: SMUN | C21: 202 | D21: Loop | E21: 1/12 | F21: 1169.179 | G21: Straight | H21: LH | I21: SL
A22: =ROW()-3 -> 19 | B22: SMUN | C22: 203b | D22: Loop | E22: 1/12 | F22: 1169.256 | G22: Straight | H22: RH | I22: SL | L22: 10
A23: =ROW()-3 -> 20 | B23: SMUN | C23: 205a | D23: Loop | E23: 1/12 | F23: 1169.534 | G23: Straight | H23: RH | I23: SL | L23: 3
A24: =ROW()-3 -> 21 | B24: SMUN | C24: 242a | D24: Loop | E24: 1/12 | F24: 1170.325 | G24: Straight | H24: LH | I24: SL | L24: 10
A25: =ROW()-3 -> 22 | B25: SMUN | C25: 243b | D25: Loop | E25: 1/12 | F25: 1170.352 | G25: Straight | H25: LH | I25: SL | L25: 3
A26: =ROW()-3 -> 23 | B26: SMUN | C26: 244 | D26: Loop | E26: 1/12 | F26: 1170.4 | G26: Straight | H26: RH | I26: SL
A27: =ROW()-3 -> 24 | B27: SMUN | C27: 245a | D27: Loop | E27: 1/12 | F27: 1170.413 | G27: Straight | H27: RH | I27: SL | L27: 3
A28: =ROW()-3 -> 25 | B28: SMUN | C28: 295a | D28: Loop | E28: 1/12 | F28: 1170.5 | G28: Straight | H28: LH | I28: SL | L28: 3
A29: =ROW()-3 -> 26 | B29: SMUN | C29: 203a | D29: D/S | E29: 1/12 | F29: 1169.37 | G29: Straight | H29: RH | I29: SL
A30: =ROW()-3 -> 27 | B30: SMUN | C30: 204 | D30: D/S | E30: 1/12 | F30: 1169.37 | G30: Straight | H30: RH | I30: SL
A31: =ROW()-3 -> 28 | B31: SMUN | C31: 241 | D31: D/S | E31: 1/12 | F31: 1170.21 | G31: Straight | H31: LH | I31: SL
A32: =ROW()-3 -> 29 | B32: SMUN | C32: 242b | D32: D/S | E32: 1/12 | F32: 1170.21 | G32: Straight | H32: LH | I32: SL
A33: =ROW()-3 -> 30 | B33: SMUN | C33: 247 | D33: D/S | E33: 1/12 | F33: 1170.54 | G33: Straight | H33: RH | I33: SL
A34: =ROW()-3 -> 31 | B34: SMUN | C34: 246 | D34: D/S | E34: 1/12 | F34: 1170.54 | G34: Straight | H34: LH | I34: SL
A35: =ROW()-3 -> 32 | B35: SMUN | C35: 252 | D35: D/S | E35: 1/12 | F35: 1170.871 | G35: Straight | H35: RH | I35: SL
A36: =ROW()-3 -> 33 | B36: SMUN | C36: 251b | D36: D/S | E36: 1/12 | F36: 1170.871 | G36: Straight | H36: RH | I36: SL
A37: =ROW()-3 -> 34 | B37: SMUN | C37: 297a | D37: D/S | E37: 1/12 | F37: 1171.541 | G37: Straight | H37: LH | I37: SL
A38: =ROW()-3 -> 35 | B38: SMUN | C38: 296 | D38: D/S | E38: 1/12 | F38: 1171.659 | G38: Straight | H38: RH | I38: SL
A39: =ROW()-3 -> 36 | B39: SBJN | C39: 201b | D39: Main Line | E39: 1/12 | F39: 1187.353 | G39: Straight | H39: LH | I39: Facing | L39: 3
A40: =ROW()-3 -> 37 | B40: SBJN | C40: 243a | D40: Main Line | E40: 1/12 | F40: 1188.478 | G40: Straight | H40: RH | I40: Trailing | L40: 3
A41: =ROW()-3 -> 38 | B41: SBJN | C41: 244b | D41: Main Line | E41: 1/12 | F41: 1188.491 | G41: Straight | H41: RH | I41: Facing | L41: 3
...

Sheet DFWO
A1: S.No. | B1: Location | D1: Number | E1: Line/ Loop Line/ Cross Over | F1: Remark
B2: km | C2: m
A3: 1 | B3: 2 | C3: 3 | D3: 4 | E3: 5 | F3: 7
A4: 1 | B4: 1218 | C4: 897.2 | D4: (RR) | E4: Main Line | F4: GVGN-KNNN
A5: 2 | B5: 1248 | C5: 646.4 | D5: (LR) | E5: Main Line | F5: CHAN-SNL
A6: 3 | B6: 1169 | C6: 273 | D6: (LR) | E6: Goods Line No 4 | F6: SMUN Station
A7: 4 | B7: 1169 | C7: 304.04 | D7: (LR) | E7: Goods Line No 5 | F7: SMUN Station
A8: 5 | B8: 1169 | C8: 317 | D8: (LR) | E8: Goods Line No 5 | F8: SMUN Station
A9: 6 | B9: 1169 | C9: 378 | D9: (RR) | E9: Goods Line No 5 | F9: SMUN Station
A10: 7 | B10: 1170 | C10: 268.8 | D10: (RR) | E10: Goods Line No 4 | F10: SMUN Station
A11: 8 | B11: 1170 | C11: 485.6 | D11: (RR) | E11: SMUN-C4 | F11: SMUN Station
A12: 9 | B12: 1170 | C12: 557 | D12: (LR) | E12: Line Between Common Loop Line No 1 and 1A | F12: SMUN Station
A13: 10 | B13: 1170 | C13: 698 | D13: (LR) | E13: Ballast Siding Line | F13: SMUN Station
A14: 11 | B14: 1170 | C14: 743 | D14: (RR) | E14: Common Loop Line 3A | F14: SMUN Station
A15: 12 | B15: 1170 | C15: 773 | D15: (LR) | E15: Ballast Siding Line | F15: SMUN Station
... A51: 48 | B51: 1238 | C51: 680.06 | D51: (LR) | E51: CHAN-C9 | F51: CHAN Station

Sheet Scheduled inspection
A1: Section under IMSD SMUN (Curve Details)
A2: S. No | B2: Curve No. | D2: S. No | E2: Curve No.
A4: 1 | B4: 315 | C4: In-Charge | D4: 46 | E4: 360 | F4: Sectional
A5: 2 | B5: 316 | D5: 47 | E5: 361
A6: 3 | B6: 317 | D6: 48 | E6: 362
A7: 4 | B7: 318 | D7: 49 | E7: 363
A8: 5 | B8: 319 | D8: 50 | E8: 364
A9: 6 | B9: 320 | D9: 51 | E9: 365 | F9: In-Charge
A10: 7 | B10: 321 | C10: Sectional | D10: 52 | E10: 366
A11: 8 | B11: 322 | D11: 53 | E11: 367
A12: 9 | B12: 323 | C12: In-Charge | D12: 54 | E12: 368
A13: 10 | B13: 324 | D13: 55 | E13: 369
A14: 11 | B14: 325 | C14: Sectional | D14: 56 | E14: 370 | F14: Sectional
A15: 12 | B15: 326 | D15: 57 | E15: 371
A16: 13 | B16: 327 | D16: 58 | E16: 372
A17: 14 | B17: 328 | D17: 59 | E17: 373
A18: 15 | B18: 329 | D18: 60 | E18: 374
A19: 16 | B19: 330 | C19: In-Charge | D19: 61 | E19: 375 | F19: In-Charge
A20: 17 | B20: 331 | D20: 62 | E20: 376
A21: 18 | B21: 332 | D21: 63 | E21: 377
A22: 19 | B22: 333 | D22: 64 | E22: 378
A23: 20 | B23: 334 | D23: 65 | E23: 379
A24: 21 | B24: 335 | C24: Sectional | D24: 66 | E24: 380
A25: 22 | B25: 336 | D25: 67 | E25: 381
A26: 23 | B26: 337 | D26: 68 | E26: 382 | F26: Sectional
A27: 24 | B27: 338 | D27: 69 | E27: 383
A28: 25 | B28: 339 | D28: 70 | E28: 384
A29: 26 | B29: 340 | C29: In-Charge | D29: 71 | E29: 385
A30: 27 | B30: 341 | D30: 72 | E30: 386
A31: 28 | B31: 342 | D31: 73 | E31: 387 | F31: In-Charge
A32: 29 | B32: 343 | D32: 74 | E32: 388
A33: 30 | B33: 344 | D33: 75 | E33: 389
A34: 31 | B34: 345 | D34: 76 | E34: 390
A35: 32 | B35: 346 | D35: 77 | E35: 391
A36: 33 | B36: 347 | D36: 78 | E36: 392 | F36: Sectional
A37: 34 | B37: 348 | C37: Sectional | D37: 79 | E37: 393
A38: 35 | B38: 349 | D38: 80 | E38: 394
A39: 36 | B39: 350 | D39: 81 | E39: 395
A40: 37 | B40: 351 | C40: In-Charge | D40: 82 | E40: 396
A41: 38 | B41: 352 | C41: Sectional | D41: 83 | E41: 397
...

Sheet Staff_Master_DATA
A1: MsMhdsVsM ÝsV dkWjhMksj dkWiksZjs'ku vkWQ bf.M;k fy- Dedicated Freight Corridor Corporation of India Ltd. Hkkjr ljdkj ¼jsy ea=ky;½ dk miØe A Govt. of India (Ministry of Railways) Enterprise
A2: CONTACT DETAILS OF STAFF UNDER IMSD-SMUN SECTION
A3: S.N. | B3: Name of Employee | C3: Designation | D3: Emp-Id | E3: Place of posting | F3: Mobile No. | G3: E-mail-id
A4: क्र. स. | B4: कर्मचारी का नाम | C4: पदनाम | D4: कर्मचारी कोड | E4: पदस्थान | F4: मोबाइल न | G4: ई- मेल आईडी
A5: 1 | B5: Shri Vivek Kumar Azad | C5: ASSISTANT PROJECT MANAGER/CIVIL | D5: 101518 | E5: NEW SHAMBHU | F5: 8872671873 | G5: vkazad@dfcc.co.in
B6: =_xlfn.TRANSLATE(B5,"en","hi") -> श्री विवेक कुमार आजाद | C6: =_xlfn.TRANSLATE(C5,"en","hi") -> सहायक परियोजना प्रबंधक/सिविल | E6: =_xlfn.TRANSLATE(E5,"en","hi") -> नया शंभू
A7: 2 | B7: Shri Arjun kumar | C7: EXECUTIVE/CIVIL | D7: 101801 | E7: NEW SHAMBHU | F7: 8295416161
B8: =_xlfn.TRANSLATE(B7,"en","hi") -> श्री अर्जुन कुमार | C8: =_xlfn.TRANSLATE(C7,"en","hi") -> कार्यकारी/सिविल | E8: =_xlfn.TRANSLATE(E7,"en","hi") -> नया शंभू
A9: 2 | B9: Shri Gaya Prashad | C9: EXECUTIVE/CIVIL | D9: 105960 | E9: NEW SIR-HIND | F9: 8295416161
B10: =_xlfn.TRANSLATE(B9,"en","hi") -> श्री गया प्रसाद | C10: =_xlfn.TRANSLATE(C9,"en","hi") -> कार्यकारी/सिविल | E10: =_xlfn.TRANSLATE(E9,"en","hi") -> नया सर-हिंद
A11: 2 | B11: Shri Tej Pal | C11: JUNIOR EXECUTIVE/CIVIL | D11: 101686 | E11: NEW SIR-HIND | F11: 8295416161 | G11: tejpal@dfcc.co.in
B12: =_xlfn.TRANSLATE(B11,"en","hi") -> श्री तेज पाल | C12: =_xlfn.TRANSLATE(C11,"en","hi") -> जूनियर एग्जीक्यूटिव/सिविल | E12: =_xlfn.TRANSLATE(E11,"en","hi") -> नया सर-हिंद
A13: 3 | B13: Shri Ved Prakash | C13: JUNIOR EXECUTIVE/CIVIL | D13: 101646 | E13: NEW CHAWA PAIL | F13: 7665685189 | G13: vprathore@dfcc.co.in
B14: =_xlfn.TRANSLATE(B13,"en","hi") -> श्री वेद प्रकाश | C14: =_xlfn.TRANSLATE(C13,"en","hi") -> जूनियर एग्जीक्यूटिव/सिविल | E14: =_xlfn.TRANSLATE(E13,"en","hi") -> न्यू चावा पेल
A15: 4 | B15: Shri Sanni Kumar Sharma | C15: MTS/CIVIL | D15: 102431 | E15: NEW SHAMBHU | F15: 7870056089
B16: =_xlfn.TRANSLATE(B15,"en","hi") -> श्री सन्नी कुमार शर्मा | C16: =_xlfn.TRANSLATE(C15,"en","hi") -> एमटीएस/सिविल | E16: =_xlfn.TRANSLATE(E15,"en","hi") -> नया शंभू
A17: 5 | B17: Shri Ranjeet Kumar | C17: MTS/CIVIL | D17: 103258 | E17: NEW SHAMBHU | F17: 9570703677
B18: =_xlfn.TRANSLATE(B17,"en","hi") -> श्री रंजीत कुमार | C18: =_xlfn.TRANSLATE(C17,"en","hi") -> एमटीएस/सिविल | E18: =_xlfn.TRANSLATE(E17,"en","hi") -> नया शंभू
A19: 6 | B19: Shri Gautam Kumar | C19: MTS/CIVIL | D19: 103259 | E19: NEW SHAMBHU | F19: 7011209332
B20: =_xlfn.TRANSLATE(B19,"en","hi") -> श्री गौतम कुमार | C20: =_xlfn.TRANSLATE(C19,"en","hi") -> एमटीएस/सिविल | E20: =_xlfn.TRANSLATE(E19,"en","hi") -> नया शंभू
A21: 7 | B21: Shri Lal Chand | C21: MTS/CIVIL | D21: 102924 | E21: NEW SIR-HIND | F21: 9649218216
B22: =_xlfn.TRANSLATE(B21,"en","hi") -> श्री लाल चन्द | C22: =_xlfn.TRANSLATE(C21,"en","hi") -> एमटीएस/सिविल | E22: =_xlfn.TRANSLATE(E21,"en","hi") -> नया सर-हिंद
A23: 8 | B23: Shri Sudhir Kumar | C23: MTS/CIVIL | D23: 103257 | E23: NEW KHANNA | F23: 8210018687
B24: =_xlfn.TRANSLATE(B23,"en","hi") -> श्री सुधीर कुमार | C24: =_xlfn.TRANSLATE(C23,"en","hi") -> एमटीएस/सिविल | E24: =_xlfn.TRANSLATE(E23,"en","hi") -> न्यू खन्ना
A25: 9 | B25: Shri Suraj Verma | C25: MTS/CIVIL | D25: 102623 | E25: NEW KHANNA | F25: 9239845014
B26: =_xlfn.TRANSLATE(B25,"en","hi") -> श्री सूरज वर्मा | C26: =_xlfn.TRANSLATE(C25,"en","hi") -> एमटीएस/सिविल | E26: =_xlfn.TRANSLATE(E25,"en","hi") -> न्यू खन्ना
A27: 10 | B27: Shri Amar Molana | C27: MTS/CIVIL | D27: 102460 | E27: NEW CHAWA PAIL | F27: 7788020121
B28: =_xlfn.TRANSLATE(B27,"en","hi") -> श्री अमर मोलाना | C28: =_xlfn.TRANSLATE(C27,"en","hi") -> एमटीएस/सिविल | E28: =_xlfn.TRANSLATE(E27,"en","hi") -> न्यू चावा पेल
A29: 11 | B29: Shri Harpal Singh | C29: SENIOR EXECUTIVE/CIVIL (Re-employed) | D29: 105102 | E29: NEW SHAMBHU | F29: 7340855287
B30: =_xlfn.TRANSLATE(B29,"en","hi") -> श्री हरपाल सिंह | C30: =_xlfn.TRANSLATE(C29,"en","hi") -> वरिष्ठ कार्यकारी/सिविल (पुन: नियोजित) | E30: =_xlfn.TRANSLATE(E29,"en","hi") -> नया शंभू
A31: 12 | B31: Shri Surendera Kumar | C31: SENIOR EXECUTIVE/CIVIL (Re-employed) | D31: 104962 | E31: NEW KHANNA | F31: 7658008725
B32: =_xlfn.TRANSLATE(B31,"en","hi") -> श्री सुरेंद्र कुमार | C32: =_xlfn.TRANSLATE(C31,"en","hi") -> वरिष्ठ कार्यकारी/सिविल (पुन: नियोजित) | E32: =_xlfn.TRANSLATE(E31,"en","hi") -> न्यू खन्ना

Sheet ExMaster_DATA
A1: Staff data under IMSD-SMUN
A2: Sr. No | B2: AWPO ID | C2: Name | D2: Father's Name | E2: Beat No | F2: Km From-To | G2: Contect Number | H2: Designation | I2: Residence | J2: District | K2: Other contect Number | L2: Photo | N2: Email- ID
A3: =ROW()-2 -> 1 | B3: 53863 | C3: Sanjeev Kumar | D3: Joginder Singh | E3: Beat No. 19 | F3: 1164.500 to 1170.535 | G3: 7341182346 | H3: KEYMAN | I3: VPO Khuda Khurd PO Ambala cant | J3: Ambala | K3: 8708557327 | L3: #VALUE! | M3: =_xlfn.IMAGE("https://quickchart.io/qr?size=300&text=" & _xlfn.ENCODEURL( "AWPO ID: " & B3 & CHAR(10) & "Name: " & C3 & CHAR(10) & "Father's Name: " & D3 & CHAR(10) & "Designation: " & H3 & CHAR(10) & "Details: " & E3 & CHAR(10) & "Contact No: " & G3 & CHAR(10) & "Emergency Contact: " & K3 & CHAR(10) & "Important Nos:" & CHAR(10) & "1. Arjun Kumar: +91 77798 60477" & CHAR(10) & "2. Vivek Kumar Azad: +91 88726 71873" )) -> #VALUE!
A4: =ROW()-2 -> 2 | B4: 46490 | C4: Kuldeep Singh | D4: Amarjit Singh | E4: Beat No. 20 | F4: 1170.535 to 1176.01 | G4: 7087352069 | H4: KEYMAN | I4: VPO Sarala kalan | J4: Patiala | K4: 7087052069 | L4: #VALUE! | M4: =_xlfn.IMAGE("https://quickchart.io/qr?size=300&text=" & _xlfn.ENCODEURL( "AWPO ID: " & B4 & CHAR(10) & "Name: " & C4 & CHAR(10) & "Father Name: " & D4 & CHAR(10) & "Designation: " & H4 & CHAR(10) & E4 & CHAR(10) & "Contact No: " & G4 & CHAR(10) & "Emergency Contact No: " & K4 & CHAR(10) & "Important no:" & CHAR(10) & "1. Ajrun kumar +91 77798 60477" & CHAR(10) & "2. Vivek Kumar Azad +91-88726 71873" )) -> #VALUE! | N4: Kuldeepsingh11973@gmail.com
A5: =ROW()-2 -> 3 | B5: 46527 | C5: Bhupal Singh | D5: Harkishan Singh | E5: Beat No. 21 | F5: 1176.0 to 1183.800 | G5: 9465362321 | H5: KEYMAN | I5: #No. -18 Golden Enclave teh Rajpura | J5: Patiala | K5: 6280072537 | L5: #VALUE! | M5: =_xlfn.IMAGE("https://quickchart.io/qr?size=300&text=" & _xlfn.ENCODEURL( "AWPO ID: " & B5 & CHAR(10) & "Name: " & C5 & CHAR(10) & "Father Name: " & D5 & CHAR(10) & "Designation: " & H5 & CHAR(10) & E5 & CHAR(10) & "Contact No: " & G5 & CHAR(10) & "Emergency Contact No: " & K5 & CHAR(10) & "Important no:" & CHAR(10) & "1. Ajrun kumar +91 77798 60477" & CHAR(10) & "2. Vivek Kumar Azad +91-88726 71873" )) -> #VALUE!
A6: =ROW()-2 -> 4 | B6: 50332 | C6: Gurdeep Singh | D6: Harnam SIngh | E6: Beat No. 22 | F6: 1183.800 to 1189.29 | G6: 6239826819 | H6: KEYMAN | I6: VPO Salempur PO Bras | J6: Fategarh Sahib | K6: 6239826819 | L6: #VALUE! | M6: =_xlfn.IMAGE("https://quickchart.io/qr?size=300&text=" & _xlfn.ENCODEURL( "AWPO ID: " & B6 & CHAR(10) & "Name: " & C6 & CHAR(10) & "Father Name: " & D6 & CHAR(10) & "Designation: " & H6 & CHAR(10) & E6 & CHAR(10) & "Contact No: " & G6 & CHAR(10) & "Emergency Contact No: " & K6 & CHAR(10) & "Important no:" & CHAR(10) & "1. Ajrun kumar +91 77798 60477" & CHAR(10) & "2. Vivek Kumar Azad +91-88726 71873" )) -> #VALUE!
A7: =ROW()-2 -> 5 | B7: 46246 | C7: Gurwinder Singh | D7: Labh Singh | E7: Beat No. 23 | F7: 1189.29 to 1195.295 | G7: 9465551335 | H7: KEYMAN | I7: VPO Kasiana PO Chieala | J7: Patiala | K7: 9465251335 8699131335 | L7: #VALUE! | M7: =_xlfn.IMAGE("https://quickchart.io/qr?size=300&text=" & _xlfn.ENCODEURL( "AWPO ID: " & B7 & CHAR(10) & "Name: " & C7 & CHAR(10) & "Father Name: " & D7 & CHAR(10) & "Designation: " & H7 & CHAR(10) & E7 & CHAR(10) & "Contact No: " & G7 & CHAR(10) & "Emergency Contact No: " & K7 & CHAR(10) & "Important no:" & CHAR(10) & "1. Ajrun kumar +91 77798 60477" & CHAR(10) & "2. Vivek Kumar Azad +91-88726 71873" )) -> #VALUE!
A8: =ROW()-2 -> 6 | B8: 53922 | C8: Harwinder Singh | D8: Ram Chand | E8: Beat No. 24 | F8: 1195.06 to 1201.11 | G8: 8847533591 | H8: KEYMAN | I8: Patiala | J8: Fategarh Sahib | K8: 7814469867 | L8: #VALUE! | M8: =_xlfn.IMAGE("https://quickchart.io/qr?size=300&text=" & _xlfn.ENCODEURL( "AWPO ID: " & B8 & CHAR(10) & "Name: " & C8 & CHAR(10) & "Father Name: " & D8 & CHAR(10) & "Designation: " & H8 & CHAR(10) & E8 & CHAR(10) & "Contact No: " & G8 & CHAR(10) & "Emergency Contact No: " & K8 & CHAR(10) & "Important no:" & CHAR(10) & "1. Ajrun kumar +91 77798 60477" & CHAR(10) & "2. Vivek Kumar Azad +91-88726 71873" )) -> #VALUE!
A9: =ROW()-2 -> 7 | B9: 48789 | C9: Avtar Singh | D9: Roshan Singh | E9: Beat No. 25 | F9: 1201.59 to 1207.395 | G9: 9855456186 | H9: KEYMAN | I9: VPO Mahadian | J9: Fategarh Sahib | K9: 9646644017 | L9: #VALUE! | M9: =_xlfn.IMAGE("https://quickchart.io/qr?size=300&text=" & _xlfn.ENCODEURL( "AWPO ID: " & B9 & CHAR(10) & "Name: " & C9 & CHAR(10) & "Father Name: " & D9 & CHAR(10) & "Designation: " & H9 & CHAR(10) & E9 & CHAR(10) & "Contact No: " & G9 & CHAR(10) & "Emergency Contact No: " & K11 & CHAR(10) & "Important no:" & CHAR(10) & "1. Ajrun kumar +91 77798 60477" & CHAR(10) & "2. Vivek Kumar Azad +91-88726 71873" )) -> #VALUE!
A10: =ROW()-2 -> 8 | B10: 53265 | C10: Harwinder Singh | D10: Ramchand | E10: Beat No. 26 | F10: 1207.395 to 1213.195 | G10: 9417462599 | H10: KEYMAN | I10: VPO Malakpur PO Malko majra | J10: Fategarh Sahib | K10: 7009507732 | L10: #VALUE! | M10: =_xlfn.IMAGE("https://quickchart.io/qr?size=300&text=" & _xlfn.ENCODEURL( "AWPO ID: " & B10 & CHAR(10) & "Name: " & C10 & CHAR(10) & "Father Name: " & D10 & CHAR(10) & "Designation: " & H10 & CHAR(10) & E10 & CHAR(10) & "Contact No: " & G10 & CHAR(10) & "Emergency Contact No: " & K10 & CHAR(10) & "Important no:" & CHAR(10) & "1. Ajrun kumar +91 77798 60477" & CHAR(10) & "2. Vivek Kumar Azad +91-88726 71873" )) -> #VALUE! | N10: hs2883633@gmail.com
A11: =ROW()-2 -> 9 | B11: 47127 | C11: Jaswinder Singh | D11: Amar Singh | E11: Beat No.27 | F11: 1217.195 to 1224.895 | G11: 9468647575 | H11: KEYMAN | I11: VPO Majra manna Singh wala PO Khanian teh Amloh | J11: Fategarh Sahib | K11: 9478808855 | L11: #VALUE! | M11: =_xlfn.IMAGE("https://quickchart.io/qr?size=300&text=" & _xlfn.ENCODEURL( "AWPO ID: " & B11 & CHAR(10) & "Name: " & C11 & CHAR(10) & "Father Name: " & D11 & CHAR(10) & "Designation: " & H11 & CHAR(10) & E11 & CHAR(10) & "Contact No: " & G11 & CHAR(10) & "Emergency Contact No: " & K11 & CHAR(10) & "Important no:" & CHAR(10) & "1. Ajrun kumar +91 77798 60477" & CHAR(10) & "2. Vivek Kumar Azad +91-88726 71873" )) -> #VALUE! | N11: jassi2060k@gmail.com
A12: =ROW()-2 -> 10 | B12: 49319 | C12: Jagjeet Singh | D12: Kaka Singh | E12: Beat No. 28 | F12: 1224.89 to 1228.895 | G12: 8290590570 | H12: KEYMAN | I12: VPO Jaspalo | J12: Ludhiana | K12: 8699006787 | L12: #VALUE! | M12: =_xlfn.IMAGE("https://quickchart.io/qr?size=300&text=" & _xlfn.ENCODEURL( "AWPO ID: " & B12 & CHAR(10) & "Name: " & C12 & CHAR(10) & "Father Name: " & D12 & CHAR(10) & "Designation: " & H12 & CHAR(10) & E12 & CHAR(10) & "Contact No: " & G12 & CHAR(10) & "Emergency Contact No: " & K12 & CHAR(10) & "Important no:" & CHAR(10) & "1. Ajrun kumar +91 77798 60477" & CHAR(10) & "2. Vivek Kumar Azad +91-88726 71873" )) -> #VALUE! | N12: Jagjitsingh8383@gmail.Com
A13: =ROW()-2 -> 11 | B13: 53626 | C13: Lakhvir Singh | D13: Surender Singh | E13: Beat No. 29 | F13: 1228.895 to 1232.947 | G13: 9468647575 | H13: KEYMAN | I13: VPO Rajewal teh khanna | J13: Ludhiana | K13: 9815449609 | L13: #VALUE! | M13: =_xlfn.IMAGE("https://quickchart.io/qr?size=300&text=" & _xlfn.ENCODEURL( "AWPO ID: " & B13 & CHAR(10) & "Name: " & C13 & CHAR(10) & "Father Name: " & D13 & CHAR(10) & "Designation: " & H13 & CHAR(10) & E13 & CHAR(10) & "Contact No: " & G13 & CHAR(10) & "Emergency Contact No: " & K13 & CHAR(10) & "Important no:" & CHAR(10) & "1. Ajrun kumar +91 77798 60477" & CHAR(10) & "2. Vivek Kumar Azad +91-88726 71873" )) -> #VALUE! | N13: Lakhveer4481535@gmail.com
A14: =ROW()-2 -> 12 | B14: 48319 | C14: Gurpreet Singh | D14: Darbara Singh | E14: Beat No. 30 | F14: 1232.947 to 1237.0 | G14: 7508648281 | H14: KEYMAN | I14: VPO Ramgarh Teh Amloh | J14: Fategarh Sahib | L14: #VALUE! | M14: =_xlfn.IMAGE("https://quickchart.io/qr?size=300&text=" & _xlfn.ENCODEURL( "AWPO ID: " & B14 & CHAR(10) & "Name: " & C14 & CHAR(10) & "Father Name: " & D14 & CHAR(10) & "Designation: " & H14 & CHAR(10) & E14 & CHAR(10) & "Contact No: " & G14 & CHAR(10) & "Emergency Contact No: " & K14 & CHAR(10) & "Important no:" & CHAR(10) & "1. Ajrun kumar +91 77798 60477" & CHAR(10) & "2. Vivek Kumar Azad +91-88726 71873" )) -> #VALUE! | N14: aujlagopi034@gmail.com
A15: =ROW()-2 -> 13 | B15: 47110 | C15: Kuljeet singh | D15: Bhajan Singh | E15: Beat No. 31 | F15: 1237.0 to 1242.0 | G15: 7973833770 | H15: KEYMAN | I15: VPO Chakohi Teh Khanna | J15: Ludhiana | K15: 6283880187 | L15: #VALUE! | M15: =_xlfn.IMAGE("https://quickchart.io/qr?size=300&text=" & _xlfn.ENCODEURL( "AWPO ID: " & B15 & CHAR(10) & "Name: " & C15 & CHAR(10) & "Father Name: " & D15 & CHAR(10) & "Designation: " & H15 & CHAR(10) & E15 & CHAR(10) & "Contact No: " & G15 & CHAR(10) & "Emergency Contact No: " & K15 & CHAR(10) & "Important no:" & CHAR(10) & "1. Ajrun kumar +91 77798 60477" & CHAR(10) & "2. Vivek Kumar Azad +91-88726 71873" )) -> #VALUE! | N15: Singhkuljit864@gmail.com
A16: =ROW()-2 -> 14 | B16: 46535 | C16: Nirbhai Singh | D16: Mohinder Singh | E16: Beat No. 32 | F16: 1242.0 to 1249.500 | G16: 9855659595 | H16: KEYMAN | I16: Khaira PO Mrhadudhan teh Samrala | J16: Ludhiana | K16: 9814653302 | L16: #VALUE! | M16: =_xlfn.IMAGE("https://quickchart.io/qr?size=300&text=" & _xlfn.ENCODEURL( "AWPO ID: " & B16 & CHAR(10) & "Name: " & C16 & CHAR(10) & "Father Name: " & D16 & CHAR(10) & "Designation: " & H16 & CHAR(10) & E16 & CHAR(10) & "Contact No: " & G16 & CHAR(10) & "Emergency Contact No: " & K17 & CHAR(10) & "Important no:" & CHAR(10) & "1. Ajrun kumar +91 77798 60477" & CHAR(10) & "2. Vivek Kumar Azad +91-88726 71873" )) -> #VALUE!
A17: =ROW()-2 -> 15 | B17: 53628 | C17: Sukhwinder Singh | D17: Mahinder Singh | E17: Beat No. 33 | F17: 1171.981 to 1178.150 | G17: 7508325974 | H17: KEYMAN | I17: VPO Amam nagar PO karhali | J17: Patiala | K17: 8699649317 | L17: #VALUE! | M17: =_xlfn.IMAGE("https://quickchart.io/qr?size=300&text=" & _xlfn.ENCODEURL( "AWPO ID: " & B17 & CHAR(10) & "Name: " & C17 & CHAR(10) & "Father Name: " & D17 & CHAR(10) & "Designation: " & H17 & CHAR(10) & E17 & CHAR(10) & "Contact No: " & G17 & CHAR(10) & "Emergency Contact No: " & K18 & CHAR(10) & "Important no:" & CHAR(10) & "1. Ajrun kumar +91 77798 60477" & CHAR(10) & "2. Vivek Kumar Azad +91-88726 71873" )) -> #VALUE!
A18: =ROW()-2 -> 16 | B18: 53627 | C18: Bikar Singh | D18: Jarnail Singh | E18: Beat No. 34 | F18: 1242.0 to 1249.500 | G18: 9205536128 | H18: KEYMAN | I18: VPO Khamano kalan wrd No. 7 | J18: Fategarh Sahib | K18: 8283941904 | L18: #VALUE! | M18: =_xlfn.IMAGE("https://quickchart.io/qr?size=300&text=" & _xlfn.ENCODEURL( "AWPO ID: " & B18 & CHAR(10) & "Name: " & C18 & CHAR(10) & "Father Name: " & D18 & CHAR(10) & "Designation: " & H18 & CHAR(10) & E18 & CHAR(10) & "Contact No: " & G18 & CHAR(10) & "Emergency Contact No: " & K18 & CHAR(10) & "Important no:" & CHAR(10) & "1. Ajrun kumar +91 77798 60477" & CHAR(10) & "2. Vivek Kumar Azad +91-88726 71873" )) -> #VALUE!
A19: =ROW()-2 -> 17 | B19: 53923 | C19: Balwinder Singh | D19: Gurcharan Singh | E19: Rest | F19: Giver | G19: 913746358 | H19: KEYMAN | I19: VPO Kalewal PO Kheri Noudh singh | J19: Fategarh Sahib | K19: 7087219969 | L19: #VALUE! | M19: =_xlfn.IMAGE("https://quickchart.io/qr?size=300&text=" & _xlfn.ENCODEURL( "AWPO ID: " & B19 & CHAR(10) & "Name: " & C19 & CHAR(10) & "Father Name: " & D19 & CHAR(10) & "Designation: " & H19 & CHAR(10) & E19 & CHAR(10) & "Contact No: " & G19 & CHAR(10) & "Emergency Contact No: " & K19 & CHAR(10) & "Important no:" & CHAR(10) & "1. Ajrun kumar +91 77798 60477" & CHAR(10) & "2. Vivek Kumar Azad +91-88726 71873" )) -> #VALUE! | N19: babbusingh3934@gmail.com
A20: =ROW()-2 -> 18 | B20: 53924 | C20: Harwinder Singh | D20: Sukhdev Singh | E20: Rest | F20: Giver | G20: 9465326270 | H20: KEYMAN | I20: VPO Maru | J20: Patiala | K20: 9814170346 | L20: #VALUE! | M20: =_xlfn.IMAGE("https://quickchart.io/qr?size=300&text=" & _xlfn.ENCODEURL( "AWPO ID: " & B20 & CHAR(10) & "Name: " & C20 & CHAR(10) & "Father Name: " & D20 & CHAR(10) & "Designation: " & H20 & CHAR(10) & E20 & CHAR(10) & "Contact No: " & G20 & CHAR(10) & "Emergency Contact No: " & K20 & CHAR(10) & "Important no:" & CHAR(10) & "1. Ajrun kumar +91 77798 60477" & CHAR(10) & "2. Vivek Kumar Azad +91-88726 71873" )) -> #VALUE! | N20: harwinder8344@gmail.com
A21: =ROW()-2 -> 19 | B21: 12323 | C21: Satnam Singh | D21: Joginder Singh | E21: BR. 108 | F21: ROR-RAJPURA D-Tour | G21: 8295369825 | H21: Br. Watchman | I21: VPO Korwa khurd | J21: Ambala | K21: 9817732424 | L21: #VALUE! | M21: =_xlfn.IMAGE("https://quickchart.io/qr?size=300&text=" & _xlfn.ENCODEURL( "AWPO ID: " & B21 & CHAR(10) & "Name: " & C21 & CHAR(10) & "Father Name: " & D21 & CHAR(10) & "Designation: " & H21 & CHAR(10) & E21 & CHAR(10) & "Contact No: " & G21 & CHAR(10) & "Emergency Contact No: " & K21 & CHAR(10) & "Important no:" & CHAR(10) & "1. Ajrun kumar +91 77798 60477" & CHAR(10) & "2. Vivek Kumar Azad +91-88726 71873" )) -> #VALUE!
A22: =ROW()-2 -> 20 | B22: 12772 | C22: Surinder Singh | D22: Tek Singh | E22: BR. 108 | F22: ROR-RAJPURA D-Tour | G22: 7529026738 | H22: Br. Watchman | I22: Samana Green City | J22: Patiala | K22: 8728850923 | L22: #VALUE! | M22: =_xlfn.IMAGE("https://quickchart.io/qr?size=300&text=" & _xlfn.ENCODEURL( "AWPO ID: " & B22 & CHAR(10) & "Name: " & C22 & CHAR(10) & "Father Name: " & D22 & CHAR(10) & "Designation: " & H22 & CHAR(10) & E22 & CHAR(10) & "Contact No: " & G22 & CHAR(10) & "Emergency Contact No: " & K22 & CHAR(10) & "Important no:" & CHAR(10) & "1. Ajrun kumar +91 77798 60477" & CHAR(10) & "2. Vivek Kumar Azad +91-88726 71873" )) -> #VALUE!
A23: =ROW()-2 -> 21 | B23: 11469 | C23: Jasvir Singh | D23: Ishar Singh | E23: BR. 108 | F23: ROR-RAJPURA D-Tour | G23: 8398036955 | H23: Br. Watchman | I23: Korwa khurd | J23: Ambala | K23: 8397031057 | L23: #VALUE! | M23: =_xlfn.IMAGE("https://quickchart.io/qr?size=300&text=" & _xlfn.ENCODEURL( "AWPO ID: " & B23 & CHAR(10) & "Name: " & C23 & CHAR(10) & "Father Name: " & D23 & CHAR(10) & "Designation: " & H23 & CHAR(10) & E23 & CHAR(10) & "Contact No: " & G23 & CHAR(10) & "Emergency Contact No: " & K23 & CHAR(10) & "Important no:" & CHAR(10) & "1. Ajrun kumar +91 77798 60477" & CHAR(10) & "2. Vivek Kumar Azad +91-88726 71873" )) -> #VALUE!
