Workbook
Name Slicer_Emp_Id: #N/A
Name Slicer_Type_of_leave: #N/A

Sheet Leave Report 2024
B1: Leave Report Emplyee working under APM/Civil/SMUN (Ambala Unit) | K1: EMP-ID | N1: 101518
B2: Session- 2025 | K2: CL | L2: HALF CL | M2: RH | N2: LAP | O2: LHAP | P2: PATERNITY
A3: S.No: | B3: Name of Employee | C3: Emp-Id | D3: Designation | E3: Place of posting | F3: Type of leave | G3: No of days | H3: From | I3: To | J3: Year | K3: 0
A4: =ROW()-3 -> 1 | B4: Shri Vivek Kumar Azad | C4: =IFERROR(VLOOKUP(B4,'Master Sheet 2024'!$B$4:$F$17,2,0),"") -> 101518 | D4: =IFERROR(VLOOKUP(B4,'Master Sheet 2024'!$B$4:$F$17,3,0),"") -> JPM/CIVIL | E4: =IFERROR(VLOOKUP(B4,'Master Sheet 2024'!$B$4:$F$17,4,0),"") -> SMUN | F4: LAP | G4: 5 | H4: 45733 | I4: 45737 | J4: =TEXT(H4,"YYYY") -> 2025 | L4: .
A5: =ROW()-3 -> 2 | B5: Shri Tej Pal | C5: =IFERROR(VLOOKUP(B5,'Master Sheet 2024'!$B$4:$F$17,2,0),"") -> 101686 | D5: =IFERROR(VLOOKUP(B5,'Master Sheet 2024'!$B$4:$F$17,3,0),"") -> Jr. Executive/CIVIL | E5: =IFERROR(VLOOKUP(B5,'Master Sheet 2024'!$B$4:$F$17,4,0),"") -> NSIR | F5: CL | G5: 2 | H5: 45698 | I5: 45699 | J5: =TEXT(H5,"YYYY") -> 2025
A6: =ROW()-3 -> 3 | B6: Shri Tej Pal | C6: =IFERROR(VLOOKUP(B6,'Master Sheet 2024'!$B$4:$F$17,2,0),"") -> 101686 | D6: =IFERROR(VLOOKUP(B6,'Master Sheet 2024'!$B$4:$F$17,3,0),"") -> Jr. Executive/CIVIL | E6: =IFERROR(VLOOKUP(B6,'Master Sheet 2024'!$B$4:$F$17,4,0),"") -> NSIR | F6: CL | G6: 1 | H6: 45701 | I6: 45701 | J6: =TEXT(H6,"YYYY") -> 2025
A7: =ROW()-3 -> 4 | B7: Shri Ved Prakash | C7: =IFERROR(VLOOKUP(B7,'Master Sheet 2024'!$B$4:$F$17,2,0),"") -> 101646 | D7: =IFERROR(VLOOKUP(B7,'Master Sheet 2024'!$B$4:$F$17,3,0),"") -> Executive/CIVIL | E7: =IFERROR(VLOOKUP(B7,'Master Sheet 2024'!$B$4:$F$17,4,0),"") -> KNNN | F7: LAP | G7: 3 | H7: 45754 | I7: 45756 | J7: =TEXT(H7,"YYYY") -> 2025
A8: =ROW()-3 -> 5 | B8: Shri Ranjit Kumar | C8: =IFERROR(VLOOKUP(B8,'Master Sheet 2024'!$B$4:$F$17,2,0),"") -> 103258 | D8: =IFERROR(VLOOKUP(B8,'Master Sheet 2024'!$B$4:$F$17,3,0),"") -> MTS/CIVIL | E8: =IFERROR(VLOOKUP(B8,'Master Sheet 2024'!$B$4:$F$17,4,0),"") -> SMUN | F8: LAP | G8: 10 | H8: 45750 | I8: 45759 | J8: =TEXT(H8,"YYYY") -> 2025
A9: =ROW()-3 -> 6 | B9: Shri Lal Chand | C9: =IFERROR(VLOOKUP(B9,'Master Sheet 2024'!$B$4:$F$17,2,0),"") -> 102924 | D9: =IFERROR(VLOOKUP(B9,'Master Sheet 2024'!$B$4:$F$17,3,0),"") -> MTS/CIVIL | E9: =IFERROR(VLOOKUP(B9,'Master Sheet 2024'!$B$4:$F$17,4,0),"") -> NSIR | F9: LAP | G9: 10 | H9: 45701 | I9: 45710 | J9: =TEXT(H9,"YYYY") -> 2025
A10: =ROW()-3 -> 7 | B10: Shri Surender Kumar | C10: =IFERROR(VLOOKUP(B10,'Master Sheet 2024'!$B$4:$F$17,2,0),"") -> 104962 | D10: =IFERROR(VLOOKUP(B10,'Master Sheet 2024'!$B$4:$F$17,3,0),"") -> Sr. Executive/CIVIL (Re-employed) | E10: =IFERROR(VLOOKUP(B10,'Master Sheet 2024'!$B$4:$F$17,4,0),"") -> KNNN | F10: CL | G10: 2 | H10: 45754 | I10: 45755 | J10: =TEXT(H10,"YYYY") -> 2025
A11: =ROW()-3 -> 8 | B11: Shri Amar Molana | C11: =IFERROR(VLOOKUP(B11,'Master Sheet 2024'!$B$4:$F$17,2,0),"") -> 102460 | D11: =IFERROR(VLOOKUP(B11,'Master Sheet 2024'!$B$4:$F$17,3,0),"") -> MTS/CIVIL | E11: =IFERROR(VLOOKUP(B11,'Master Sheet 2024'!$B$4:$F$17,4,0),"") -> CHAN | F11: LAP | G11: 24 | H11: 45715 | I11: 45738 | J11: =TEXT(H11,"YYYY") -> 2025
A12: =ROW()-3 -> 9 | B12: Shri Amar Molana | C12: =IFERROR(VLOOKUP(B12,'Master Sheet 2024'!$B$4:$F$17,2,0),"") -> 102460 | D12: =IFERROR(VLOOKUP(B12,'Master Sheet 2024'!$B$4:$F$17,3,0),"") -> MTS/CIVIL | E12: =IFERROR(VLOOKUP(B12,'Master Sheet 2024'!$B$4:$F$17,4,0),"") -> CHAN | F12: LHAP | G12: 7 | H12: 45739 | I12: 45745 | J12: =TEXT(H12,"YYYY") -> 2025
A13: =ROW()-3 -> 10 | B13: Shri Vivek Kumar Azad | C13: =IFERROR(VLOOKUP(B13,'Master Sheet 2024'!$B$4:$F$17,2,0),"") -> 101518 | D13: =IFERROR(VLOOKUP(B13,'Master Sheet 2024'!$B$4:$F$17,3,0),"") -> JPM/CIVIL | E13: =IFERROR(VLOOKUP(B13,'Master Sheet 2024'!$B$4:$F$17,4,0),"") -> SMUN | F13: CL | G13: 1 | H13: 14/08/2025 | I13: 14/08/2025 | J13: =TEXT(H13,"YYYY") -> 14/08/2025
A14: =ROW()-3 -> 11 | B14: Shri Gautam Kumar | C14: =IFERROR(VLOOKUP(B14,'Master Sheet 2024'!$B$4:$F$17,2,0),"") -> 103259 | D14: =IFERROR(VLOOKUP(B14,'Master Sheet 2024'!$B$4:$F$17,3,0),"") -> MTS/CIVIL | E14: =IFERROR(VLOOKUP(B14,'Master Sheet 2024'!$B$4:$F$17,4,0),"") -> SMUN | F14: LAP | G14: 4 | H14: 16/07/2025 | I14: 19/07/2025 | J14: =TEXT(H14,"YYYY") -> 16/07/2025
A15: =ROW()-3 -> 12 | B15: Shri Sudhir Kumar | C15: =IFERROR(VLOOKUP(B15,'Master Sheet 2024'!$B$4:$F$17,2,0),"") -> 103257 | D15: =IFERROR(VLOOKUP(B15,'Master Sheet 2024'!$B$4:$F$17,3,0),"") -> MTS/CIVIL | E15: =IFERROR(VLOOKUP(B15,'Master Sheet 2024'!$B$4:$F$17,4,0),"") -> KNNN | F15: LAP | G15: 17 | H15: 29/07/2025 | I15: 14/08/2025 | J15: =TEXT(H15,"YYYY") -> 29/07/2025
A16: =ROW()-3 -> 13 | B16: Shri Sanni Kumar Sharma | C16: =IFERROR(VLOOKUP(B16,'Master Sheet 2024'!$B$4:$F$17,2,0),"") -> 102431 | D16: =IFERROR(VLOOKUP(B16,'Master Sheet 2024'!$B$4:$F$17,3,0),"") -> MTS/CIVIL | E16: =IFERROR(VLOOKUP(B16,'Master Sheet 2024'!$B$4:$F$17,4,0),"") -> SMUN | F16: LAP | G16: 10 | H16: 21/08/2025 | I16: 30/09/2025 | J16: =TEXT(H16,"YYYY") -> 21/08/2025
A17: =ROW()-3 -> 14 | B17: Shri Suraj Verma | C17: =IFERROR(VLOOKUP(B17,'Master Sheet 2024'!$B$4:$F$17,2,0),"") -> 102623 | D17: =IFERROR(VLOOKUP(B17,'Master Sheet 2024'!$B$4:$F$17,3,0),"") -> MTS/CIVIL | E17: =IFERROR(VLOOKUP(B17,'Master Sheet 2024'!$B$4:$F$17,4,0),"") -> KNNN | F17: LAP | G17: 9 | H17: 45817 | I17: 14/09/2025 | J17: =TEXT(H17,"YYYY") -> 2025
A18: =ROW()-3 -> 15 | B18: Shri Harpal Singh | C18: =IFERROR(VLOOKUP(B18,'Master Sheet 2024'!$B$4:$F$17,2,0),"") -> 105102 | D18: =IFERROR(VLOOKUP(B18,'Master Sheet 2024'!$B$4:$F$17,3,0),"") -> Sr. Executive/CIVIL (Re-employed) | E18: =IFERROR(VLOOKUP(B18,'Master Sheet 2024'!$B$4:$F$17,4,0),"") -> SMUN | F18: CL | G18: 4 | H18: 45909 | I18: 13/9/2025 | J18: =TEXT(H18,"YYYY") -> 2025
A19: =ROW()-3 -> 16 | B19: Sh. Dayal Singh (Black-Smith) | C19: =IFERROR(VLOOKUP(B19,'Master Sheet 2024'!$B$4:$F$17,2,0),"") -> 105900 | D19: =IFERROR(VLOOKUP(B19,'Master Sheet 2024'!$B$4:$F$17,3,0),"") -> Jr. Executive/Civil Re-employed | E19: =IFERROR(VLOOKUP(B19,'Master Sheet 2024'!$B$4:$F$17,4,0),"") -> SMUN | F19: CL | G19: 1 | H19: 28/8/2025 | I19: 28/8/2025 | J19: =TEXT(H19,"YYYY") -> 28/8/2025
A20: =ROW()-3 -> 17 | B20: Shri Ranjit Kumar | C20: =IFERROR(VLOOKUP(B20,'Master Sheet 2024'!$B$4:$F$17,2,0),"") -> 103258 | D20: =IFERROR(VLOOKUP(B20,'Master Sheet 2024'!$B$4:$F$17,3,0),"") -> MTS/CIVIL | E20: =IFERROR(VLOOKUP(B20,'Master Sheet 2024'!$B$4:$F$17,4,0),"") -> SMUN | F20: CL | G20: 8 | H20: 21/10/2025 | I20: 29/10/2025 | J20: =TEXT(H20,"YYYY") -> 21/10/2025
A21: =ROW()-3 -> 18 | B21: Shri Ranjit Kumar | C21: =IFERROR(VLOOKUP(B21,'Master Sheet 2024'!$B$4:$F$17,2,0),"") -> 103258 | D21: =IFERROR(VLOOKUP(B21,'Master Sheet 2024'!$B$4:$F$17,3,0),"") -> MTS/CIVIL | E21: =IFERROR(VLOOKUP(B21,'Master Sheet 2024'!$B$4:$F$17,4,0),"") -> SMUN | F21: RH | G21: 2 | H21: 30/10/2025 | I21: 31/10/2025 | J21: =TEXT(H21,"YYYY") -> 30/10/2025
A22: =ROW()-3 -> 19 | B22: Shri Gautam Kumar | C22: =IFERROR(VLOOKUP(B22,'Master Sheet 2024'!$B$4:$F$17,2,0),"") -> 103259 | D22: =IFERROR(VLOOKUP(B22,'Master Sheet 2024'!$B$4:$F$17,3,0),"") -> MTS/CIVIL | E22: =IFERROR(VLOOKUP(B22,'Master Sheet 2024'!$B$4:$F$17,4,0),"") -> SMUN | F22: CL | G22: 3 | H22: 22/10/2025 | I22: 24/10/2025 | J22: =TEXT(H22,"YYYY") -> 22/10/2025
A23: =ROW()-3 -> 20 | B23: Shri Gautam Kumar | C23: =IFERROR(VLOOKUP(B23,'Master Sheet 2024'!$B$4:$F$17,2,0),"") -> 103259 | D23: =IFERROR(VLOOKUP(B23,'Master Sheet 2024'!$B$4:$F$17,3,0),"") -> MTS/CIVIL | E23: =IFERROR(VLOOKUP(B23,'Master Sheet 2024'!$B$4:$F$17,4,0),"") -> SMUN | F23: RH | G23: 2 | H23: 25/10/2025 | I23: 26/10/2025 | J23: =TEXT(H23,"YYYY") -> 25/10/2025
A24: =ROW()-3 -> 21 | C24: =IFERROR(VLOOKUP(B24,'Master Sheet 2024'!$B$4:$F$17,2,0),"") | D24: =IFERROR(VLOOKUP(B24,'Master Sheet 2024'!$B$4:$F$17,3,0),"") | E24: =IFERROR(VLOOKUP(B24,'Master Sheet 2024'!$B$4:$F$17,4,0),"") | J24: =TEXT(H24,"YYYY") -> 1900
A25: =ROW()-3 -> 22 | C25: =IFERROR(VLOOKUP(B25,'Master Sheet 2024'!$B$4:$F$17,2,0),"") | D25: =IFERROR(VLOOKUP(B25,'Master Sheet 2024'!$B$4:$F$17,3,0),"") | E25: =IFERROR(VLOOKUP(B25,'Master Sheet 2024'!$B$4:$F$17,4,0),"") | J25: =TEXT(H25,"YYYY") -> 1900
A26: =ROW()-3 -> 23 | C26: =IFERROR(VLOOKUP(B26,'Master Sheet 2024'!$B$4:$F$17,2,0),"") | D26: =IFERROR(VLOOKUP(B26,'Master Sheet 2024'!$B$4:$F$17,3,0),"") | E26: =IFERROR(VLOOKUP(B26,'Master Sheet 2024'!$B$4:$F$17,4,0),"") | J26: =TEXT(H26,"YYYY") -> 1900
A27: =ROW()-3 -> 24 | C27: =IFERROR(VLOOKUP(B27,'Master Sheet 2024'!$B$4:$F$17,2,0),"") | D27: =IFERROR(VLOOKUP(B27,'Master Sheet 2024'!$B$4:$F$17,3,0),"") | E27: =IFERROR(VLOOKUP(B27,'Master Sheet 2024'!$B$4:$F$17,4,0),"") | J27: =TEXT(H27,"YYYY") -> 1900
A28: =ROW()-3 -> 25 | C28: =IFERROR(VLOOKUP(B28,'Master Sheet 2024'!$B$4:$F$17,2,0),"") | D28: =IFERROR(VLOOKUP(B28,'Master Sheet 2024'!$B$4:$F$17,3,0),"") | E28: =IFERROR(VLOOKUP(B28,'Master Sheet 2024'!$B$4:$F$17,4,0),"") | J28: =TEXT(H28,"YYYY") -> 1900
A29: =ROW()-3 -> 26 | C29: =IFERROR(VLOOKUP(B29,'Master Sheet 2024'!$B$4:$F$17,2,0),"") | D29: =IFERROR(VLOOKUP(B29,'Master Sheet 2024'!$B$4:$F$17,3,0),"") | E29: =IFERROR(VLOOKUP(B29,'Master Sheet 2024'!$B$4:$F$17,4,0),"") | J29: =TEXT(H29,"YYYY") -> 1900
A30: =ROW()-3 -> 27 | C30: =IFERROR(VLOOKUP(B30,'Master Sheet 2024'!$B$4:$F$17,2,0),"") | D30: =IFERROR(VLOOKUP(B30,'Master Sheet 2024'!$B$4:$F$17,3,0),"") | E30: =IFERROR(VLOOKUP(B30,'Master Sheet 2024'!$B$4:$F$17,4,0),"") | J30: =TEXT(H30,"YYYY") -> 1900
A31: =ROW()-3 -> 28 | C31: =IFERROR(VLOOKUP(B31,'Master Sheet 2024'!$B$4:$F$17,2,0),"") | D31: =IFERROR(VLOOKUP(B31,'Master Sheet 2024'!$B$4:$F$17,3,0),"") | E31: =IFERROR(VLOOKUP(B31,'Master Sheet 2024'!$B$4:$F$17,4,0),"") | J31: =TEXT(H31,"YYYY") -> 1900
A32: =ROW()-3 -> 29 | C32: =IFERROR(VLOOKUP(B32,'Master Sheet 2024'!$B$4:$F$17,2,0),"") | D32: =IFERROR(VLOOKUP(B32,'Master Sheet 2024'!$B$4:$F$17,3,0),"") | E32: =IFERROR(VLOOKUP(B32,'Master Sheet 2024'!$B$4:$F$17,4,0),"") | J32: =TEXT(H32,"YYYY") -> 1900
A33: =ROW()-3 -> 30 | C33: =IFERROR(VLOOKUP(B33,'Master Sheet 2024'!$B$4:$F$17,2,0),"") | D33: =IFERROR(VLOOKUP(B33,'Master Sheet 2024'!$B$4:$F$17,3,0),"") | E33: =IFERROR(VLOOKUP(B33,'Master Sheet 2024'!$B$4:$F$17,4,0),"") | J33: =TEXT(H33,"YYYY") -> 1900
A34: =ROW()-3 -> 31 | C34: =IFERROR(VLOOKUP(B34,'Master Sheet 2024'!$B$4:$F$17,2,0),"") | D34: =IFERROR(VLOOKUP(B34,'Master Sheet 2024'!$B$4:$F$17,3,0),"") | E34: =IFERROR(VLOOKUP(B34,'Master Sheet 2024'!$B$4:$F$17,4,0),"") | J34: =TEXT(H34,"YYYY") -> 1900
A35: =ROW()-3 -> 32 | C35: =IFERROR(VLOOKUP(B35,'Master Sheet 2024'!$B$4:$F$17,2,0),"") | D35: =IFERROR(VLOOKUP(B35,'Master Sheet 2024'!$B$4:$F$17,3,0),"") | E35: =IFERROR(VLOOKUP(B35,'Master Sheet 2024'!$B$4:$F$17,4,0),"") | J35: =TEXT(H35,"YYYY") -> 1900
... A49: =ROW()-3 -> 46 | C49: =IFERROR(VLOOKUP(B49,'Master Sheet 2024'!$B$4:$F$17,2,0),"") | D49: =IFERROR(VLOOKUP(B49,'Master Sheet 2024'!$B$4:$F$17,3,0),"") | E49: =IFERROR(VLOOKUP(B49,'Master Sheet 2024'!$B$4:$F$17,4,0),"") | J49: =TEXT(H49,"YYYY") -> 1900
A50: =ROW()-3 -> 47 | B50: Shri Vivek Kumar Azad | C50: =IFERROR(VLOOKUP(B50,'Master Sheet 2024'!$B$4:$F$17,2,0),"") -> 101518 | D50: =IFERROR(VLOOKUP(B50,'Master Sheet 2024'!$B$4:$F$17,3,0),"") -> JPM/CIVIL | E50: =IFERROR(VLOOKUP(B50,'Master Sheet 2024'!$B$4:$F$17,4,0),"") -> SMUN | F50: CL | G50: 1 | H50: 14/08/2025 | I50: 14/08/2025 | J50: =TEXT(H50,"YYYY") -> 14/08/2025
A51: =ROW()-3 -> 48 | B51: Shri Gautam Kumar | C51: =IFERROR(VLOOKUP(B51,'Master Sheet 2024'!$B$4:$F$17,2,0),"") -> 103259 | D51: =IFERROR(VLOOKUP(B51,'Master Sheet 2024'!$B$4:$F$17,3,0),"") -> MTS/CIVIL | E51: =IFERROR(VLOOKUP(B51,'Master Sheet 2024'!$B$4:$F$17,4,0),"") -> SMUN | F51: LAP | G51: 4 | H51: 16/07/2025 | I51: 19/07/2025 | J51: =TEXT(H51,"YYYY") -> 16/07/2025
A52: =ROW()-3 -> 49 | C52: =IFERROR(VLOOKUP(B52,'Master Sheet 2024'!$B$4:$F$17,2,0),"") | D52: =IFERROR(VLOOKUP(B52,'Master Sheet 2024'!$B$4:$F$17,3,0),"") | E52: =IFERROR(VLOOKUP(B52,'Master Sheet 2024'!$B$4:$F$17,4,0),"") | J52: =TEXT(H52,"YYYY") -> 1900
A53: =ROW()-3 -> 50 | C53: =IFERROR(VLOOKUP(B53,'Master Sheet 2024'!$B$4:$F$17,2,0),"") | D53: =IFERROR(VLOOKUP(B53,'Master Sheet 2024'!$B$4:$F$17,3,0),"") | E53: =IFERROR(VLOOKUP(B53,'Master Sheet 2024'!$B$4:$F$17,4,0),"") | J53: =TEXT(H53,"YYYY") -> 1900
...

Sheet Master Sheet 2024
A1: Leave Report Emplyee working under JPM/Civil/SMUN (Ambala Unit)
A2: Session- 2025
A3: S.No: | B3: Name of Employee | C3: Emp-Id | D3: Designation | E3: Posted at | F3: Remark
A4: 1 | B4: Shri Vivek Kumar Azad | C4: 101518 | D4: JPM/CIVIL | E4: SMUN | F4: CL
A5: 2 | B5: Shri Tej Pal | C5: 101686 | D5: Jr. Executive/CIVIL | E5: NSIR | F5: HALF CL
A6: 3 | B6: Shri Ved Prakash | C6: 101646 | D6: Executive/CIVIL | E6: KNNN | F6: RH
A7: 4 | B7: Shri Sanni Kumar Sharma | C7: 102431 | D7: MTS/CIVIL | E7: SMUN | F7: LAP
A8: 5 | B8: Shri Ranjit Kumar | C8: 103258 | D8: MTS/CIVIL | E8: SMUN | F8: LHAP | Q8: =LEN(A4) -> 1
A9: 6 | B9: Shri Gautam Kumar | C9: 103259 | D9: MTS/CIVIL | E9: SMUN | F9: PATERNITY
A10: 7 | B10: Shri Lal Chand | C10: 102924 | D10: MTS/CIVIL | E10: NSIR | F10: TRANSFER LEAVE
A11: 8 | B11: Shri Sudhir Kumar | C11: 103257 | D11: MTS/CIVIL | E11: KNNN
A12: 9 | B12: Shri Suraj Verma | C12: 102623 | D12: MTS/CIVIL | E12: KNNN
A13: 10 | B13: Shri Amar Molana | C13: 102460 | D13: MTS/CIVIL | E13: CHAN
A14: 11 | B14: Shri Harpal Singh | C14: 105102 | D14: Sr. Executive/CIVIL (Re-employed) | E14: SMUN
A15: 12 | B15: Shri Surender Kumar | C15: 104962 | D15: Sr. Executive/CIVIL (Re-employed) | E15: KNNN
A16: 13 | B16: Sh. Dayal Singh (Black-Smith) | C16: 105900 | D16: Jr. Executive/Civil Re-employed | E16: SMUN
A17: 14 | B17: Sh. Swarn Singh (Black-Smith) | C17: 105899 | D17: Sr.Executive/Civil Re-employed | E17: CHAN

Sheet CL CARD-24
F1: Annexure-III
F2: Dedicated Frieght Corridor Corporation of India Limited - CGM/ AMBALA
F3: CASUAL LEAVE/ RH RECORD -2025
F4: S.No: | G4: =VLOOKUP(T9,'Master Sheet 2024'!A4:F17,2,0) -> #N/A | H4: Name of Emp.: | I4: =IFERROR(VLOOKUP(L4,'Master Sheet 2024'!$B$4:$F$17,2,0),"") | K4: Emp. Coade: | L4: 101518 | M4: Designation: | N4: =VLOOKUP(T9,'Master Sheet 2024'!A4:F17,4,0) -> #N/A | O4: Posted at: | P4: =VLOOKUP(T9,'Master Sheet 2024'!A4:F17,5,0) -> #N/A
F6: CL Avialed on | H6: No.of days | I6: Balance | J6: Brief reason for leave | N6: Sig.of Employee | O6: Forwarded by if any | P6: Sanctioned by
F7: From | G7: To | I7: 8
F8: =VLOOKUP('CL CARD-24'!$L$4,'Leave Report 2024'!$A$4:$I$60,7,0) -> #N/A | G8: =VLOOKUP('CL CARD-24'!$L$4,'Leave Report 2024'!$A$4:$I$60,8,0) -> #N/A | H8: =VLOOKUP('CL CARD-24'!$L$4,'Leave Report 2024'!$A$4:$I$60,9,0) -> #N/A | I8: =SUM(I7-H8) -> #N/A
F9: =VLOOKUP('CL CARD-24'!$L$4,'Leave Report 2024'!$A$4:$I$60,7,0) -> #N/A | G9: =VLOOKUP('CL CARD-24'!$L$4,'Leave Report 2024'!$A$4:$I$60,8,0) -> #N/A | H9: =VLOOKUP('CL CARD-24'!$L$4,'Leave Report 2024'!$A$4:$I$60,9,0) -> #N/A | I9: =SUM(I8-H9) -> #N/A | T9: 103259
F10: =VLOOKUP('CL CARD-24'!$L$4,'Leave Report 2024'!$A$4:$I$60,7,0) -> #N/A | G10: =VLOOKUP('CL CARD-24'!$L$4,'Leave Report 2024'!$A$4:$I$60,8,0) -> #N/A | H10: =VLOOKUP('CL CARD-24'!$L$4,'Leave Report 2024'!$A$4:$I$60,9,0) -> #N/A | I10: =SUM(I9-H10) -> #N/A
F11: =VLOOKUP('CL CARD-24'!$L$4,'Leave Report 2024'!$A$4:$I$60,7,0) -> #N/A | G11: =VLOOKUP('CL CARD-24'!$L$4,'Leave Report 2024'!$A$4:$I$60,8,0) -> #N/A | H11: =VLOOKUP('CL CARD-24'!$L$4,'Leave Report 2024'!$A$4:$I$60,9,0) -> #N/A | I11: =SUM(I10-H11) -> #N/A
F12: =VLOOKUP('CL CARD-24'!$L$4,'Leave Report 2024'!$A$4:$I$60,7,0) -> #N/A | G12: =VLOOKUP('CL CARD-24'!$L$4,'Leave Report 2024'!$A$4:$I$60,8,0) -> #N/A | H12: =VLOOKUP('CL CARD-24'!$L$4,'Leave Report 2024'!$A$4:$I$60,9,0) -> #N/A | I12: =SUM(I11-H12) -> #N/A
F13: =VLOOKUP('CL CARD-24'!$L$4,'Leave Report 2024'!$A$4:$I$60,7,0) -> #N/A | G13: =VLOOKUP('CL CARD-24'!$L$4,'Leave Report 2024'!$A$4:$I$60,8,0) -> #N/A | H13: =VLOOKUP('CL CARD-24'!$L$4,'Leave Report 2024'!$A$4:$I$60,9,0) -> #N/A | I13: =SUM(I12-H13) -> #N/A
F14: =VLOOKUP('CL CARD-24'!$L$4,'Leave Report 2024'!$A$4:$I$60,7,0) -> #N/A | G14: =VLOOKUP('CL CARD-24'!$L$4,'Leave Report 2024'!$A$4:$I$60,8,0) -> #N/A | H14: =VLOOKUP('CL CARD-24'!$L$4,'Leave Report 2024'!$A$4:$I$60,9,0) -> #N/A | I14: =SUM(I13-H14) -> #N/A
F15: =VLOOKUP('CL CARD-24'!$L$4,'Leave Report 2024'!$A$4:$I$60,7,0) -> #N/A | G15: =VLOOKUP('CL CARD-24'!$L$4,'Leave Report 2024'!$A$4:$I$60,8,0) -> #N/A | H15: =VLOOKUP('CL CARD-24'!$L$4,'Leave Report 2024'!$A$4:$I$60,9,0) -> #N/A | I15: =SUM(I14-H15) -> #N/A
F16: =VLOOKUP('CL CARD-24'!$L$4,'Leave Report 2024'!$A$4:$I$60,7,0) -> #N/A | G16: =VLOOKUP('CL CARD-24'!$L$4,'Leave Report 2024'!$A$4:$I$60,8,0) -> #N/A | H16: =VLOOKUP('CL CARD-24'!$L$4,'Leave Report 2024'!$A$4:$I$60,9,0) -> #N/A | I16: =SUM(I15-H16) -> #N/A
I27: 2
F28: Restricted Holidays (RH)-02
I29: =SUM(I27-H29) -> 2
I30: =SUM(I29-H30) -> 2
F35: Instructions:
G36: 1. A total of 08 CL and 02 RH shall be admissible year, as per the terms and condition contained in DFCCIL Leave Rules.
G37: 2. This card shall be maintained by the Holder and CL/RH will be sanctioned only in it.
G38: 3.In case of this card, it will be presumed that the holder has availed of all the CL/RH due to him/her.No duplicate card will be issued
N39: Issued by HR/CGM Ajmer Unit on 02.01.2023
