Workbook

Sheet Horizontal Curve List (ML)
H1: LIST OF HORIZONTAL CURVE OF DFC MAIN LINE [EDFC SAHNEWAL - PILKHANI SECTION- 301]
A2: Curve No. | B2: Delta | C2: Radius (m) | D2: Degree of Curve | E2: TTP-1 Spiral Start | F2: CTP-1 Circular Curve Start | G2: CTP-2 Circular Curve End | H2: TTP-2 Spiral End | I2: Straight Length (m) | J2: Transition Length (m) | K2: Circular Length (m) | L2: Applied Cant (mm) | M2: Equilibrium Cant (mm) | N2: Cant Deficiency (mm) | O2: Versine in (mm) | P2: Permissible Speed (km/ph) | Q2: Hand of Curve | R2: Remarks
A3: 1 | B3: 02°18'00" | C3: 2000 | D3: 0.875 | E3: 1076474.5 | F3: 1076534.5 | G3: 1076554.8 | H3: 1076614.8 | I3: =E4-H3 -> 137.3939 | J3: =H3-G3 -> 60 | K3: =G3-F3 -> 20.2828 | L3: 60 | M3: 59 | N3: =M3-L3 -> -1 | O3: =ABS((20^2*125)/C3) -> 25 | P3: 100 | Q3: LHS
A4: 2 | B4: 02°28'07" | C4: 2000 | D4: 0.875 | E4: 1076752.2 | F4: 1076812.2 | G4: 1076838.4 | H4: 1076898.4 | I4: =E5-H4 -> 525.2833 | J4: =H4-G4 -> 60 | K4: =G4-F4 -> 26.1744 | L4: 60 | M4: 59 | N4: =M4-L4 -> -1 | O4: =ABS((20^2*125)/C4) -> 25 | P4: 100 | Q4: RHS
A5: 3 | B5: 01°05'49" | C5: 3500 | D5: 0.5 | E5: 1077423.7 | F5: 1077463.7 | G5: 1077490.7 | H5: 1077530.7 | I5: =E6-H5 -> 374.937 | J5: =H5-G5 -> 40 | K5: =G5-F5 -> 27.0163 | L5: 30 | M5: 33.713 | N5: =M5-L5 -> 3.713 | O5: =ABS((20^2*125)/C5) -> 14.285714 | P5: 100 | Q5: RHS
A6: 4 | B6: 01°05'05" | C6: 7000 | D6: 0.25 | E6: 1077905.6 | F6: 1077925.6 | G6: 1078038.1 | H6: 1078058.1 | I6: =E7-H6 -> 3690.8045 | J6: =H6-G6 -> 20 | K6: =G6-F6 -> 112.5167 | L6: 10 | M6: 16.857 | N6: =M6-L6 -> 6.857 | O6: =ABS((20^2*125)/C6) -> 7.1428571 | P6: 100 | Q6: LHS
A7: 5 | B7: 01°18'49" | C7: 3000 | D7: 0.58333333 | E7: 1081748.9 | F7: 1081788.9 | G7: 1081817.7 | H7: 1081857.7 | I7: =E8-H7 -> 153.1878 | J7: =H7-G7 -> 40 | K7: =G7-F7 -> 28.7737 | L7: 40 | M7: 45.932 | N7: =M7-L7 -> 5.932 | O7: =ABS((20^2*125)/C7) -> 16.666667 | P7: 100 | Q7: RHS
A8: 6 | B8: 03°18'05" | C8: 1750.0003 | D8: 0.99999983 | E8: 1082010.9 | F8: 1082080.9 | G8: 1082111.7 | H8: 1082181.7 | I8: =E9-H8 -> 162.3465 | J8: =H8-G8 -> 70 | K8: =G8-F8 -> 30.8314 | L8: 70 | M8: 78.74 | N8: =M8-L8 -> 8.74 | O8: =ABS((20^2*125)/C8) -> 28.571424 | P8: 100 | Q8: LHS
A9: 7 | B9: 01°55'35" | C9: 2500 | D9: 0.7 | E9: 1082344.1 | F9: 1082394.1 | G9: 1082428.1 | H9: 1082478.1 | I9: =E10-H9 -> 255.4706 | J9: =H9-G9 -> 50 | K9: =G9-F9 -> 34.0556 | L9: 60 | M9: 55.118 | N9: =M9-L9 -> -4.882 | O9: =ABS((20^2*125)/C9) -> 20 | P9: 100 | Q9: RHS
A10: 8 | B10: 01°47'58" | C10: 2500 | D10: 0.7 | E10: 1082733.6 | F10: 1082783.6 | G10: 1082812.1 | H10: 1082862.1 | I10: =E11-H10 -> 261.7136 | J10: =H10-G10 -> 50 | K10: =G10-F10 -> 28.5114 | L10: 50 | M10: 55.118 | N10: =M10-L10 -> 5.118 | O10: =ABS((20^2*125)/C10) -> 20 | P10: 100 | Q10: RHS
A11: 9 | B11: 01°45'12" | C11: 2500 | D11: 0.7 | E11: 1083123.8 | F11: 1083173.8 | G11: 1083200.3 | H11: 1083250.3 | I11: =E12-H11 -> 685.0792 | J11: =H11-G11 -> 50 | K11: =G11-F11 -> 26.4994 | L11: 50 | M11: 55.118 | N11: =M11-L11 -> 5.118 | O11: =ABS((20^2*125)/C11) -> 20 | P11: 100 | Q11: LHS
A12: 10 | B12: 00°51'41" | C12: 5000 | D12: 0.35 | E12: 1083935.4 | F12: 1083975.4 | G12: 1084010.6 | H12: 1084050.6 | I12: =E13-H12 -> 123.9782 | J12: =H12-G12 -> 40 | K12: =G12-F12 -> 35.1735 | L12: 20 | M12: 27.559 | N12: =M12-L12 -> 7.559 | O12: =ABS((20^2*125)/C12) -> 10 | P12: 100 | Q12: LHS
A13: 11 | B13: 00°51'37" | C13: 5000 | D13: 0.35 | E13: 1084174.6 | F13: 1084214.6 | G13: 1084249.6 | H13: 1084289.6 | I13: =E14-H13 -> 227.7116 | J13: =H13-G13 -> 40 | K13: =G13-F13 -> 35.0846 | L13: 20 | M13: 27.559 | N13: =M13-L13 -> 7.559 | O13: =ABS((20^2*125)/C13) -> 10 | P13: 100 | Q13: RHS
A14: 12 | B14: 01°14'58" | C14: 3000 | D14: 0.58333333 | E14: 1084517.4 | F14: 1084557.4 | G14: 1084582.8 | H14: 1084622.8 | I14: =E15-H14 -> 62.0547 | J14: =H14-G14 -> 40 | K14: =G14-F14 -> 25.4197 | L14: 40 | M14: 45.932 | N14: =M14-L14 -> 5.932 | O14: =ABS((20^2*125)/C14) -> 16.666667 | P14: 100 | Q14: RHS
... A74: 72 | B74: 11°40'25" | C74: 1750.0003 | D74: 0.99999983 | E74: 1147068.4 | F74: 1147138.4 | G74: 1147424.9 | H74: 1147494.9 | I74: =E75-H74 -> 433.3187 | J74: =H74-G74 -> 70 | K74: =G74-F74 -> 286.5502 | L74: 70 | M74: 78.736 | N74: =M74-L74 -> 8.736 | O74: =ABS((20^2*125)/C74) -> 28.571424 | P74: 100 | Q74: RHS
A75: 73 | B75: 65°35'05" | C75: 701 | D75: 2.4964337 | E75: 1147928.3 | F75: 1148088.3 | G75: 1148730.5 | H75: 1148890.5 | I75: =E76-H75 -> 455.26 | J75: =H75-G75 -> 160 | K75: =G75-F75 -> 642.2538 | L75: 165 | M75: 196.845 | N75: =M75-L75 -> 31.845 | O75: =ABS((20^2*125)/C75) -> 71.326676 | P75: 100 | Q75: LHS | R75: Ambala Detour
A76: 74 | B76: 108°49'30" | C76: 700.08 | D76: 2.4997143 | E76: 1149345.8 | F76: 1149505.8 | G76: 1150675.3 | H76: 1150835.3 | I76: =E77-H76 -> 373.33 | J76: =H76-G76 -> 160 | K76: =G76-F76 -> 1169.5414 | L76: 165 | M76: 196.707 | N76: =M76-L76 -> 31.707 | O76: =ABS((20^2*125)/C76) -> 71.420409 | P76: 100 | Q76: RHS
A77: 75 | B77: 63°32'08" | C77: 700 | D77: 2.5 | E77: 1151208.6 | F77: 1151368.6 | G77: 1151984.9 | H77: 1152144.9 | I77: =E78-H77 -> 177.9528 | J77: =H77-G77 -> 160 | K77: =G77-F77 -> 616.2327 | L77: 165 | M77: 196.528 | N77: =M77-L77 -> 31.528 | O77: =ABS((20^2*125)/C77) -> 71.428571 | P77: 100 | Q77: LHS
A78: 76 | B78: 00°27'53" | C78: 9999.9999 | D78: 0.175 | E78: 1152322.8 | F78: 1152352.8 | G78: 1152403.9 | H78: 1152433.9 | I78: =E79-H78 -> 101.2352 | J78: =H78-G78 -> 30 | K78: =G78-F78 -> 51.1001 | L78: 10 | M78: 13.61 | N78: =M78-L78 -> 3.61 | O78: =ABS((20^2*125)/C78) -> 5.0000001 | P78: 100 | Q78: RHS
A79: 77 | B79: 00°27'53" | C79: 10000 | D79: 0.175 | E79: 1152535.2 | F79: 1152565.2 | G79: 1152616.3 | H79: 1152646.3 | I79: =E80-H79 -> 1037.1291 | J79: =H79-G79 -> 30 | K79: =G79-F79 -> 51.1001 | L79: 10 | M79: 13.61 | N79: =M79-L79 -> 3.61 | O79: =ABS((20^2*125)/C79) -> 5 | P79: 100 | Q79: LHS
A80: 78 | B80: 01°12'13" | C80: 3500 | D80: 0.5 | E80: 1153683.4 | F80: 1153723.4 | G80: 1153756.9 | H80: 1153796.9 | I80: =E81-H80 -> 270.525 | J80: =H80-G80 -> 40 | K80: =G80-F80 -> 33.5254 | L80: 30 | M80: 39.006 | N80: =M80-L80 -> 9.006 | O80: =ABS((20^2*125)/C80) -> 14.285714 | P80: 100 | Q80: RHS
A81: 79 | B81: 00°33'32" | C81: 12000 | D81: 0.14583333 | E81: 1154067.4 | F81: 1154087.4 | G81: 1154184.5 | H81: 1154204.5 | I81: =E82-H81 -> 697.3826 | J81: =H81-G81 -> 20 | K81: =G81-F81 -> 97.027 | L81: 10 | M81: 11.27 | N81: =M81-L81 -> 1.27 | O81: =ABS((20^2*125)/C81) -> 4.1666667 | P81: 100 | Q81: RHS
A82: 80 | B82: 00°38'01" | C82: 10000 | D82: 0.175 | E82: 1154901.8 | F82: 1154921.8 | G82: 1155012.4 | H82: 1155032.4 | I82: =E83-H82 -> 60.3662 | J82: =H82-G82 -> 20 | K82: =G82-F82 -> 90.5824 | L82: 10 | M82: 13.525 | N82: =M82-L82 -> 3.525 | O82: =ABS((20^2*125)/C82) -> 5 | P82: 100 | Q82: LHS
A83: 81 | B83: 01°50'55" | C83: 2500 | D83: 0.7 | E83: 1155092.8 | F83: 1155142.8 | G83: 1155173.5 | H83: 1155223.5 | I83: =E84-H83 -> 68.3512 | J83: =H83-G83 -> 50 | K83: =G83-F83 -> 30.6584 | L83: 50 | M83: 54.715 | N83: =M83-L83 -> 4.715 | O83: =ABS((20^2*125)/C83) -> 20 | P83: 100 | Q83: LHS
A84: 82 | B84: 01°51'28" | C84: 2250 | D84: 0.77777778 | E84: 1155291.8 | F84: 1155341.8 | G84: 1155364.8 | H84: 1155414.8 | I84: =E85-H84 -> 2345.6809 | J84: =H84-G84 -> 50 | K84: =G84-F84 -> 22.956 | L84: 50 | M84: 60.787 | N84: =M84-L84 -> 10.787 | O84: =ABS((20^2*125)/C84) -> 22.222222 | P84: 100 | Q84: RHS
A85: 83 | B85: 00°33'46" | C85: 8099.9999 | D85: 0.21604939 | E85: 1157760.4 | F85: 1157790.4 | G85: 1157840 | H85: 1157870 | I85: =E86-H85 -> 55.784 | J85: =H85-G85 -> 30 | K85: =G85-F85 -> 49.5504 | L85: 10 | M85: 16.802 | N85: =M85-L85 -> 6.802 | O85: =ABS((20^2*125)/C85) -> 6.1728396 | P85: 100 | Q85: LHS
A86: 84 | B86: 00°32'26" | C86: 7000.0001 | D86: 0.25 | E86: 1157925.8 | F86: 1157965.8 | G86: 1157991.8 | H86: 1158031.8 | I86: =E87-H86 -> 151.9676 | J86: =H86-G86 -> 40 | K86: =G86-F86 -> 26.027 | L86: 10 | M86: 19.502 | N86: =M86-L86 -> 9.502 | O86: =ABS((20^2*125)/C86) -> 7.142857 | P86: 100 | Q86: RHS
A87: 85 | B87: 01°08'10" | C87: 4000 | D87: 0.4375 | E87: 1158183.8 | F87: 1158213.8 | G87: 1158263.1 | H87: 1158293.1 | I87: =E88-H87 -> 60.6749 | J87: =H87-G87 -> 30 | K87: =G87-F87 -> 49.3162 | L87: 30 | M87: 34.024 | N87: =M87-L87 -> 4.024 | O87: =ABS((20^2*125)/C87) -> 12.5 | P87: 100 | Q87: RHS
... A107: 105 | B107: 00°32'21" | C107: 10000 | D107: 0.175 | E107: 1173227.7 | F107: 1173247.7 | G107: 1173321.8 | H107: 1173341.8 | I107: =E108-H107 -> 1484.7109 | J107: =H107-G107 -> 20 | K107: =G107-F107 -> 74.0839 | L107: 10 | M107: 13.525 | N107: =M107-L107 -> 3.525 | O107: =ABS((20^2*125)/C107) -> 5 | P107: 100 | Q107: LHS
A108: 106 | B108: 14°21'53" | C108: 800 | D108: 2.1875 | E108: 1174826.5 | F108: 1174966.5 | G108: 1175027.1 | H108: 1175167.1 | I108: =E109-H108 -> 53.641 | J108: =H108-G108 -> 140 | K108: =G108-F108 -> 60.5678 | L108: 165 | M108: 171.787 | N108: =M108-L108 -> 6.787 | O108: =ABS((20^2*125)/C108) -> 62.5 | P108: 100 | Q108: LHS | R108: Rajpura Detour
A109: 107 | B109: 42°03'37" | C109: 700.0069 | D109: 2.4999754 | E109: 1175220.7 | F109: 1175300.7 | G109: 1175734.6 | H109: 1175814.6 | I109: =E110-H109 -> 179.4867 | J109: =H109-G109 -> 80 | K109: =G109-F109 -> 433.8668 | L109: 150 | M109: 195.915 | N109: =M109-L109 -> 45.915 | O109: =ABS((20^2*125)/C109) -> 71.427867 | P109: 100 | Q109: RHS
A110: 108 | B110: 32°25'13" | C110: 700.0069 | D110: 2.4999754 | E110: 1175994 | F110: 1176074 | G110: 1176390.1 | H110: 1176470.1 | I110: =E111-H110 -> 784.1791 | J110: =H110-G110 -> 80 | K110: =G110-F110 -> 316.091 | L110: 150 | M110: 195.904 | N110: =M110-L110 -> 45.904 | O110: =ABS((20^2*125)/C110) -> 71.427867 | P110: 100 | Q110: LHS
A111: 109 | B111: 08°50'12" | C111: 4000 | D111: 0.4375 | E111: 1177254.3 | F111: 1177284.3 | G111: 1177871.2 | H111: 1177901.2 | I111: =E112-H111 -> 153.7197 | J111: =H111-G111 -> 30 | K111: =G111-F111 -> 586.9236 | L111: 30 | M111: 34.004 | N111: =M111-L111 -> 4.004 | O111: =ABS((20^2*125)/C111) -> 12.5 | P111: 100 | Q111: RHS
A112: 110 | B112: 01°32'37" | C112: 3500 | D112: 0.5 | E112: 1178055 | F112: 1178095 | G112: 1178149.3 | H112: 1178189.3 | I112: =E113-H112 -> 524.8252 | J112: =H112-G112 -> 40 | K112: =G112-F112 -> 54.2983 | L112: 30 | M112: 38.99 | N112: =M112-L112 -> 8.99 | O112: =ABS((20^2*125)/C112) -> 14.285714 | P112: 100 | Q112: LHS
A113: 111 | B113: 03°41'05" | C113: 1700.0003 | D113: 1.0294116 | E113: 1178714.1 | F113: 1178784.1 | G113: 1178823.4 | H113: 1178893.4 | I113: =E114-H113 -> 54.1594 | J113: =H113-G113 -> 70 | K113: =G113-F113 -> 39.3288 | L113: 80 | M113: 80.607 | N113: =M113-L113 -> 0.607 | O113: =ABS((20^2*125)/C113) -> 29.41176 | P113: 100 | Q113: RHS
A114: 112 | B114: 04°34'48" | C114: 1750.0003 | D114: 0.99999983 | E114: 1178947.6 | F114: 1179017.6 | G114: 1179087.5 | H114: 1179157.5 | I114: =E115-H114 -> 627.5532 | J114: =H114-G114 -> 70 | K114: =G114-F114 -> 69.8874 | L114: 70 | M114: 78.304 | N114: =M114-L114 -> 8.304 | O114: =ABS((20^2*125)/C114) -> 28.571424 | P114: 100 | Q114: LHS
A115: 113 | B115: 02°02'50" | C115: 2500 | D115: 0.7 | E115: 1179785 | F115: 1179835 | G115: 1179874.3 | H115: 1179924.3 | I115: =E116-H115 -> 137.1455 | J115: =H115-G115 -> 50 | K115: =G115-F115 -> 39.3274 | L115: 50 | M115: 54.693 | N115: =M115-L115 -> 4.693 | O115: =ABS((20^2*125)/C115) -> 20 | P115: 100 | Q115: LHS
A116: 114 | B116: 01°39'40" | C116: 7000 | D116: 0.25 | E116: 1180061.5 | F116: 1180081.5 | G116: 1180264.4 | H116: 1180284.4 | I116: =E117-H116 -> 393.7497 | J116: =H116-G116 -> 20 | K116: =G116-F116 -> 182.9263 | L116: 20 | M116: 19.305 | N116: =M116-L116 -> -0.695 | O116: =ABS((20^2*125)/C116) -> 7.1428571 | P116: 100 | Q116: RHS
A117: 115 | B117: 00°47'45" | C117: 4499.9999 | D117: 0.3888889 | E117: 1180678.2 | F117: 1180708.2 | G117: 1180740.7 | H117: 1180770.7 | I117: =E118-H117 -> 83.4928 | J117: =H117-G117 -> 30 | K117: =G117-F117 -> 32.496 | L117: 30 | M117: 30.578 | N117: =M117-L117 -> 0.578 | O117: =ABS((20^2*125)/C117) -> 11.111111 | P117: 100 | Q117: LHS
A118: 116 | B118: 00°47'45" | C118: 5800 | D118: 0.30172414 | E118: 1180854.1 | F118: 1180874.1 | G118: 1180934.7 | H118: 1180954.7 | I118: =E119-H118 -> 229.2865 | J118: =H118-G118 -> 20 | K118: =G118-F118 -> 60.5504 | L118: 20 | M118: 23.724 | N118: =M118-L118 -> 3.724 | O118: =ABS((20^2*125)/C118) -> 8.6206897 | P118: 100 | Q118: RHS
...

Sheet  Curve List for Drg.
A1: DETAIL OF DFC CURVE
A2: CURVE NO. | B2: DEF.ANGLE | C2: DEGREE | D2: RADIUS(M) | E2: CCL(M) | F2: TTL/TL (M) | G2: TRL(M) | H2: SPEED (Vmax) | I2: Ca. (mm) | J2: Cd. (mm) | K2: Hand of Curve
A3: 1 | B3: ='Horizontal Curve List (ML)'!B3 -> 02°18'00" | C3: 0.875° | D3: 2000 | E3: 20.2828 | G3: 60 | H3: 100 | I3: 60 | J3: 1 | K3: LH
A4: 2 | B4: ='Horizontal Curve List (ML)'!B4 -> 02°28'07" | C4: 0.875° | D4: 2000 | E4: 26.1744 | G4: 60 | H4: 100 | I4: 60 | J4: 1 | K4: RH
A5: 3 | B5: ='Horizontal Curve List (ML)'!B5 -> 01°05'49" | C5: 0.5° | D5: 3500 | E5: 27.0163 | G5: 40 | H5: 100 | I5: 30 | J5: 3.713 | K5: RH
A6: 4 | B6: ='Horizontal Curve List (ML)'!B6 -> 01°05'05" | C6: 0.25° | D6: 7000 | E6: 112.5167 | G6: 20 | H6: 100 | I6: 10 | J6: 6.857 | K6: LH
A7: 5 | B7: ='Horizontal Curve List (ML)'!B7 -> 01°18'49" | C7: 0.583° | D7: 3000 | E7: 28.7737 | G7: 40 | H7: 100 | I7: 40 | J7: 5.932 | K7: RH
A8: 6 | B8: ='Horizontal Curve List (ML)'!B8 -> 03°18'05" | C8: 1° | D8: 1750.0003 | E8: 30.8314 | G8: 70 | H8: 100 | I8: 70 | J8: 8.74 | K8: LH
A9: 7 | B9: ='Horizontal Curve List (ML)'!B9 -> 01°55'35" | C9: 0.7° | D9: 2500 | E9: 34.0556 | G9: 50 | H9: 100 | I9: 60 | J9: 4.882 | K9: RH
A10: 8 | B10: ='Horizontal Curve List (ML)'!B10 -> 01°47'58" | C10: 0.7° | D10: 2500 | E10: 28.5114 | G10: 50 | H10: 100 | I10: 50 | J10: 5.118 | K10: RH
A11: 9 | B11: ='Horizontal Curve List (ML)'!B11 -> 01°45'12" | C11: 0.7° | D11: 2500 | E11: 26.4994 | G11: 50 | H11: 100 | I11: 50 | J11: 5.118 | K11: LH
A12: 10 | B12: ='Horizontal Curve List (ML)'!B12 -> 00°51'41" | C12: 0.35° | D12: 5000 | E12: 35.1735 | G12: 40 | H12: 100 | I12: 20 | J12: 7.559 | K12: LH
A13: 11 | B13: ='Horizontal Curve List (ML)'!B13 -> 00°51'37" | C13: 0.35° | D13: 5000 | E13: 35.0846 | G13: 40 | H13: 100 | I13: 20 | J13: 7.559 | K13: RH
A14: 12 | B14: ='Horizontal Curve List (ML)'!B14 -> 01°14'58" | C14: 0.583° | D14: 3000 | E14: 25.4197 | G14: 40 | H14: 100 | I14: 40 | J14: 5.932 | K14: RH
... A66: 64 | B66: ='Horizontal Curve List (ML)'!B66 -> 00°29'56" | C66: 0.219° | D66: 7999.9999 | E66: 49.677 | G66: 20 | H66: 100 | I66: 10 | J66: 7.221 | K66: LH
A67: 65 | B67: ='Horizontal Curve List (ML)'!B67 -> 03°16'22" | C67: 0.972° | D67: 1800.0002 | E67: 32.8139 | G67: 70 | H67: 100 | I67: 70 | J67: 6.549 | K67: LH | L67: New Dukheri Yard'
A68: 66 | B68: ='Horizontal Curve List (ML)'!B68 -> 04°03'25" | C68: 1.167° | D68: 1500.0007 | E68: 26.2079 | G68: 80 | H68: 100 | I68: 90 | J68: 1.86 | K68: RH
A69: 67 | B69: ='Horizontal Curve List (ML)'!B69 -> 02°25'47" | C69: 0.7° | D69: 2500 | E69: 56.0155 | G69: 50 | H69: 100 | I69: 50 | J69: 5.118 | K69: LH
A70: 68 | B70: ='Horizontal Curve List (ML)'!B70 -> 02°02'07" | C70: 0.632° | D70: 2770 | E70: 58.3953 | G70: 40 | H70: 100 | I70: 40 | J70: 9.744 | K70: LH
A71: 69 | B71: ='Horizontal Curve List (ML)'!B71 -> 04°01'16" | C71: 1.094° | D71: 1600.0003 | E71: 42.2939 | G71: 70 | H71: 100 | I71: 80 | J71: 6.117 | K71: RH
A72: 70 | B72: ='Horizontal Curve List (ML)'!B72 -> 04°39'40" | C72: 1° | D72: 1750.0003 | E72: 72.3675 | G72: 70 | H72: 100 | I72: 70 | J72: 8.736 | K72: RH
A73: 71 | B73: ='Horizontal Curve List (ML)'!B73 -> 03°15'59" | C73: 0.875° | D73: 2000 | E73: 54.0225 | G73: 60 | H73: 100 | I73: 60 | J73: 8.894 | K73: RH
A74: 72 | B74: ='Horizontal Curve List (ML)'!B74 -> 11°40'25" | C74: 1° | D74: 1750.0003 | E74: 286.5502 | G74: 70 | H74: 100 | I74: 70 | J74: 8.736 | K74: RH
A75: 73 | B75: ='Horizontal Curve List (ML)'!B75 -> 65°35'05" | C75: 2.496° | D75: 701 | E75: 642.2538 | G75: 160 | H75: 100 | I75: 165 | J75: 31.845 | K75: LH
A76: 74 | B76: ='Horizontal Curve List (ML)'!B76 -> 108°49'30" | C76: 2.5° | D76: 700.08 | E76: 1169.5414 | G76: 160 | H76: 100 | I76: 165 | J76: 31.707 | K76: RH
A77: 75 | B77: ='Horizontal Curve List (ML)'!B77 -> 63°32'08" | C77: 2.5° | D77: 700 | E77: 616.2327 | G77: 160 | H77: 100 | I77: 165 | J77: 31.528 | K77: LH
A78: 76 | B78: ='Horizontal Curve List (ML)'!B78 -> 00°27'53" | C78: 0.175° | D78: 9999.9999 | E78: 51.1001 | G78: 30 | H78: 100 | I78: 10 | J78: 3.61 | K78: RH
A79: 77 | B79: ='Horizontal Curve List (ML)'!B79 -> 00°27'53" | C79: 0.175° | D79: 10000 | E79: 51.1001 | G79: 30 | H79: 100 | I79: 10 | J79: 3.61 | K79: LH
... A98: 96 | B98: ='Horizontal Curve List (ML)'!B98 -> 03°41'39" | C98: 1° | D98: 1750.0003 | E98: 42.8354 | G98: 70 | H98: 100 | I98: 70 | J98: 8.322 | K98: LH
A99: 97 | B99: ='Horizontal Curve List (ML)'!B99 -> 00°39'09" | C99: 0.175° | D99: 10000 | E99: 93.8696 | G99: 20 | H99: 100 | I99: 10 | J99: 3.53 | K99: RH | L99: New Shambhu
A100: 98 | B100: ='Horizontal Curve List (ML)'!B100 -> 01°14'50" | C100: 0.438° | D100: 4000 | E100: 57.0634 | G100: 30 | H100: 100 | I100: 30 | J100: 4.024 | K100: LH
A101: 99 | B101: ='Horizontal Curve List (ML)'!B101 -> 00°38'07" | C101: 0.25° | D101: 7000 | E101: 47.617 | G101: 30 | H101: 100 | I101: 10 | J101: 9.442 | K101: RH
A102: 100 | B102: ='Horizontal Curve List (ML)'!B102 -> 03°00'49" | C102: 1° | D102: 1750.0003 | E102: 22.0455 | G102: 70 | H102: 100 | I102: 70 | J102: 8.322 | K102: LH
A103: 101 | B103: ='Horizontal Curve List (ML)'!B103 -> 03°36'44" | C103: 0.5° | D103: 3500 | E103: 180.6645 | G103: 40 | H103: 100 | I103: 30 | J103: 9.005 | K103: RH
A104: 102 | B104: ='Horizontal Curve List (ML)'!B104 -> 00°35'42" | C104: 0.292° | D104: 5999.9999 | E104: 22.299 | G104: 40 | H104: 100 | I104: 20 | J104: 2.753 | K104: LH
A105: 103 | B105: ='Horizontal Curve List (ML)'!B105 -> 00°45'16" | C105: 0.35° | D105: 5000.0001 | E105: 25.8285 | G105: 40 | H105: 100 | I105: 20 | J105: 7.304 | K105: LH
A106: 104 | B106: ='Horizontal Curve List (ML)'!B106 -> 00°45'16" | C106: 0.35° | D106: 5000 | E106: 25.8285 | G106: 40 | H106: 100 | I106: 20 | J106: 7.304 | K106: RH
A107: 105 | B107: ='Horizontal Curve List (ML)'!B107 -> 00°32'21" | C107: 0.175° | D107: 10000 | E107: 74.0839 | G107: 20 | H107: 100 | I107: 10 | J107: 3.525 | K107: LH
A108: 106 | B108: ='Horizontal Curve List (ML)'!B108 -> 14°21'53" | C108: 2.188° | D108: 800 | E108: 60.5678 | G108: 140 | H108: 100 | I108: 165 | J108: 6.787 | K108: LH
A109: 107 | B109: ='Horizontal Curve List (ML)'!B109 -> 42°03'37" | C109: 2.5° | D109: 700.0069 | E109: 433.8668 | G109: 80 | H109: 100 | I109: 150 | J109: 45.915 | K109: RH
...
