Workbook
Name Excel_BuiltIn_Print_Titles: 'Old LS-Reports'!$B$1:$IV$3
Name HTML_1: NA()
Name HTML_2: NA()
Name HTML_all: NA()
Name HTML_tables: NA()

Sheet Old LS-Reports
B1: DFCC_301_L_Section Report from IR KM : 282-289 kms (Linked Line)
A2: DFCC Chainage | B2: Station | C2: Existing | G2: DFCC Chainage | H2: Track Center | I2: Proposed | M2: PRL-ERL | N2: PFL-EFL | O2: Left Toe | Q2: Right Toe | S2: Natural Ground Levels | T2: Cut/Fill (PFL-GL) | U2: Cut/Fill (PFL- Left Toe Level) | V2: Cut/Fill (PFL- Right Toe Level)
C3: Northing | D3: Easting | E3: ERL | F3: EFL | I3: Northing | J3: Easting | K3: PFL | L3: PRL | O3: Offset | P3: Level | Q3: Offset | R3: Level
A4: =G4 -> 91255.985 | B4: =282255-1.6748 -> 282253.33 | C4: 3369307.3 | D4: 659129.3 | E4: 270.48735 | F4: =E4-0.688 -> 269.79935 | G4: 91255.985 | H4: -10.564108 | I4: 3369298.7 | J4: 659123.21 | K4: 270.54029 | L4: 271.28229 | M4: =+K4-E4 -> 0.0529393 | N4: =+L4-F4 -> 1.4829393 | O4: -9.3996 | P4: 267.61381 | Q4: 5.1578 | R4: 269.73472 | S4: 268.3306 | T4: =K4-S4 -> 2.2096828 | U4: =L4-P4 -> 3.6684776 | V4: =L4-R4 -> 1.5475632 | W4: =VLOOKUP(B4,[1]CivilReport!$A$2:$E$342,5,FALSE)-H4 -> -0.000892
A5: =G5 -> 91262.659 | B5: 282260 | C5: 3369311.1 | D5: 659123.84 | E5: 270.47779 | F5: =E5-0.688 -> 269.78979 | G5: 91262.659 | H5: -10.562917 | I5: 3369302.5 | J5: 659117.75 | K5: 270.54169 | L5: 271.28369 | M5: =+K5-E5 -> 0.0639004 | N5: =+L5-F5 -> 1.4939004 | O5: -9.2271763 | P5: 267.70144 | Q5: 5.2443634 | R5: 269.69284 | S5: 268.70097 | T5: =K5-S5 -> 1.8407201 | U5: =L5-P5 -> 3.5822548 | V5: =L5-R5 -> 1.5908483 | W5: =VLOOKUP(B5,[1]CivilReport!$A$2:$E$342,5,FALSE)-H5 -> -8.35e-05
A6: =G6 -> 91282.663 | B6: 282280 | C6: 3369322.7 | D6: 659107.49 | E6: 270.44567 | F6: =E6-0.688 -> 269.75767 | G6: 91282.663 | H6: -10.566157 | I6: 3369314 | J6: 659101.4 | K6: 270.54591 | L6: 271.28791 | M6: =+K6-E6 -> 0.1002341 | N6: =+L6-F6 -> 1.5302341 | O6: -9.568242 | P6: 267.53512 | Q6: 5.2355211 | R6: 269.70148 | S6: 268.81865 | T6: =K6-S6 -> 1.7272571 | U6: =L6-P6 -> 3.7527877 | V6: =L6-R6 -> 1.5864273 | W6: =VLOOKUP(B6,[1]CivilReport!$A$2:$E$342,5,FALSE)-H6 -> 0.0001571
A7: =G7 -> 91302.662 | B7: 282300 | C7: 3369334.2 | D7: 659091.15 | E7: 270.41562 | F7: =E7-0.688 -> 269.72762 | G7: 91302.662 | H7: -10.569928 | I7: 3369325.6 | J7: 659085.06 | K7: 270.55019 | L7: 271.29219 | M7: =+K7-E7 -> 0.1345681 | N7: =+L7-F7 -> 1.5645681 | O7: -10.242247 | P7: 267.203 | Q7: 5.200746 | R7: 269.72375 | S7: 268.61623 | T7: =K7-S7 -> 1.9339559 | U7: =L7-P7 -> 4.0891888 | V7: =L7-R7 -> 1.5684381 | W7: =VLOOKUP(B7,[1]CivilReport!$A$2:$E$342,5,FALSE)-H7 -> -7.24e-05
A8: =G8 -> 91322.662 | B8: 282320 | C8: 3369345.7 | D8: 659074.8 | E8: 270.41024 | F8: =E8-0.688 -> 269.72224 | G8: 91322.662 | H8: -10.571623 | I8: 3369337.1 | J8: 659068.71 | K8: 270.56264 | L8: 271.30464 | M8: =+K8-E8 -> 0.1524056 | N8: =+L8-F8 -> 1.5824056 | O8: -11.065498 | P8: 266.80323 | Q8: 5.4278813 | R8: 269.62204 | S8: 267.97099 | T8: =K8-S8 -> 2.5916573 | U8: =L8-P8 -> 4.5014157 | V8: =L8-R8 -> 1.6826073 | W8: =VLOOKUP(B8,[1]CivilReport!$A$2:$E$342,5,FALSE)-H8 -> 0.0006226
A9: =G9 -> 91342.675 | B9: 282340 | C9: 3369357.3 | D9: 659058.47 | E9: 270.41059 | F9: =E9-0.688 -> 269.72259 | G9: 91342.675 | H9: -10.597033 | I9: 3369348.6 | J9: 659052.35 | K9: 270.58072 | L9: 271.32272 | M9: =+K9-E9 -> 0.1701295 | N9: =+L9-F9 -> 1.6001295 | O9: -10.801967 | P9: 266.95307 | Q9: 5.4815567 | R9: 269.61327 | S9: 268.618 | T9: =K9-S9 -> 1.9627226 | U9: =L9-P9 -> 4.36965 | V9: =L9-R9 -> 1.709445 | W9: =VLOOKUP(B9,[1]CivilReport!$A$2:$E$342,5,FALSE)-H9 -> 3.33e-05
A10: =G10 -> 91362.633 | B10: 282360 | C10: 3369368.8 | D10: 659042.13 | E10: 270.40493 | F10: =E10-0.688 -> 269.71693 | G10: 91362.633 | H10: -10.597217 | I10: 3369360.1 | J10: 659036.04 | K10: 270.59874 | L10: 271.34074 | M10: =+K10-E10 -> 0.1938138 | N10: =+L10-F10 -> 1.6238138 | O10: -11.394652 | P10: 266.67475 | Q10: 5.6419947 | R10: 269.55108 | S10: 267.78253 | T10: =K10-S10 -> 2.8162101 | U10: =L10-P10 -> 4.6659925 | V10: =L10-R10 -> 1.789664 | W10: =VLOOKUP(B10,[1]CivilReport!$A$2:$E$342,5,FALSE)-H10 -> -0.0007827
A11: =G11 -> 91382.633 | B11: 282380 | C11: 3369380.3 | D11: 659025.75 | E11: 270.38673 | F11: =E11-0.688 -> 269.69873 | G11: 91382.633 | H11: -10.544742 | I11: 3369371.6 | J11: 659019.7 | K11: 270.61681 | L11: 271.35881 | M11: =+K11-E11 -> 0.2300742 | N11: =+L11-F11 -> 1.6600742 | O11: -11.705894 | P11: 266.53719 | Q11: 5.5997239 | R11: 269.59028 | S11: 267.19837 | T11: =K11-S11 -> 3.418431 | U11: =L11-P11 -> 4.8216134 | V11: =L11-R11 -> 1.7685286 | W11: =VLOOKUP(B11,[1]CivilReport!$A$2:$E$342,5,FALSE)-H11 -> -0.0032585
A12: =G12 -> 91402.644 | B12: 282400 | C12: 3369391.8 | D12: 659009.38 | E12: 270.38488 | F12: =E12-0.688 -> 269.69688 | G12: 91402.644 | H12: -10.505868 | I12: 3369383.2 | J12: 659003.34 | K12: 270.63488 | L12: 271.37688 | M12: =+K12-E12 -> 0.249996 | N12: =+L12-F12 -> 1.679996 | O12: -11.752896 | P12: 266.53176 | Q12: 5.6959659 | R12: 269.56023 | S12: 267.87886 | T12: =K12-S12 -> 2.7560159 | U12: =L12-P12 -> 4.8451147 | V12: =L12-R12 -> 1.8166496 | W12: =VLOOKUP(B12,[1]CivilReport!$A$2:$E$342,5,FALSE)-H12 -> -0.0001319
A13: =G13 -> 91422.675 | B13: 282420 | C13: 3369403.3 | D13: 658993.02 | E13: 270.38683 | F13: =E13-0.688 -> 269.69883 | G13: 91422.675 | H13: -10.478938 | I13: 3369394.7 | J13: 658986.97 | K13: 270.65297 | L13: 271.39497 | M13: =+K13-E13 -> 0.2661378 | N13: =+L13-F13 -> 1.6961378 | O13: -11.219836 | P13: 266.81638 | Q13: 5.5375119 | R13: 269.65755 | S13: 267.99195 | T13: =K13-S13 -> 2.6610218 | U13: =L13-P13 -> 4.5785848 | V13: =L13-R13 -> 1.7374226 | W13: =VLOOKUP(B13,[1]CivilReport!$A$2:$E$342,5,FALSE)-H13 -> -6.15e-05
A14: =G14 -> 91442.675 | B14: 282440 | C14: 3369414.8 | D14: 658976.69 | E14: 270.35411 | F14: =E14-0.688 -> 269.66611 | G14: 91442.675 | H14: -10.504801 | I14: 3369406.2 | J14: 658970.62 | K14: 270.67103 | L14: 271.41303 | M14: =+K14-E14 -> 0.3169195 | N14: =+L14-F14 -> 1.7469195 | O14: -11.149146 | P14: 266.86979 | Q14: 5.4948463 | R14: 269.69694 | S14: 268.22453 | T14: =K14-S14 -> 2.4465052 | U14: =L14-P14 -> 4.5432398 | V14: =L14-R14 -> 1.7160898 | W14: =VLOOKUP(B14,[1]CivilReport!$A$2:$E$342,5,FALSE)-H14 -> -0.0001992
A15: =G15 -> 91462.672 | B15: 282460 | C15: 3369426.3 | D15: 658960.35 | E15: 270.33011 | F15: =E15-0.688 -> 269.64211 | G15: 91462.672 | H15: -10.528038 | I15: 3369417.7 | J15: 658954.28 | K15: 270.68909 | L15: 271.43109 | M15: =+K15-E15 -> 0.3589849 | N15: =+L15-F15 -> 1.7889849 | O15: -11.071306 | P15: 266.92677 | Q15: 5.6026388 | R15: 269.66111 | S15: 268.41494 | T15: =K15-S15 -> 2.2741542 | U15: =L15-P15 -> 4.5043197 | V15: =L15-R15 -> 1.769986 | W15: =VLOOKUP(B15,[1]CivilReport!$A$2:$E$342,5,FALSE)-H15 -> 3.85e-05
A16: =G16 -> 91482.672 | B16: 282480 | C16: 3369437.9 | D16: 658944.02 | E16: 270.31359 | F16: =E16-0.688 -> 269.62559 | G16: 91482.672 | H16: -10.549026 | I16: 3369429.3 | J16: 658937.93 | K16: 270.70715 | L16: 271.44915 | M16: =+K16-E16 -> 0.3935616 | N16: =+L16-F16 -> 1.8235616 | O16: -10.187242 | P16: 267.38687 | Q16: 5.8980291 | R16: 269.53147 | S16: 268.62011 | T16: =K16-S16 -> 2.0870444 | U16: =L16-P16 -> 4.0622875 | V16: =L16-R16 -> 1.9176813 | W16: =VLOOKUP(B16,[1]CivilReport!$A$2:$E$342,5,FALSE)-H16 -> -0.0009744
... A344: =G344 -> 98042.94 | B344: 289037.93 | C344: 3373269.6 | D344: 653624.59 | E344: 268.81053 | F344: =E344-0.688 -> 268.12253 | G344: 98042.94 | H344: -14.236 | I344: 3373258.4 | J344: 653615.88 | K344: 268.119 | L344: 268.861 | M344: =+K344-E344 -> -0.6915254 | N344: =+L344-F344 -> 0.7384746 | O344: -7.7438376 | P344: 265.87796 | Q344: 4.1278887 | R344: 267.68594 | S344: 266.41471 | T344: =K344-S344 -> 1.7042869 | U344: =L344-P344 -> 2.9830392 | V344: =L344-R344 -> 1.1750647 | W344: =VLOOKUP(B344,[1]CivilReport!$A$2:$E$342,5,FALSE)-H344 -> 0
A346: =G346 -> 289037.6 | B346: 289037.93 | C346: 3373269.8 | D346: 653624.34 | E346: 268.811 | F346: =E346-0.688 -> 268.123 | G346: 289037.6 | H346: 14.236 | I346: 653615.88 | J346: 3373258.4 | K346: 268.119 | L346: =K346+0.638 -> 268.757 | M346: =ROUND((L346-E346),3) -> -0.054 | N346: =ROUND((K346-F346),3) -> -0.004 | P346: 265.875 | S346: 266.415 | T346: =ROUND(K346-S346,3) -> 1.704
A347: =G347 -> 289039.7 | B347: 289040 | C347: 3373271.1 | D347: 653622.6 | E347: 268.817 | F347: =E347-0.688 -> 268.129 | G347: 289039.7 | H347: 14.191 | I347: 653613.26 | J347: 3373260.4 | K347: 268.12 | L347: =K347+0.638 -> 268.758 | M347: =ROUND((L347-E347),3) -> -0.059 | N347: =ROUND((K347-F347),3) -> -0.009 | P347: 265.967 | S347: 266.472 | T347: =ROUND(K347-S347,3) -> 1.648
A348: =G348 -> 289059.7 | B348: 289060 | C348: 3373283 | D348: 653606.5 | E348: 268.861 | F348: =E348-0.688 -> 268.173 | G348: 289059.7 | H348: 13.763 | I348: 653597.43 | J348: 3373272.6 | K348: 268.127 | L348: =K348+0.638 -> 268.765 | M348: =ROUND((L348-E348),3) -> -0.096 | N348: =ROUND((K348-F348),3) -> -0.046 | P348: 266.742 | S348: 266.942 | T348: =ROUND(K348-S348,3) -> 1.185
A349: =G349 -> 289079.7 | B349: 289080 | C349: 3373294.9 | D349: 653590.43 | E349: 268.853 | F349: =E349-0.688 -> 268.165 | G349: 289079.7 | H349: 13.379 | I349: 653581.6 | J349: 3373284.8 | K349: 268.133 | L349: =K349+0.638 -> 268.771 | M349: =ROUND((L349-E349),3) -> -0.082 | N349: =ROUND((K349-F349),3) -> -0.032 | P349: 266.688 | S349: 267.542 | T349: =ROUND(K349-S349,3) -> 0.591
A350: =G350 -> 289100 | B350: 289100 | C350: 3373306.9 | D350: 653574.47 | E350: 268.84 | F350: =E350-0.688 -> 268.152 | G350: 289100 | H350: 13.151 | I350: 653565.77 | J350: 3373297 | K350: 268.14 | L350: =K350+0.638 -> 268.778 | M350: =ROUND((L350-E350),3) -> -0.062 | N350: =ROUND((K350-F350),3) -> -0.012 | P350: 266.04 | S350: 267.14 | T350: =ROUND(K350-S350,3) -> 1
A351: =G351 -> 289120 | B351: 289120 | C351: 3373319.1 | D351: 653558.6 | E351: 268.822 | F351: =E351-0.688 -> 268.134 | G351: 289120 | H351: 13.095 | I351: 653549.94 | J351: 3373309.3 | K351: 268.147 | L351: =K351+0.638 -> 268.785 | M351: =ROUND((L351-E351),3) -> -0.037 | N351: =ROUND((K351-F351),3) -> 0.013 | P351: 266.21 | S351: 267.269 | T351: =ROUND(K351-S351,3) -> 0.878
A352: =G352 -> 289140 | B352: 289140 | C352: 3373331.3 | D352: 653542.73 | E352: 268.803 | F352: =E352-0.688 -> 268.115 | G352: 289140 | H352: 13.038 | I352: 653534.11 | J352: 3373321.5 | K352: 268.154 | L352: =K352+0.638 -> 268.792 | M352: =ROUND((L352-E352),3) -> -0.011 | N352: =ROUND((K352-F352),3) -> 0.039 | P352: 267.071 | S352: 267.554 | T352: =ROUND(K352-S352,3) -> 0.6
A353: =G353 -> 289160 | B353: 289160 | C353: 3373343.5 | D353: 653526.91 | E353: 268.796 | F353: =E353-0.688 -> 268.108 | G353: 289160 | H353: 13.042 | I353: 653518.27 | J353: 3373333.7 | K353: 268.161 | L353: =K353+0.638 -> 268.799 | M353: =ROUND((L353-E353),3) -> 0.003 | N353: =ROUND((K353-F353),3) -> 0.053 | P353: 266.748 | S353: 267.541 | T353: =ROUND(K353-S353,3) -> 0.62
A354: =G354 -> 289180 | B354: 289180 | C354: 3373355.8 | D354: 653511.11 | E354: 268.799 | F354: =E354-0.688 -> 268.111 | G354: 289180 | H354: 13.108 | I354: 653502.44 | J354: 3373345.9 | K354: 268.168 | L354: =K354+0.638 -> 268.806 | M354: =ROUND((L354-E354),3) -> 0.007 | N354: =ROUND((K354-F354),3) -> 0.057 | P354: 267.256 | S354: 268.106 | T354: =ROUND(K354-S354,3) -> 0.062
A355: =G355 -> 289200 | B355: 289200 | C355: 3373368.1 | D355: 653495.31 | E355: 268.843 | F355: =E355-0.688 -> 268.155 | G355: 289200 | H355: 13.162 | I355: 653486.61 | J355: 3373358.1 | K355: 268.175 | L355: =K355+0.638 -> 268.813 | M355: =ROUND((L355-E355),3) -> -0.03 | N355: =ROUND((K355-F355),3) -> 0.02 | P355: 266.861 | S355: 268.004 | T355: =ROUND(K355-S355,3) -> 0.171
A356: =G356 -> 289220 | B356: 289220 | C356: 3373380.3 | D356: 653479.5 | E356: 268.897 | F356: =E356-0.688 -> 268.209 | G356: 289220 | H356: 13.189 | I356: 653470.78 | J356: 3373370.4 | K356: 268.181 | L356: =K356+0.638 -> 268.819 | M356: =ROUND((L356-E356),3) -> -0.078 | N356: =ROUND((K356-F356),3) -> -0.028 | P356: 266.993 | S356: 268.283 | T356: =ROUND(K356-S356,3) -> -0.102
A357: =G357 -> 289240 | B357: 289240 | C357: 3373392.5 | D357: 653463.65 | E357: 268.959 | F357: =E357-0.688 -> 268.271 | G357: 289240 | H357: 13.202 | I357: 653454.92 | J357: 3373382.6 | K357: 268.188 | L357: =K357+0.638 -> 268.826 | M357: =ROUND((L357-E357),3) -> -0.133 | N357: =ROUND((K357-F357),3) -> -0.083 | P357: 266.57 | S357: 268.169 | T357: =ROUND(K357-S357,3) -> 0.019
... A370: =G370 -> 289499.8 | B370: 289500 | C370: 3373547.5 | D370: 653254.95 | E370: 269.041 | F370: =E370-0.688 -> 268.353 | G370: 289499.8 | H370: 19.483 | I370: 653242.52 | J370: 3373532.5 | K370: 268.277 | L370: =K370+0.638 -> 268.915 | M370: =ROUND((L370-E370),3) -> -0.126 | N370: =ROUND((K370-F370),3) -> -0.076 | P370: 268.674 | S370: 268.717 | T370: =ROUND(K370-S370,3) -> -0.44
A371: =G371 -> 289499.8 | B371: 289500 | C371: 3373547.5 | D371: 653254.95 | E371: 269.041 | F371: =E371-0.688 -> 268.353 | G371: 289499.8 | H371: 19.478 | I371: 653243.27 | J371: 3373531.9 | K371: 268.277 | L371: =K371+0.638+0.029 -> 268.944 | M371: =ROUND((L371-E371),3) -> -0.097 | N371: =ROUND((K371-F371),3) -> -0.076 | P371: 268.674 | S371: 268.717 | T371: =ROUND(K371-S371,3) -> -0.44
A372: =G372 -> 289519.8 | B372: 289520 | C372: 3373559.4 | D372: 653238.84 | E372: 268.973 | F372: =E372-0.688 -> 268.285 | G372: 289519.8 | H372: 20.049 | I372: 653226.84 | J372: 3373543.3 | K372: 268.284 | L372: =K372+0.638+0.029 -> 268.951 | M372: =ROUND((L372-E372),3) -> -0.022 | N372: =ROUND((K372-F372),3) -> -0.001 | P372: 268.528 | S372: 268.586 | T372: =ROUND(K372-S372,3) -> -0.302
A373: =G373 -> 289539.8 | B373: 289540 | C373: 3373571.3 | D373: 653222.75 | E373: 268.92 | F373: =E373-0.688 -> 268.232 | G373: 289539.8 | H373: 20.62 | I373: 653210.41 | J373: 3373554.7 | K373: 268.291 | L373: =K373+0.638+0.029 -> 268.958 | M373: =ROUND((L373-E373),3) -> 0.038 | N373: =ROUND((K373-F373),3) -> 0.059 | P373: 268.651 | S373: 268.405 | T373: =ROUND(K373-S373,3) -> -0.114
A374: =G374 -> 289559.8 | B374: 289560 | C374: 3373583.2 | D374: 653206.67 | E374: 268.895 | F374: =E374-0.688 -> 268.207 | G374: 289559.8 | H374: 21.204 | I374: 653194 | J374: 3373566.2 | K374: 268.298 | L374: =K374+0.638+0.029 -> 268.965 | M374: =ROUND((L374-E374),3) -> 0.07 | N374: =ROUND((K374-F374),3) -> 0.091 | P374: 268.779 | S374: 268.454 | T374: =ROUND(K374-S374,3) -> -0.156
A375: =G375 -> 289579.8 | B375: 289580 | C375: 3373595.1 | D375: 653190.6 | E375: 268.895 | F375: =E375-0.688 -> 268.207 | G375: 289579.8 | H375: 21.77 | I375: 653177.59 | J375: 3373577.6 | K375: 268.305 | L375: =K375+0.638+0.029 -> 268.972 | M375: =ROUND((L375-E375),3) -> 0.077 | N375: =ROUND((K375-F375),3) -> 0.098 | P375: 268.701 | S375: 268.644 | T375: =ROUND(K375-S375,3) -> -0.339
A376: =G376 -> 289599.9 | B376: 289600 | C376: 3373607 | D376: 653174.52 | E376: 268.896 | F376: =E376-0.688 -> 268.208 | G376: 289599.9 | H376: 22.333 | I376: 653161.19 | J376: 3373589 | K376: 268.311 | L376: =K376+0.638+0.029 -> 268.978 | M376: =ROUND((L376-E376),3) -> 0.082 | N376: =ROUND((K376-F376),3) -> 0.103 | P376: 268.622 | S376: 268.655 | T376: =ROUND(K376-S376,3) -> -0.344
A377: =G377 -> 289619.9 | B377: 289620 | C377: 3373618.9 | D377: 653158.44 | E377: 268.874 | F377: =E377-0.688 -> 268.186 | G377: 289619.9 | H377: 22.897 | I377: 653144.79 | J377: 3373600.5 | K377: 268.329 | L377: =K377+0.638+0.029 -> 268.996 | M377: =ROUND((L377-E377),3) -> 0.122 | N377: =ROUND((K377-F377),3) -> 0.143 | P377: 268.766 | S377: 268.844 | T377: =ROUND(K377-S377,3) -> -0.515
A378: =G378 -> 289639.8 | B378: 289640 | C378: 3373630.7 | D378: 653142.32 | E378: 268.892 | F378: =E378-0.688 -> 268.204 | G378: 289639.8 | H378: 23.387 | I378: 653128.38 | J378: 3373611.9 | K378: 268.358 | L378: =K378+0.638+0.029 -> 269.025 | M378: =ROUND((L378-E378),3) -> 0.133 | N378: =ROUND((K378-F378),3) -> 0.154 | P378: 268.891 | S378: 268.91 | T378: =ROUND(K378-S378,3) -> -0.552
A379: =G379 -> 289659.8 | B379: 289660 | C379: 3373642.5 | D379: 653126.19 | E379: 268.925 | F379: =E379-0.688 -> 268.237 | G379: 289659.8 | H379: 23.854 | I379: 653111.96 | J379: 3373623.3 | K379: 268.387 | L379: =K379+0.638+0.029 -> 269.054 | M379: =ROUND((L379-E379),3) -> 0.129 | N379: =ROUND((K379-F379),3) -> 0.15 | P379: 268.996 | S379: 268.915 | T379: =ROUND(K379-S379,3) -> -0.528
A380: =G380 -> 289679.8 | B380: 289680 | C380: 3373654.4 | D380: 653110.09 | E380: 268.945 | F380: =E380-0.688 -> 268.257 | G380: 289679.8 | H380: 24.375 | I380: 653095.49 | J380: 3373634.7 | K380: 268.416 | L380: =K380+0.638+0.029 -> 269.083 | M380: =ROUND((L380-E380),3) -> 0.138 | N380: =ROUND((K380-F380),3) -> 0.159 | P380: 269.006 | S380: 268.995 | T380: =ROUND(K380-S380,3) -> -0.579
...

Sheet Correlation sheet
A1: DFCC LINK LINE NEW SHAMBHU TO RAJPURA | J1: PVI | K1: Revised Elevation With Respect to (New TBM) | M1: Difference- (Between Old PFL & REV PFL
A2: IR KM POST | B2: IR KM | C2: DFCC KM | D2: EASTING | E2: NORTHING | F2: PFL | G2: PRL | H2: REVISED CONTINIOUS DFCC CHAINAGE | I2: REMARK | K2: (PFL) | L2: (RL)
C3: =(H4-H3)-C4 -> -91062.452 | H3: =H24-547.3 -> 1171467.1 | J3: 1577.233 | K3: 270.257 | L3: =K3+0.713 -> 270.97
B4: 282253.33 | C4: 91255.985 | D4: 659123.21 | E4: 3369298.7 | F4: 270.54029 | G4: =F4+0.742 -> 271.28229 | H4: =(C4-C5)+H5 -> 1171660.6 | I4: Start of Link Line | K4: =K3+(1/$J$3)*(H4-H3) -> 270.3797 | L4: =K4+0.713 -> 271.0927 | M4: =(F4-K4) -> 0.16058197
B5: 282260 | C5: 91262.659 | D5: 659117.75 | E5: 3369302.5 | F5: 270.54169 | G5: =F5+0.742 -> 271.28369 | H5: =(C5-C6)+H6 -> 1171667.3 | K5: =K4+(1/$J$3)*(H5-H4) -> 270.38394 | L5: =K5+0.713 -> 271.09694 | M5: =(F5-K5) -> 0.15775651
B6: 282280 | C6: 91282.663 | D6: 659101.4 | E6: 3369314 | F6: 270.54591 | G6: =F6+0.742 -> 271.28791 | H6: =(C6-C7)+H7 -> 1171687.3 | K6: =K5+(1/$J$3)*(H6-H5) -> 270.39662 | L6: =K6+0.713 -> 271.10962 | M6: =(F6-K6) -> 0.14928744
B7: 282300 | C7: 91302.662 | D7: 659085.06 | E7: 3369325.6 | F7: 270.55019 | G7: =F7+0.742 -> 271.29219 | H7: =(C7-C8)+H8 -> 1171707.3 | K7: =K6+(1/$J$3)*(H7-H6) -> 270.4093 | L7: =K7+0.713 -> 271.1223 | M7: =(F7-K7) -> 0.14088984
B8: 282320 | C8: 91322.662 | D8: 659068.71 | E8: 3369337.1 | F8: 270.56264 | G8: =F8+0.742 -> 271.30464 | H8: =(C8-C9)+H9 -> 1171727.3 | K8: =K7+(1/$J$3)*(H8-H7) -> 270.42198 | L8: =K8+0.713 -> 271.13498 | M8: =(F8-K8) -> 0.1406655
B9: 282340 | C9: 91342.675 | D9: 659052.35 | E9: 3369348.6 | F9: 270.58072 | G9: =F9+0.742 -> 271.32272 | H9: =(C9-C10)+H10 -> 1171747.3 | K9: =K8+(1/$J$3)*(H9-H8) -> 270.43467 | L9: =K9+0.713 -> 271.14767 | M9: =(F9-K9) -> 0.14605123
B10: 282360 | C10: 91362.633 | D10: 659036.04 | E10: 3369360.1 | F10: 270.59874 | G10: =F10+0.742 -> 271.34074 | H10: =(C10-C11)+H11 -> 1171767.3 | K10: =K9+(1/$J$3)*(H10-H9) -> 270.44732 | L10: =K10+0.713 -> 271.16032 | M10: =(F10-K10) -> 0.15142212
B11: 282380 | C11: 91382.633 | D11: 659019.7 | E11: 3369371.6 | F11: 270.61681 | G11: =F11+0.742 -> 271.35881 | H11: =(C11-C12)+H12 -> 1171787.3 | K11: =K10+(1/$J$3)*(H11-H10) -> 270.46 | L11: =K11+0.713 -> 271.173 | M11: =(F11-K11) -> 0.15680429
B12: 282400 | C12: 91402.644 | D12: 659003.34 | E12: 3369383.2 | F12: 270.63488 | G12: =F12+0.742 -> 271.37688 | H12: =(C12-C13)+H13 -> 1171807.3 | K12: =K11+(1/$J$3)*(H12-H11) -> 270.47269 | L12: =K12+0.713 -> 271.18569 | M12: =(F12-K12) -> 0.16218888
B13: 282420 | C13: 91422.675 | D13: 658986.97 | E13: 3369394.7 | F13: 270.65297 | G13: =F13+0.742 -> 271.39497 | H13: =(C13-C14)+H14 -> 1171827.3 | K13: =K12+(1/$J$3)*(H13-H12) -> 270.48539 | L13: =K13+0.713 -> 271.19839 | M13: =(F13-K13) -> 0.16757899
B14: 282440 | C14: 91442.675 | D14: 658970.62 | E14: 3369406.2 | F14: 270.67103 | G14: =F14+0.742 -> 271.41303 | H14: =(C14-C15)+H15 -> 1171847.3 | K14: =K13+(1/$J$3)*(H14-H13) -> 270.49807 | L14: =K14+0.713 -> 271.21107 | M14: =(F14-K14) -> 0.17296115
B15: 282460 | C15: 91462.672 | D15: 658954.28 | E15: 3369417.7 | F15: 270.68909 | G15: =F15+0.742 -> 271.43109 | H15: =(C15-C16)+H16 -> 1171867.3 | K15: =K14+(1/$J$3)*(H15-H14) -> 270.51075 | L15: =K15+0.713 -> 271.22375 | M15: =(F15-K15) -> 0.17834282
B16: 282480 | C16: 91482.672 | D16: 658937.93 | E16: 3369429.3 | F16: 270.70715 | G16: =F16+0.742 -> 271.44915 | H16: =(C16-C17)+H17 -> 1171887.3 | K16: =K15+(1/$J$3)*(H16-H15) -> 270.52343 | L16: =K16+0.713 -> 271.23643 | M16: =(F16-K16) -> 0.18372499
... B20: 282560 | C20: 91562.67 | D20: 658872.55 | E20: 3369475.4 | F20: 270.7794 | G20: =F20+0.742 -> 271.5214 | H20: =(C20-C21)+H21 -> 1171967.3 | K20: =K19+(1/$J$3)*(H20-H19) -> 270.57415 | L20: =K20+0.713 -> 271.28715 | M20: =(F20-K20) -> 0.20525292
B21: 282573.01 | C21: 91575.679 | D21: 658861.91 | E21: 3369482.9 | F21: 270.79 | G21: =F21+0.742 -> 271.532 | H21: 1171980.3 | K21: =K20+(1/$J$3)*(H21-H20) -> 270.5824 | L21: =K21+0.713 -> 271.2954 | M21: =(F21-K21) -> 0.20760293
B22: 282580 | C22: 91582.67 | D22: 658856.2 | E22: 3369486.9 | F22: 270.79746 | G22: =F22+0.742 -> 271.53946 | H22: 1171987.3 | I22: =(C22-C21)+H21 -> 1171987.3 | K22: =K21+(1/$J$3)*(H22-H21) -> 270.58683 | L22: =K22+0.713 -> 271.29983 | M22: =(F22-K22) -> 0.21063498
B23: 282600 | C23: 91602.586 | D23: 658839.92 | E23: 3369498.4 | F23: 270.81545 | G23: =F23+0.742 -> 271.55745 | H23: 1172007.2 | K23: =K22+(1/$J$3)*(H23-H22) -> 270.59946 | L23: =K23+0.713 -> 271.31246 | M23: =(F23-K23) -> 0.21599421
C24: 0 | G24: =F24+0.742 -> 0.742 | H24: 1172014.4 | J24: 1182.493 | K24: 270.604 | L24: =K24+0.713 -> 271.317
B25: 282620 | C25: 91622.686 | D25: 658823.49 | E25: 3369509.9 | F25: 270.8336 | G25: =F25+0.742 -> 271.5756 | H25: 1172027.3 | K25: =K24+(1/$J$24)*(H25-H24) -> 270.61494 | L25: =K25+0.713 -> 271.32794 | M25: =(F25-K25) -> 0.21866539
B26: 282640 | C26: 91642.686 | D26: 658807.15 | E26: 3369521.5 | F26: 270.85167 | G26: =F26+0.742 -> 271.59367 | H26: 1172047.3 | K26: =K25+(1/$J$24)*(H26-H25) -> 270.63185 | L26: =K26+0.713 -> 271.34485 | M26: =(F26-K26) -> 0.21981457
B27: 282660 | C27: 91662.663 | D27: 658790.82 | E27: 3369533 | F27: 270.86971 | G27: =F27+0.742 -> 271.61171 | H27: 1172067.3 | K27: =K26+(1/$J$24)*(H27-H26) -> 270.64875 | L27: =K27+0.713 -> 271.36175 | M27: =(F27-K27) -> 0.2209628
B28: 282680 | C28: 91682.663 | D28: 658774.47 | E28: 3369544.5 | F28: 270.88777 | G28: =F28+0.742 -> 271.62977 | H28: 1172087.3 | K28: =K27+(1/$J$24)*(H28-H27) -> 270.66566 | L28: =K28+0.713 -> 271.37866 | M28: =(F28-K28) -> 0.22211198
B29: 282700 | C29: 91702.67 | D29: 658758.12 | E29: 3369556 | F29: 270.90584 | G29: =F29+0.742 -> 271.64784 | H29: 1172107.3 | K29: =K28+(1/$J$24)*(H29-H28) -> 270.68258 | L29: =K29+0.713 -> 271.39558 | M29: =(F29-K29) -> 0.22326154
B30: 282720 | C30: 91722.67 | D30: 658741.77 | E30: 3369567.5 | F30: 270.9239 | G30: =F30+0.742 -> 271.6659 | H30: 1172127.3 | K30: =K29+(1/$J$24)*(H30-H29) -> 270.69949 | L30: =K30+0.713 -> 271.41249 | M30: =(F30-K30) -> 0.22441063
B31: 282740 | C31: 91742.655 | D31: 658725.44 | E31: 3369579.1 | F31: 270.94195 | G31: =F31+0.742 -> 271.68395 | H31: 1172147.3 | K31: =K30+(1/$J$24)*(H31-H30) -> 270.71639 | L31: =K31+0.713 -> 271.42939 | M31: =(F31-K31) -> 0.22555909
B32: 282760 | C32: 91762.655 | D32: 658709.09 | E32: 3369590.6 | F32: 270.96001 | G32: =F32+0.742 -> 271.70201 | H32: 1172167.3 | K32: =K31+(1/$J$24)*(H32-H31) -> 270.73331 | L32: =K32+0.713 -> 271.44631 | M32: =(F32-K32) -> 0.22670817
B33: 282780 | C33: 91782.668 | D33: 658692.73 | E33: 3369602.1 | F33: 270.97809 | G33: =F33+0.742 -> 271.72009 | H33: 1172187.3 | K33: =K32+(1/$J$24)*(H33-H32) -> 270.75023 | L33: =K33+0.713 -> 271.46323 | M33: =(F33-K33) -> 0.22785766
B34: 282800 | C34: 91802.66 | D34: 658676.39 | E34: 3369613.6 | F34: 270.99614 | G34: =F34+0.742 -> 271.73814 | H34: 1172207.3 | K34: =K33+(1/$J$24)*(H34-H33) -> 270.76714 | L34: =K34+0.713 -> 271.48014 | M34: =(F34-K34) -> 0.2290065
B35: 282820 | C35: 91822.66 | D35: 658660.05 | E35: 3369625.2 | F35: 271.01421 | G35: =F35+0.742 -> 271.75621 | H35: 1172227.3 | K35: =K34+(1/$J$24)*(H35-H34) -> 270.78405 | L35: =K35+0.713 -> 271.49705 | M35: =(F35-K35) -> 0.23015559
B36: 282840 | C36: 91842.664 | D36: 658643.7 | E36: 3369636.7 | F36: 271.03227 | G36: =F36+0.742 -> 271.77427 | H36: 1172247.3 | K36: =K35+(1/$J$24)*(H36-H35) -> 270.80097 | L36: =K36+0.713 -> 271.51397 | M36: =(F36-K36) -> 0.23130478
... B43: 282980 | C43: 91982.666 | D43: 658528.97 | E43: 3369716.9 | F43: 271.05469 | G43: =F43+0.742 -> 271.79669 | H43: 1172387.3 | K43: =K42+(1/$J$24)*(H43-H42) -> 270.91936 | L43: =K43+0.713 -> 271.63236 | M43: =(F43-K43) -> 0.13532499
A44: 283 | B44: 283000 | C44: 92002.667 | D44: 658512.48 | E44: 3369728.2 | F44: 271.05469 | G44: =F44+0.742 -> 271.79669 | H44: 1172407.3 | K44: =K43+(1/$J$24)*(H44-H43) -> 270.93628 | L44: =K44+0.713 -> 271.64928 | M44: =(F44-K44) -> 0.11841072
A45: 283 | B45: 283000 | C45: 92002.667 | D45: 658512.48 | E45: 3369728.2 | F45: 271.05469 | G45: =F45+0.742 -> 271.79669 | H45: 1172407.3 | K45: =K44+(1/$J$24)*(H45-H44) -> 270.93628 | L45: =K45+0.713 -> 271.64928 | M45: =(F45-K45) -> 0.11841072
C46: 0 | G46: =F46+0.742 -> 0.742 | H46: 1172412.9 | J46: 0 | K46: 270.941 | L46: =K46+0.713 -> 271.654
B47: 283020 | C47: 92022.674 | D47: 658495.98 | E47: 3369739.5 | F47: 271.05469 | G47: =F47+0.742 -> 271.79669 | H47: 1172427.3 | K47: =K46+(0/0.00000001)*(H47-H46) -> 270.941 | L47: =K47+0.713 -> 271.654 | M47: =(F47-K47) -> 0.1136875
B48: 283040 | C48: 92042.671 | D48: 658479.48 | E48: 3369750.9 | F48: 271.05469 | G48: =F48+0.742 -> 271.79669 | H48: 1172447.3 | K48: =K47+(0/0.00000001)*(H48-H47) -> 270.941 | L48: =K48+0.713 -> 271.654 | M48: =(F48-K48) -> 0.1136875
B49: 283060 | C49: 92062.673 | D49: 658462.98 | E49: 3369762.2 | F49: 271.05469 | G49: =F49+0.742 -> 271.79669 | H49: 1172467.3 | K49: =K48+(0/0.00000001)*(H49-H48) -> 270.941 | L49: =K49+0.713 -> 271.654 | M49: =(F49-K49) -> 0.1136875
...

Sheet Revised LS
A1: IR KM | B1: DFCC KM | C1: DFCC NEW KM | D1: Difference-(Between Old RL & Revised RL)m. | E1: (ERL) | F1: PRL | G1: PRL-ERL | H1: (EFL) | I1: PFL | J1: (PFL-EFL) | K1: EXG. GL AT TOE OF DFC TRACK (LH) | L1: GL | M1: HEIGHT OF BANKING (+)/ DEPTH OF CUTTING (-) (PFL-GL) | N1: DFC TRACK CENTER (-) LHS (+) RHS FROM IR TRACK | O1: Remarks
A2: 282253.33 | B2: 91255.985 | C2: =VLOOKUP($B2,'Correlation sheet'!$C$4:$M$373,6,FALSE) -> 1171660.6 | D2: =VLOOKUP($B2,'Correlation sheet'!$C$4:$N$373,11,FALSE) -> 0.16058197 | E2: =VLOOKUP($B2,'Old LS-Reports'!$A$4:$V$344,5,FALSE)-D2 -> 270.32676 | F2: =VLOOKUP($B2,'Correlation sheet'!$C$4:$M$373,10,FALSE) -> 271.0927 | G2: =F2-E2 -> 0.7659393 | H2: =VLOOKUP($B2,'Old LS-Reports'!$A$4:$V$344,6,FALSE)-D2 -> 269.63876 | I2: =VLOOKUP($B2,'Correlation sheet'!$C$4:$M$373,9,FALSE) -> 270.3797 | J2: =I2-H2 -> 0.7409393 | K2: =VLOOKUP($B2,'Old LS-Reports'!$A$4:$V$344,16,FALSE)-D2 -> 267.45323 | L2: =VLOOKUP($B2,'Old LS-Reports'!$A$4:$V$344,19,FALSE)-D2 -> 268.17002 | M2: =I2-L2 -> 2.2096828 | N2: =VLOOKUP($B2,'Old LS-Reports'!$A$4:$V$344,8,FALSE) -> -10.564108
A3: 282260 | B3: 91262.659 | C3: =VLOOKUP($B3,'Correlation sheet'!$C$4:$M$373,6,FALSE) -> 1171667.3 | D3: =VLOOKUP($B3,'Correlation sheet'!$C$4:$N$373,11,FALSE) -> 0.15775651 | E3: =VLOOKUP($B3,'Old LS-Reports'!$A$4:$V$344,5,FALSE)-D3 -> 270.32004 | F3: =VLOOKUP($B3,'Correlation sheet'!$C$4:$M$373,10,FALSE) -> 271.09694 | G3: =F3-E3 -> 0.7769004 | H3: =VLOOKUP($B3,'Old LS-Reports'!$A$4:$V$344,6,FALSE)-D3 -> 269.63204 | I3: =VLOOKUP($B3,'Correlation sheet'!$C$4:$M$373,9,FALSE) -> 270.38394 | J3: =I3-H3 -> 0.7519004 | K3: =VLOOKUP($B3,'Old LS-Reports'!$A$4:$V$344,16,FALSE)-D3 -> 267.54368 | L3: =VLOOKUP($B3,'Old LS-Reports'!$A$4:$V$344,19,FALSE)-D3 -> 268.54322 | M3: =I3-L3 -> 1.8407201 | N3: =VLOOKUP($B3,'Old LS-Reports'!$A$4:$V$344,8,FALSE) -> -10.562917
A4: 282280 | B4: 91282.663 | C4: =VLOOKUP($B4,'Correlation sheet'!$C$4:$M$373,6,FALSE) -> 1171687.3 | D4: =VLOOKUP($B4,'Correlation sheet'!$C$4:$N$373,11,FALSE) -> 0.14928744 | E4: =VLOOKUP($B4,'Old LS-Reports'!$A$4:$V$344,5,FALSE)-D4 -> 270.29638 | F4: =VLOOKUP($B4,'Correlation sheet'!$C$4:$M$373,10,FALSE) -> 271.10962 | G4: =F4-E4 -> 0.8132341 | H4: =VLOOKUP($B4,'Old LS-Reports'!$A$4:$V$344,6,FALSE)-D4 -> 269.60838 | I4: =VLOOKUP($B4,'Correlation sheet'!$C$4:$M$373,9,FALSE) -> 270.39662 | J4: =I4-H4 -> 0.7882341 | K4: =VLOOKUP($B4,'Old LS-Reports'!$A$4:$V$344,16,FALSE)-D4 -> 267.38583 | L4: =VLOOKUP($B4,'Old LS-Reports'!$A$4:$V$344,19,FALSE)-D4 -> 268.66936 | M4: =I4-L4 -> 1.7272571 | N4: =VLOOKUP($B4,'Old LS-Reports'!$A$4:$V$344,8,FALSE) -> -10.566157
A5: 282300 | B5: 91302.662 | C5: =VLOOKUP($B5,'Correlation sheet'!$C$4:$M$373,6,FALSE) -> 1171707.3 | D5: =VLOOKUP($B5,'Correlation sheet'!$C$4:$N$373,11,FALSE) -> 0.14088984 | E5: =VLOOKUP($B5,'Old LS-Reports'!$A$4:$V$344,5,FALSE)-D5 -> 270.27473 | F5: =VLOOKUP($B5,'Correlation sheet'!$C$4:$M$373,10,FALSE) -> 271.1223 | G5: =F5-E5 -> 0.8475681 | H5: =VLOOKUP($B5,'Old LS-Reports'!$A$4:$V$344,6,FALSE)-D5 -> 269.58673 | I5: =VLOOKUP($B5,'Correlation sheet'!$C$4:$M$373,9,FALSE) -> 270.4093 | J5: =I5-H5 -> 0.8225681 | K5: =VLOOKUP($B5,'Old LS-Reports'!$A$4:$V$344,16,FALSE)-D5 -> 267.06211 | L5: =VLOOKUP($B5,'Old LS-Reports'!$A$4:$V$344,19,FALSE)-D5 -> 268.47534 | M5: =I5-L5 -> 1.9339559 | N5: =VLOOKUP($B5,'Old LS-Reports'!$A$4:$V$344,8,FALSE) -> -10.569928
A6: 282320 | B6: 91322.662 | C6: =VLOOKUP($B6,'Correlation sheet'!$C$4:$M$373,6,FALSE) -> 1171727.3 | D6: =VLOOKUP($B6,'Correlation sheet'!$C$4:$N$373,11,FALSE) -> 0.1406655 | E6: =VLOOKUP($B6,'Old LS-Reports'!$A$4:$V$344,5,FALSE)-D6 -> 270.26957 | F6: =VLOOKUP($B6,'Correlation sheet'!$C$4:$M$373,10,FALSE) -> 271.13498 | G6: =F6-E6 -> 0.8654056 | H6: =VLOOKUP($B6,'Old LS-Reports'!$A$4:$V$344,6,FALSE)-D6 -> 269.58157 | I6: =VLOOKUP($B6,'Correlation sheet'!$C$4:$M$373,9,FALSE) -> 270.42198 | J6: =I6-H6 -> 0.8404056 | K6: =VLOOKUP($B6,'Old LS-Reports'!$A$4:$V$344,16,FALSE)-D6 -> 266.66256 | L6: =VLOOKUP($B6,'Old LS-Reports'!$A$4:$V$344,19,FALSE)-D6 -> 267.83032 | M6: =I6-L6 -> 2.5916573 | N6: =VLOOKUP($B6,'Old LS-Reports'!$A$4:$V$344,8,FALSE) -> -10.571623
A7: 282340 | B7: 91342.675 | C7: =VLOOKUP($B7,'Correlation sheet'!$C$4:$M$373,6,FALSE) -> 1171747.3 | D7: =VLOOKUP($B7,'Correlation sheet'!$C$4:$N$373,11,FALSE) -> 0.14605123 | E7: =VLOOKUP($B7,'Old LS-Reports'!$A$4:$V$344,5,FALSE)-D7 -> 270.26454 | F7: =VLOOKUP($B7,'Correlation sheet'!$C$4:$M$373,10,FALSE) -> 271.14767 | G7: =F7-E7 -> 0.8831295 | H7: =VLOOKUP($B7,'Old LS-Reports'!$A$4:$V$344,6,FALSE)-D7 -> 269.57654 | I7: =VLOOKUP($B7,'Correlation sheet'!$C$4:$M$373,9,FALSE) -> 270.43467 | J7: =I7-H7 -> 0.8581295 | K7: =VLOOKUP($B7,'Old LS-Reports'!$A$4:$V$344,16,FALSE)-D7 -> 266.80702 | L7: =VLOOKUP($B7,'Old LS-Reports'!$A$4:$V$344,19,FALSE)-D7 -> 268.47194 | M7: =I7-L7 -> 1.9627226 | N7: =VLOOKUP($B7,'Old LS-Reports'!$A$4:$V$344,8,FALSE) -> -10.597033
A8: 282360 | B8: 91362.633 | C8: =VLOOKUP($B8,'Correlation sheet'!$C$4:$M$373,6,FALSE) -> 1171767.3 | D8: =VLOOKUP($B8,'Correlation sheet'!$C$4:$N$373,11,FALSE) -> 0.15142212 | E8: =VLOOKUP($B8,'Old LS-Reports'!$A$4:$V$344,5,FALSE)-D8 -> 270.25351 | F8: =VLOOKUP($B8,'Correlation sheet'!$C$4:$M$373,10,FALSE) -> 271.16032 | G8: =F8-E8 -> 0.9068138 | H8: =VLOOKUP($B8,'Old LS-Reports'!$A$4:$V$344,6,FALSE)-D8 -> 269.56551 | I8: =VLOOKUP($B8,'Correlation sheet'!$C$4:$M$373,9,FALSE) -> 270.44732 | J8: =I8-H8 -> 0.8818138 | K8: =VLOOKUP($B8,'Old LS-Reports'!$A$4:$V$344,16,FALSE)-D8 -> 266.52333 | L8: =VLOOKUP($B8,'Old LS-Reports'!$A$4:$V$344,19,FALSE)-D8 -> 267.63111 | M8: =I8-L8 -> 2.8162101 | N8: =VLOOKUP($B8,'Old LS-Reports'!$A$4:$V$344,8,FALSE) -> -10.597217
A9: 282380 | B9: 91382.633 | C9: =VLOOKUP($B9,'Correlation sheet'!$C$4:$M$373,6,FALSE) -> 1171787.3 | D9: =VLOOKUP($B9,'Correlation sheet'!$C$4:$N$373,11,FALSE) -> 0.15680429 | E9: =VLOOKUP($B9,'Old LS-Reports'!$A$4:$V$344,5,FALSE)-D9 -> 270.22993 | F9: =VLOOKUP($B9,'Correlation sheet'!$C$4:$M$373,10,FALSE) -> 271.173 | G9: =F9-E9 -> 0.9430742 | H9: =VLOOKUP($B9,'Old LS-Reports'!$A$4:$V$344,6,FALSE)-D9 -> 269.54193 | I9: =VLOOKUP($B9,'Correlation sheet'!$C$4:$M$373,9,FALSE) -> 270.46 | J9: =I9-H9 -> 0.9180742 | K9: =VLOOKUP($B9,'Old LS-Reports'!$A$4:$V$344,16,FALSE)-D9 -> 266.38039 | L9: =VLOOKUP($B9,'Old LS-Reports'!$A$4:$V$344,19,FALSE)-D9 -> 267.04157 | M9: =I9-L9 -> 3.418431 | N9: =VLOOKUP($B9,'Old LS-Reports'!$A$4:$V$344,8,FALSE) -> -10.544742
A10: 282400 | B10: 91402.644 | C10: =VLOOKUP($B10,'Correlation sheet'!$C$4:$M$373,6,FALSE) -> 1171807.3 | D10: =VLOOKUP($B10,'Correlation sheet'!$C$4:$N$373,11,FALSE) -> 0.16218888 | E10: =VLOOKUP($B10,'Old LS-Reports'!$A$4:$V$344,5,FALSE)-D10 -> 270.22269 | F10: =VLOOKUP($B10,'Correlation sheet'!$C$4:$M$373,10,FALSE) -> 271.18569 | G10: =F10-E10 -> 0.962996 | H10: =VLOOKUP($B10,'Old LS-Reports'!$A$4:$V$344,6,FALSE)-D10 -> 269.53469 | I10: =VLOOKUP($B10,'Correlation sheet'!$C$4:$M$373,9,FALSE) -> 270.47269 | J10: =I10-H10 -> 0.937996 | K10: =VLOOKUP($B10,'Old LS-Reports'!$A$4:$V$344,16,FALSE)-D10 -> 266.36957 | L10: =VLOOKUP($B10,'Old LS-Reports'!$A$4:$V$344,19,FALSE)-D10 -> 267.71667 | M10: =I10-L10 -> 2.7560159 | N10: =VLOOKUP($B10,'Old LS-Reports'!$A$4:$V$344,8,FALSE) -> -10.505868
A11: 282420 | B11: 91422.675 | C11: =VLOOKUP($B11,'Correlation sheet'!$C$4:$M$373,6,FALSE) -> 1171827.3 | D11: =VLOOKUP($B11,'Correlation sheet'!$C$4:$N$373,11,FALSE) -> 0.16757899 | E11: =VLOOKUP($B11,'Old LS-Reports'!$A$4:$V$344,5,FALSE)-D11 -> 270.21925 | F11: =VLOOKUP($B11,'Correlation sheet'!$C$4:$M$373,10,FALSE) -> 271.19839 | G11: =F11-E11 -> 0.9791378 | H11: =VLOOKUP($B11,'Old LS-Reports'!$A$4:$V$344,6,FALSE)-D11 -> 269.53125 | I11: =VLOOKUP($B11,'Correlation sheet'!$C$4:$M$373,9,FALSE) -> 270.48539 | J11: =I11-H11 -> 0.9541378 | K11: =VLOOKUP($B11,'Old LS-Reports'!$A$4:$V$344,16,FALSE)-D11 -> 266.6488 | L11: =VLOOKUP($B11,'Old LS-Reports'!$A$4:$V$344,19,FALSE)-D11 -> 267.82437 | M11: =I11-L11 -> 2.6610218 | N11: =VLOOKUP($B11,'Old LS-Reports'!$A$4:$V$344,8,FALSE) -> -10.478938
A12: 282440 | B12: 91442.675 | C12: =VLOOKUP($B12,'Correlation sheet'!$C$4:$M$373,6,FALSE) -> 1171847.3 | D12: =VLOOKUP($B12,'Correlation sheet'!$C$4:$N$373,11,FALSE) -> 0.17296115 | E12: =VLOOKUP($B12,'Old LS-Reports'!$A$4:$V$344,5,FALSE)-D12 -> 270.18115 | F12: =VLOOKUP($B12,'Correlation sheet'!$C$4:$M$373,10,FALSE) -> 271.21107 | G12: =F12-E12 -> 1.0299195 | H12: =VLOOKUP($B12,'Old LS-Reports'!$A$4:$V$344,6,FALSE)-D12 -> 269.49315 | I12: =VLOOKUP($B12,'Correlation sheet'!$C$4:$M$373,9,FALSE) -> 270.49807 | J12: =I12-H12 -> 1.0049195 | K12: =VLOOKUP($B12,'Old LS-Reports'!$A$4:$V$344,16,FALSE)-D12 -> 266.69683 | L12: =VLOOKUP($B12,'Old LS-Reports'!$A$4:$V$344,19,FALSE)-D12 -> 268.05156 | M12: =I12-L12 -> 2.4465052 | N12: =VLOOKUP($B12,'Old LS-Reports'!$A$4:$V$344,8,FALSE) -> -10.504801
A13: 282460 | B13: 91462.672 | C13: =VLOOKUP($B13,'Correlation sheet'!$C$4:$M$373,6,FALSE) -> 1171867.3 | D13: =VLOOKUP($B13,'Correlation sheet'!$C$4:$N$373,11,FALSE) -> 0.17834282 | E13: =VLOOKUP($B13,'Old LS-Reports'!$A$4:$V$344,5,FALSE)-D13 -> 270.15176 | F13: =VLOOKUP($B13,'Correlation sheet'!$C$4:$M$373,10,FALSE) -> 271.22375 | G13: =F13-E13 -> 1.0719849 | H13: =VLOOKUP($B13,'Old LS-Reports'!$A$4:$V$344,6,FALSE)-D13 -> 269.46376 | I13: =VLOOKUP($B13,'Correlation sheet'!$C$4:$M$373,9,FALSE) -> 270.51075 | J13: =I13-H13 -> 1.0469849 | K13: =VLOOKUP($B13,'Old LS-Reports'!$A$4:$V$344,16,FALSE)-D13 -> 266.74843 | L13: =VLOOKUP($B13,'Old LS-Reports'!$A$4:$V$344,19,FALSE)-D13 -> 268.23659 | M13: =I13-L13 -> 2.2741542 | N13: =VLOOKUP($B13,'Old LS-Reports'!$A$4:$V$344,8,FALSE) -> -10.528038
... A354: 289037.93 | B354: 98042.94 | C354: =VLOOKUP($B354,'Correlation sheet'!$C$4:$M$373,6,FALSE) -> 1178447.6 | D354: =VLOOKUP($B354,'Correlation sheet'!$C$4:$N$373,11,FALSE) -> 0.072372934 | E354: =VLOOKUP($B354,'Old LS-Reports'!$A$4:$V$344,5,FALSE)-D354 -> 268.73815 | F354: =VLOOKUP($B354,'Correlation sheet'!$C$4:$M$373,10,FALSE) -> 268.75963 | G354: =F354-E354 -> 0.0214746 | H354: =VLOOKUP($B354,'Old LS-Reports'!$A$4:$V$344,6,FALSE)-D354 -> 268.05015 | I354: =VLOOKUP($B354,'Correlation sheet'!$C$4:$M$373,9,FALSE) -> 268.04663 | J354: =I354-H354 -> -0.0035254 | K354: =VLOOKUP($B354,'Old LS-Reports'!$A$4:$V$344,16,FALSE)-D354 -> 265.80559 | L354: =VLOOKUP($B354,'Old LS-Reports'!$A$4:$V$344,19,FALSE)-D354 -> 266.34234 | M354: =I354-L354 -> 1.7042869 | N354: =VLOOKUP($B354,'Old LS-Reports'!$A$4:$V$344,8,FALSE) -> -14.236
A356: 289037.93 | B356: 289037.6 | C356: =VLOOKUP($B356,'Correlation sheet'!$C$370:$M$423,6,FALSE) -> 1178467.6 | D356: =VLOOKUP($B356,'Correlation sheet'!$C$370:$M$423,11,FALSE) -> 0.066508205 | E356: =VLOOKUP(B356,'Old LS-Reports'!A346:V397,5,FALSE)-D356 -> 268.74449 | F356: =VLOOKUP($B356,'Correlation sheet'!$C$370:$M$423,10,FALSE) -> 268.72349 | G356: =ROUND(F356-E356,3) -> -0.021 | H356: =VLOOKUP(B356,'Old LS-Reports'!A346:V397,6,FALSE)-D356 -> 268.05649 | I356: =VLOOKUP($B356,'Correlation sheet'!$C$370:$M$423,9,FALSE) -> 268.05249 | J356: =ROUND(I356-H356,3) -> -0.004 | K356: =VLOOKUP(B356,'Old LS-Reports'!A346:V397,16,FALSE)-D356 -> 265.80849 | L356: =VLOOKUP(B356,'Old LS-Reports'!A346:V397,19,FALSE)-D356 -> 266.34849 | M356: =ROUND(I356-L356,3) -> 1.704 | N356: =VLOOKUP(B356,'Old LS-Reports'!A346:V397,8,FALSE) -> 14.236
A357: 289040 | B357: 289039.7 | C357: =VLOOKUP($B357,'Correlation sheet'!$C$370:$M$423,6,FALSE) -> 1178469.7 | D357: =VLOOKUP($B357,'Correlation sheet'!$C$370:$M$423,11,FALSE) -> 0.066891918 | E357: =VLOOKUP(B357,'Old LS-Reports'!A347:V398,5,FALSE)-D357 -> 268.75011 | F357: =VLOOKUP($B357,'Correlation sheet'!$C$370:$M$423,10,FALSE) -> 268.72411 | G357: =ROUND(F357-E357,3) -> -0.026 | H357: =VLOOKUP(B357,'Old LS-Reports'!A347:V398,6,FALSE)-D357 -> 268.06211 | I357: =VLOOKUP($B357,'Correlation sheet'!$C$370:$M$423,9,FALSE) -> 268.05311 | J357: =ROUND(I357-H357,3) -> -0.009 | K357: =VLOOKUP(B357,'Old LS-Reports'!A347:V398,16,FALSE)-D357 -> 265.90011 | L357: =VLOOKUP(B357,'Old LS-Reports'!A347:V398,19,FALSE)-D357 -> 266.40511 | M357: =ROUND(I357-L357,3) -> 1.648 | N357: =VLOOKUP(B357,'Old LS-Reports'!A347:V398,8,FALSE) -> 14.191
A358: 289060 | B358: 289059.7 | C358: =VLOOKUP($B358,'Correlation sheet'!$C$370:$M$423,6,FALSE) -> 1178489.7 | D358: =VLOOKUP($B358,'Correlation sheet'!$C$370:$M$423,11,FALSE) -> 0.068022514 | E358: =VLOOKUP(B358,'Old LS-Reports'!A348:V399,5,FALSE)-D358 -> 268.79298 | F358: =VLOOKUP($B358,'Correlation sheet'!$C$370:$M$423,10,FALSE) -> 268.72998 | G358: =ROUND(F358-E358,3) -> -0.063 | H358: =VLOOKUP(B358,'Old LS-Reports'!A348:V399,6,FALSE)-D358 -> 268.10498 | I358: =VLOOKUP($B358,'Correlation sheet'!$C$370:$M$423,9,FALSE) -> 268.05898 | J358: =ROUND(I358-H358,3) -> -0.046 | K358: =VLOOKUP(B358,'Old LS-Reports'!A348:V399,16,FALSE)-D358 -> 266.67398 | L358: =VLOOKUP(B358,'Old LS-Reports'!A348:V399,19,FALSE)-D358 -> 266.87398 | M358: =ROUND(I358-L358,3) -> 1.185 | N358: =VLOOKUP(B358,'Old LS-Reports'!A348:V399,8,FALSE) -> 13.763
A359: 289080 | B359: 289079.7 | C359: =VLOOKUP($B359,'Correlation sheet'!$C$370:$M$423,6,FALSE) -> 1178509.7 | D359: =VLOOKUP($B359,'Correlation sheet'!$C$370:$M$423,11,FALSE) -> 0.06815311 | E359: =VLOOKUP(B359,'Old LS-Reports'!A349:V400,5,FALSE)-D359 -> 268.78485 | F359: =VLOOKUP($B359,'Correlation sheet'!$C$370:$M$423,10,FALSE) -> 268.73585 | G359: =ROUND(F359-E359,3) -> -0.049 | H359: =VLOOKUP(B359,'Old LS-Reports'!A349:V400,6,FALSE)-D359 -> 268.09685 | I359: =VLOOKUP($B359,'Correlation sheet'!$C$370:$M$423,9,FALSE) -> 268.06485 | J359: =ROUND(I359-H359,3) -> -0.032 | K359: =VLOOKUP(B359,'Old LS-Reports'!A349:V400,16,FALSE)-D359 -> 266.61985 | L359: =VLOOKUP(B359,'Old LS-Reports'!A349:V400,19,FALSE)-D359 -> 267.47385 | M359: =ROUND(I359-L359,3) -> 0.591 | N359: =VLOOKUP(B359,'Old LS-Reports'!A349:V400,8,FALSE) -> 13.379
A360: 289100 | B360: 289100 | C360: =VLOOKUP($B360,'Correlation sheet'!$C$370:$M$423,6,FALSE) -> 1178530 | D360: =VLOOKUP($B360,'Correlation sheet'!$C$370:$M$423,11,FALSE) -> 0.069195665 | E360: =VLOOKUP(B360,'Old LS-Reports'!A350:V401,5,FALSE)-D360 -> 268.7708 | F360: =VLOOKUP($B360,'Correlation sheet'!$C$370:$M$423,10,FALSE) -> 268.7418 | G360: =ROUND(F360-E360,3) -> -0.029 | H360: =VLOOKUP(B360,'Old LS-Reports'!A350:V401,6,FALSE)-D360 -> 268.0828 | I360: =VLOOKUP($B360,'Correlation sheet'!$C$370:$M$423,9,FALSE) -> 268.0708 | J360: =ROUND(I360-H360,3) -> -0.012 | K360: =VLOOKUP(B360,'Old LS-Reports'!A350:V401,16,FALSE)-D360 -> 265.9708 | L360: =VLOOKUP(B360,'Old LS-Reports'!A350:V401,19,FALSE)-D360 -> 267.0708 | M360: =ROUND(I360-L360,3) -> 1 | N360: =VLOOKUP(B360,'Old LS-Reports'!A350:V401,8,FALSE) -> 13.151
A361: 289120 | B361: 289120 | C361: =VLOOKUP($B361,'Correlation sheet'!$C$370:$M$423,6,FALSE) -> 1178550 | D361: =VLOOKUP($B361,'Correlation sheet'!$C$370:$M$423,11,FALSE) -> 0.070326261 | E361: =VLOOKUP(B361,'Old LS-Reports'!A351:V402,5,FALSE)-D361 -> 268.75167 | F361: =VLOOKUP($B361,'Correlation sheet'!$C$370:$M$423,10,FALSE) -> 268.74767 | G361: =ROUND(F361-E361,3) -> -0.004 | H361: =VLOOKUP(B361,'Old LS-Reports'!A351:V402,6,FALSE)-D361 -> 268.06367 | I361: =VLOOKUP($B361,'Correlation sheet'!$C$370:$M$423,9,FALSE) -> 268.07667 | J361: =ROUND(I361-H361,3) -> 0.013 | K361: =VLOOKUP(B361,'Old LS-Reports'!A351:V402,16,FALSE)-D361 -> 266.13967 | L361: =VLOOKUP(B361,'Old LS-Reports'!A351:V402,19,FALSE)-D361 -> 267.19867 | M361: =ROUND(I361-L361,3) -> 0.878 | N361: =VLOOKUP(B361,'Old LS-Reports'!A351:V402,8,FALSE) -> 13.095
A362: 289140 | B362: 289140 | C362: =VLOOKUP($B362,'Correlation sheet'!$C$370:$M$423,6,FALSE) -> 1178570 | D362: =VLOOKUP($B362,'Correlation sheet'!$C$370:$M$423,11,FALSE) -> 0.071456857 | E362: =VLOOKUP(B362,'Old LS-Reports'!A352:V403,5,FALSE)-D362 -> 268.73154 | F362: =VLOOKUP($B362,'Correlation sheet'!$C$370:$M$423,10,FALSE) -> 268.75354 | G362: =ROUND(F362-E362,3) -> 0.022 | H362: =VLOOKUP(B362,'Old LS-Reports'!A352:V403,6,FALSE)-D362 -> 268.04354 | I362: =VLOOKUP($B362,'Correlation sheet'!$C$370:$M$423,9,FALSE) -> 268.08254 | J362: =ROUND(I362-H362,3) -> 0.039 | K362: =VLOOKUP(B362,'Old LS-Reports'!A352:V403,16,FALSE)-D362 -> 266.99954 | L362: =VLOOKUP(B362,'Old LS-Reports'!A352:V403,19,FALSE)-D362 -> 267.48254 | M362: =ROUND(I362-L362,3) -> 0.6 | N362: =VLOOKUP(B362,'Old LS-Reports'!A352:V403,8,FALSE) -> 13.038
A363: 289160 | B363: 289160 | C363: =VLOOKUP($B363,'Correlation sheet'!$C$370:$M$423,6,FALSE) -> 1178590 | D363: =VLOOKUP($B363,'Correlation sheet'!$C$370:$M$423,11,FALSE) -> 0.072587453 | E363: =VLOOKUP(B363,'Old LS-Reports'!A353:V404,5,FALSE)-D363 -> 268.72341 | F363: =VLOOKUP($B363,'Correlation sheet'!$C$370:$M$423,10,FALSE) -> 268.75941 | G363: =ROUND(F363-E363,3) -> 0.036 | H363: =VLOOKUP(B363,'Old LS-Reports'!A353:V404,6,FALSE)-D363 -> 268.03541 | I363: =VLOOKUP($B363,'Correlation sheet'!$C$370:$M$423,9,FALSE) -> 268.08841 | J363: =ROUND(I363-H363,3) -> 0.053 | K363: =VLOOKUP(B363,'Old LS-Reports'!A353:V404,16,FALSE)-D363 -> 266.67541 | L363: =VLOOKUP(B363,'Old LS-Reports'!A353:V404,19,FALSE)-D363 -> 267.46841 | M363: =ROUND(I363-L363,3) -> 0.62 | N363: =VLOOKUP(B363,'Old LS-Reports'!A353:V404,8,FALSE) -> 13.042
A364: 289180 | B364: 289180 | C364: =VLOOKUP($B364,'Correlation sheet'!$C$370:$M$423,6,FALSE) -> 1178610 | D364: =VLOOKUP($B364,'Correlation sheet'!$C$370:$M$423,11,FALSE) -> 0.073718049 | E364: =VLOOKUP(B364,'Old LS-Reports'!A354:V405,5,FALSE)-D364 -> 268.72528 | F364: =VLOOKUP($B364,'Correlation sheet'!$C$370:$M$423,10,FALSE) -> 268.76528 | G364: =ROUND(F364-E364,3) -> 0.04 | H364: =VLOOKUP(B364,'Old LS-Reports'!A354:V405,6,FALSE)-D364 -> 268.03728 | I364: =VLOOKUP($B364,'Correlation sheet'!$C$370:$M$423,9,FALSE) -> 268.09428 | J364: =ROUND(I364-H364,3) -> 0.057 | K364: =VLOOKUP(B364,'Old LS-Reports'!A354:V405,16,FALSE)-D364 -> 267.18228 | L364: =VLOOKUP(B364,'Old LS-Reports'!A354:V405,19,FALSE)-D364 -> 268.03228 | M364: =ROUND(I364-L364,3) -> 0.062 | N364: =VLOOKUP(B364,'Old LS-Reports'!A354:V405,8,FALSE) -> 13.108
A365: 289200 | B365: 289200 | C365: =VLOOKUP($B365,'Correlation sheet'!$C$370:$M$423,6,FALSE) -> 1178630 | D365: =VLOOKUP($B365,'Correlation sheet'!$C$370:$M$423,11,FALSE) -> 0.074848645 | E365: =VLOOKUP(B365,'Old LS-Reports'!A355:V406,5,FALSE)-D365 -> 268.76815 | F365: =VLOOKUP($B365,'Correlation sheet'!$C$370:$M$423,10,FALSE) -> 268.77115 | G365: =ROUND(F365-E365,3) -> 0.003 | H365: =VLOOKUP(B365,'Old LS-Reports'!A355:V406,6,FALSE)-D365 -> 268.08015 | I365: =VLOOKUP($B365,'Correlation sheet'!$C$370:$M$423,9,FALSE) -> 268.10015 | J365: =ROUND(I365-H365,3) -> 0.02 | K365: =VLOOKUP(B365,'Old LS-Reports'!A355:V406,16,FALSE)-D365 -> 266.78615 | L365: =VLOOKUP(B365,'Old LS-Reports'!A355:V406,19,FALSE)-D365 -> 267.92915 | M365: =ROUND(I365-L365,3) -> 0.171 | N365: =VLOOKUP(B365,'Old LS-Reports'!A355:V406,8,FALSE) -> 13.162
A366: 289220 | B366: 289220 | C366: =VLOOKUP($B366,'Correlation sheet'!$C$370:$M$423,6,FALSE) -> 1178650 | D366: =VLOOKUP($B366,'Correlation sheet'!$C$370:$M$423,11,FALSE) -> 0.074979241 | E366: =VLOOKUP(B366,'Old LS-Reports'!A356:V407,5,FALSE)-D366 -> 268.82202 | F366: =VLOOKUP($B366,'Correlation sheet'!$C$370:$M$423,10,FALSE) -> 268.77702 | G366: =ROUND(F366-E366,3) -> -0.045 | H366: =VLOOKUP(B366,'Old LS-Reports'!A356:V407,6,FALSE)-D366 -> 268.13402 | I366: =VLOOKUP($B366,'Correlation sheet'!$C$370:$M$423,9,FALSE) -> 268.10602 | J366: =ROUND(I366-H366,3) -> -0.028 | K366: =VLOOKUP(B366,'Old LS-Reports'!A356:V407,16,FALSE)-D366 -> 266.91802 | L366: =VLOOKUP(B366,'Old LS-Reports'!A356:V407,19,FALSE)-D366 -> 268.20802 | M366: =ROUND(I366-L366,3) -> -0.102 | N366: =VLOOKUP(B366,'Old LS-Reports'!A356:V407,8,FALSE) -> 13.189
A367: 289240 | B367: 289240 | C367: =VLOOKUP($B367,'Correlation sheet'!$C$370:$M$423,6,FALSE) -> 1178670 | D367: =VLOOKUP($B367,'Correlation sheet'!$C$370:$M$423,11,FALSE) -> 0.076109837 | E367: =VLOOKUP(B367,'Old LS-Reports'!A357:V408,5,FALSE)-D367 -> 268.88289 | F367: =VLOOKUP($B367,'Correlation sheet'!$C$370:$M$423,10,FALSE) -> 268.78289 | G367: =ROUND(F367-E367,3) -> -0.1 | H367: =VLOOKUP(B367,'Old LS-Reports'!A357:V408,6,FALSE)-D367 -> 268.19489 | I367: =VLOOKUP($B367,'Correlation sheet'!$C$370:$M$423,9,FALSE) -> 268.11189 | J367: =ROUND(I367-H367,3) -> -0.083 | K367: =VLOOKUP(B367,'Old LS-Reports'!A357:V408,16,FALSE)-D367 -> 266.49389 | L367: =VLOOKUP(B367,'Old LS-Reports'!A357:V408,19,FALSE)-D367 -> 268.09289 | M367: =ROUND(I367-L367,3) -> 0.019 | N367: =VLOOKUP(B367,'Old LS-Reports'!A357:V408,8,FALSE) -> 13.202
... A407: 290081.7 | B407: 290003.6 | C407: =VLOOKUP($B407,'Correlation sheet'!$C$370:$M$423,6,FALSE) -> 1179433.6 | D407: =VLOOKUP($B407,'Correlation sheet'!$C$370:$M$423,11,FALSE) -> 0.12937046 | E407: =VLOOKUP(B407,'Old LS-Reports'!A397:V448,5,FALSE)-D407 -> 268.81263 | F407: =VLOOKUP($B407,'Correlation sheet'!$C$370:$M$423,10,FALSE) -> 268.79363 | G407: =ROUND(F407-E407,3) -> -0.019 | H407: =VLOOKUP(B407,'Old LS-Reports'!A397:V448,6,FALSE)-D407 -> 268.18263 | I407: =VLOOKUP($B407,'Correlation sheet'!$C$370:$M$423,9,FALSE) -> 268.12263 | J407: =ROUND(I407-H407,3) -> -0.06 | K407: =VLOOKUP(B407,'Old LS-Reports'!A397:V448,16,FALSE)-D407 -> 268.82363 | L407: =VLOOKUP(B407,'Old LS-Reports'!A397:V448,19,FALSE)-D407 -> 268.68063 | M407: =ROUND(I407-L407,3) -> -0.558 | N407: =VLOOKUP(B407,'Old LS-Reports'!A397:V448,8,FALSE) -> 21.46
